Workbook

Sheet icis_resin_reference
A1: source_file | B1: source_sheet | C1: source_range | D1: source_row | E1: source_cell | F1: date_source_cell | G1: date_range | H1: forecast_date | I1: time_period | J1: time_period_year | K1: time_period_month | L1: forecast_series | M1: resin_index_type | N1: resin_index_level | O1: value_source_column | P1: value_source_header_cell | Q1: value | R1: raw_value_text | S1: formula
A2: Index Fprecast\ICIS Dashboard Price Forecast 2026-05-04 152801_v1.xls | B2: ICIS Price History | C2: B13:D46 | D2: 14 | E2: C14 | F2: B14 | G2: Jan-2025 | H2: 2025-01-01 | I2: January 2025 | J2: 2025 | K2: 1 | L2: PET Bottle Grade FOB Asia SE Assessment Spot 2-6 Weeks Full Market Range Weekly (Low) : USD/tonne | M2: ICIS Asia SE Low | N2: Low | O2: C | P2: C13 | Q2: 866 | R2: 866.0 | S2: 866
A3: Index Fprecast\ICIS Dashboard Price Forecast 2026-05-04 152801_v1.xls | B3: ICIS Price History | C3: B13:D46 | D3: 14 | E3: D14 | F3: B14 | G3: Jan-2025 | H3: 2025-01-01 | I3: January 2025 | J3: 2025 | K3: 1 | L3: PET Bottle Grade FOB China Assessment Spot 4-12 Weeks Full Market Range Weekly (Mid) : USD/tonne | M3: ICIS China Mid | N3: Mid | O3: D | P3: D13 | Q3: 799.5 | R3: 799.5 | S3: 799.5
A4: Index Fprecast\ICIS Dashboard Price Forecast 2026-05-04 152801_v1.xls | B4: ICIS Price History | C4: B13:D46 | D4: 15 | E4: C15 | F4: B15 | G4: Feb-2025 | H4: 2025-02-01 | I4: February 2025 | J4: 2025 | K4: 2 | L4: PET Bottle Grade FOB Asia SE Assessment Spot 2-6 Weeks Full Market Range Weekly (Low) : USD/tonne | M4: ICIS Asia SE Low | N4: Low | O4: C | P4: C13 | Q4: 882.5 | R4: 882.5 | S4: 882.5
A5: Index Fprecast\ICIS Dashboard Price Forecast 2026-05-04 152801_v1.xls | B5: ICIS Price History | C5: B13:D46 | D5: 15 | E5: D15 | F5: B15 | G5: Feb-2025 | H5: 2025-02-01 | I5: February 2025 | J5: 2025 | K5: 2 | L5: PET Bottle Grade FOB China Assessment Spot 4-12 Weeks Full Market Range Weekly (Mid) : USD/tonne | M5: ICIS China Mid | N5: Mid | O5: D | P5: D13 | Q5: 803.1 | R5: 803.1 | S5: 803.1
A6: Index Fprecast\ICIS Dashboard Price Forecast 2026-05-04 152801_v1.xls | B6: ICIS Price History | C6: B13:D46 | D6: 16 | E6: C16 | F6: B16 | G6: Mar-2025 | H6: 2025-03-01 | I6: March 2025 | J6: 2025 | K6: 3 | L6: PET Bottle Grade FOB Asia SE Assessment Spot 2-6 Weeks Full Market Range Weekly (Low) : USD/tonne | M6: ICIS Asia SE Low | N6: Low | O6: C | P6: C13 | Q6: 886.3 | R6: 886.3 | S6: 886.3
A7: Index Fprecast\ICIS Dashboard Price Forecast 2026-05-04 152801_v1.xls | B7: ICIS Price History | C7: B13:D46 | D7: 16 | E7: D16 | F7: B16 | G7: Mar-2025 | H7: 2025-03-01 | I7: March 2025 | J7: 2025 | K7: 3 | L7: PET Bottle Grade FOB China Assessment Spot 4-12 Weeks Full Market Range Weekly (Mid) : USD/tonne | M7: ICIS China Mid | N7: Mid | O7: D | P7: D13 | Q7: 786.3 | R7: 786.3 | S7: 786.3
A8: Index Fprecast\ICIS Dashboard Price Forecast 2026-05-04 152801_v1.xls | B8: ICIS Price History | C8: B13:D46 | D8: 17 | E8: C17 | F8: B17 | G8: Apr-2025 | H8: 2025-04-01 | I8: April 2025 | J8: 2025 | K8: 4 | L8: PET Bottle Grade FOB Asia SE Assessment Spot 2-6 Weeks Full Market Range Weekly (Low) : USD/tonne | M8: ICIS Asia SE Low | N8: Low | O8: C | P8: C13 | Q8: 857.5 | R8: 857.5 | S8: 857.5
A9: Index Fprecast\ICIS Dashboard Price Forecast 2026-05-04 152801_v1.xls | B9: ICIS Price History | C9: B13:D46 | D9: 17 | E9: D17 | F9: B17 | G9: Apr-2025 | H9: 2025-04-01 | I9: April 2025 | J9: 2025 | K9: 4 | L9: PET Bottle Grade FOB China Assessment Spot 4-12 Weeks Full Market Range Weekly (Mid) : USD/tonne | M9: ICIS China Mid | N9: Mid | O9: D | P9: D13 | Q9: 745.6 | R9: 745.6 | S9: 745.6
A10: Index Fprecast\ICIS Dashboard Price Forecast 2026-05-04 152801_v1.xls | B10: ICIS Price History | C10: B13:D46 | D10: 18 | E10: C18 | F10: B18 | G10: May-2025 | H10: 2025-05-01 | I10: May 2025 | J10: 2025 | K10: 5 | L10: PET Bottle Grade FOB Asia SE Assessment Spot 2-6 Weeks Full Market Range Weekly (Low) : USD/tonne | M10: ICIS Asia SE Low | N10: Low | O10: C | P10: C13 | Q10: 872 | R10: 872.0 | S10: 872
A11: Index Fprecast\ICIS Dashboard Price Forecast 2026-05-04 152801_v1.xls | B11: ICIS Price History | C11: B13:D46 | D11: 18 | E11: D18 | F11: B18 | G11: May-2025 | H11: 2025-05-01 | I11: May 2025 | J11: 2025 | K11: 5 | L11: PET Bottle Grade FOB China Assessment Spot 4-12 Weeks Full Market Range Weekly (Mid) : USD/tonne | M11: ICIS China Mid | N11: Mid | O11: D | P11: D13 | Q11: 775 | R11: 775.0 | S11: 775
A12: Index Fprecast\ICIS Dashboard Price Forecast 2026-05-04 152801_v1.xls | B12: ICIS Price History | C12: B13:D46 | D12: 19 | E12: C19 | F12: B19 | G12: Jun-2025 | H12: 2025-06-01 | I12: June 2025 | J12: 2025 | K12: 6 | L12: PET Bottle Grade FOB Asia SE Assessment Spot 2-6 Weeks Full Market Range Weekly (Low) : USD/tonne | M12: ICIS Asia SE Low | N12: Low | O12: C | P12: C13 | Q12: 876.3 | R12: 876.3 | S12: 876.3
A13: Index Fprecast\ICIS Dashboard Price Forecast 2026-05-04 152801_v1.xls | B13: ICIS Price History | C13: B13:D46 | D13: 19 | E13: D19 | F13: B19 | G13: Jun-2025 | H13: 2025-06-01 | I13: June 2025 | J13: 2025 | K13: 6 | L13: PET Bottle Grade FOB China Assessment Spot 4-12 Weeks Full Market Range Weekly (Mid) : USD/tonne | M13: ICIS China Mid | N13: Mid | O13: D | P13: D13 | Q13: 793.1 | R13: 793.1 | S13: 793.1
... A33: Index Fprecast\ICIS Dashboard Price Forecast 2026-05-04 152801_v1.xls | B33: ICIS Price History | C33: B13:D46 | D33: 29 | E33: D29 | F33: B29 | G33: Apr-2026 | H33: 2026-04-01 | I33: April 2026 | J33: 2026 | K33: 4 | L33: PET Bottle Grade FOB China Assessment Spot 4-12 Weeks Full Market Range Weekly (Mid) : USD/tonne | M33: ICIS China Mid | N33: Mid | O33: D | P33: D13 | Q33: 1191.9 | R33: 1191.9 | S33: 1191.9
A34: Index Fprecast\ICIS Dashboard Price Forecast 2026-05-04 152801_v1.xls | B34: ICIS Price History | C34: B13:D46 | D34: 30 | E34: C30 | F34: B30 | G34: 01-May-2026 | H34: 2026-05-01 | I34: May 2026 | J34: 2026 | K34: 5 | L34: PET Bottle Grade FOB Asia SE Assessment Spot 2-6 Weeks Full Market Range Weekly (Low) : USD/tonne | M34: ICIS Asia SE Low | N34: Low | O34: C | P34: C13 | Q34: 1344.9874 | R34: 1345 | S34: =(C29*E30)+'ICIS Price History'!C29
A35: Index Fprecast\ICIS Dashboard Price Forecast 2026-05-04 152801_v1.xls | B35: ICIS Price History | C35: B13:D46 | D35: 31 | E35: C31 | F35: B31 | G35: 01-Jun-2026 | H35: 2026-06-01 | I35: June 2026 | J35: 2026 | K35: 6 | L35: PET Bottle Grade FOB Asia SE Assessment Spot 2-6 Weeks Full Market Range Weekly (Low) : USD/tonne | M35: ICIS Asia SE Low | N35: Low | O35: C | P35: C13 | Q35: 1438.2883 | R35: 1438 | S35: =(C30*E31)+'ICIS Price History'!C30
A36: Index Fprecast\ICIS Dashboard Price Forecast 2026-05-04 152801_v1.xls | B36: ICIS Price History | C36: B13:D46 | D36: 32 | E36: C32 | F36: B32 | G36: 01-Jul-2026 | H36: 2026-07-01 | I36: July 2026 | J36: 2026 | K36: 7 | L36: PET Bottle Grade FOB Asia SE Assessment Spot 2-6 Weeks Full Market Range Weekly (Low) : USD/tonne | M36: ICIS Asia SE Low | N36: Low | O36: C | P36: C13 | Q36: 1527.7512 | R36: 1528 | S36: =(C31*E32)+'ICIS Price History'!C31
A37: Index Fprecast\ICIS Dashboard Price Forecast 2026-05-04 152801_v1.xls | B37: ICIS Price History | C37: B13:D46 | D37: 33 | E37: C33 | F37: B33 | G37: 01-Aug-2026 | H37: 2026-08-01 | I37: August 2026 | J37: 2026 | K37: 8 | L37: PET Bottle Grade FOB Asia SE Assessment Spot 2-6 Weeks Full Market Range Weekly (Low) : USD/tonne | M37: ICIS Asia SE Low | N37: Low | O37: C | P37: C13 | Q37: 1644.1813 | R37: 1644 | S37: =(C32*E33)+'ICIS Price History'!C32
A38: Index Fprecast\ICIS Dashboard Price Forecast 2026-05-04 152801_v1.xls | B38: ICIS Price History | C38: B13:D46 | D38: 34 | E38: C34 | F38: B34 | G38: 01-Sep-2026 | H38: 2026-09-01 | I38: September 2026 | J38: 2026 | K38: 9 | L38: PET Bottle Grade FOB Asia SE Assessment Spot 2-6 Weeks Full Market Range Weekly (Low) : USD/tonne | M38: ICIS Asia SE Low | N38: Low | O38: C | P38: C13 | Q38: 1733.4419 | R38: 1733 | S38: =(C33*E34)+'ICIS Price History'!C33
A39: Index Fprecast\ICIS Dashboard Price Forecast 2026-05-04 152801_v1.xls | B39: ICIS Price History | C39: B13:D46 | D39: 35 | E39: C35 | F39: B35 | G39: 01-Oct-2026 | H39: 2026-10-01 | I39: October 2026 | J39: 2026 | K39: 10 | L39: PET Bottle Grade FOB Asia SE Assessment Spot 2-6 Weeks Full Market Range Weekly (Low) : USD/tonne | M39: ICIS Asia SE Low | N39: Low | O39: C | P39: C13 | Q39: 1773.8889 | R39: 1774 | S39: =(C34*E35)+'ICIS Price History'!C34
A40: Index Fprecast\ICIS Dashboard Price Forecast 2026-05-04 152801_v1.xls | B40: ICIS Price History | C40: B13:D46 | D40: 36 | E40: C36 | F40: B36 | G40: 01-Nov-2026 | H40: 2026-11-01 | I40: November 2026 | J40: 2026 | K40: 11 | L40: PET Bottle Grade FOB Asia SE Assessment Spot 2-6 Weeks Full Market Range Weekly (Low) : USD/tonne | M40: ICIS Asia SE Low | N40: Low | O40: C | P40: C13 | Q40: 1824.5714 | R40: 1825 | S40: =(C35*E36)+'ICIS Price History'!C35
A41: Index Fprecast\ICIS Dashboard Price Forecast 2026-05-04 152801_v1.xls | B41: ICIS Price History | C41: B13:D46 | D41: 37 | E41: C37 | F41: B37 | G41: 01-Dec-2026 | H41: 2026-12-01 | I41: December 2026 | J41: 2026 | K41: 12 | L41: PET Bottle Grade FOB Asia SE Assessment Spot 2-6 Weeks Full Market Range Weekly (Low) : USD/tonne | M41: ICIS Asia SE Low | N41: Low | O41: C | P41: C13 | Q41: 1896.0808 | R41: 1896 | S41: =(C36*E37)+'ICIS Price History'!C36
A42: Index Fprecast\ICIS Dashboard Price Forecast 2026-05-04 152801_v1.xls | B42: ICIS Price History | C42: B13:D46 | D42: 38 | E42: C38 | F42: B38 | G42: 01-Jan-2027 | H42: 2027-01-01 | I42: January 2027 | J42: 2027 | K42: 1 | L42: PET Bottle Grade FOB Asia SE Assessment Spot 2-6 Weeks Full Market Range Weekly (Low) : USD/tonne | M42: ICIS Asia SE Low | N42: Low | O42: C | P42: C13 | Q42: 1891.5877 | R42: 1892 | S42: =(C37*E38)+'ICIS Price History'!C37
A43: Index Fprecast\ICIS Dashboard Price Forecast 2026-05-04 152801_v1.xls | B43: ICIS Price History | C43: B13:D46 | D43: 39 | E43: C39 | F43: B39 | G43: 01-Feb-2027 | H43: 2027-02-01 | I43: February 2027 | J43: 2027 | K43: 2 | L43: PET Bottle Grade FOB Asia SE Assessment Spot 2-6 Weeks Full Market Range Weekly (Low) : USD/tonne | M43: ICIS Asia SE Low | N43: Low | O43: C | P43: C13 | Q43: 1887.1158 | R43: 1887 | S43: =(C38*E39)+'ICIS Price History'!C38
A44: Index Fprecast\ICIS Dashboard Price Forecast 2026-05-04 152801_v1.xls | B44: ICIS Price History | C44: B13:D46 | D44: 40 | E44: C40 | F44: B40 | G44: 01-Mar-2027 | H44: 2027-03-01 | I44: March 2027 | J44: 2027 | K44: 3 | L44: PET Bottle Grade FOB Asia SE Assessment Spot 2-6 Weeks Full Market Range Weekly (Low) : USD/tonne | M44: ICIS Asia SE Low | N44: Low | O44: C | P44: C13 | Q44: 1882.6651 | R44: 1883 | S44: =(C39*E40)+'ICIS Price History'!C39
A45: Index Fprecast\ICIS Dashboard Price Forecast 2026-05-04 152801_v1.xls | B45: ICIS Price History | C45: B13:D46 | D45: 41 | E45: C41 | F45: B41 | G45: 01-Apr-2027 | H45: 2027-04-01 | I45: April 2027 | J45: 2027 | K45: 4 | L45: PET Bottle Grade FOB Asia SE Assessment Spot 2-6 Weeks Full Market Range Weekly (Low) : USD/tonne | M45: ICIS Asia SE Low | N45: Low | O45: C | P45: C13 | Q45: 1867.2515 | R45: 1867 | S45: =(C40*E41)+'ICIS Price History'!C40
... A50: Index Fprecast\ICIS Dashboard Price Forecast 2026-05-04 152801_v1.xls | B50: ICIS Price History | C50: B13:D46 | D50: 46 | E50: C46 | F50: B46 | G50: 01-Sep-2027 | H50: 2027-09-01 | I50: September 2027 | J50: 2027 | K50: 9 | L50: PET Bottle Grade FOB Asia SE Assessment Spot 2-6 Weeks Full Market Range Weekly (Low) : USD/tonne | M50: ICIS Asia SE Low | N50: Low | O50: C | P50: C13 | Q50: 1884.8878 | R50: 1885 | S50: =(C45*E46)+'ICIS Price History'!C45

Sheet monthly_wide_reference
A1: time_period | B1: time_period_year | C1: time_period_month | D1: forecast_date | E1: date_range | F1: ICIS Asia SE Low | G1: ICIS China Mid
A2: January 2025 | B2: 2025 | C2: 1 | D2: 2025-01-01 | E2: Jan-2025 | F2: 866 | G2: 799.5
A3: February 2025 | B3: 2025 | C3: 2 | D3: 2025-02-01 | E3: Feb-2025 | F3: 882.5 | G3: 803.1
A4: March 2025 | B4: 2025 | C4: 3 | D4: 2025-03-01 | E4: Mar-2025 | F4: 886.3 | G4: 786.3
A5: April 2025 | B5: 2025 | C5: 4 | D5: 2025-04-01 | E5: Apr-2025 | F5: 857.5 | G5: 745.6
A6: May 2025 | B6: 2025 | C6: 5 | D6: 2025-05-01 | E6: May-2025 | F6: 872 | G6: 775
A7: June 2025 | B7: 2025 | C7: 6 | D7: 2025-06-01 | E7: Jun-2025 | F7: 876.3 | G7: 793.1
A8: July 2025 | B8: 2025 | C8: 7 | D8: 2025-07-01 | E8: Jul-2025 | F8: 861.3 | G8: 781.9
A9: August 2025 | B9: 2025 | C9: 8 | D9: 2025-08-01 | E9: Aug-2025 | F9: 846 | G9: 774
A10: September 2025 | B10: 2025 | C10: 9 | D10: 2025-09-01 | E10: Sep-2025 | F10: 831.3 | G10: 765
A11: October 2025 | B11: 2025 | C11: 10 | D11: 2025-10-01 | E11: Oct-2025 | F11: 821 | G11: 752
A12: November 2025 | B12: 2025 | C12: 11 | D12: 2025-11-01 | E12: Nov-2025 | F12: 808.8 | G12: 748.8
A13: December 2025 | B13: 2025 | C13: 12 | D13: 2025-12-01 | E13: Dec-2025 | F13: 805 | G13: 756.3
... A17: April 2026 | B17: 2026 | C17: 4 | D17: 2026-04-01 | E17: Apr-2026 | F17: 1287.5 | G17: 1191.9
A18: May 2026 | B18: 2026 | C18: 5 | D18: 2026-05-01 | E18: 01-May-2026 | F18: 1344.9874
A19: June 2026 | B19: 2026 | C19: 6 | D19: 2026-06-01 | E19: 01-Jun-2026 | F19: 1438.2883
A20: July 2026 | B20: 2026 | C20: 7 | D20: 2026-07-01 | E20: 01-Jul-2026 | F20: 1527.7512
A21: August 2026 | B21: 2026 | C21: 8 | D21: 2026-08-01 | E21: 01-Aug-2026 | F21: 1644.1813
A22: September 2026 | B22: 2026 | C22: 9 | D22: 2026-09-01 | E22: 01-Sep-2026 | F22: 1733.4419
A23: October 2026 | B23: 2026 | C23: 10 | D23: 2026-10-01 | E23: 01-Oct-2026 | F23: 1773.8889
A24: November 2026 | B24: 2026 | C24: 11 | D24: 2026-11-01 | E24: 01-Nov-2026 | F24: 1824.5714
A25: December 2026 | B25: 2026 | C25: 12 | D25: 2026-12-01 | E25: 01-Dec-2026 | F25: 1896.0808
A26: January 2027 | B26: 2027 | C26: 1 | D26: 2027-01-01 | E26: 01-Jan-2027 | F26: 1891.5877
A27: February 2027 | B27: 2027 | C27: 2 | D27: 2027-02-01 | E27: 01-Feb-2027 | F27: 1887.1158
A28: March 2027 | B28: 2027 | C28: 3 | D28: 2027-03-01 | E28: 01-Mar-2027 | F28: 1882.6651
A29: April 2027 | B29: 2027 | C29: 4 | D29: 2027-04-01 | E29: 01-Apr-2027 | F29: 1867.2515
... A34: September 2027 | B34: 2027 | C34: 9 | D34: 2027-09-01 | E34: 01-Sep-2027 | F34: 1884.8878

Sheet raw_B13_D46
A1: source_file | B1: source_sheet | C1: source_range | D1: source_row | E1: source_column | F1: source_cell | G1: text | H1: value | I1: formula
A2: Index Fprecast\ICIS Dashboard Price Forecast 2026-05-04 152801_v1.xls | B2: ICIS Price History | C2: B13:D46 | D2: 13 | E2: B | F2: B13 | G2: Monthly | H2: Monthly | I2: Monthly
A3: Index Fprecast\ICIS Dashboard Price Forecast 2026-05-04 152801_v1.xls | B3: ICIS Price History | C3: B13:D46 | D3: 13 | E3: C | F3: C13 | G3: PET Bottle Grade FOB Asia SE Assessment Spot 2-6 Weeks Full Market Range Weekly (Low) : USD/tonne | H3: PET Bottle Grade FOB Asia SE Assessment Spot 2-6 Weeks Full Market Range Weekly (Low) : USD/tonne | I3: PET Bottle Grade FOB Asia SE Assessment Spot 2-6 Weeks Full Market Range Weekly (Low) : USD/tonne
A4: Index Fprecast\ICIS Dashboard Price Forecast 2026-05-04 152801_v1.xls | B4: ICIS Price History | C4: B13:D46 | D4: 13 | E4: D | F4: D13 | G4: PET Bottle Grade FOB China Assessment Spot 4-12 Weeks Full Market Range Weekly (Mid) : USD/tonne | H4: PET Bottle Grade FOB China Assessment Spot 4-12 Weeks Full Market Range Weekly (Mid) : USD/tonne | I4: PET Bottle Grade FOB China Assessment Spot 4-12 Weeks Full Market Range Weekly (Mid) : USD/tonne
A5: Index Fprecast\ICIS Dashboard Price Forecast 2026-05-04 152801_v1.xls | B5: ICIS Price History | C5: B13:D46 | D5: 14 | E5: B | F5: B14 | G5: Jan-2025 | H5: Jan-2025 | I5: Jan-2025
A6: Index Fprecast\ICIS Dashboard Price Forecast 2026-05-04 152801_v1.xls | B6: ICIS Price History | C6: B13:D46 | D6: 14 | E6: C | F6: C14 | G6: 866.0 | H6: 866 | I6: 866
A7: Index Fprecast\ICIS Dashboard Price Forecast 2026-05-04 152801_v1.xls | B7: ICIS Price History | C7: B13:D46 | D7: 14 | E7: D | F7: D14 | G7: 799.5 | H7: 799.5 | I7: 799.5
A8: Index Fprecast\ICIS Dashboard Price Forecast 2026-05-04 152801_v1.xls | B8: ICIS Price History | C8: B13:D46 | D8: 15 | E8: B | F8: B15 | G8: Feb-2025 | H8: Feb-2025 | I8: Feb-2025
A9: Index Fprecast\ICIS Dashboard Price Forecast 2026-05-04 152801_v1.xls | B9: ICIS Price History | C9: B13:D46 | D9: 15 | E9: C | F9: C15 | G9: 882.5 | H9: 882.5 | I9: 882.5
A10: Index Fprecast\ICIS Dashboard Price Forecast 2026-05-04 152801_v1.xls | B10: ICIS Price History | C10: B13:D46 | D10: 15 | E10: D | F10: D15 | G10: 803.1 | H10: 803.1 | I10: 803.1
A11: Index Fprecast\ICIS Dashboard Price Forecast 2026-05-04 152801_v1.xls | B11: ICIS Price History | C11: B13:D46 | D11: 16 | E11: B | F11: B16 | G11: Mar-2025 | H11: Mar-2025 | I11: Mar-2025
A12: Index Fprecast\ICIS Dashboard Price Forecast 2026-05-04 152801_v1.xls | B12: ICIS Price History | C12: B13:D46 | D12: 16 | E12: C | F12: C16 | G12: 886.3 | H12: 886.3 | I12: 886.3
A13: Index Fprecast\ICIS Dashboard Price Forecast 2026-05-04 152801_v1.xls | B13: ICIS Price History | C13: B13:D46 | D13: 16 | E13: D | F13: D16 | G13: 786.3 | H13: 786.3 | I13: 786.3
A14: Index Fprecast\ICIS Dashboard Price Forecast 2026-05-04 152801_v1.xls | B14: ICIS Price History | C14: B13:D46 | D14: 17 | E14: B | F14: B17 | G14: Apr-2025 | H14: Apr-2025 | I14: Apr-2025
A15: Index Fprecast\ICIS Dashboard Price Forecast 2026-05-04 152801_v1.xls | B15: ICIS Price History | C15: B13:D46 | D15: 17 | E15: C | F15: C17 | G15: 857.5 | H15: 857.5 | I15: 857.5
A16: Index Fprecast\ICIS Dashboard Price Forecast 2026-05-04 152801_v1.xls | B16: ICIS Price History | C16: B13:D46 | D16: 17 | E16: D | F16: D17 | G16: 745.6 | H16: 745.6 | I16: 745.6
A17: Index Fprecast\ICIS Dashboard Price Forecast 2026-05-04 152801_v1.xls | B17: ICIS Price History | C17: B13:D46 | D17: 18 | E17: B | F17: B18 | G17: May-2025 | H17: May-2025 | I17: May-2025
A18: Index Fprecast\ICIS Dashboard Price Forecast 2026-05-04 152801_v1.xls | B18: ICIS Price History | C18: B13:D46 | D18: 18 | E18: C | F18: C18 | G18: 872.0 | H18: 872 | I18: 872
A19: Index Fprecast\ICIS Dashboard Price Forecast 2026-05-04 152801_v1.xls | B19: ICIS Price History | C19: B13:D46 | D19: 18 | E19: D | F19: D18 | G19: 775.0 | H19: 775 | I19: 775
A20: Index Fprecast\ICIS Dashboard Price Forecast 2026-05-04 152801_v1.xls | B20: ICIS Price History | C20: B13:D46 | D20: 19 | E20: B | F20: B19 | G20: Jun-2025 | H20: Jun-2025 | I20: Jun-2025
A21: Index Fprecast\ICIS Dashboard Price Forecast 2026-05-04 152801_v1.xls | B21: ICIS Price History | C21: B13:D46 | D21: 19 | E21: C | F21: C19 | G21: 876.3 | H21: 876.3 | I21: 876.3
A22: Index Fprecast\ICIS Dashboard Price Forecast 2026-05-04 152801_v1.xls | B22: ICIS Price History | C22: B13:D46 | D22: 19 | E22: D | F22: D19 | G22: 793.1 | H22: 793.1 | I22: 793.1
A23: Index Fprecast\ICIS Dashboard Price Forecast 2026-05-04 152801_v1.xls | B23: ICIS Price History | C23: B13:D46 | D23: 20 | E23: B | F23: B20 | G23: Jul-2025 | H23: Jul-2025 | I23: Jul-2025
A24: Index Fprecast\ICIS Dashboard Price Forecast 2026-05-04 152801_v1.xls | B24: ICIS Price History | C24: B13:D46 | D24: 20 | E24: C | F24: C20 | G24: 861.3 | H24: 861.3 | I24: 861.3
A25: Index Fprecast\ICIS Dashboard Price Forecast 2026-05-04 152801_v1.xls | B25: ICIS Price History | C25: B13:D46 | D25: 20 | E25: D | F25: D20 | G25: 781.9 | H25: 781.9 | I25: 781.9
A26: Index Fprecast\ICIS Dashboard Price Forecast 2026-05-04 152801_v1.xls | B26: ICIS Price History | C26: B13:D46 | D26: 21 | E26: B | F26: B21 | G26: Aug-2025 | H26: Aug-2025 | I26: Aug-2025
A27: Index Fprecast\ICIS Dashboard Price Forecast 2026-05-04 152801_v1.xls | B27: ICIS Price History | C27: B13:D46 | D27: 21 | E27: C | F27: C21 | G27: 846.0 | H27: 846 | I27: 846
A28: Index Fprecast\ICIS Dashboard Price Forecast 2026-05-04 152801_v1.xls | B28: ICIS Price History | C28: B13:D46 | D28: 21 | E28: D | F28: D21 | G28: 774.0 | H28: 774 | I28: 774
A29: Index Fprecast\ICIS Dashboard Price Forecast 2026-05-04 152801_v1.xls | B29: ICIS Price History | C29: B13:D46 | D29: 22 | E29: B | F29: B22 | G29: Sep-2025 | H29: Sep-2025 | I29: Sep-2025
A30: Index Fprecast\ICIS Dashboard Price Forecast 2026-05-04 152801_v1.xls | B30: ICIS Price History | C30: B13:D46 | D30: 22 | E30: C | F30: C22 | G30: 831.3 | H30: 831.3 | I30: 831.3
A31: Index Fprecast\ICIS Dashboard Price Forecast 2026-05-04 152801_v1.xls | B31: ICIS Price History | C31: B13:D46 | D31: 22 | E31: D | F31: D22 | G31: 765.0 | H31: 765 | I31: 765
A32: Index Fprecast\ICIS Dashboard Price Forecast 2026-05-04 152801_v1.xls | B32: ICIS Price History | C32: B13:D46 | D32: 23 | E32: B | F32: B23 | G32: Oct-2025 | H32: Oct-2025 | I32: Oct-2025
A33: Index Fprecast\ICIS Dashboard Price Forecast 2026-05-04 152801_v1.xls | B33: ICIS Price History | C33: B13:D46 | D33: 23 | E33: C | F33: C23 | G33: 821.0 | H33: 821 | I33: 821
A34: Index Fprecast\ICIS Dashboard Price Forecast 2026-05-04 152801_v1.xls | B34: ICIS Price History | C34: B13:D46 | D34: 23 | E34: D | F34: D23 | G34: 752.0 | H34: 752 | I34: 752
A35: Index Fprecast\ICIS Dashboard Price Forecast 2026-05-04 152801_v1.xls | B35: ICIS Price History | C35: B13:D46 | D35: 24 | E35: B | F35: B24 | G35: Nov-2025 | H35: Nov-2025 | I35: Nov-2025
A36: Index Fprecast\ICIS Dashboard Price Forecast 2026-05-04 152801_v1.xls | B36: ICIS Price History | C36: B13:D46 | D36: 24 | E36: C | F36: C24 | G36: 808.8 | H36: 808.8 | I36: 808.8
A37: Index Fprecast\ICIS Dashboard Price Forecast 2026-05-04 152801_v1.xls | B37: ICIS Price History | C37: B13:D46 | D37: 24 | E37: D | F37: D24 | G37: 748.8 | H37: 748.8 | I37: 748.8
A38: Index Fprecast\ICIS Dashboard Price Forecast 2026-05-04 152801_v1.xls | B38: ICIS Price History | C38: B13:D46 | D38: 25 | E38: B | F38: B25 | G38: Dec-2025 | H38: Dec-2025 | I38: Dec-2025
A39: Index Fprecast\ICIS Dashboard Price Forecast 2026-05-04 152801_v1.xls | B39: ICIS Price History | C39: B13:D46 | D39: 25 | E39: C | F39: C25 | G39: 805.0 | H39: 805 | I39: 805
A40: Index Fprecast\ICIS Dashboard Price Forecast 2026-05-04 152801_v1.xls | B40: ICIS Price History | C40: B13:D46 | D40: 25 | E40: D | F40: D25 | G40: 756.3 | H40: 756.3 | I40: 756.3
...

Sheet run_metadata
A1: field | B1: value
A2: run_timestamp | B2: 2026-05-15T16:50:51
A3: source_file | B3: Index Fprecast\ICIS Dashboard Price Forecast 2026-05-04 152801_v1.xls
A4: source_sheet | B4: ICIS Price History
A5: source_range | B5: B13:D46
A6: requested_mid_range_note | B6: The requested B13:C46 range contains ICIS Low in column C. ICIS Mid is in column D, so B13:D46 is extracted.
A7: raw_cells | B7: 102
A8: reference_rows | B8: 49
A9: wide_rows | B9: 33
A10: resin_index_types | B10: ICIS Asia SE Low, ICIS China Mid
A11: output_excel | B11: Index Fprecast\icis_resin_index_reference_table.xlsx
A12: output_csv | B12: Index Fprecast\icis_resin_index_reference_table.csv
A13: output_wide_csv | B13: Index Fprecast\icis_resin_index_reference_wide.csv
