Workbook
Name \: #REF!
Name \0: #REF!
Name \a: #N/A
Name \a: #N/A
Name \a: #REF!
Name \b: #REF!
Name \c: #REF!
Name \E: #REF!
Name \F: #REF!
Name \G: #REF!
Name \i: #REF!
Name \III_1: '[1]Back-up'!$A$1:$Q$37
Name \III_1: #REF!
Name \III_2: '[1]Back-up'!#REF!
Name \III_2: #REF!
Name \III_3: '[1]Back-up'!#REF!
Name \III_3: #REF!
Name \III_4: '[1]Back-up'!#REF!
Name \III_4: #REF!
Name \III_5: '[1]Back-up'!#REF!
Name \III_5: #REF!
Name \III_6: #REF!
Name \m: #REF!
Name \P: #REF!
Name \page1: #REF!
Name \page2: #REF!
Name \page3: #REF!
Name \page4: #REF!
Name \page5: #REF!
Name \page6: #REF!
Name \page7: #REF!
Name \page8: #REF!
Name \page9: #REF!
Name \pages10: #REF!
Name \pages11: #REF!
Name \S: #REF!
Name \T: #REF!
Name \W: #REF!
Name \z: #REF!
Name _: #REF!
Name __________________Act6: [2]Parameters!#REF!
Name __________________Act6: #REF!
Name __________________DAT10: '[3]Target Book'!#REF!
Name __________________DAT10: #REF!
Name __________________DAT11: '[3]Target Book'!#REF!
Name __________________DAT11: #REF!
Name __________________DAT12: '[3]Target Book'!#REF!
Name __________________DAT12: #REF!
Name __________________DAT13: '[3]Target Book'!#REF!
Name __________________DAT13: #REF!
Name __________________DAT14: '[3]Target Book'!#REF!
Name __________________DAT14: #REF!
Name __________________DAT15: '[3]Target Book'!#REF!
Name __________________DAT15: #REF!
Name __________________DAT16: '[3]Target Book'!#REF!
Name __________________DAT16: #REF!
Name __________________DAT17: '[3]Target Book'!#REF!
Name __________________DAT17: #REF!
Name __________________DAT18: '[3]Target Book'!#REF!
Name __________________DAT18: #REF!

Sheet Base Listas
A1: Resin Index | B1: Material | C1: Plant Name | D1: Plants | E1: Cost Centre
A2: Indexador de Resina | B2: Fornecedor | C2: Resina | D2: Planta | E2: Centro | G2: Incoterm | K2: 45658
A3: ICIS China mid (M-1) | B3: ALPEK | C3: Manaus | D3: MANAUS | E3: 4151 | F3: SPOT | G3: CIF | K3: 45689 | M3: SET'25
A4: ICIS China low | B4: INDORAMA | C4: Manaus - Gatorade | D4: MANAUS FORA | E4: 4151 | F4: CONTRATO | G4: FOB | K4: 45717 | M4: DEZ'25
A5: IHS no Coke | B5: CPR | C5: Manaus (ABI) | D5: SUAPE | E5: 4196 | K5: 45748 | M5: JAN'26
A6: ICIS 5 REGIONS | B6: VG | C6: Suape | D6: LOUVEIRA | E6: 4185 | K6: 45778
A7: ICIS 3 REGIONS | C7: Suape - Gatorade | D7: VESPASIANO | E7: 4188 | K7: 45809
A8: MAXIQUIM MIN | C8: Suape (ABI) | D8: LINDÓIA | E8: 418A | K8: 45839
A9: MAXIQUIM MAX | C9: Suape (Especial SUL) | K9: 45870
A10: MAXIQUIM MED | C10: Lindóia | K10: 45901
C11: Louveira | K11: 45931
C12: Vespasiano | K12: 45962
K13: 45992
K14: 46023
K15: 46054
K16: 46082
K17: 46113
K18: 46143
K19: 46174
K20: 46204
K21: 46235
K22: 46266
K23: 46296
K24: 46327
... K62: 47484

Sheet  Amcor  - Brazil  
I3: Queries
I4: Multiple categories on Column B and Column C ,
E5: File Name : | F5: 04. Amcor.xlsx | I5: what are those ?
E6: Sheet name | F6: Resina | I6: In which combinaton of Country x Supplier --- this will fall under ?
S7: Need more help understanding the below | AD7: For a specific , Supplier + Resin Type + Index , what would be the TLC ? | AL7: Actual formuale as per the Excel for Brazil and Amcor ?
AD8: Scenario 1
S9: 1. In the Resina , Core Pricing sheet we try to find for combination of Product/Supplier/ Plants / Market Index to calculate the final price | U9: Our traditional CIF formulae works , but has a lot of combinations , across supplires , plants | AA9: which Resin Index to use ?
S10: 2. Resin sheet is used to calculate the Total Landing Cost for Different Types of Resins , Suppliers and Resin Indexes
S11: 3. Formulae mismtach between , what is there in the Resina sheet and what detailed in the formulae ?
S12: 3. Pricing sheets are calculated at specific granularity in the Monthly sheets like "MAR'26 , APR'26 , at specific stages like "Preforma / Garraga"
S13: 4. How are the other sheets used in the calculation ? How is this sheet used in the calculation ? | V13: Monthly sheet calculation
S14: Indexadores | AQ14: Index | AR14: 1111.25
S15: BD Conv | AQ15: Freight | AR15: 124.22
S16: Carga | AQ16: Duties | AR16: 257
S17: Check | AQ17: Others | AR17: 167
R18: 5 | S18: 5.which Specific combination we need to consider ? | AQ18: TLC | AR18: =SUM(AR14:AR17) -> 1659.47
S19: 6. what is the link between Resina sheet and MAR'26 sheet ?

Sheet Resina
B2: AVISO! | E2: 45839 | F2: 45870 | G2: 45901 | H2: 45931 | I2: 45962 | J2: 45992 | K2: 46023 | L2: 46054 | M2: 46082 | N2: 46113 | O2: =EDATE(N2,1) -> 46143
D3: P-TAX | E3: 5.547055 | F3: 5.5284913 | G3: 5.4469238 | H3: 5.3674091 | I3: 5.3855261 | J3: 5.3408526 | K3: 5.4530909 | L3: 5.3380238 | M3: 5.2006167 | N3: 5.2315864 | O3: =_xlfn.XLOOKUP(EDATE(O2,-1),'[444]P-TAX Diária'!$1:$1,'[444]P-TAX Diária'!$35:$35,0) -> 0
C5: SUAPE | E5: 45839 | F5: 45870 | G5: 45901 | H5: 45931 | I5: 45962 | J5: 45992 | K5: 46023 | L5: 46054 | M5: 46082 | N5: 46113 | O5: =EDATE(N5,1) -> 46143
B6: ALPEK | C6: Suape | D6: ICIS China mid (M-1) | E6: 793.125 | F6: 781.875 | G6: 774 | H6: 765 | I6: 752 | J6: 748.75 | K6: 756.25 | L6: 818.125 | M6: 838.13 | N6: 1111.25 | O6: =IFERROR(INDEX([444]RESINA!$A$2:$AZ$500, MATCH(EDATE(O5,-1),[444]RESINA!$A$2:$A$500,0), MATCH($D$6,[444]RESINA!$A$2:$AZ$2,0)),"-") -> 0
D7: International freight | E7: 206.62222 | F7: =F11/22.5 -> 288.8 | G7: =G11/22.5 -> 165.15556 | H7: =H11/22.5 -> 148.35556 | I7: =I11/22.5 -> 117.95556 | J7: =J11/22.5 -> 88.844444 | K7: =K11/22.5 -> 75.511111 | L7: =L11/22.5 -> 65.466667 | M7: =M11/22.5 -> 66.044444 | ... O7: =O11/22.5 -> 0
D8: Local freight
D9: Duties | E9: 207.94742 | F9: =SUM(F6:F7)*20.8% -> 222.7004 | G9: =SUM(G6:G7)*20.8% -> 195.34436 | H9: =SUM(H6:H7)*20.8% -> 189.97796 | I9: =SUM(I6:I7)*20.8% -> 180.95076 | J9: =SUM(J6:J7)*20.8% -> 174.21964 | K9: =SUM(K6:K7)*20.8% -> 173.00631 | L9: =SUM(L6:L7)*20.8% -> 183.78707 | M9: =SUM(M6:M7)*20.8% -> 188.06828 | ... O9: =SUM(O6:O7)*20.8% -> 0
D10: Others | E10: 167 | F10: =90+77 -> 167 | G10: =90+77 -> 167 | H10: =90+77 -> 167 | I10: =90+77 -> 167 | J10: =90+77 -> 167 | K10: =90+77 -> 167 | L10: =90+77 -> 167 | M10: =90+77 -> 167 | ... O10: =90+77 -> 167
D11: Drewry | E11: 4649 | F11: 6498 | G11: 3716 | H11: 3338 | I11: 2654 | J11: 1999 | K11: 1699 | L11: 1473 | M11: 1486 | N11: 2795 | O11: =_xlfn.XLOOKUP(EDATE(O5,-1),[444]RESINA!$A:$A,[444]RESINA!$B:$B,0) -> 0
A12: =_xlfn.CONCAT(C5,B6,D12) -> SUAPEALPEKSell Side Resina USD | D12: Sell Side Resina USD | E12: 1374.6946 | F12: =SUM(F6:F10) -> 1460.3754 | G12: =SUM(G6:G10) -> 1301.4999 | H12: =SUM(H6:H10) -> 1270.3335 | I12: =SUM(I6:I10) -> 1217.9063 | J12: =SUM(J6:J10) -> 1178.8141 | K12: =SUM(K6:K10) -> 1171.7674 | L12: =SUM(L6:L10) -> 1234.3787 | M12: =SUM(M6:M10) -> 1259.2427 | ... O12: =SUM(O6:O10) -> 167
A13: =_xlfn.CONCAT(C5,B6,D13) -> SUAPEALPEKBuy Side Resina USD | C13: Suape (ABI) | D13: Buy Side Resina USD | E13: 1266.8968 | F13: 1254.2197 | G13: 1269.5954 | H13: 1232.4699 | I13: 1155.6782 | J13: 1122.0245 | K13: 1088.7028 | L13: 1129.2609 | M13: 1157.6381 | N13: 1515.5363 | O13: =IFERROR(INDEX([444]RATIONAL!$C$72:$DS$197, MATCH(EDATE(O5,-1),[444]RATIONAL!$B$72:$B$197,0), MATCH(_xlfn.CONCAT($B$6,$C$13),[444]RATIONAL!$C$1:$DS$1,0)),"-") -> -
N14: =N12/[445]Resina!$N$12-1 -> -0.081412682
C16: SUAPE | E16: 45839 | F16: 45870 | G16: 45901 | H16: 45931 | I16: 45962 | J16: 45992 | K16: 46023 | L16: 46054 | M16: 46082 | N16: 46113 | O16: =EDATE(N16,1) -> 46143
B17: VG | C17: Suape | D17: MAXIQUIM MED | E17: 4400 | F17: 4450 | G17: 4400 | H17: 4450 | I17: 4300 | J17: 4100 | K17: 3700 | L17: 3100 | M17: 3400 | N17: =IFERROR(INDEX([444]RESINA!$A$2:$AZ$500, MATCH(N16,[444]RESINA!$A$2:$A$500,0), MATCH($D$41,[444]RESINA!$A$2:$AZ$2,0)),"-") -> 0 | O17: =IFERROR(INDEX([444]RESINA!$A$2:$AZ$500, MATCH(O16,[444]RESINA!$A$2:$A$500,0), MATCH($D$41,[444]RESINA!$A$2:$AZ$2,0)),"-") -> 0
D19: Maxiquim SE Med (M-2/3/4) | I19: =AVERAGE(E17:G17)/70% -> 6309.5238 | J19: =AVERAGE(F17:H17)/70% -> 6333.3333 | K19: =AVERAGE(G17:I17)/70% -> 6261.9048 | L19: =AVERAGE(H17:J17)/70% -> 6119.0476 | M19: =AVERAGE(I17:K17)/70% -> 5761.9048 | N19: =AVERAGE(J17:L17)/70% -> 5190.4762 | O19: =AVERAGE(K17:M17)/70% -> 4857.1429
D20: Local freight | I20: 590 | J20: 590 | K20: 590 | L20: 590 | M20: 590 | N20: 590 | O20: 590
D21: Fixed cost BRL/Ton | I21: 2390 | J21: 2390 | K21: 2390 | L21: 2390 | M21: 2390 | N21: 2390 | O21: 2390
D22: Discount | I22: -538.8 | J22: -538.8 | K22: -538.8 | L22: -538.8 | M22: -538.8 | N22: -538.8 | O22: -538.8
D23: Adder | I23: 386.5 | J23: 386.5 | K23: 386.5 | L23: 386.5 | M23: 386.5 | N23: 386.5 | O23: 386.5
A25: =_xlfn.CONCAT(C16,B17,D25) -> SUAPEVGSell Side Resina USD | D25: Sell Side Resina USD | I25: =SUM(I19:I23)/I3 -> 1696.626 | J25: =SUM(J19:J23)/J3 -> 1715.2754 | K25: =SUM(K19:K23)/K3 -> 1666.872 | L25: =SUM(L19:L23)/L3 -> 1676.0412 | M25: =SUM(M19:M23)/M3 -> 1651.6512 | N25: =SUM(N19:N23)/N3 -> 1532.6472 | O25: =SUM(O19:O23)/O3 -> #DIV/0!
A26: =_xlfn.CONCAT(C16,B17,D26) -> SUAPEVGBuy Side Resina USD | C26: Suape | D26: Buy Side Resina USD | I26: 1740.412 | J26: 1768.3437 | K26: 1692.6505 | L26: 1675.6131 | M26: 1610.0071 | N26: 1436.6372 | O26: =(_xlfn.XLOOKUP(EDATE(O16,-2),'[444]RATIONAL PCR'!$B:$B,'[444]RATIONAL PCR'!$I:$I,0)+587.32)/O3 -> #DIV/0!
C29: MANAUS | E29: 45839 | F29: 45870 | G29: 45901 | H29: 45931 | I29: 45962 | J29: 45992 | K29: 46023 | L29: 46054 | M29: 46082 | N29: 46113 | O29: =EDATE(N29,1) -> 46143
B30: ALPEK | C30: Manaus | D30: ICIS China mid (M-1) | E30: 793.125 | F30: 781.875 | G30: 774 | H30: 765 | I30: 752 | J30: 748.75 | K30: 756.25 | L30: 818.125 | M30: 838.13 | N30: 1111.25 | O30: =IFERROR(INDEX([444]RESINA!$A$2:$AZ$500, MATCH(EDATE(O29,-1),[444]RESINA!$A$2:$A$500,0), MATCH($D$30,[444]RESINA!$A$2:$AZ$2,0)),"-") -> 0
D31: International freight | E31: 226.62222 | F31: =F35/22.5+20 -> 308.8 | G31: =G35/22.5+20 -> 185.15556 | H31: =H35/22.5+20 -> 168.35556 | I31: =I35/22.5+20 -> 137.95556 | J31: =J35/22.5+20 -> 108.84444 | K31: =K35/22.5+20 -> 95.511111 | L31: =L35/22.5+20 -> 85.466667 | M31: =M35/22.5+20 -> 86.044444 | ... O31: =O35/22.5+20 -> 20
D32: Local freight
D33: Duties | E33: 212.10742 | F33: =SUM(F30:F31)*20.8% -> 226.8604 | G33: =SUM(G30:G31)*20.8% -> 199.50436 | H33: =SUM(H30:H31)*20.8% -> 194.13796 | I33: =SUM(I30:I31)*20.8% -> 185.11076 | J33: =SUM(J30:J31)*20.8% -> 178.37964 | K33: =SUM(K30:K31)*20.8% -> 177.16631 | L33: =SUM(L30:L31)*20.8% -> 187.94707 | M33: =SUM(M30:M31)*20.8% -> 192.22828 | ... O33: =SUM(O30:O31)*20.8% -> 4.16
D34: Seguro | E34: 167 | F34: =90+77 -> 167 | G34: =90+77 -> 167 | H34: =90+77 -> 167 | I34: =90+77 -> 167 | J34: =90+77 -> 167 | K34: =90+77 -> 167 | L34: =90+77 -> 167 | M34: =90+77 -> 167 | ... O34: =90+77 -> 167
D35: Drewry | E35: 4649 | F35: 6498 | G35: 3716 | H35: 3338 | I35: 2654 | J35: 1999 | K35: 1699 | L35: 1473 | M35: 1486 | N35: 2795 | O35: =_xlfn.XLOOKUP(EDATE(O29,-1),[444]RESINA!$A:$A,[444]RESINA!$B:$B,0) -> 0
A36: =_xlfn.CONCAT(C29,B30,D36) -> MANAUSALPEKSell Side Resina USD | D36: Sell Side Resina USD | E36: 1398.8546 | F36: =SUM(F30:F34) -> 1484.5354 | G36: =SUM(G30:G34) -> 1325.6599 | H36: =SUM(H30:H34) -> 1294.4935 | I36: =SUM(I30:I34) -> 1242.0663 | J36: =SUM(J30:J34) -> 1202.9741 | K36: =SUM(K30:K34) -> 1195.9274 | L36: =SUM(L30:L34) -> 1258.5387 | M36: =SUM(M30:M34) -> 1283.4027 | ... O36: =SUM(O30:O34) -> 191.16
A37: =_xlfn.CONCAT(C29,B30,D37) -> MANAUSALPEKBuy Side Resina USD | C37: Manaus (ABI) | D37: Buy Side Resina USD | E37: 1325.8207 | F37: 1312.653 | G37: 1323.6237 | H37: 1290.0616 | I37: 1210.1052 | J37: 1175.1493 | K37: 1140.5383 | L37: 1182.6657 | M37: 1212.1409 | N37: 1583.8873 | O37: =IFERROR(INDEX([444]RATIONAL!$C$72:$DS$197, MATCH(EDATE(O29,-1),[444]RATIONAL!$B$72:$B$197,0), MATCH(_xlfn.CONCAT($B$30,$C$37),[444]RATIONAL!$C$1:$DS$1,0)),"-") -> -
N38: =N36/[445]Resina!$N$35-1 -> -0.080338258
C40: MANAUS | E40: 45839 | F40: 45870 | G40: 45901 | H40: 45931 | I40: 45962 | J40: 45992 | K40: 46023 | L40: 46054 | M40: 46082 | N40: 46113 | O40: =EDATE(N40,1) -> 46143
B41: VG | C41: Manaus | D41: MAXIQUIM MED | E41: 4400 | F41: 4450 | G41: 4400 | H41: 4450 | I41: 4300 | J41: 4100 | K41: 3700 | L41: 3100 | M41: 3400 | N41: =IFERROR(INDEX([444]RESINA!$A$2:$AZ$500, MATCH(N40,[444]RESINA!$A$2:$A$500,0), MATCH($D$41,[444]RESINA!$A$2:$AZ$2,0)),"-") -> 0 | O41: =IFERROR(INDEX([444]RESINA!$A$2:$AZ$500, MATCH(O40,[444]RESINA!$A$2:$A$500,0), MATCH($D$41,[444]RESINA!$A$2:$AZ$2,0)),"-") -> 0
D42: Maxiquim SE Med (M-2/3/4) | I42: =AVERAGE(E41:G41)/70% -> 6309.5238 | J42: =AVERAGE(F41:H41)/70% -> 6333.3333 | K42: =AVERAGE(G41:I41)/70% -> 6261.9048 | L42: =AVERAGE(H41:J41)/70% -> 6119.0476 | M42: =AVERAGE(I41:K41)/70% -> 5761.9048 | N42: =AVERAGE(J41:L41)/70% -> 5190.4762 | O42: =AVERAGE(K41:M41)/70% -> 4857.1429
D43: Local freight | I43: 950 | J43: 950 | K43: 950 | L43: 950 | M43: 950 | N43: 950 | O43: 950
D44: Fixed cost BRL/Ton | I44: 2390 | J44: 2390 | K44: 2390 | L44: 2390 | M44: 2390 | N44: 2390 | O44: 2390
D45: Discount | I45: -538.8 | J45: -538.8 | K45: -538.8 | L45: -538.8 | M45: -538.8 | N45: -538.8 | O45: -538.8
D46: Adder | I46: 386.5 | J46: 386.5 | K46: 386.5 | L46: 386.5 | M46: 386.5 | N46: 386.5 | O46: 386.5
D47: Drewry | I47: 2654 | J47: 1999 | K47: 1699 | L47: 1473 | M47: 1486 | N47: 2795 | O47: =_xlfn.XLOOKUP(EDATE(O40,-1),[444]RESINA!$A:$A,[444]RESINA!$B:$B,0) -> 0
A48: =_xlfn.CONCAT(C40,B41,D48) -> MANAUSVGSell Side Resina USD | D48: Sell Side Resina USD | I48: =SUM(I42:I46)/I3 -> 1763.4719 | J48: =SUM(J42:J46)/J3 -> 1782.6804 | K48: =SUM(K42:K46)/K3 -> 1732.8896 | L48: =SUM(L42:L46)/L3 -> 1743.4818 | M48: =SUM(M42:M46)/M3 -> 1720.8738 | N48: =SUM(N42:N46)/N3 -> 1601.46 | O48: =SUM(O42:O46)/O3 -> #DIV/0!
...

Sheet MAR'26
AH1: ZBRP | AJ1: ZBSR | AK1: ZBFS | AL1: ZBCP | AN1: ZBSR | AO1: ZBUT | AP1: ZBLA | AQ1: ZBTMx | AR1: ZBTMx | AT1: ZBSR | AU1: ZBTMx | AW1: ZBOP | AX1: ZBFC | AY1: ZBPP | BA1: ZBCTx | BB1: ZBUB | BC1: ZBLL | BD1: ZBCTx | BE1: ZBCTx | BF1: ZBCTx | BH1: ZBSB | BJ1: ZBLB | BK1: ZBLB | BM1: ZBSB | BN1: ZBOB | BO1: ZBFB | BP1: ZBPB | BR1: ZBOP | DE1: CARGA | DH1: 1 | DI1: 2 | DJ1: 3 | DK1: 4 | DL1: 5 | DM1: 6 | DN1: 7 | DO1: 8 | DP1: 9 | DQ1: 10 | DR1: 11 | DS1: 12 | DT1: 13 | DU1: 14 | DV1: 15 | DW1: 16 | DX1: 17 | DY1: 18 | DZ1: 19 | EA1: 20 | EB1: 21 | EC1: 22 | ED1: 23 | EE1: 24
H3: 46082 | AK3: PREFORMA | BA3: GARRAFA | BR3: 0 | BY3: ANÁLISE | CD3: PREÇO BASE | CI3: Custo
C4: Cost Centre | D4: Plants | F4: Client | H4: Incoterm | K4: Material Description | L4: Weight | M4: Additive | W4: % Viring | Z4: Recycled Resin | AF4: Sales Unit | AG4: Fx Rate | AS4: Preform (intermediate product) | BG4: Bottle (final product) | BQ4: Bottle Price | BT4: Net Price (BRL per 1000 units) | BW4: Change vs Last Price
B5: Centro Preforma | C5: Centro | D5: Planta | E5: Cód. Cliente | F5: Descrição Cliente | G5: Grupo | H5: Incoterm | I5: Localização Cliente | J5: Cód. Produto | K5: Descrição do Material | L5: Peso (g) | M5: Aditivo 1 | N5: % Aditivo 1 | O5: Custo Aditivo 1 BRL | P5: Aditivo 2 | Q5: % Aditivo 2 | R5: Custo Aditivo 2 BRL | S5: Aditivo 3 | T5: % Aditivo 3 | U5: Custo Aditivo 3 BRL | V5: Tipo de Resina | W5: % Virgem | X5: Fornecedor | Y5: Sell Side Resina USD | Z5: % PCR | AA5: Fornecedor | AB5: Sell Side Resina USD | AC5: Início da validade | AD5: Atualização Resina | AE5: Atualização Indexadores | AF5: Unidade de Venda | AG5: P-TAX AVG m-1 | AH5: Total Resina (BRL p/ mil) | AI5: Scrap % | AJ5: Scrap (BRL) | AK5: Repasse Tributação | AL5: Aditivo (BRL) | AM5: Scrap % | AN5: Scrap (BRL) | AO5: Energia Elétrica (BRL) | AP5: Mão-de-obra (BRL) | AQ5: Manutenção USD | AR5: Manutenção (BRL) | AS5: Scrap % | AT5: Scrap (BRL) | AU5: Outros Custos (BRL) | AV5: Total Conversão (BRL p/000) | AW5: Amortização (BRL) | AX5: Freight BRL | AY5: Packaging BRL | AZ5: Preço Preforma | BA5: Conversão (BRL) | BB5: Energia Elétrica (BRL) | BC5: Mão-de-obra (BRL) | BD5: Manutenção USD | BE5: Manutenção (BRL) | BF5: Outros Custos (BRL) | BG5: Scrap % | BH5: Scrap (BRL) | BI5: Total Conversão (BRL p/000) | BJ5: Rótulo (BRL) | BK5: Colocação Rótulo (BRL) | BL5: Scrap % | BM5: Scrap (BRL) | BN5: Amortização (BRL) | BO5: Freight (BRL) | BP5: Packaging (BRL) | BQ5: Preço Frasco | BR5: Desconto | BT5: Preço Líquido BRL/000 | BU5: 9,25% PIS COFINS + 12% ICMS | BV5: Preço com Impostos BRL /000 | BW5: Variação Last Price | BY5: EBIT SEM SG&A(%) | BZ5: EBIT SEM SG&A(USD) | CA5: MARGEM DE CONTRIBUIÇÃO (USD) | CB5: MOR (USD) | CD5: 0.1 | CE5: EBIT SEM SG&A(USD) | CF5: MARGEM DE CONTRIBUIÇÃO (USD) | CG5: MOR (USD) | CI5: Buy Side Resina USD | CJ5: Buy Side Resina USD | CK5: Total Resina (BRL p/ mil) | CL5: Scrap (BRL) | CM5: Crédito ICMS | CN5: CTP | CO5: Packaging + Freight + Pigmento | CP5: Total | CQ5: Variable Costs CTP | DG5: ZBRP | DH5: ZBSR | DI5: ZBSB | DJ5: ZBCP | DK5: ZBFP | DL5: ZBFC | DM5: ZBFB | DN5: ZBTMx | DO5: ZBCTx | DP5: ZBLB | DQ5: ZBMR | DR5: ZBML | DS5: ZBPP | DT5: ZBPB | DU5: ZBOP | DV5: ZBOB | DW5: ZBSG | DX5: ZBFS | DY5: ZBUT | DZ5: ZBUB | EA5: ZBLA | EB5: ZBLL | EC5: ZBPE | ED5: ZBPL | EE5: Total | EF5: Corrigir | EG5: ZBTM | EH5: ZBCT | EI5: Total
AO6: Energy | AP6: Labor | AU6: IPCA | BB6: Energy | BC6: Labor | BF6: IPCA | BO6: IGPM | BP6: IGPM | CL6: 0.01
A7: =_xlfn.CONCAT(D7,L7) -> Louveira25.5 | B7: 4151 | C7: 4185 | D7: Louveira | F7: AMBEV | G7: CONTRATO | H7: FOB | K7: F,500ML,GATORADE,CR | L7: 25.5 | M7: CR | V7: Virgem | W7: 1 | X7: ALPEK | Y7: =IF($X7="",0,HLOOKUP($H$3,Resina!$E$2:$AK$93,MATCH("MANAUS"&$X7&$Y$5,Resina!$A$2:$A$93,0))) -> 1283.4027 | Z7: 0 | AB7: =IF($AA7="",0,HLOOKUP($H$3,Resina!$E$2:$AK$93,MATCH("MANAUS"&$AA7&$AB$5,Resina!$A$2:$A$93,0))) -> 0 | AC7: 46091 | AD7: Mensal | AE7: 45839 | AF7: MIL | AG7: =_xlfn.XLOOKUP($H$3,Resina!$2:$2,Resina!$3:$3,0) -> 5.2006167 | AH7: =(L7*((Y7*W7)+(AB7*Z7)))*AG7/1000 -> 170.19938 | AI7: 0.005 | AJ7: =AH7*AI7 -> 0.85099692 | AO7: =_xlfn.XLOOKUP($D7&$L7&$AK$3,'BD Conv'!$A:$A,'BD Conv'!$H:$H,0)*_xlfn.XLOOKUP($D7,'BD Conv'!$C$17:$C$19,'BD Conv'!$F$17:$F$19,0)*(1+(HLOOKUP($B7&AO$6,Indexadores!$C$2:$AH$32,MATCH($AE7,Indexadores!$A$2:$A$32,0)))) -> 0 | AS7: 0.005 | AT7: =(AU7+AO7)*AS7 -> 0 | AU7: =_xlfn.XLOOKUP($D7&$L7&$AK$3,'BD Conv'!$A:$A,'BD Conv'!$H:$H,0)*_xlfn.XLOOKUP($D7,'BD Conv'!$C$17:$C$19,'BD Conv'!$E$17:$E$19,0)*(1+(HLOOKUP($B7&AU$6,Indexadores!$C$2:$AH$32,MATCH($AE7,Indexadores!$A$2:$A$32,0)))) -> 0 | AV7: =SUM(AN7,AO7,AP7,(AQ7*AG7),AR7,AT7,AU7) -> 0 | AW7: =_xlfn.XLOOKUP($A7&$AK$3,'BD Conv'!$A:$A,'BD Conv'!$I:$I,0) -> 0 | AZ7: =SUM(AH7,AJ7,AK7,AL7,AV7,AW7:AY7) -> 171.05038 | BB7: =_xlfn.XLOOKUP($D7&$L7&$BA$3,'BD Conv'!$A:$A,'BD Conv'!$J:$J,0)*_xlfn.XLOOKUP($D7,'BD Conv'!$C$17:$C$19,'BD Conv'!$F$17:$F$19,0)*(1+(HLOOKUP($C7&BB$6,Indexadores!$C$2:$AH$32,MATCH($AE7,Indexadores!$A$2:$A$32,0)))) -> 0 | BF7: =_xlfn.XLOOKUP($D7&$L7&$BA$3,'BD Conv'!$A:$A,'BD Conv'!$J:$J,0)*_xlfn.XLOOKUP($D7,'BD Conv'!$C$17:$C$19,'BD Conv'!$E$17:$E$19,0)*(1+(HLOOKUP($C7&BF$6,Indexadores!$C$2:$AH$32,MATCH($AE7,Indexadores!$A$2:$A$32,0)))) -> 0 | BG7: 0.01 | BH7: =(AZ7+BB7+BF7)*BG7 -> 1.7105038 | BI7: =SUM(BA7,BB7,BC7,(BD7*AG7),BE7,BF7,BH7) -> 1.7105038 | BN7: =_xlfn.XLOOKUP($A7&$BA$3,'BD Conv'!$A:$A,'BD Conv'!$K:$K,0) -> 0 | BQ7: =SUM(BI7,BJ7,BK7,BM7,BN7,BO7,BP7) -> 1.7105038 | BR7: =-BQ7*$BR$3 -> 0 | BT7: =AZ7+BQ7+BR7+BS7 -> 172.76088 | BU7: =BV7-BT7 -> 43.568798 | BV7: =BT7/(1-(12%+1.65%+7.6%) +12%*(1.65%+7.6%)) -> 216.32968 | BY7: =BT7/CP7-1 -> 0.064083962 | BZ7: =(BT7-CP7)/AG7 -> 2.0006173 | CA7: =(BT7-CK7-CL7-AL7-AX7-AY7-BO7-BP7+CQ7)/AG7 -> 2.0006173 | CB7: =(BT7-AH7)/AG7 -> 0.49253788 | CD7: =CP7*(1+$CD$5) -> 178.59208 | CE7: =(CD7-CP7)/AG7 -> 3.121869 | CF7: =(CD7-CK7-CL7-AL7-AX7-AY7-BO7-BP7+CQ7)/AG7 -> 3.121869 | CG7: =(CD7-AH7)/AG7 -> 1.6137895 | CI7: =IF($X7="",0,HLOOKUP($H$3,Resina!$E$2:$AK$93,MATCH("MANAUS"&$X7&$CI$5,Resina!$A$2:$A$93,0))) -> 1212.1409 | CJ7: =IF($AA7="",0,HLOOKUP($H$3,Resina!$E$2:$AK$93,MATCH("MANAUS"&$AA7&$CJ$5,Resina!$A$2:$A$93,0))) -> 0 | CK7: =L7*((CI7*W7)+(CJ7*Z7))*AG7/1000 -> 160.74895 | CL7: =CK7*$CL$6 -> 1.6074895 | CM7: =IF(D7="Manaus FORA",-((CK7/0.88*0.12)*(1-9.25%))," ") | CO7: =AX7+AY7+BO7+BP7+AL7+AN7+BJ7+BK7+BM7 -> 0 | CP7: =SUM(CK7:CO7) -> 162.35644 | DE7: =_xlfn.CONCAT(D7,L7) -> Louveira25.5 | DF7: =L7 -> 25.5 | DG7: =ROUND(SUMIF($1:$1,DG$5,7:7),2) -> 170.2 | DH7: =ROUND(SUMIF($1:$1,DH$5,7:7),2) -> 0.85 | DI7: =ROUND(SUMIF($1:$1,DI$5,7:7),2) -> 1.71 | DJ7: =ROUND(SUMIF($1:$1,DJ$5,7:7),2) -> 0 | DK7: =ROUND(SUMIF($1:$1,DK$5,7:7),2) -> 0 | DL7: =ROUND(SUMIF($1:$1,DL$5,7:7),2) -> 0 | DM7: =ROUND(SUMIF($1:$1,DM$5,7:7),2) -> 0 | DN7: =ROUND(SUMIF($1:$1,DN$5,7:7),2) -> 0 | ... ED7: =ROUND(SUMIF($1:$1,ED$5,7:7),2) -> 0 | EE7: =SUM(DG7:ED7) -> 172.76 | EF7: =ROUND(SUM(EE7-BT7),2) -> 0 | EG7: =IF(DN7<>0,DN7-EF7,0) -> 0 | EH7: =IF(EG7=0,DO7-EF7,DO7) -> 0 | EI7: =SUM(DG7:DM7)+SUM(DP7:ED7)+EG7+EH7 -> 172.76
A8: =_xlfn.CONCAT(D8,L8) -> Louveira25.5 | B8: 4151 | C8: 4185 | D8: Louveira | F8: AMBEV | G8: CONTRATO | H8: FOB | K8: F,500ML,GATORADE,CR | L8: 25.5 | M8: CR | V8: Virgem | W8: 0.7 | X8: ALPEK | Y8: =IF($X8="",0,HLOOKUP($H$3,Resina!$E$2:$AK$93,MATCH("MANAUS"&$X8&$Y$5,Resina!$A$2:$A$93,0))) -> 1283.4027 | Z8: 0.3 | AA8: VG | AB8: =IF($AA8="",0,HLOOKUP($H$3,Resina!$E$2:$AK$93,MATCH("MANAUS"&$AA8&$AB$5,Resina!$A$2:$A$93,0))) -> 1720.8738 | AC8: =$AC$7 -> 46091 | AD8: Mensal | AE8: =$AE$7 -> 45839 | AF8: MIL | AG8: =_xlfn.XLOOKUP($H$3,Resina!$2:$2,Resina!$3:$3,0) -> 5.2006167 | AH8: =(L8*((Y8*W8)+(AB8*Z8)))*AG8/1000 -> 187.60404 | AI8: 0.005 | AJ8: =AH8*AI8 -> 0.93802022 | AO8: =_xlfn.XLOOKUP($D8&$L8&$AK$3,'BD Conv'!$A:$A,'BD Conv'!$H:$H,0)*_xlfn.XLOOKUP($D8,'BD Conv'!$C$17:$C$19,'BD Conv'!$F$17:$F$19,0)*(1+(HLOOKUP($B8&AO$6,Indexadores!$C$2:$AH$32,MATCH($AE8,Indexadores!$A$2:$A$32,0)))) -> 0 | AS8: 0.005 | AT8: =(AU8+AO8)*AS8 -> 0 | AU8: =_xlfn.XLOOKUP($D8&$L8&$AK$3,'BD Conv'!$A:$A,'BD Conv'!$H:$H,0)*_xlfn.XLOOKUP($D8,'BD Conv'!$C$17:$C$19,'BD Conv'!$E$17:$E$19,0)*(1+(HLOOKUP($B8&AU$6,Indexadores!$C$2:$AH$32,MATCH($AE8,Indexadores!$A$2:$A$32,0)))) -> 0 | AV8: =SUM(AN8,AO8,AP8,(AQ8*AG8),AR8,AT8,AU8) -> 0 | AW8: =_xlfn.XLOOKUP($A8&$AK$3,'BD Conv'!$A:$A,'BD Conv'!$I:$I,0) -> 0 | AZ8: =SUM(AH8,AJ8,AK8,AL8,AV8,AW8:AY8) -> 188.54207 | BB8: =_xlfn.XLOOKUP($D8&$L8&$BA$3,'BD Conv'!$A:$A,'BD Conv'!$J:$J,0)*_xlfn.XLOOKUP($D8,'BD Conv'!$C$17:$C$19,'BD Conv'!$F$17:$F$19,0)*(1+(HLOOKUP($C8&BB$6,Indexadores!$C$2:$AH$32,MATCH($AE8,Indexadores!$A$2:$A$32,0)))) -> 0 | BF8: =_xlfn.XLOOKUP($D8&$L8&$BA$3,'BD Conv'!$A:$A,'BD Conv'!$J:$J,0)*_xlfn.XLOOKUP($D8,'BD Conv'!$C$17:$C$19,'BD Conv'!$E$17:$E$19,0)*(1+(HLOOKUP($C8&BF$6,Indexadores!$C$2:$AH$32,MATCH($AE8,Indexadores!$A$2:$A$32,0)))) -> 0 | BG8: 0.01 | BH8: =(AZ8+BB8+BF8)*BG8 -> 1.8854207 | BI8: =SUM(BA8,BB8,BC8,(BD8*AG8),BE8,BF8,BH8) -> 1.8854207 | BN8: =_xlfn.XLOOKUP($A8&$BA$3,'BD Conv'!$A:$A,'BD Conv'!$K:$K,0) -> 0 | BQ8: =SUM(BI8,BJ8,BK8,BM8,BN8,BO8,BP8) -> 1.8854207 | BR8: =-BQ8*$BR$3 -> 0 | BT8: =AZ8+BQ8+BR8+BS8 -> 190.42749 | BU8: =BV8-BT8 -> 48.024162 | BV8: =BT8/(1-(12%+1.65%+7.6%) +12%*(1.65%+7.6%)) -> 238.45165 | BY8: =BT8/CP8-1 -> 0.033985099 | BZ8: =(BT8-CP8)/AG8 -> 1.2035082 | CA8: =(BT8-CK8-CL8-AL8-AX8-AY8-BO8-BP8+CQ8)/AG8 -> 1.2035082 | CB8: =(BT8-AH8)/AG8 -> 0.54290502 | CD8: =CP8*(1+$CD$5) -> 202.58535 | CE8: =(CD8-CP8)/AG8 -> 3.541282 | CF8: =(CD8-CK8-CL8-AL8-AX8-AY8-BO8-BP8+CQ8)/AG8 -> 3.541282 | CG8: =(CD8-AH8)/AG8 -> 2.8806788 | CI8: =IF($X8="",0,HLOOKUP($H$3,Resina!$E$2:$AK$93,MATCH("MANAUS"&$X8&$CI$5,Resina!$A$2:$A$93,0))) -> 1212.1409 | CJ8: =IF($AA8="",0,HLOOKUP($H$3,Resina!$E$2:$AK$93,MATCH("MANAUS"&$AA8&$CJ$5,Resina!$A$2:$A$93,0))) -> 1754.965 | CK8: =L8*((CI8*W8)+(CJ8*Z8))*AG8/1000 -> 182.34505 | CL8: =CK8*$CL$6 -> 1.8234505 | CM8: =IF(D8="Manaus FORA",-((CK8/0.88*0.12)*(1-9.25%))," ") | CO8: =AX8+AY8+BO8+BP8+AL8+AN8+BJ8+BK8+BM8 -> 0 | CP8: =SUM(CK8:CO8) -> 184.1685 | DE8: =_xlfn.CONCAT(D8,L8) -> Louveira25.5 | DF8: =L8 -> 25.5 | DG8: =ROUND(SUMIF($1:$1,DG$5,8:8),2) -> 187.6 | DH8: =ROUND(SUMIF($1:$1,DH$5,8:8),2) -> 0.94 | DI8: =ROUND(SUMIF($1:$1,DI$5,8:8),2) -> 1.89 | DJ8: =ROUND(SUMIF($1:$1,DJ$5,8:8),2) -> 0 | DK8: =ROUND(SUMIF($1:$1,DK$5,8:8),2) -> 0 | DL8: =ROUND(SUMIF($1:$1,DL$5,8:8),2) -> 0 | DM8: =ROUND(SUMIF($1:$1,DM$5,8:8),2) -> 0 | DN8: =ROUND(SUMIF($1:$1,DN$5,8:8),2) -> 0 | ... ED8: =ROUND(SUMIF($1:$1,ED$5,8:8),2) -> 0 | EE8: =SUM(DG8:ED8) -> 190.43 | EF8: =ROUND(SUM(EE8-BT8),2) -> 0 | EG8: =IF(DN8<>0,DN8-EF8,0) -> 0 | EH8: =IF(EG8=0,DO8-EF8,DO8) -> 0 | EI8: =SUM(DG8:DM8)+SUM(DP8:ED8)+EG8+EH8 -> 190.43
A9: =_xlfn.CONCAT(D9,L9) -> Manaus25.5 | B9: 4151 | C9: 4151 | D9: Manaus | F9: AMBEV | G9: CONTRATO | H9: FOB | K9: PREFORMA | L9: 25.5 | M9: CR | V9: Virgem | W9: 1 | X9: ALPEK | Y9: =IF($X9="",0,HLOOKUP($H$3,Resina!$E$2:$AK$93,MATCH($D9&$X9&$Y$5,Resina!$A$2:$A$93,0))) -> 1283.4027 | Z9: 0 | AB9: =IF($AA9="",0,HLOOKUP($H$3,Resina!$E$2:$AK$93,MATCH($D9&$AA9&$AB$5,Resina!$A$2:$A$93,0))) -> 0 | AC9: =$AC$7 -> 46091 | AD9: Mensal | AE9: =$AE$7 -> 45839 | AF9: MIL | AG9: =_xlfn.XLOOKUP($H$3,Resina!$2:$2,Resina!$3:$3,0) -> 5.2006167 | AH9: =(L9*((Y9*W9)+(AB9*Z9)))*AG9/1000 -> 170.19938 | AI9: 0.005 | AJ9: =AH9*AI9 -> 0.85099692 | AO9: =_xlfn.XLOOKUP($D9&$L9&$AK$3,'BD Conv'!$A:$A,'BD Conv'!$H:$H,0)*_xlfn.XLOOKUP($D9,'BD Conv'!$C$17:$C$19,'BD Conv'!$F$17:$F$19,0)*(1+(HLOOKUP($B9&AO$6,Indexadores!$C$2:$AH$32,MATCH($AE9,Indexadores!$A$2:$A$32,0)))) -> 0 | AS9: 0.005 | AT9: =(AU9+AO9)*AS9 -> 0 | AU9: =_xlfn.XLOOKUP($D9&$L9&$AK$3,'BD Conv'!$A:$A,'BD Conv'!$H:$H,0)*_xlfn.XLOOKUP($D9,'BD Conv'!$C$17:$C$19,'BD Conv'!$E$17:$E$19,0)*(1+(HLOOKUP($B9&AU$6,Indexadores!$C$2:$AH$32,MATCH($AE9,Indexadores!$A$2:$A$32,0)))) -> 0 | AV9: =SUM(AN9,AO9,AP9,(AQ9*AG9),AR9,AT9,AU9) -> 0 | AW9: =_xlfn.XLOOKUP($A9&$AK$3,'BD Conv'!$A:$A,'BD Conv'!$I:$I,0) -> 0 | AZ9: =SUM(AH9,AJ9,AK9,AL9,AV9,AW9:AY9) -> 171.05038 | BI9: =SUM(BA9,BB9,BC9,(BD9*AG9),BE9,BF9,BH9) -> 0 | BN9: =_xlfn.XLOOKUP($A9&$BA$3,'BD Conv'!$A:$A,'BD Conv'!$K:$K,0) -> 0 | BQ9: =SUM(BI9,BJ9,BK9,BM9,BN9,BO9,BP9) -> 0 | BR9: =-BQ9*$BR$3 -> 0 | BT9: =AZ9+BQ9+BR9+BS9 -> 171.05038 | BU9: =BV9-BT9 -> 43.137424 | BV9: =BT9/(1-(12%+1.65%+7.6%) +12%*(1.65%+7.6%)) -> 214.1878 | BY9: =BT9/CP9-1 -> 0.053548477 | BZ9: =(BT9-CP9)/AG9 -> 1.6717133 | CA9: =(BT9-CK9-CL9-AL9-AX9-AY9-BO9-BP9+CQ9)/AG9 -> 1.6717133 | CB9: =(BT9-AH9)/AG9 -> 0.16363385 | CD9: =CP9*(1+$CD$5) -> 178.59208 | CE9: =(CD9-CP9)/AG9 -> 3.121869 | CF9: =(CD9-CK9-CL9-AL9-AX9-AY9-BO9-BP9+CQ9)/AG9 -> 3.121869 | CG9: =(CD9-AH9)/AG9 -> 1.6137895 | CI9: =IF($X9="",0,HLOOKUP($H$3,Resina!$E$2:$AK$93,MATCH($D9&$X9&$CI$5,Resina!$A$2:$A$93,0))) -> 1212.1409 | CJ9: =IF($AA9="",0,HLOOKUP($H$3,Resina!$E$2:$AK$93,MATCH($D9&$AA9&$CJ$5,Resina!$A$2:$A$93,0))) -> 0 | CK9: =L9*((CI9*W9)+(CJ9*Z9))*AG9/1000 -> 160.74895 | CL9: =CK9*$CL$6 -> 1.6074895 | CM9: =IF(D9="Manaus FORA",-((CK9/0.88*0.12)*(1-9.25%))," ") | CO9: =AX9+AY9+BO9+BP9+AL9+AN9+BJ9+BK9+BM9 -> 0 | CP9: =SUM(CK9:CO9) -> 162.35644 | DE9: =_xlfn.CONCAT(D9,L9) -> Manaus25.5 | DF9: =L9 -> 25.5 | DG9: =ROUND(SUMIF($1:$1,DG$5,9:9),2) -> 170.2 | DH9: =ROUND(SUMIF($1:$1,DH$5,9:9),2) -> 0.85 | DI9: =ROUND(SUMIF($1:$1,DI$5,9:9),2) -> 0 | DJ9: =ROUND(SUMIF($1:$1,DJ$5,9:9),2) -> 0 | DK9: =ROUND(SUMIF($1:$1,DK$5,9:9),2) -> 0 | DL9: =ROUND(SUMIF($1:$1,DL$5,9:9),2) -> 0 | DM9: =ROUND(SUMIF($1:$1,DM$5,9:9),2) -> 0 | DN9: =ROUND(SUMIF($1:$1,DN$5,9:9),2) -> 0 | ... ED9: =ROUND(SUMIF($1:$1,ED$5,9:9),2) -> 0 | EE9: =SUM(DG9:ED9) -> 171.05 | EF9: =ROUND(SUM(EE9-BT9),2) -> 0 | EG9: =IF(DN9<>0,DN9-EF9,0) -> 0 | EH9: =IF(EG9=0,DO9-EF9,DO9) -> 0 | EI9: =SUM(DG9:DM9)+SUM(DP9:ED9)+EG9+EH9 -> 171.05
A10: =_xlfn.CONCAT(D10,L10) -> Manaus25.5 | B10: 4151 | C10: 4151 | D10: Manaus | F10: AMBEV | G10: CONTRATO | H10: FOB | K10: PREFORMA | L10: 25.5 | M10: CR | V10: Virgem | W10: 0.7 | X10: ALPEK | Y10: =IF($X10="",0,HLOOKUP($H$3,Resina!$E$2:$AK$93,MATCH($D10&$X10&$Y$5,Resina!$A$2:$A$93,0))) -> 1283.4027 | Z10: 0.3 | AA10: VG | AB10: =IF($AA10="",0,HLOOKUP($H$3,Resina!$E$2:$AK$93,MATCH($D10&$AA10&$AB$5,Resina!$A$2:$A$93,0))) -> 1720.8738 | AC10: =$AC$7 -> 46091 | AD10: Mensal | AE10: =$AE$7 -> 45839 | AF10: MIL | AG10: =_xlfn.XLOOKUP($H$3,Resina!$2:$2,Resina!$3:$3,0) -> 5.2006167 | AH10: =(L10*((Y10*W10)+(AB10*Z10)))*AG10/1000 -> 187.60404 | AI10: 0.005 | AJ10: =AH10*AI10 -> 0.93802022 | AO10: =_xlfn.XLOOKUP($D10&$L10&$AK$3,'BD Conv'!$A:$A,'BD Conv'!$H:$H,0)*_xlfn.XLOOKUP($D10,'BD Conv'!$C$17:$C$19,'BD Conv'!$F$17:$F$19,0)*(1+(HLOOKUP($B10&AO$6,Indexadores!$C$2:$AH$32,MATCH($AE10,Indexadores!$A$2:$A$32,0)))) -> 0 | AS10: 0.005 | AT10: =(AU10+AO10)*AS10 -> 0 | AU10: =_xlfn.XLOOKUP($D10&$L10&$AK$3,'BD Conv'!$A:$A,'BD Conv'!$H:$H,0)*_xlfn.XLOOKUP($D10,'BD Conv'!$C$17:$C$19,'BD Conv'!$E$17:$E$19,0)*(1+(HLOOKUP($B10&AU$6,Indexadores!$C$2:$AH$32,MATCH($AE10,Indexadores!$A$2:$A$32,0)))) -> 0 | AV10: =SUM(AN10,AO10,AP10,(AQ10*AG10),AR10,AT10,AU10) -> 0 | AW10: =_xlfn.XLOOKUP($A10&$AK$3,'BD Conv'!$A:$A,'BD Conv'!$I:$I,0) -> 0 | AZ10: =SUM(AH10,AJ10,AK10,AL10,AV10,AW10:AY10) -> 188.54207 | BI10: =SUM(BA10,BB10,BC10,(BD10*AG10),BE10,BF10,BH10) -> 0 | BN10: =_xlfn.XLOOKUP($A10&$BA$3,'BD Conv'!$A:$A,'BD Conv'!$K:$K,0) -> 0 | BQ10: =SUM(BI10,BJ10,BK10,BM10,BN10,BO10,BP10) -> 0 | BR10: =-BQ10*$BR$3 -> 0 | BT10: =AZ10+BQ10+BR10+BS10 -> 188.54207 | BU10: =BV10-BT10 -> 47.548675 | BV10: =BT10/(1-(12%+1.65%+7.6%) +12%*(1.65%+7.6%)) -> 236.09074 | BY10: =BT10/CP10-1 -> 0.023747623 | BZ10: =(BT10-CP10)/AG10 -> 0.84097028 | CA10: =(BT10-CK10-CL10-AL10-AX10-AY10-BO10-BP10+CQ10)/AG10 -> 0.84097028 | CB10: =(BT10-AH10)/AG10 -> 0.18036711 | CD10: =CP10*(1+$CD$5) -> 202.58535 | CE10: =(CD10-CP10)/AG10 -> 3.541282 | CF10: =(CD10-CK10-CL10-AL10-AX10-AY10-BO10-BP10+CQ10)/AG10 -> 3.541282 | CG10: =(CD10-AH10)/AG10 -> 2.8806788 | CI10: =IF($X10="",0,HLOOKUP($H$3,Resina!$E$2:$AK$93,MATCH($D10&$X10&$CI$5,Resina!$A$2:$A$93,0))) -> 1212.1409 | CJ10: =IF($AA10="",0,HLOOKUP($H$3,Resina!$E$2:$AK$93,MATCH($D10&$AA10&$CJ$5,Resina!$A$2:$A$93,0))) -> 1754.965 | CK10: =L10*((CI10*W10)+(CJ10*Z10))*AG10/1000 -> 182.34505 | CL10: =CK10*$CL$6 -> 1.8234505 | CM10: =IF(D10="Manaus FORA",-((CK10/0.88*0.12)*(1-9.25%))," ") | CO10: =AX10+AY10+BO10+BP10+AL10+AN10+BJ10+BK10+BM10 -> 0 | CP10: =SUM(CK10:CO10) -> 184.1685 | DE10: =_xlfn.CONCAT(D10,L10) -> Manaus25.5 | DF10: =L10 -> 25.5 | DG10: =ROUND(SUMIF($1:$1,DG$5,10:10),2) -> 187.6 | DH10: =ROUND(SUMIF($1:$1,DH$5,10:10),2) -> 0.94 | DI10: =ROUND(SUMIF($1:$1,DI$5,10:10),2) -> 0 | DJ10: =ROUND(SUMIF($1:$1,DJ$5,10:10),2) -> 0 | DK10: =ROUND(SUMIF($1:$1,DK$5,10:10),2) -> 0 | DL10: =ROUND(SUMIF($1:$1,DL$5,10:10),2) -> 0 | DM10: =ROUND(SUMIF($1:$1,DM$5,10:10),2) -> 0 | DN10: =ROUND(SUMIF($1:$1,DN$5,10:10),2) -> 0 | ... ED10: =ROUND(SUMIF($1:$1,ED$5,10:10),2) -> 0 | EE10: =SUM(DG10:ED10) -> 188.54 | EF10: =ROUND(SUM(EE10-BT10),2) -> 0 | EG10: =IF(DN10<>0,DN10-EF10,0) -> 0 | EH10: =IF(EG10=0,DO10-EF10,DO10) -> 0 | EI10: =SUM(DG10:DM10)+SUM(DP10:ED10)+EG10+EH10 -> 188.54
A11: =_xlfn.CONCAT(D11,L11) -> Manaus38 | B11: 4151 | C11: 4151 | D11: Manaus | F11: AMBEV | G11: CONTRATO | H11: FOB | K11: PREFORMA | L11: 38 | M11: CR | V11: Virgem | W11: 1 | X11: ALPEK | Y11: =IF($X11="",0,HLOOKUP($H$3,Resina!$E$2:$AK$93,MATCH($D11&$X11&$Y$5,Resina!$A$2:$A$93,0))) -> 1283.4027 | Z11: 0 | AA11: VG | AB11: =IF($AA11="",0,HLOOKUP($H$3,Resina!$E$2:$AK$93,MATCH($D11&$AA11&$AB$5,Resina!$A$2:$A$93,0))) -> 1720.8738 | AC11: =$AC$7 -> 46091 | AD11: Mensal | AE11: =$AE$7 -> 45839 | AF11: MIL | AG11: =_xlfn.XLOOKUP($H$3,Resina!$2:$2,Resina!$3:$3,0) -> 5.2006167 | AH11: =(L11*((Y11*W11)+(AB11*Z11)))*AG11/1000 -> 253.63045 | AI11: 0.005 | AJ11: =AH11*AI11 -> 1.2681523 | AO11: =_xlfn.XLOOKUP($D11&$L11&$AK$3,'BD Conv'!$A:$A,'BD Conv'!$H:$H,0)*_xlfn.XLOOKUP($D11,'BD Conv'!$C$17:$C$19,'BD Conv'!$F$17:$F$19,0)*(1+(HLOOKUP($B11&AO$6,Indexadores!$C$2:$AH$32,MATCH($AE11,Indexadores!$A$2:$A$32,0)))) -> 14.28 | AS11: 0.005 | AT11: =(AU11+AO11)*AS11 -> 0.357 | AU11: =_xlfn.XLOOKUP($D11&$L11&$AK$3,'BD Conv'!$A:$A,'BD Conv'!$H:$H,0)*_xlfn.XLOOKUP($D11,'BD Conv'!$C$17:$C$19,'BD Conv'!$E$17:$E$19,0)*(1+(HLOOKUP($B11&AU$6,Indexadores!$C$2:$AH$32,MATCH($AE11,Indexadores!$A$2:$A$32,0)))) -> 57.12 | AV11: =SUM(AN11,AO11,AP11,(AQ11*AG11),AR11,AT11,AU11) -> 71.757 | AW11: =_xlfn.XLOOKUP($A11&$AK$3,'BD Conv'!$A:$A,'BD Conv'!$I:$I,0) -> 0 | AZ11: =SUM(AH11,AJ11,AK11,AL11,AV11,AW11:AY11) -> 326.65561 | BI11: =SUM(BA11,BB11,BC11,(BD11*AG11),BE11,BF11,BH11) -> 0 | BN11: =_xlfn.XLOOKUP($A11&$BA$3,'BD Conv'!$A:$A,'BD Conv'!$K:$K,0) -> 0 | BQ11: =SUM(BI11,BJ11,BK11,BM11,BN11,BO11,BP11) -> 0 | BR11: =-BQ11*$BR$3 -> 0 | BT11: =AZ11+BQ11+BR11+BS11 -> 326.65561 | BU11: =BV11-BT11 -> 82.379713 | BV11: =BT11/(1-(12%+1.65%+7.6%) +12%*(1.65%+7.6%)) -> 409.03532 | BY11: =BT11/CP11-1 -> 0.35013495 | BZ11: =(BT11-CP11)/AG11 -> 16.288967 | CA11: =(BT11-CK11-CL11-AL11-AX11-AY11-BO11-BP11+CQ11)/AG11 -> 16.288967 | CB11: =(BT11-AH11)/AG11 -> 14.041633 | CD11: =CP11*(1+$CD$5) -> 266.13722 | CE11: =(CD11-CP11)/AG11 -> 4.652197 | CF11: =(CD11-CK11-CL11-AL11-AX11-AY11-BO11-BP11+CQ11)/AG11 -> 4.652197 | CG11: =(CD11-AH11)/AG11 -> 2.4048629 | CI11: =IF($X11="",0,HLOOKUP($H$3,Resina!$E$2:$AK$93,MATCH($D11&$X11&$CI$5,Resina!$A$2:$A$93,0))) -> 1212.1409 | CJ11: =IF($AA11="",0,HLOOKUP($H$3,Resina!$E$2:$AK$93,MATCH($D11&$AA11&$CJ$5,Resina!$A$2:$A$93,0))) -> 1754.965 | CK11: =L11*((CI11*W11)+(CJ11*Z11))*AG11/1000 -> 239.54746 | CL11: =CK11*$CL$6 -> 2.3954746 | CM11: =IF(D11="Manaus FORA",-((CK11/0.88*0.12)*(1-9.25%))," ") | CO11: =AX11+AY11+BO11+BP11+AL11+AN11+BJ11+BK11+BM11 -> 0 | CP11: =SUM(CK11:CO11) -> 241.94293 | DE11: =_xlfn.CONCAT(D11,L11) -> Manaus38 | DF11: =L11 -> 38 | DG11: =ROUND(SUMIF($1:$1,DG$5,11:11),2) -> 253.63 | DH11: =ROUND(SUMIF($1:$1,DH$5,11:11),2) -> 1.63 | DI11: =ROUND(SUMIF($1:$1,DI$5,11:11),2) -> 0 | DJ11: =ROUND(SUMIF($1:$1,DJ$5,11:11),2) -> 0 | DK11: =ROUND(SUMIF($1:$1,DK$5,11:11),2) -> 0 | DL11: =ROUND(SUMIF($1:$1,DL$5,11:11),2) -> 0 | DM11: =ROUND(SUMIF($1:$1,DM$5,11:11),2) -> 0 | DN11: =ROUND(SUMIF($1:$1,DN$5,11:11),2) -> 57.12 | ... ED11: =ROUND(SUMIF($1:$1,ED$5,11:11),2) -> 0 | EE11: =SUM(DG11:ED11) -> 326.66 | EF11: =ROUND(SUM(EE11-BT11),2) -> 0 | EG11: =IF(DN11<>0,DN11-EF11,0) -> 57.12 | EH11: =IF(EG11=0,DO11-EF11,DO11) -> 0 | EI11: =SUM(DG11:DM11)+SUM(DP11:ED11)+EG11+EH11 -> 326.66
A12: =_xlfn.CONCAT(D12,L12) -> Manaus38 | B12: 4151 | C12: 4151 | D12: Manaus | F12: AMBEV | G12: CONTRATO | H12: FOB | K12: PREFORMA | L12: 38 | M12: CR | V12: Virgem | W12: 0.6 | X12: ALPEK | Y12: =IF($X12="",0,HLOOKUP($H$3,Resina!$E$2:$AK$93,MATCH($D12&$X12&$Y$5,Resina!$A$2:$A$93,0))) -> 1283.4027 | Z12: 0.4 | AA12: VG | AB12: =IF($AA12="",0,HLOOKUP($H$3,Resina!$E$2:$AK$93,MATCH($D12&$AA12&$AB$5,Resina!$A$2:$A$93,0))) -> 1720.8738 | AC12: =$AC$7 -> 46091 | AD12: Mensal | AE12: =$AE$7 -> 45839 | AF12: MIL | AG12: =_xlfn.XLOOKUP($H$3,Resina!$2:$2,Resina!$3:$3,0) -> 5.2006167 | AH12: =(L12*((Y12*W12)+(AB12*Z12)))*AG12/1000 -> 288.21226 | AI12: 0.005 | AJ12: =AH12*AI12 -> 1.4410613 | AO12: =_xlfn.XLOOKUP($D12&$L12&$AK$3,'BD Conv'!$A:$A,'BD Conv'!$H:$H,0)*_xlfn.XLOOKUP($D12,'BD Conv'!$C$17:$C$19,'BD Conv'!$F$17:$F$19,0)*(1+(HLOOKUP($B12&AO$6,Indexadores!$C$2:$AH$32,MATCH($AE12,Indexadores!$A$2:$A$32,0)))) -> 14.28 | AS12: 0.005 | AT12: =(AU12+AO12)*AS12 -> 0.357 | AU12: =_xlfn.XLOOKUP($D12&$L12&$AK$3,'BD Conv'!$A:$A,'BD Conv'!$H:$H,0)*_xlfn.XLOOKUP($D12,'BD Conv'!$C$17:$C$19,'BD Conv'!$E$17:$E$19,0)*(1+(HLOOKUP($B12&AU$6,Indexadores!$C$2:$AH$32,MATCH($AE12,Indexadores!$A$2:$A$32,0)))) -> 57.12 | AV12: =SUM(AN12,AO12,AP12,(AQ12*AG12),AR12,AT12,AU12) -> 71.757 | AW12: =_xlfn.XLOOKUP($A12&$AK$3,'BD Conv'!$A:$A,'BD Conv'!$I:$I,0) -> 0 | AZ12: =SUM(AH12,AJ12,AK12,AL12,AV12,AW12:AY12) -> 361.41033 | BI12: =SUM(BA12,BB12,BC12,(BD12*AG12),BE12,BF12,BH12) -> 0 | BN12: =_xlfn.XLOOKUP($A12&$BA$3,'BD Conv'!$A:$A,'BD Conv'!$K:$K,0) -> 0 | BQ12: =SUM(BI12,BJ12,BK12,BM12,BN12,BO12,BP12) -> 0 | BR12: =-BQ12*$BR$3 -> 0 | BT12: =AZ12+BQ12+BR12+BS12 -> 361.41033 | BU12: =BV12-BT12 -> 91.144553 | BV12: =BT12/(1-(12%+1.65%+7.6%) +12%*(1.65%+7.6%)) -> 452.55488 | BY12: =BT12/CP12-1 -> 0.26685321 | BZ12: =(BT12-CP12)/AG12 -> 14.638341 | CA12: =(BT12-CK12-CL12-AL12-AX12-AY12-BO12-BP12+CQ12)/AG12 -> 14.638341 | CB12: =(BT12-AH12)/AG12 -> 14.074881 | CD12: =CP12*(1+$CD$5) -> 313.81012 | CE12: =(CD12-CP12)/AG12 -> 5.4855404 | CF12: =(CD12-CK12-CL12-AL12-AX12-AY12-BO12-BP12+CQ12)/AG12 -> 5.4855404 | CG12: =(CD12-AH12)/AG12 -> 4.9220808 | CI12: =IF($X12="",0,HLOOKUP($H$3,Resina!$E$2:$AK$93,MATCH($D12&$X12&$CI$5,Resina!$A$2:$A$93,0))) -> 1212.1409 | CJ12: =IF($AA12="",0,HLOOKUP($H$3,Resina!$E$2:$AK$93,MATCH($D12&$AA12&$CJ$5,Resina!$A$2:$A$93,0))) -> 1754.965 | CK12: =L12*((CI12*W12)+(CJ12*Z12))*AG12/1000 -> 282.45735 | CL12: =CK12*$CL$6 -> 2.8245735 | CM12: =IF(D12="Manaus FORA",-((CK12/0.88*0.12)*(1-9.25%))," ") | CO12: =AX12+AY12+BO12+BP12+AL12+AN12+BJ12+BK12+BM12 -> 0 | CP12: =SUM(CK12:CO12) -> 285.28193 | DE12: =_xlfn.CONCAT(D12,L12) -> Manaus38 | DF12: =L12 -> 38 | DG12: =ROUND(SUMIF($1:$1,DG$5,12:12),2) -> 288.21 | DH12: =ROUND(SUMIF($1:$1,DH$5,12:12),2) -> 1.8 | DI12: =ROUND(SUMIF($1:$1,DI$5,12:12),2) -> 0 | DJ12: =ROUND(SUMIF($1:$1,DJ$5,12:12),2) -> 0 | DK12: =ROUND(SUMIF($1:$1,DK$5,12:12),2) -> 0 | DL12: =ROUND(SUMIF($1:$1,DL$5,12:12),2) -> 0 | DM12: =ROUND(SUMIF($1:$1,DM$5,12:12),2) -> 0 | DN12: =ROUND(SUMIF($1:$1,DN$5,12:12),2) -> 57.12 | ... ED12: =ROUND(SUMIF($1:$1,ED$5,12:12),2) -> 0 | EE12: =SUM(DG12:ED12) -> 361.41 | EF12: =ROUND(SUM(EE12-BT12),2) -> 0 | EG12: =IF(DN12<>0,DN12-EF12,0) -> 57.12 | EH12: =IF(EG12=0,DO12-EF12,DO12) -> 0 | EI12: =SUM(DG12:DM12)+SUM(DP12:ED12)+EG12+EH12 -> 361.41
A13: =_xlfn.CONCAT(D13,L13) -> Manaus38 | B13: 4151 | C13: 4151 | D13: Manaus | F13: AMBEV | G13: CONTRATO | H13: FOB | K13: PREFORMA | L13: 38 | M13: CR | V13: Virgem | W13: 0.4 | X13: ALPEK | Y13: =IF($X13="",0,HLOOKUP($H$3,Resina!$E$2:$AK$93,MATCH($D13&$X13&$Y$5,Resina!$A$2:$A$93,0))) -> 1283.4027 | Z13: 0.6 | AA13: VG | AB13: =IF($AA13="",0,HLOOKUP($H$3,Resina!$E$2:$AK$93,MATCH($D13&$AA13&$AB$5,Resina!$A$2:$A$93,0))) -> 1720.8738 | AC13: =$AC$7 -> 46091 | AD13: Mensal | AE13: =$AE$7 -> 45839 | AF13: MIL | AG13: =_xlfn.XLOOKUP($H$3,Resina!$2:$2,Resina!$3:$3,0) -> 5.2006167 | AH13: =(L13*((Y13*W13)+(AB13*Z13)))*AG13/1000 -> 305.50317 | AI13: 0.005 | AJ13: =AH13*AI13 -> 1.5275159 | AO13: =_xlfn.XLOOKUP($D13&$L13&$AK$3,'BD Conv'!$A:$A,'BD Conv'!$H:$H,0)*_xlfn.XLOOKUP($D13,'BD Conv'!$C$17:$C$19,'BD Conv'!$F$17:$F$19,0)*(1+(HLOOKUP($B13&AO$6,Indexadores!$C$2:$AH$32,MATCH($AE13,Indexadores!$A$2:$A$32,0)))) -> 14.28 | AS13: 0.005 | AT13: =(AU13+AO13)*AS13 -> 0.357 | AU13: =_xlfn.XLOOKUP($D13&$L13&$AK$3,'BD Conv'!$A:$A,'BD Conv'!$H:$H,0)*_xlfn.XLOOKUP($D13,'BD Conv'!$C$17:$C$19,'BD Conv'!$E$17:$E$19,0)*(1+(HLOOKUP($B13&AU$6,Indexadores!$C$2:$AH$32,MATCH($AE13,Indexadores!$A$2:$A$32,0)))) -> 57.12 | AV13: =SUM(AN13,AO13,AP13,(AQ13*AG13),AR13,AT13,AU13) -> 71.757 | AW13: =_xlfn.XLOOKUP($A13&$AK$3,'BD Conv'!$A:$A,'BD Conv'!$I:$I,0) -> 0 | AZ13: =SUM(AH13,AJ13,AK13,AL13,AV13,AW13:AY13) -> 378.78769 | BI13: =SUM(BA13,BB13,BC13,(BD13*AG13),BE13,BF13,BH13) -> 0 | BN13: =_xlfn.XLOOKUP($A13&$BA$3,'BD Conv'!$A:$A,'BD Conv'!$K:$K,0) -> 0 | BQ13: =SUM(BI13,BJ13,BK13,BM13,BN13,BO13,BP13) -> 0 | BR13: =-BQ13*$BR$3 -> 0 | BT13: =AZ13+BQ13+BR13+BS13 -> 378.78769 | BU13: =BV13-BT13 -> 95.526972 | BV13: =BT13/(1-(12%+1.65%+7.6%) +12%*(1.65%+7.6%)) -> 474.31466 | BY13: =BT13/CP13-1 -> 0.23403136 | BZ13: =(BT13-CP13)/AG13 -> 13.813027 | CA13: =(BT13-CK13-CL13-AL13-AX13-AY13-BO13-BP13+CQ13)/AG13 -> 13.813027 | CB13: =(BT13-AH13)/AG13 -> 14.091505 | CD13: =CP13*(1+$CD$5) -> 337.64657 | CE13: =(CD13-CP13)/AG13 -> 5.9022121 | CF13: =(CD13-CK13-CL13-AL13-AX13-AY13-BO13-BP13+CQ13)/AG13 -> 5.9022121 | CG13: =(CD13-AH13)/AG13 -> 6.1806897 | CI13: =IF($X13="",0,HLOOKUP($H$3,Resina!$E$2:$AK$93,MATCH($D13&$X13&$CI$5,Resina!$A$2:$A$93,0))) -> 1212.1409 | CJ13: =IF($AA13="",0,HLOOKUP($H$3,Resina!$E$2:$AK$93,MATCH($D13&$AA13&$CJ$5,Resina!$A$2:$A$93,0))) -> 1754.965 | CK13: =L13*((CI13*W13)+(CJ13*Z13))*AG13/1000 -> 303.9123 | CL13: =CK13*$CL$6 -> 3.039123 | CM13: =IF(D13="Manaus FORA",-((CK13/0.88*0.12)*(1-9.25%))," ") | CO13: =AX13+AY13+BO13+BP13+AL13+AN13+BJ13+BK13+BM13 -> 0 | CP13: =SUM(CK13:CO13) -> 306.95143 | DE13: =_xlfn.CONCAT(D13,L13) -> Manaus38 | DF13: =L13 -> 38 | DG13: =ROUND(SUMIF($1:$1,DG$5,13:13),2) -> 305.5 | DH13: =ROUND(SUMIF($1:$1,DH$5,13:13),2) -> 1.88 | DI13: =ROUND(SUMIF($1:$1,DI$5,13:13),2) -> 0 | DJ13: =ROUND(SUMIF($1:$1,DJ$5,13:13),2) -> 0 | DK13: =ROUND(SUMIF($1:$1,DK$5,13:13),2) -> 0 | DL13: =ROUND(SUMIF($1:$1,DL$5,13:13),2) -> 0 | DM13: =ROUND(SUMIF($1:$1,DM$5,13:13),2) -> 0 | DN13: =ROUND(SUMIF($1:$1,DN$5,13:13),2) -> 57.12 | ... ED13: =ROUND(SUMIF($1:$1,ED$5,13:13),2) -> 0 | EE13: =SUM(DG13:ED13) -> 378.78 | EF13: =ROUND(SUM(EE13-BT13),2) -> -0.01 | EG13: =IF(DN13<>0,DN13-EF13,0) -> 57.13 | EH13: =IF(EG13=0,DO13-EF13,DO13) -> 0 | EI13: =SUM(DG13:DM13)+SUM(DP13:ED13)+EG13+EH13 -> 378.79
A14: =_xlfn.CONCAT(D14,L14) -> Manaus38 | B14: 4151 | C14: 4151 | D14: Manaus | F14: AMBEV | G14: CONTRATO | H14: FOB | K14: PREFORMA | L14: 38 | M14: CR | V14: Virgem | W14: 0 | Y14: =IF($X14="",0,HLOOKUP($H$3,Resina!$E$2:$AK$93,MATCH($D14&$X14&$Y$5,Resina!$A$2:$A$93,0))) -> 0 | Z14: 1 | AA14: VG | AB14: =IF($AA14="",0,HLOOKUP($H$3,Resina!$E$2:$AK$93,MATCH($D14&$AA14&$AB$5,Resina!$A$2:$A$93,0))) -> 1720.8738 | AC14: =$AC$7 -> 46091 | AD14: Mensal | AE14: =$AE$7 -> 45839 | AF14: MIL | AG14: =_xlfn.XLOOKUP($H$3,Resina!$2:$2,Resina!$3:$3,0) -> 5.2006167 | AH14: =(L14*((Y14*W14)+(AB14*Z14)))*AG14/1000 -> 340.08498 | AI14: 0.005 | AJ14: =AH14*AI14 -> 1.7004249 | AO14: =_xlfn.XLOOKUP($D14&$L14&$AK$3,'BD Conv'!$A:$A,'BD Conv'!$H:$H,0)*_xlfn.XLOOKUP($D14,'BD Conv'!$C$17:$C$19,'BD Conv'!$F$17:$F$19,0)*(1+(HLOOKUP($B14&AO$6,Indexadores!$C$2:$AH$32,MATCH($AE14,Indexadores!$A$2:$A$32,0)))) -> 14.28 | AS14: 0.005 | AT14: =(AU14+AO14)*AS14 -> 0.357 | AU14: =_xlfn.XLOOKUP($D14&$L14&$AK$3,'BD Conv'!$A:$A,'BD Conv'!$H:$H,0)*_xlfn.XLOOKUP($D14,'BD Conv'!$C$17:$C$19,'BD Conv'!$E$17:$E$19,0)*(1+(HLOOKUP($B14&AU$6,Indexadores!$C$2:$AH$32,MATCH($AE14,Indexadores!$A$2:$A$32,0)))) -> 57.12 | AV14: =SUM(AN14,AO14,AP14,(AQ14*AG14),AR14,AT14,AU14) -> 71.757 | AW14: =_xlfn.XLOOKUP($A14&$AK$3,'BD Conv'!$A:$A,'BD Conv'!$I:$I,0) -> 0 | AZ14: =SUM(AH14,AJ14,AK14,AL14,AV14,AW14:AY14) -> 413.54241 | BI14: =SUM(BA14,BB14,BC14,(BD14*AG14),BE14,BF14,BH14) -> 0 | BN14: =_xlfn.XLOOKUP($A14&$BA$3,'BD Conv'!$A:$A,'BD Conv'!$K:$K,0) -> 0 | BQ14: =SUM(BI14,BJ14,BK14,BM14,BN14,BO14,BP14) -> 0 | BR14: =-BQ14*$BR$3 -> 0 | BT14: =AZ14+BQ14+BR14+BS14 -> 413.54241 | BU14: =BV14-BT14 -> 104.29181 | BV14: =BT14/(1-(12%+1.65%+7.6%) +12%*(1.65%+7.6%)) -> 517.83422 | BY14: =BT14/CP14-1 -> 0.18057012 | BZ14: =(BT14-CP14)/AG14 -> 12.162401 | CA14: =(BT14-CK14-CL14-AL14-AX14-AY14-BO14-BP14+CQ14)/AG14 -> 12.162401 | CB14: =(BT14-AH14)/AG14 -> 14.124753 | CD14: =CP14*(1+$CD$5) -> 385.31946 | CE14: =(CD14-CP14)/AG14 -> 6.7355555 | CF14: =(CD14-CK14-CL14-AL14-AX14-AY14-BO14-BP14+CQ14)/AG14 -> 6.7355555 | CG14: =(CD14-AH14)/AG14 -> 8.6979076 | CI14: =IF($X14="",0,HLOOKUP($H$3,Resina!$E$2:$AK$93,MATCH($D14&$X14&$CI$5,Resina!$A$2:$A$93,0))) -> 0 | CJ14: =IF($AA14="",0,HLOOKUP($H$3,Resina!$E$2:$AK$93,MATCH($D14&$AA14&$CJ$5,Resina!$A$2:$A$93,0))) -> 1754.965 | CK14: =L14*((CI14*W14)+(CJ14*Z14))*AG14/1000 -> 346.8222 | CL14: =CK14*$CL$6 -> 3.468222 | CM14: =IF(D14="Manaus FORA",-((CK14/0.88*0.12)*(1-9.25%))," ") | CO14: =AX14+AY14+BO14+BP14+AL14+AN14+BJ14+BK14+BM14 -> 0 | CP14: =SUM(CK14:CO14) -> 350.29042 | DE14: =_xlfn.CONCAT(D14,L14) -> Manaus38 | DF14: =L14 -> 38 | DG14: =ROUND(SUMIF($1:$1,DG$5,14:14),2) -> 340.08 | DH14: =ROUND(SUMIF($1:$1,DH$5,14:14),2) -> 2.06 | DI14: =ROUND(SUMIF($1:$1,DI$5,14:14),2) -> 0 | DJ14: =ROUND(SUMIF($1:$1,DJ$5,14:14),2) -> 0 | DK14: =ROUND(SUMIF($1:$1,DK$5,14:14),2) -> 0 | DL14: =ROUND(SUMIF($1:$1,DL$5,14:14),2) -> 0 | DM14: =ROUND(SUMIF($1:$1,DM$5,14:14),2) -> 0 | DN14: =ROUND(SUMIF($1:$1,DN$5,14:14),2) -> 57.12 | ... ED14: =ROUND(SUMIF($1:$1,ED$5,14:14),2) -> 0 | EE14: =SUM(DG14:ED14) -> 413.54 | EF14: =ROUND(SUM(EE14-BT14),2) -> 0 | EG14: =IF(DN14<>0,DN14-EF14,0) -> 57.12 | EH14: =IF(EG14=0,DO14-EF14,DO14) -> 0 | EI14: =SUM(DG14:DM14)+SUM(DP14:ED14)+EG14+EH14 -> 413.54
A15: =_xlfn.CONCAT(D15,L15) -> Manaus38 | B15: 4151 | C15: 4151 | D15: Manaus | F15: AMBEV | G15: CONTRATO | H15: FOB | K15: PREFORMA | L15: 38 | M15: VD | V15: Virgem | W15: 1 | X15: ALPEK | Y15: =IF($X15="",0,HLOOKUP($H$3,Resina!$E$2:$AK$93,MATCH($D15&$X15&$Y$5,Resina!$A$2:$A$93,0))) -> 1283.4027 | Z15: 0 | AA15: VG | AB15: =IF($AA15="",0,HLOOKUP($H$3,Resina!$E$2:$AK$93,MATCH($D15&$AA15&$AB$5,Resina!$A$2:$A$93,0))) -> 1720.8738 | AC15: =$AC$7 -> 46091 | AD15: Mensal | AE15: =$AE$7 -> 45839 | AF15: MIL | AG15: =_xlfn.XLOOKUP($H$3,Resina!$2:$2,Resina!$3:$3,0) -> 5.2006167 | AH15: =(L15*((Y15*W15)+(AB15*Z15)))*AG15/1000 -> 253.63045 | AI15: 0.005 | AJ15: =AH15*AI15 -> 1.2681523 | AO15: =_xlfn.XLOOKUP($D15&$L15&$AK$3,'BD Conv'!$A:$A,'BD Conv'!$H:$H,0)*_xlfn.XLOOKUP($D15,'BD Conv'!$C$17:$C$19,'BD Conv'!$F$17:$F$19,0)*(1+(HLOOKUP($B15&AO$6,Indexadores!$C$2:$AH$32,MATCH($AE15,Indexadores!$A$2:$A$32,0)))) -> 14.28 | AS15: 0.005 | AT15: =(AU15+AO15)*AS15 -> 0.357 | AU15: =_xlfn.XLOOKUP($D15&$L15&$AK$3,'BD Conv'!$A:$A,'BD Conv'!$H:$H,0)*_xlfn.XLOOKUP($D15,'BD Conv'!$C$17:$C$19,'BD Conv'!$E$17:$E$19,0)*(1+(HLOOKUP($B15&AU$6,Indexadores!$C$2:$AH$32,MATCH($AE15,Indexadores!$A$2:$A$32,0)))) -> 57.12 | AV15: =SUM(AN15,AO15,AP15,(AQ15*AG15),AR15,AT15,AU15) -> 71.757 | AW15: =_xlfn.XLOOKUP($A15&$AK$3,'BD Conv'!$A:$A,'BD Conv'!$I:$I,0) -> 0 | AZ15: =SUM(AH15,AJ15,AK15,AL15,AV15,AW15:AY15) -> 326.65561 | BI15: =SUM(BA15,BB15,BC15,(BD15*AG15),BE15,BF15,BH15) -> 0 | BN15: =_xlfn.XLOOKUP($A15&$BA$3,'BD Conv'!$A:$A,'BD Conv'!$K:$K,0) -> 0 | BQ15: =SUM(BI15,BJ15,BK15,BM15,BN15,BO15,BP15) -> 0 | BR15: =-BQ15*$BR$3 -> 0 | BT15: =AZ15+BQ15+BR15+BS15 -> 326.65561 | BU15: =BV15-BT15 -> 82.379713 | BV15: =BT15/(1-(12%+1.65%+7.6%) +12%*(1.65%+7.6%)) -> 409.03532 | BY15: =BT15/CP15-1 -> 0.35013495 | BZ15: =(BT15-CP15)/AG15 -> 16.288967 | CA15: =(BT15-CK15-CL15-AL15-AX15-AY15-BO15-BP15+CQ15)/AG15 -> 16.288967 | CB15: =(BT15-AH15)/AG15 -> 14.041633 | CD15: =CP15*(1+$CD$5) -> 266.13722 | CE15: =(CD15-CP15)/AG15 -> 4.652197 | CF15: =(CD15-CK15-CL15-AL15-AX15-AY15-BO15-BP15+CQ15)/AG15 -> 4.652197 | CG15: =(CD15-AH15)/AG15 -> 2.4048629 | CI15: =IF($X15="",0,HLOOKUP($H$3,Resina!$E$2:$AK$93,MATCH($D15&$X15&$CI$5,Resina!$A$2:$A$93,0))) -> 1212.1409 | CJ15: =IF($AA15="",0,HLOOKUP($H$3,Resina!$E$2:$AK$93,MATCH($D15&$AA15&$CJ$5,Resina!$A$2:$A$93,0))) -> 1754.965 | CK15: =L15*((CI15*W15)+(CJ15*Z15))*AG15/1000 -> 239.54746 | CL15: =CK15*$CL$6 -> 2.3954746 | CM15: =IF(D15="Manaus FORA",-((CK15/0.88*0.12)*(1-9.25%))," ") | CO15: =AX15+AY15+BO15+BP15+AL15+AN15+BJ15+BK15+BM15 -> 0 | CP15: =SUM(CK15:CO15) -> 241.94293 | DE15: =_xlfn.CONCAT(D15,L15) -> Manaus38 | DF15: =L15 -> 38 | DG15: =ROUND(SUMIF($1:$1,DG$5,15:15),2) -> 253.63 | DH15: =ROUND(SUMIF($1:$1,DH$5,15:15),2) -> 1.63 | DI15: =ROUND(SUMIF($1:$1,DI$5,15:15),2) -> 0 | DJ15: =ROUND(SUMIF($1:$1,DJ$5,15:15),2) -> 0 | DK15: =ROUND(SUMIF($1:$1,DK$5,15:15),2) -> 0 | DL15: =ROUND(SUMIF($1:$1,DL$5,15:15),2) -> 0 | DM15: =ROUND(SUMIF($1:$1,DM$5,15:15),2) -> 0 | DN15: =ROUND(SUMIF($1:$1,DN$5,15:15),2) -> 57.12 | ... ED15: =ROUND(SUMIF($1:$1,ED$5,15:15),2) -> 0 | EE15: =SUM(DG15:ED15) -> 326.66 | EF15: =ROUND(SUM(EE15-BT15),2) -> 0 | EG15: =IF(DN15<>0,DN15-EF15,0) -> 57.12 | EH15: =IF(EG15=0,DO15-EF15,DO15) -> 0 | EI15: =SUM(DG15:DM15)+SUM(DP15:ED15)+EG15+EH15 -> 326.66
A16: =_xlfn.CONCAT(D16,L16) -> Manaus38 | B16: 4151 | C16: 4151 | D16: Manaus | F16: AMBEV | G16: CONTRATO | H16: FOB | K16: PREFORMA | L16: 38 | M16: VD | V16: Virgem | W16: 0.6 | X16: ALPEK | Y16: =IF($X16="",0,HLOOKUP($H$3,Resina!$E$2:$AK$93,MATCH($D16&$X16&$Y$5,Resina!$A$2:$A$93,0))) -> 1283.4027 | Z16: 0.4 | AA16: VG | AB16: =IF($AA16="",0,HLOOKUP($H$3,Resina!$E$2:$AK$93,MATCH($D16&$AA16&$AB$5,Resina!$A$2:$A$93,0))) -> 1720.8738 | AC16: =$AC$7 -> 46091 | AD16: Mensal | AE16: =$AE$7 -> 45839 | AF16: MIL | AG16: =_xlfn.XLOOKUP($H$3,Resina!$2:$2,Resina!$3:$3,0) -> 5.2006167 | AH16: =(L16*((Y16*W16)+(AB16*Z16)))*AG16/1000 -> 288.21226 | AI16: 0.005 | AJ16: =AH16*AI16 -> 1.4410613 | AO16: =_xlfn.XLOOKUP($D16&$L16&$AK$3,'BD Conv'!$A:$A,'BD Conv'!$H:$H,0)*_xlfn.XLOOKUP($D16,'BD Conv'!$C$17:$C$19,'BD Conv'!$F$17:$F$19,0)*(1+(HLOOKUP($B16&AO$6,Indexadores!$C$2:$AH$32,MATCH($AE16,Indexadores!$A$2:$A$32,0)))) -> 14.28 | AS16: 0.005 | AT16: =(AU16+AO16)*AS16 -> 0.357 | AU16: =_xlfn.XLOOKUP($D16&$L16&$AK$3,'BD Conv'!$A:$A,'BD Conv'!$H:$H,0)*_xlfn.XLOOKUP($D16,'BD Conv'!$C$17:$C$19,'BD Conv'!$E$17:$E$19,0)*(1+(HLOOKUP($B16&AU$6,Indexadores!$C$2:$AH$32,MATCH($AE16,Indexadores!$A$2:$A$32,0)))) -> 57.12 | AV16: =SUM(AN16,AO16,AP16,(AQ16*AG16),AR16,AT16,AU16) -> 71.757 | AW16: =_xlfn.XLOOKUP($A16&$AK$3,'BD Conv'!$A:$A,'BD Conv'!$I:$I,0) -> 0 | AZ16: =SUM(AH16,AJ16,AK16,AL16,AV16,AW16:AY16) -> 361.41033 | BI16: =SUM(BA16,BB16,BC16,(BD16*AG16),BE16,BF16,BH16) -> 0 | BN16: =_xlfn.XLOOKUP($A16&$BA$3,'BD Conv'!$A:$A,'BD Conv'!$K:$K,0) -> 0 | BQ16: =SUM(BI16,BJ16,BK16,BM16,BN16,BO16,BP16) -> 0 | BR16: =-BQ16*$BR$3 -> 0 | BT16: =AZ16+BQ16+BR16+BS16 -> 361.41033 | BU16: =BV16-BT16 -> 91.144553 | BV16: =BT16/(1-(12%+1.65%+7.6%) +12%*(1.65%+7.6%)) -> 452.55488 | BY16: =BT16/CP16-1 -> 0.26685321 | BZ16: =(BT16-CP16)/AG16 -> 14.638341 | CA16: =(BT16-CK16-CL16-AL16-AX16-AY16-BO16-BP16+CQ16)/AG16 -> 14.638341 | CB16: =(BT16-AH16)/AG16 -> 14.074881 | CD16: =CP16*(1+$CD$5) -> 313.81012 | CE16: =(CD16-CP16)/AG16 -> 5.4855404 | CF16: =(CD16-CK16-CL16-AL16-AX16-AY16-BO16-BP16+CQ16)/AG16 -> 5.4855404 | CG16: =(CD16-AH16)/AG16 -> 4.9220808 | CI16: =IF($X16="",0,HLOOKUP($H$3,Resina!$E$2:$AK$93,MATCH($D16&$X16&$CI$5,Resina!$A$2:$A$93,0))) -> 1212.1409 | CJ16: =IF($AA16="",0,HLOOKUP($H$3,Resina!$E$2:$AK$93,MATCH($D16&$AA16&$CJ$5,Resina!$A$2:$A$93,0))) -> 1754.965 | CK16: =L16*((CI16*W16)+(CJ16*Z16))*AG16/1000 -> 282.45735 | CL16: =CK16*$CL$6 -> 2.8245735 | CM16: =IF(D16="Manaus FORA",-((CK16/0.88*0.12)*(1-9.25%))," ") | CO16: =AX16+AY16+BO16+BP16+AL16+AN16+BJ16+BK16+BM16 -> 0 | CP16: =SUM(CK16:CO16) -> 285.28193 | DE16: =_xlfn.CONCAT(D16,L16) -> Manaus38 | DF16: =L16 -> 38 | DG16: =ROUND(SUMIF($1:$1,DG$5,16:16),2) -> 288.21 | DH16: =ROUND(SUMIF($1:$1,DH$5,16:16),2) -> 1.8 | DI16: =ROUND(SUMIF($1:$1,DI$5,16:16),2) -> 0 | DJ16: =ROUND(SUMIF($1:$1,DJ$5,16:16),2) -> 0 | DK16: =ROUND(SUMIF($1:$1,DK$5,16:16),2) -> 0 | DL16: =ROUND(SUMIF($1:$1,DL$5,16:16),2) -> 0 | DM16: =ROUND(SUMIF($1:$1,DM$5,16:16),2) -> 0 | DN16: =ROUND(SUMIF($1:$1,DN$5,16:16),2) -> 57.12 | ... ED16: =ROUND(SUMIF($1:$1,ED$5,16:16),2) -> 0 | EE16: =SUM(DG16:ED16) -> 361.41 | EF16: =ROUND(SUM(EE16-BT16),2) -> 0 | EG16: =IF(DN16<>0,DN16-EF16,0) -> 57.12 | EH16: =IF(EG16=0,DO16-EF16,DO16) -> 0 | EI16: =SUM(DG16:DM16)+SUM(DP16:ED16)+EG16+EH16 -> 361.41
A17: =_xlfn.CONCAT(D17,L17) -> Manaus38 | B17: 4151 | C17: 4151 | D17: Manaus | F17: AMBEV | G17: CONTRATO | H17: FOB | K17: PREFORMA | L17: 38 | M17: VD | V17: Virgem | W17: 0.4 | X17: ALPEK | Y17: =IF($X17="",0,HLOOKUP($H$3,Resina!$E$2:$AK$93,MATCH($D17&$X17&$Y$5,Resina!$A$2:$A$93,0))) -> 1283.4027 | Z17: 0.6 | AA17: VG | AB17: =IF($AA17="",0,HLOOKUP($H$3,Resina!$E$2:$AK$93,MATCH($D17&$AA17&$AB$5,Resina!$A$2:$A$93,0))) -> 1720.8738 | AC17: =$AC$7 -> 46091 | AD17: Mensal | AE17: =$AE$7 -> 45839 | AF17: MIL | AG17: =_xlfn.XLOOKUP($H$3,Resina!$2:$2,Resina!$3:$3,0) -> 5.2006167 | AH17: =(L17*((Y17*W17)+(AB17*Z17)))*AG17/1000 -> 305.50317 | AI17: 0.005 | AJ17: =AH17*AI17 -> 1.5275159 | AO17: =_xlfn.XLOOKUP($D17&$L17&$AK$3,'BD Conv'!$A:$A,'BD Conv'!$H:$H,0)*_xlfn.XLOOKUP($D17,'BD Conv'!$C$17:$C$19,'BD Conv'!$F$17:$F$19,0)*(1+(HLOOKUP($B17&AO$6,Indexadores!$C$2:$AH$32,MATCH($AE17,Indexadores!$A$2:$A$32,0)))) -> 14.28 | AS17: 0.005 | AT17: =(AU17+AO17)*AS17 -> 0.357 | AU17: =_xlfn.XLOOKUP($D17&$L17&$AK$3,'BD Conv'!$A:$A,'BD Conv'!$H:$H,0)*_xlfn.XLOOKUP($D17,'BD Conv'!$C$17:$C$19,'BD Conv'!$E$17:$E$19,0)*(1+(HLOOKUP($B17&AU$6,Indexadores!$C$2:$AH$32,MATCH($AE17,Indexadores!$A$2:$A$32,0)))) -> 57.12 | AV17: =SUM(AN17,AO17,AP17,(AQ17*AG17),AR17,AT17,AU17) -> 71.757 | AW17: =_xlfn.XLOOKUP($A17&$AK$3,'BD Conv'!$A:$A,'BD Conv'!$I:$I,0) -> 0 | AZ17: =SUM(AH17,AJ17,AK17,AL17,AV17,AW17:AY17) -> 378.78769 | BI17: =SUM(BA17,BB17,BC17,(BD17*AG17),BE17,BF17,BH17) -> 0 | BN17: =_xlfn.XLOOKUP($A17&$BA$3,'BD Conv'!$A:$A,'BD Conv'!$K:$K,0) -> 0 | BQ17: =SUM(BI17,BJ17,BK17,BM17,BN17,BO17,BP17) -> 0 | BR17: =-BQ17*$BR$3 -> 0 | BT17: =AZ17+BQ17+BR17+BS17 -> 378.78769 | BU17: =BV17-BT17 -> 95.526972 | BV17: =BT17/(1-(12%+1.65%+7.6%) +12%*(1.65%+7.6%)) -> 474.31466 | BY17: =BT17/CP17-1 -> 0.23403136 | BZ17: =(BT17-CP17)/AG17 -> 13.813027 | CA17: =(BT17-CK17-CL17-AL17-AX17-AY17-BO17-BP17+CQ17)/AG17 -> 13.813027 | CB17: =(BT17-AH17)/AG17 -> 14.091505 | CD17: =CP17*(1+$CD$5) -> 337.64657 | CE17: =(CD17-CP17)/AG17 -> 5.9022121 | CF17: =(CD17-CK17-CL17-AL17-AX17-AY17-BO17-BP17+CQ17)/AG17 -> 5.9022121 | CG17: =(CD17-AH17)/AG17 -> 6.1806897 | CI17: =IF($X17="",0,HLOOKUP($H$3,Resina!$E$2:$AK$93,MATCH($D17&$X17&$CI$5,Resina!$A$2:$A$93,0))) -> 1212.1409 | CJ17: =IF($AA17="",0,HLOOKUP($H$3,Resina!$E$2:$AK$93,MATCH($D17&$AA17&$CJ$5,Resina!$A$2:$A$93,0))) -> 1754.965 | CK17: =L17*((CI17*W17)+(CJ17*Z17))*AG17/1000 -> 303.9123 | CL17: =CK17*$CL$6 -> 3.039123 | CM17: =IF(D17="Manaus FORA",-((CK17/0.88*0.12)*(1-9.25%))," ") | CO17: =AX17+AY17+BO17+BP17+AL17+AN17+BJ17+BK17+BM17 -> 0 | CP17: =SUM(CK17:CO17) -> 306.95143 | DE17: =_xlfn.CONCAT(D17,L17) -> Manaus38 | DF17: =L17 -> 38 | DG17: =ROUND(SUMIF($1:$1,DG$5,17:17),2) -> 305.5 | DH17: =ROUND(SUMIF($1:$1,DH$5,17:17),2) -> 1.88 | DI17: =ROUND(SUMIF($1:$1,DI$5,17:17),2) -> 0 | DJ17: =ROUND(SUMIF($1:$1,DJ$5,17:17),2) -> 0 | DK17: =ROUND(SUMIF($1:$1,DK$5,17:17),2) -> 0 | DL17: =ROUND(SUMIF($1:$1,DL$5,17:17),2) -> 0 | DM17: =ROUND(SUMIF($1:$1,DM$5,17:17),2) -> 0 | DN17: =ROUND(SUMIF($1:$1,DN$5,17:17),2) -> 57.12 | ... ED17: =ROUND(SUMIF($1:$1,ED$5,17:17),2) -> 0 | EE17: =SUM(DG17:ED17) -> 378.78 | EF17: =ROUND(SUM(EE17-BT17),2) -> -0.01 | EG17: =IF(DN17<>0,DN17-EF17,0) -> 57.13 | EH17: =IF(EG17=0,DO17-EF17,DO17) -> 0 | EI17: =SUM(DG17:DM17)+SUM(DP17:ED17)+EG17+EH17 -> 378.79
A18: =_xlfn.CONCAT(D18,L18) -> Manaus38 | B18: 4151 | C18: 4151 | D18: Manaus | F18: AMBEV | G18: CONTRATO | H18: FOB | K18: PREFORMA | L18: 38 | M18: VD | V18: Virgem | W18: 0 | Y18: =IF($X18="",0,HLOOKUP($H$3,Resina!$E$2:$AK$93,MATCH($D18&$X18&$Y$5,Resina!$A$2:$A$93,0))) -> 0 | Z18: 1 | AA18: VG | AB18: =IF($AA18="",0,HLOOKUP($H$3,Resina!$E$2:$AK$93,MATCH($D18&$AA18&$AB$5,Resina!$A$2:$A$93,0))) -> 1720.8738 | AC18: =$AC$7 -> 46091 | AD18: Mensal | AE18: =$AE$7 -> 45839 | AF18: MIL | AG18: =_xlfn.XLOOKUP($H$3,Resina!$2:$2,Resina!$3:$3,0) -> 5.2006167 | AH18: =(L18*((Y18*W18)+(AB18*Z18)))*AG18/1000 -> 340.08498 | AI18: 0.005 | AJ18: =AH18*AI18 -> 1.7004249 | AO18: =_xlfn.XLOOKUP($D18&$L18&$AK$3,'BD Conv'!$A:$A,'BD Conv'!$H:$H,0)*_xlfn.XLOOKUP($D18,'BD Conv'!$C$17:$C$19,'BD Conv'!$F$17:$F$19,0)*(1+(HLOOKUP($B18&AO$6,Indexadores!$C$2:$AH$32,MATCH($AE18,Indexadores!$A$2:$A$32,0)))) -> 14.28 | AS18: 0.005 | AT18: =(AU18+AO18)*AS18 -> 0.357 | AU18: =_xlfn.XLOOKUP($D18&$L18&$AK$3,'BD Conv'!$A:$A,'BD Conv'!$H:$H,0)*_xlfn.XLOOKUP($D18,'BD Conv'!$C$17:$C$19,'BD Conv'!$E$17:$E$19,0)*(1+(HLOOKUP($B18&AU$6,Indexadores!$C$2:$AH$32,MATCH($AE18,Indexadores!$A$2:$A$32,0)))) -> 57.12 | AV18: =SUM(AN18,AO18,AP18,(AQ18*AG18),AR18,AT18,AU18) -> 71.757 | AW18: =_xlfn.XLOOKUP($A18&$AK$3,'BD Conv'!$A:$A,'BD Conv'!$I:$I,0) -> 0 | AZ18: =SUM(AH18,AJ18,AK18,AL18,AV18,AW18:AY18) -> 413.54241 | BI18: =SUM(BA18,BB18,BC18,(BD18*AG18),BE18,BF18,BH18) -> 0 | BN18: =_xlfn.XLOOKUP($A18&$BA$3,'BD Conv'!$A:$A,'BD Conv'!$K:$K,0) -> 0 | BQ18: =SUM(BI18,BJ18,BK18,BM18,BN18,BO18,BP18) -> 0 | BR18: =-BQ18*$BR$3 -> 0 | BT18: =AZ18+BQ18+BR18+BS18 -> 413.54241 | BU18: =BV18-BT18 -> 104.29181 | BV18: =BT18/(1-(12%+1.65%+7.6%) +12%*(1.65%+7.6%)) -> 517.83422 | BY18: =BT18/CP18-1 -> 0.18057012 | BZ18: =(BT18-CP18)/AG18 -> 12.162401 | CA18: =(BT18-CK18-CL18-AL18-AX18-AY18-BO18-BP18+CQ18)/AG18 -> 12.162401 | CB18: =(BT18-AH18)/AG18 -> 14.124753 | CD18: =CP18*(1+$CD$5) -> 385.31946 | CE18: =(CD18-CP18)/AG18 -> 6.7355555 | CF18: =(CD18-CK18-CL18-AL18-AX18-AY18-BO18-BP18+CQ18)/AG18 -> 6.7355555 | CG18: =(CD18-AH18)/AG18 -> 8.6979076 | CI18: =IF($X18="",0,HLOOKUP($H$3,Resina!$E$2:$AK$93,MATCH($D18&$X18&$CI$5,Resina!$A$2:$A$93,0))) -> 0 | CJ18: =IF($AA18="",0,HLOOKUP($H$3,Resina!$E$2:$AK$93,MATCH($D18&$AA18&$CJ$5,Resina!$A$2:$A$93,0))) -> 1754.965 | CK18: =L18*((CI18*W18)+(CJ18*Z18))*AG18/1000 -> 346.8222 | CL18: =CK18*$CL$6 -> 3.468222 | CM18: =IF(D18="Manaus FORA",-((CK18/0.88*0.12)*(1-9.25%))," ") | CO18: =AX18+AY18+BO18+BP18+AL18+AN18+BJ18+BK18+BM18 -> 0 | CP18: =SUM(CK18:CO18) -> 350.29042 | DE18: =_xlfn.CONCAT(D18,L18) -> Manaus38 | DF18: =L18 -> 38 | DG18: =ROUND(SUMIF($1:$1,DG$5,18:18),2) -> 340.08 | DH18: =ROUND(SUMIF($1:$1,DH$5,18:18),2) -> 2.06 | DI18: =ROUND(SUMIF($1:$1,DI$5,18:18),2) -> 0 | DJ18: =ROUND(SUMIF($1:$1,DJ$5,18:18),2) -> 0 | DK18: =ROUND(SUMIF($1:$1,DK$5,18:18),2) -> 0 | DL18: =ROUND(SUMIF($1:$1,DL$5,18:18),2) -> 0 | DM18: =ROUND(SUMIF($1:$1,DM$5,18:18),2) -> 0 | DN18: =ROUND(SUMIF($1:$1,DN$5,18:18),2) -> 57.12 | ... ED18: =ROUND(SUMIF($1:$1,ED$5,18:18),2) -> 0 | EE18: =SUM(DG18:ED18) -> 413.54 | EF18: =ROUND(SUM(EE18-BT18),2) -> 0 | EG18: =IF(DN18<>0,DN18-EF18,0) -> 57.12 | EH18: =IF(EG18=0,DO18-EF18,DO18) -> 0 | EI18: =SUM(DG18:DM18)+SUM(DP18:ED18)+EG18+EH18 -> 413.54
