Workbook
Name \P: #REF!
Name \P: #REF!
Name _________CTM1: #REF!
Name _________CTM1: #REF!
Name _________CTM2: #REF!
Name _________CTM3: #REF!
Name _________CTM4: #REF!
Name ________CTM1: #REF!
Name ________CTM2: #REF!
Name ________CTM3: #REF!
Name ________CTM4: #REF!
Name _______CTM1: #REF!
Name _______CTM2: #REF!
Name _______CTM3: #REF!
Name _______CTM4: #REF!
Name ______CTM1: #REF!
Name ______CTM2: #REF!
Name ______CTM3: #REF!
Name ______CTM4: #REF!
Name _____CTM1: #REF!
Name _____CTM2: #REF!
Name _____CTM3: #REF!
Name _____CTM4: #REF!
Name _____pag2: #REF!
Name _____pag3: #REF!
Name ____CTM1: #REF!
Name ____CTM2: #REF!
Name ____CTM3: #REF!
Name ____CTM4: #REF!
Name ____pag2: #REF!
Name ____pag3: #REF!
Name ___CTM1: #REF!
Name ___CTM2: #REF!
Name ___CTM3: #REF!
Name ___CTM4: #REF!
Name ___pag2: #REF!
Name ___pag3: #REF!
Name __CTM1: #REF!
Name __CTM2: #REF!
Name __CTM3: #REF!
Name __CTM4: #REF!
Name __pag2: #REF!
Name __pag3: #REF!
Name _38LINE: #REF!
Name _4LINEADJ: #REF!
Name _94BPRICE: #REF!
Name _CTM1: #REF!
Name _CTM2: #REF!
Name _CTM3: #REF!
Name _CTM4: #REF!
Name _MAG1: #REF!
Name _MAG1: '[1]Mag 1'!$E$2:$E$208
Name _MAG2: #REF!
Name _MAG2: '[1]Mag 2'!$E$82:$E$208
Name _MAG3: #REF!
Name _MAG3: '[1]Mag 3'!$E$4:$E$208
Name _MAG4: #REF!
Name _MAG4: '[1]Mag 4'!$E$4:$E$208
Name _MOR2: #REF!
Name _MOR2: #REF!

Sheet ICIS Price Forecast
B2: ICIS Dashboard Price Forecast
B4: Generated | C4: 17 Apr 2026 22:17:20
B5: Date Range 1 | C5: From 17 Apr 2025 To 01 Oct 2027
B6: Original Currency | C6: USD | D6: USD
B7: Original Unit | C7: tonne | D7: tonne
B8: Selected Currency | C8: USD
B9: Selected Unit | C9: tonne
B10: Price Forecast Range | C10: 18 Months
B11: Price History Range | C11: 1 Year
B13: Date Range 1 | C13: PET Bottle Grade FOB China Spot Forecast Apr-2026 Latest | D13: PET Bottle Grade FOB China Spot 4-12 Weeks Full Market Range
B14: 18-Apr-2025 | D14: 730.00
B15: 25-Apr-2025 | D15: 735.00
B16: 02-May-2025 | D16: 752.50
B17: 09-May-2025 | D17: 755.00
B18: 16-May-2025 | D18: 792.50
B19: 23-May-2025 | D19: 790.00
B20: 30-May-2025 | D20: 785.00
B21: 06-Jun-2025 | D21: 780.00
B22: 13-Jun-2025 | D22: 782.50
B23: 20-Jun-2025 | D23: 812.50
B24: 27-Jun-2025 | D24: 797.50
B25: 04-Jul-2025 | D25: 785.00
... B50: 26-Dec-2025 | D50: 770.00
B51: 09-Jan-2026 | D51: 800
B52: 16-Jan-2026 | D52: 802.5
B53: 23-Jan-2026 | D53: 825
B54: 30-Jan-2026 | D54: 845
B55: 06-Feb-2026 | D55: 830
B56: 13-Feb-2026 | D56: 837.5
B57: 27-Feb-2026 | D57: 847.5
B58: 06-Mar-2026 | D58: 920
B59: 13-Mar-2026 | D59: 1135
B60: 20-Mar-2026 | D60: 1215
B61: 27-Mar-2026 | D61: 1175
B62: 01-Apr-2026 | C62: 1147.00 | D62: =C62 -> 1147.00
B63: 03-Apr-2026 | D63: 1190
B64: 10-Apr-2026 | D64: 1182.5
B65: 17-Apr-2026 | D65: 1190
B66: 01-May-2026 | C66: 1173.00
B67: 01-Jun-2026 | C67: 1054.00
...

Sheet Drewry
BB1: =BB3-97 -> 137.45455 | BC1: =BC3-97 -> 76.363636 | BD1: =BD3-97 -> 65.136364 | BE1: =BE3-97 -> 39.954545 | BF1: =BF3-97 -> 6.5909091
B2: 44378 | C2: 44409 | D2: 44440 | E2: 44470 | F2: 44501 | G2: 44531 | H2: 44562 | I2: 44593 | J2: 44621 | K2: 44652 | L2: 44682 | M2: 44713 | N2: 44743 | O2: 44774 | P2: 44805 | Q2: 44835 | R2: 44866 | S2: 44896 | T2: 44927 | U2: 44958 | V2: 44986 | W2: 45017 | X2: 45047 | Y2: 45078 | Z2: 45108 | AA2: 45139 | AB2: 45170 | AC2: 45200 | AD2: 45231 | AE2: 45261 | AF2: 45292 | AG2: 45323 | AH2: 45352 | AI2: 45383 | AJ2: 45413 | AK2: 45444 | AL2: 45474 | AM2: 45505 | AN2: 45536 | AO2: 45566 | AP2: 45597 | AQ2: 45627 | AR2: 45658 | AS2: 45689 | AT2: 45717 | AU2: 45748 | AV2: 45778 | AW2: 45809 | AX2: 45839 | AY2: 45870 | AZ2: 45901 | BA2: 45931 | BB2: 45962 | BC2: 45992 | BD2: 46023 | BE2: 46054 | BF2: 46082 | BG2: Apr
A3: Drewry Shanghai-CTG | B3: 350 | C3: =+C4/22 -> 386.36364 | D3: =+D4/22 -> 495 | E3: =+E4/22 -> 538.63636 | F3: =+F4/22 -> 577.27273 | G3: =+G4/22 -> 577.27273 | H3: =+H4/22 -> 577.27273 | I3: =+I4/22 -> 577.27273 | J3: =+J4/22 -> 577.27273 | ... BG3: =+BG4/22 -> 134.22727
A4: Contenedor | B4: =+B3*22 -> 7700 | C4: 8500 | D4: 10890 | E4: 11850 | F4: 12700 | G4: 12700 | H4: 12700 | I4: 12700 | J4: 12700 | K4: 12700 | L4: 12090 | M4: 10570 | N4: 10580 | O4: 10920 | P4: 10920 | Q4: 10640 | R4: 8950 | S4: 6070 | T4: 4850 | U4: 4850 | V4: 2690 | W4: 2510 | X4: 1980 | Y4: 2700 | Z4: 3153 | AA4: 2873 | AB4: 2722 | AC4: 3369 | AD4: 3269 | AE4: 2848 | AF4: 3226 | AG4: 3584 | AH4: 3670 | AI4: 3649 | AJ4: 4294 | AK4: 6049 | AL4: 8585 | AM4: 9257 | AN4: 7086 | AO4: 7536 | AP4: 5849 | AQ4: 5742 | AR4: 4700 | AS4: 4700 | AT4: 4538 | AU4: 3569 | AV4: 3685 | AW4: 3215 | AX4: 3268 | AY4: 7924 | AZ4: 5721 | BA4: 5508 | BB4: 5158 | BC4: 3814 | BD4: 3567 | BE4: 3013 | BF4: 2279 | BG4: =AVERAGE(BD4:BF4) -> 2953
AI5: =+AH4/AI4-1 -> 0.0057550014 | AJ5: =+AI4/AJ4-1 -> -0.15020959 | AK5: =+AJ4/AK4-1 -> -0.2901306 | AL5: =+AK4/AL4-1 -> -0.29539895 | AM5: =+AL4/AM4-1 -> -0.072593713 | AN5: =+AM4/AN4-1 -> 0.30637878 | AO5: =+AN4/AO4-1 -> -0.059713376 | AP5: =+AO4/AP4-1 -> 0.28842537 | ... BF5: =+BE4/BF4-1 -> 0.32207108 | BG5: 3890

Sheet Amcor - Columbia 
D2: S.No | E2: Supplier Name | F2: Excel | G2: Sheet Reference | H2: Route | I2: Description | J2: Month | K2: Price
D3: 1 | E3: Bavaria | F3: 1 Bavaria - Precio Marzo | G3: Fórmula Marzo 26 | H3: China to columbia | I3: Precio Final con ajuste flete Resina | J3: March | K3: 1099.8627
N10: Country X Supplier
J11: 1 Bavaria - Precio Marzo | N11: Historical | O11: Available
I12: Formuale Sheet | J12: Supplier Sheet | K12: Formulae | L12: Source
I13: Resin cost:Quarterly Resin index average price | J13: ICIS Index - Quaret | K13: 821 | L13: ICIS
I14: Resin freight cost | J14: Freight China–Buenaventura | K14: =97 -> 97 | L14: Drewery Index
I15: Resin financing cost (Assumption based on rPET formula) | J15: Finance | K15: 32.33
I16: Sub total (con flete reg ) | J16: vPET Resin pricing | K16: =SUM(K13:K15) -> 950.33
I18: Is Sub total (con flete reg ) the Total Landing cost
I21: Doubts
I23: what is Aurora , Enkador , Enka ? | J23: Why are they not present in the supplier sheets ?
I24: What are the prices below Sub Total ? Which is used as the final price for TLC ?
I25: From where is the 97 freight referred ?
I29: Sheet Names :
I30: 1. Fórmula Marzo 26 | J30: TLC formulae considered for the calculation
I31: 2. Fórmula Ago | J31: TLC formulae sheet for different time frame
I32: 3. PCR Aurora | J32: Need more understanding of this sheet
I33: 4. PCR Enkador | J33: Need more understanding of this sheet
I34: 5. PCR Enka | J34: This sheet is used for the Legilation charges cost , but need more understanding of this sheet
I35: 6. PCR INTERCIA | J35: Need more understanding of this sheet
I36: 7. ICIS PCR | J36: Market Data Providers for Index calculation --- > Flows into ICIS - 1
I37: 8. IHS PCR | J37: Market Data Providers for Index calculation --- > Flows into ICIS - 1
I38: 9. IHS Index | J38: Has Index data -- Need why is this sheet used ?
I39: 10. ICIS -1 | J39: Used for the TLC calculation Resin Index
I40: 11. SOFR | J40: Used for the TLC calculation
I41: 12. Drewry | J41: Used for the TLC calculation
... I45: 16. Balance | J45: Need more understanding of this sheet

Sheet Fórmula Apr (2)
C1: FÓRMULA
C11: PRECIOS DE RESINA ABI MARZO 2026
CP12: 137.45455 | CQ12: 76.363636 | CR12: 65.136364 | CS12: 39.954545 | CT12: 6.5909091 | CZ12: 1. couldn’t figure out the formula here. If its colombia why is it not quarterly
AE13: Fórmula | CV13: Estimated | CZ13: what is FIFO
B14: Translation | C14: PRICE | D14: Jul-18 | E14: Ago-2018 | F14: Sep-18 | G14: Oct-18 | H14: Nov-18 | I14: Dic-18 | J14: Ene-19 | K14: Feb-19 | L14: Mar-19 | M14: Abr-19 | N14: May-19 | O14: Jun-19 | P14: Jul-19 | Q14: Ago-19 | R14: Sep-19 | S14: Oct-19 | T14: Nov-20 | U14: Dic-20 | V14: Ene-20 | W14: Feb-20 | X14: Mar-20 | Y14: Abr-20 | Z14: May-20 | AA14: Jun-20 | AB14: Jun-20 | AC14: Jul-20 | AD14: Jul-20 | AE14: Ago-20 | AF14: Ago-20 | AG14: Sep-20 | AH14: Oct-20 | AI14: Nov-20 | AJ14: Dic-20 | AK14: Ene-21 | AL14: Feb-21 | AM14: Mar-21 | AN14: Abr-21 | AO14: May-21 | AP14: Jun-21 | AQ14: Jul-21 | AR14: Ago-21 | AS14: Sep-21 | AT14: Oct-21 | AU14: Nov-21 | AV14: Dic-21 | AW14: Ene-22 | AX14: Feb-22 | AY14: Mar-22 | AZ14: Abr-22 | BA14: Mayo-22 | BB14: Junio-22 | BC14: Julio-22 | BD14: Agosto-22 | BE14: Septiembre-22 | BF14: Octubre-22 | BG14: Noviembre-22 | BH14: Diciembre-22 | BI14: Enero-23 | BJ14: Febrero-23 | BK14: Marzo-23 | BL14: Abril-23 | BM14: Mayo-23 | BN14: Junio-23 | BO14: Julio-23 | BP14: Agosto-23 | BQ14: Septiembre-23 | BR14: Octubre-23 | BS14: Noviembre-23 | BT14: Diciembre-23 | BU14: Enero-24 | BV14: Febrero-24 | BW14: Marzo-24 | BX14: Abril-24 | BY14: Mayo-24 | BZ14: Junio-24 | CA14: Julio-24 | CB14: Agosto-24 | CC14: Septiembre-24 | CD14: Octubre-24 | CE14: Noviembre-24 | CF14: Diciembre-24 | CG14: Enero-25 | CH14: Febrero-25 | CI14: Marzo-25 | CJ14: Abril-25 | CK14: Mayo-25 | CL14: Junio-25 | CM14: Julio-25 | CN14: Agosto-25 | CO14: Septie-25 | CP14: Oct-25 | CQ14: Nov-25 | CR14: Dic-25 | CS14: Ene-26 | CT14: Feb-26 | CU14: Mar-26 | CV14: Apr-26 | CW14: May-26 | CZ14: Resina Virgen | EM14: Formulae / References Needed ?
B15: Resin Price Index | C15: ICIS China MID (n-1). | D15: May-18 | E15: Jun-18 | F15: Jul-18 | G15: Ago-18 | H15: Sep-18 | I15: Oct-18 | J15: Nov-18 | K15: Dic-18 | L15: Jan-19 | M15: Feb-19 | N15: Mar-19 | O15: Abr-19 | P15: May-19 | Q15: Jun-19 | R15: Jul-19 | S15: Ago-19 | T15: Sep-19 | U15: Oct-19 | V15: Nov-19 | W15: Dic-19 | X15: Jan-20 | Y15: Feb-20 | Z15: Mar-20 | AA15: Abr-20 | AB15: Abr-20 | AC15: May-20 | AD15: May-20 | AE15: Jun-20 | AF15: Jun-20 | AG15: Jul-20 | AH15: Ago-20 | AI15: Sep-20 | AJ15: Oct-20 | AK15: Nov-20 | AL15: Dic-20 | AM15: Jan-21 | AN15: 44228 | AO15: 44256 | AP15: 44287 | AQ15: 44317 | AR15: 44348 | AS15: 44378 | AT15: 44409 | AU15: 44440 | AV15: 44440 | AW15: 44501 | AX15: 44531 | AY15: 44562 | AZ15: 44593 | BA15: 44621 | BB15: 44652 | BC15: 44682 | BD15: 44713 | BE15: 44743 | BF15: 44774 | BG15: 44805 | BH15: 44835 | BI15: 44866 | BJ15: 44896 | BK15: 44927 | BL15: 44958 | BM15: 44986 | BN15: 45017 | BO15: 45047 | BP15: 45078 | BQ15: 45108 | BR15: 45139 | BS15: 45170 | BT15: 45200 | BU15: 45231 | BV15: 45261 | BW15: 44927 | BX15: 44958 | BY15: 44986 | BZ15: 45017 | CA15: 45047 | CB15: 45078 | CC15: 45108 | CD15: 45139 | CE15: 45536 | CF15: 45566 | CG15: 45597 | CH15: 45627 | CI15: 45658 | CJ15: 45689 | CK15: 45717 | CL15: 45748 | CM15: 45778 | CN15: 45809 | CO15: 45839 | CP15: 45870 | CQ15: 45901 | CR15: 45931 | CS15: 45962 | CT15: 45992 | CU15: 46023 | CV15: 46054 | CW15: 46082 | CZ15: Descripcion. | DA15: MAYO | DB15: JUNIO | DC15: JULIO | DD15: AGOSTO | DE15: SEPTIEMBRE | DF15: OCTUBRE | DG15: NOVIEMBRE | DH15: DICIEMBRE | DI15: ENERO | DJ15: FEBRERO | DK15: MARZO | DL15: ABRIL | DM15: MAYO | DN15: JUNIO | DO15: JULIO | DP15: AGOSTO | DQ15: SEPTIEMBRE | DR15: OCTUBRE | DS15: NOVIEMBRE | DT15: DICIEMBRE | DU15: ENERO | DV15: FEBRERO | DW15: MARZO | DX15: ABRIL | DY15: MAYO | DZ15: JUNIO | EA15: JULIO | EB15: AGOSTO | EC15: SEPTIEM | ED15: OCTUBRE | EE15: NOVIEMBRE | EF15: DICIEMBRE | EG15: ENERO | EH15: FEBRERO | EI15: MARZO
D16: 1330 | E16: 1280 | F16: 1279.38 | G16: 1275.5 | H16: 1330 | I16: 1266.25 | J16: 1125 | K16: 1058.13 | L16: 1035 | M16: 1077.5 | N16: 1096.25 | O16: 1101.25 | P16: 1004.5 | Q16: 926.25 | R16: 966.88 | S16: 889 | T16: 868.75 | U16: 840 | V16: 818.75 | W16: 824.38 | X16: 840 | Y16: 840 | Z16: 736.88 | AA16: 655 | AB16: 707.17946 | AC16: 669.38 | AD16: 687.43458 | AE16: 678.13 | AF16: 682.5409 | AG16: 659 | AH16: 647.5 | AI16: 649.38 | AJ16: 641.5 | AK16: 648.13 | AL16: 713 | AM16: 789.38 | AN16: 880.63 | AO16: 1018.75 | AP16: 960 | AQ16: 932.5 | AR16: 920 | AS16: 960 | AT16: 966.25 | AU16: 953 | AV16: 1111.88 | AW16: 1124.38 | AX16: 1026.5 | AY16: 1144 | AZ16: 1138 | BA16: 1139 | BB16: 1199 | BC16: 1216.25 | BD16: 1235 | BE16: 1125 | BF16: 1096.25 | BG16: 1048 | BH16: 975.63 | BI16: 897.5 | BJ16: 890 | BK16: 941.88 | BL16: 965 | BM16: 980 | BN16: 1018.75 | BO16: 938.13 | BP16: 882 | BQ16: 878.75 | BR16: 889 | BS16: 898.75 | BT16: 880 | BU16: 865 | BV16: 863.13 | BW16: 889.38 | BX16: 906.5 | BY16: 906.5 | BZ16: 898.13 | CA16: 885 | CB16: 885.63 | CC16: 896.25 | CD16: 874 | CE16: 815 | CF16: 842 | CG16: 802.5 | CH16: 791.25 | CI16: 799.5 | CJ16: 803.125 | CK16: 786.25 | CL16: 745.625 | CM16: 775 | CN16: 793.125 | CO16: 781.875 | CP16: =+'ICIS -1'!C16 -> 774 | CQ16: =+'ICIS -1'!C17 -> 765 | CR16: =+'ICIS -1'!C18 -> 752 | CS16: =+'ICIS -1'!C19 -> 748.75 | CT16: =+'ICIS -1'!C20 -> 756.25 | CU16: =+'ICIS -1'!C21 -> 821.075 | CV16: =AVERAGE('ICIS Price Forecast'!D62:D65) -> 1187.5 | CZ16: Inv Inicial TON | DA16: 327.54748 | DB16: 455.56748 | DC16: 551.38748 | DD16: 361.38748 | DE16: 321.644 | DF16: 392.25652 | DG16: 392.25652 | DH16: =+DG19 -> 350.06179 | DI16: =+DH19 -> 316.06179 | DJ16: =+DI19 -> 350.84056 | DK16: =+DI19 -> 350.84056 | DL16: =+DK19 -> 379.54056 | DM16: =+DL19 -> 307.54056 | DN16: =+DM19 -> 307.52056 | DO16: =+DN19 -> 236.82841 | DP16: =+DO19 -> 139.47841 | DQ16: =+DP19 -> 217.93712 | DR16: =+DQ19 -> 120.58712 | DS16: =+DR19 -> 317.58712 | ... EI16: =+EH19 -> 304.9584 | EM16: ICIS Forecast / Index data
B17: Finance | C17: Finance | D17: =+D16*4.5%/365*210 -> 34.434247 | E17: =+E16*4.5%/365*210 -> 33.139726 | F17: =+F16*4.5%/365*210 -> 33.123674 | G17: =+G16*4.5%/365*210 -> 33.023219 | H17: =+H16*4.5%/365*210 -> 34.434247 | I17: =+I16*4.5%/365*210 -> 32.783733 | J17: =+J16*4.5%/365*210 -> 29.126712 | K17: =+K16*(4.5%+1.59%)/365*210 -> 37.075136 | L17: =+L16*(4.5%+1.59%)/365*210 -> 36.264699 | M17: =+M16*(4.5%+1.59%)/365*210 -> 37.753829 | N17: =+N16*(4.5%+1.59%)/365*210 -> 38.410798 | O17: =+O16*(4.5%+1.59%)/365*210 -> 38.58599 | P17: =+P16*(4.5%+1.59%)/365*210 -> 35.196029 | Q17: =+Q16*(4.5%+1.59%)/365*210 -> 32.454277 | R17: =+R16*(4.5%+1.59%)/365*210 -> 33.877886 | ... U17: =+U16*(4.5%+1.59%)/365*210 -> 29.432219 | V17: =+V16*(4.5%+1.59%+1.9%)/365*210 -> 37.637825 | W17: =+W16*(4.5%+1.59%+1.9%)/365*210 -> 37.896636 | X17: =+X16*(4.5%+1.59%+1.9%)/365*210 -> 38.614685 | Y17: =+Y16*(4.5%+1.59%+1.9%)/365*210 -> 38.614685 | Z17: =+Z16*(4.5%+1.59%+1.9%)/365*210 -> 33.874273 | AA17: =+AA16*(4.5%+1.59%+1.9%)/365*210 -> 30.11026 | AB17: =+AB16*(4.5%+1.59%+1.9%)/365*210 -> 32.508943 | AC17: =+AC16*(4.5%+1.59%+1.9%)/365*210 -> 30.771307 | ... AH17: =+AH16*(4.5%+1.59%+1.9%)/365*210 -> 29.765486 | AI17: 29.85191 | AJ17: 29.489667 | AK17: 29.794447 | AL17: 32.776512 | AM17: 36.28769 | AN17: 40.48244 | AO17: 46.831798 | AP17: 44.131068 | AQ17: 24.529984 | AR17: 24.529984 | AS17: 25.253388 | AT17: 25.253388 | AU17: 25.069249 | AV17: 18.010318 | AW17: 20.073418 | AX17: 27.002711 | AY17: 20 | AZ17: 20 | BA17: 20 | BB17: 21 | BC17: 31.994202 | BD17: 32.487432 | BE17: 29.593814 | BF17: 28.837528 | BG17: 27.568282 | BH17: 25.664545 | BI17: 41.03519 | BJ17: 40.692278 | BK17: 48.654829 | BL17: 49.337828 | BM17: 49.255313 | BN17: 52.190236 | BO17: 49.095804 | BP17: 45.969807 | BQ17: 45.510666 | BR17: 47.311118 | BS17: 47.547395 | BT17: 45.827422 | BU17: =+(BU16+BU19+BU18)*SOFR!$F$3 -> 35.374019 | BV17: =+(BV16+BV19+BV18)*SOFR!$F$3 -> 35.877641 | BW17: =+(BW16+BW19+BW18)*SOFR!$F$3 -> 36.795528 | BX17: =+(BX16+BX19+BX18)*SOFR!$F$3 -> 37.497477 | BY17: =+(BY16+BY19+BY18)*SOFR!$F$3 -> 37.497477 | BZ17: 52.325208 | CA17: 56.881264 | CB17: 58.27184 | CC17: 54.343859 | CD17: 54.263773 | CE17: 48.211712 | CF17: 49.1991 | CG17: =+(CG16+CG19+CG18)*SOFR!$F$3 -> 35.531371 | CH17: =+(CH16+CH19+CH18)*SOFR!$F$3 -> 35.137991 | CI17: =+(CI16+CI19+CI18)*SOFR!$F$3 -> 35.168984 | CJ17: =+(CJ16+CJ19+CJ18)*SOFR!$F$3 -> 33.755597 | CK17: =+(CK16+CK19+CK18)*SOFR!$F$3 -> 33.349899 | CL17: =+(CL16+CL19+CL18)*SOFR!$F$3 -> 31.182334 | CM17: =+(CM16+CM19+CM18)*SOFR!$F$3 -> 32.293733 | CN17: =+(CN16+CN19+CN18)*SOFR!$F$3 -> 40.327828 | ... CV17: =+(CV16+CV19+CV18)*SOFR!$F$3 -> 46.217008 | CZ17: Entradas TON | DA17: 467 | DB17: 396 | DC17: 113 | DD17: 260 | DE17: 370.61252 | DF17: 313 | DG17: 313 | DH17: 313 | DI17: 313 | DJ17: 313 | DK17: 313 | DL17: 200 | DM17: 300 | DN17: 300 | DO17: 300 | DP17: 500 | DQ17: 300 | DR17: 550 | DS17: 300 | DT17: 400 | DU17: 100 | DV17: =455+160 -> 615 | DW17: =330+23 -> 353 | DX17: =330+23 -> 353 | DY17: =330+23 -> 353 | DZ17: 250 | EA17: 200 | EB17: 450 | EC17: 500 | ED17: 500 | EE17: 300 | EF17: 200 | EG17: 200 | EH17: 200 | EI17: 200 | EM17: Assumed the Same Interest rate 3.5% | EP17: Interest rate charged by banks
B18: Freight China-Buenaventura (Regular) | C18: Freight China-Buenaventura (reg) | D18: 90 | E18: 90 | F18: 90 | G18: 90 | H18: 90 | I18: 90 | J18: 90 | K18: 90 | L18: 90 | M18: 90 | N18: 90 | O18: 90 | P18: 90 | Q18: 90 | R18: 90 | S18: 90 | T18: 90 | U18: 91 | V18: =+U18*(1+1.9%) -> 92.729 | W18: =+V18*(1+1.9%) -> 94.490851 | X18: =+W18*(1+1.9%) -> 96.286177 | Y18: =+X18 -> 96.286177 | Z18: =+Y18 -> 96.286177 | AA18: =+Z18 -> 96.286177 | AB18: =+AA18 -> 96.286177 | AC18: =+AB18 -> 96.286177 | AD18: =+AC18 -> 96.286177 | AE18: =+AD18 -> 96.286177 | AF18: =+AE18 -> 96.286177 | ... AP18: =+AO18 -> 96.286177 | AQ18: 96.286177 | AR18: 96.286177 | AS18: 96.286177 | AT18: 96.286177 | AU18: 96.286177 | AV18: 96.286177 | AW18: 96.286177 | AX18: 97.286177 | AY18: 97.286177 | AZ18: 97.286177 | BA18: 97.286177 | BB18: 97.286177 | BC18: 97.286177 | BD18: 97.286177 | BE18: 97.286177 | BF18: 97.286177 | BG18: 97.286177 | BH18: 97.286177 | BI18: 97.286177 | BJ18: 97.286177 | BK18: 97.286177 | BL18: 97.286177 | BM18: 97.286177 | BN18: 97.286177 | BO18: 97.286177 | BP18: 97.286177 | BQ18: 97.286177 | BR18: 97.286177 | BS18: 97.286177 | BT18: 97.286177 | BU18: 97.286177 | BV18: 97.286177 | BW18: 97.286177 | BX18: 97.286177 | BY18: 97.286177 | BZ18: 97.286177 | CA18: 97.286177 | CB18: 97.286177 | CC18: 97.286177 | CD18: 97.286177 | CE18: 97.286177 | CF18: 97.286177 | CG18: 97.286177 | CH18: 97.286177 | CI18: 97.286177 | CJ18: 97.286177 | CK18: 97.286177 | CL18: 97.286177 | CM18: 97.286177 | CN18: 97.286177 | CO18: 97.286177 | CP18: 97.286177 | CQ18: 97.286177 | CR18: 97.286177 | CS18: 97.286177 | CT18: 97.286177 | CU18: 97.286177 | CV18: 97 | CZ18: Consumo TON | DA18: 338.98 | DB18: 300.18 | DC18: 303 | DD18: 299.74348 | DE18: 300 | DF18: 313 | DG18: 355.19473 | DH18: 347 | DI18: 278.22123 | DJ18: 244 | DK18: 284.3 | DL18: 272 | DM18: 300.02 | DN18: 370.69216 | DO18: 397.35 | DP18: 421.54128 | DQ18: 397.35 | DR18: 353 | DS18: 320 | DT18: 309.39819 | DU18: 310 | DV18: 265.94053 | DW18: 328.29 | DX18: 338 | DY18: 371 | DZ18: 350 | EA18: 349 | EB18: 349 | EC18: 300 | ED18: 300 | EE18: 349 | EF18: 349 | EG18: 349 | EH18: 349 | EI18: 349 | EM18: 97 Index remains the same
B19: Freight China-Buenaventura (Incremental) | C19: Freight China-Buenaventura (Incr) | AQ19: =+Drewry!B3-'Fórmula Apr (2)'!AQ18 -> 253.71382 | AR19: =+Drewry!C3-'Fórmula Apr (2)'!AR18 -> 290.07746 | AS19: =+Drewry!D3-'Fórmula Apr (2)'!AS18 -> 398.71382 | AT19: =+Drewry!E3-'Fórmula Apr (2)'!AT18 -> 442.35019 | AU19: =+Drewry!F3-'Fórmula Apr (2)'!AU18 -> 480.98655 | AV19: 480.98655 | AW19: 480.98655 | AX19: =+Drewry!I3-'Fórmula Apr (2)'!AX18 -> 479.98655 | AY19: 480 | AZ19: 480 | BA19: 452 | BB19: 383 | BC19: =+Drewry!N3-'Fórmula Apr (2)'!BC18 -> 383.62291 | BD19: =+Drewry!O3-'Fórmula Apr (2)'!BD18 -> 399.07746 | BE19: =+Drewry!P3-'Fórmula Apr (2)'!BE18 -> 399.07746 | BF19: =+Drewry!Q3-'Fórmula Apr (2)'!BF18 -> 386.35019 | BG19: =+Drewry!R3-'Fórmula Apr (2)'!BG18 -> 309.532 | BH19: =+Drewry!S3-'Fórmula Apr (2)'!BH18 -> 178.62291 | BI19: =+Drewry!T3-'Fórmula Apr (2)'!BI18 -> 123.16837 | BJ19: =+Drewry!U3-'Fórmula Apr (2)'!BJ18 -> 123.16837 | BK19: =+IF(Drewry!V3-'Fórmula Apr (2)'!BK18<0,0,Drewry!V3-'Fórmula Apr (2)'!BK18) -> 24.98655 | BL19: =+IF(Drewry!W3-'Fórmula Apr (2)'!BL18<0,0,Drewry!W3-'Fórmula Apr (2)'!BL18) -> 16.804732 | BM19: =+IF(Drewry!X3-'Fórmula Apr (2)'!BM18<0,0,Drewry!X3-'Fórmula Apr (2)'!BM18) -> 0 | BN19: =+IF(Drewry!Y3-'Fórmula Apr (2)'!BN18<0,0,Drewry!Y3-'Fórmula Apr (2)'!BN18) -> 25.441096 | BO19: =+IF(Drewry!Z3-'Fórmula Apr (2)'!BO18<0,0,Drewry!Z3-'Fórmula Apr (2)'!BO18) -> 46.032005 | BP19: =+IF(Drewry!AA3-'Fórmula Apr (2)'!BP18<0,0,Drewry!AA3-'Fórmula Apr (2)'!BP18) -> 33.304732 | BQ19: =+IF(Drewry!AB3-'Fórmula Apr (2)'!BQ18<0,0,Drewry!AB3-'Fórmula Apr (2)'!BQ18) -> 26.441096 | BR19: =+IF(Drewry!AC3-'Fórmula Apr (2)'!BR18<0,0,Drewry!AC3-'Fórmula Apr (2)'!BR18) -> 55.850186 | ... BV19: =+IF(Drewry!AG3-'Fórmula Apr (2)'!BV18<0,0,Drewry!AG3-'Fórmula Apr (2)'!BV18) -> 65.622914 | BW19: =+IF(Drewry!AG3-'Fórmula Apr (2)'!BW18<0,0,Drewry!AG3-'Fórmula Apr (2)'!BW18) -> 65.622914 | BX19: =+IF(Drewry!AI3-'Fórmula Apr (2)'!BX18<0,0,Drewry!AI3-'Fórmula Apr (2)'!BX18) -> 68.577459 | BY19: =+IF(Drewry!AI3-'Fórmula Apr (2)'!BY18<0,0,Drewry!AI3-'Fórmula Apr (2)'!BY18) -> 68.577459 | BZ19: =+IF(Drewry!AK3-'Fórmula Apr (2)'!BZ18<0,0,Drewry!AK3-'Fórmula Apr (2)'!BZ18) -> 177.66837 | CA19: =+IF(Drewry!AL3-'Fórmula Apr (2)'!CA18<0,0,Drewry!AL3-'Fórmula Apr (2)'!CA18) -> 292.9411 | CB19: =+IF(Drewry!AM3-'Fórmula Apr (2)'!CB18<0,0,Drewry!AM3-'Fórmula Apr (2)'!CB18) -> 323.48655 | CC19: =+IF(Drewry!AN3-'Fórmula Apr (2)'!CC18<0,0,Drewry!AN3-'Fórmula Apr (2)'!CC18) -> 224.80473 | CD19: =+IF(Drewry!AO3-'Fórmula Apr (2)'!CD18<0,0,Drewry!AO3-'Fórmula Apr (2)'!CD18) -> 245.25928 | CE19: =+IF(Drewry!AP3-'Fórmula Apr (2)'!CE18<0,0,Drewry!AP3-'Fórmula Apr (2)'!CE18) -> 168.57746 | CF19: =+IF(Drewry!AQ3-'Fórmula Apr (2)'!CF18<0,0,Drewry!AQ3-'Fórmula Apr (2)'!CF18) -> 163.71382 | CG19: =+IF(Drewry!AR3-'Fórmula Apr (2)'!CG18<0,0,Drewry!AR3-'Fórmula Apr (2)'!CG18) -> 116.35019 | ... CU19: =+IF(Drewry!BF3-'Fórmula Apr (2)'!CU18<0,0,Drewry!BF3-'Fórmula Apr (2)'!CU18) -> 6.3047319 | CV19: =Drewry!BG3-'Fórmula Apr (2)'!CV18 -> 37.227273 | CZ19: Inv Final TON | DA19: 455.56748 | DB19: 551.38748 | DC19: 361.38748 | DD19: 321.644 | DE19: 392.25652 | DF19: 392.25652 | DG19: 350.06179 | DH19: =+(DH16+DH17-DH18) -> 316.06179 | DI19: =+(DI16+DI17-DI18) -> 350.84056 | DJ19: =+(DJ16+DJ17-DJ18) -> 419.84056 | DK19: =+(DK16+DK17-DK18) -> 379.54056 | DL19: =+(DL16+DL17-DL18) -> 307.54056 | DM19: =+(DM16+DM17-DM18) -> 307.52056 | DN19: =+(DN16+DN17-DN18) -> 236.82841 | DO19: =+(DO16+DO17-DO18) -> 139.47841 | ... EI19: =+(EI16+EI17-EI18) -> 155.9584 | EM19: Need Drewery Index
B20: Sub Total (with Incremental Freight) | C20: Sub total (con flete Inc) | D20: =SUM(D16:D18) -> 1454.4342 | E20: =SUM(E16:E18) -> 1403.1397 | F20: =SUM(F16:F18) -> 1402.5037 | G20: =SUM(G16:G18) -> 1398.5232 | H20: =SUM(H16:H18) -> 1454.4342 | I20: =SUM(I16:I18) -> 1389.0337 | J20: =SUM(J16:J18) -> 1244.1267 | K20: =SUM(K16:K18) -> 1185.2051 | ... AP20: =SUM(AP16:AP18) -> 1100.4172 | AQ20: =SUM(AQ16:AQ19) -> 1307.03 | AR20: =SUM(AR16:AR19) -> 1330.8936 | AS20: =SUM(AS16:AS19) -> 1480.2534 | AT20: =SUM(AT16:AT19) -> 1530.1398 | AU20: =SUM(AU16:AU19) -> 1555.342 | AV20: 1707.163 | AW20: 1721.7261 | AX20: =SUM(AX16:AX19) -> 1630.7754 | AY20: 1741 | AZ20: 1736 | BA20: 1709 | BB20: 1701 | BC20: =SUM(BC16:BC19) -> 1729.1533 | BD20: =SUM(BD16:BD19) -> 1763.8511 | BE20: =SUM(BE16:BE19) -> 1650.9575 | BF20: =SUM(BF16:BF19) -> 1608.7239 | BG20: =SUM(BG16:BG19) -> 1482.3865 | BH20: =SUM(BH16:BH19) -> 1277.2036 | BI20: =SUM(BI16:BI19) -> 1158.9897 | BJ20: =SUM(BJ16:BJ19) -> 1151.1468 | ... CV20: =SUM(CV16:CV19) -> 1367.9443 | EM20: formulae
B21: Sub Total (with Regular Freight) | C21: Sub total (con flete reg) | AQ21: =+SUM(AQ16:AQ18) -> 1053.3162 | AR21: =+SUM(AR16:AR18) -> 1040.8162 | AS21: =+SUM(AS16:AS18) -> 1081.5396 | AT21: =+SUM(AT16:AT18) -> 1087.7896 | AU21: =+SUM(AU16:AU18) -> 1074.3554 | AV21: 1226.1765 | AW21: 1240.7396 | AX21: =+SUM(AX16:AX18) -> 1150.7889 | AY21: 1261 | AZ21: 1256 | BA21: 1257 | BB21: 1317 | BC21: =+SUM(BC16:BC18) -> 1345.5304 | BD21: =+SUM(BD16:BD18) -> 1364.7736 | BE21: =+SUM(BE16:BE18) -> 1251.88 | BF21: =+SUM(BF16:BF18) -> 1222.3737 | BG21: =+SUM(BG16:BG18) -> 1172.8545 | BH21: =+SUM(BH16:BH18) -> 1098.5807 | BI21: =+SUM(BI16:BI18) -> 1035.8214 | BJ21: =+SUM(BJ16:BJ18) -> 1027.9785 | ... CV21: =+SUM(CV16:CV18) -> 1330.717 | CZ21: Precio Inv Inical | DA21: 1258.4919 | DB21: 1267.0143 | DC21: 1304.1208 | DD21: 1298.9693 | DE21: 1254.8429 | DF21: 1215.9045 | DG21: 1220.6547 | DH21: =+DG24 -> 1226.1867 | DI21: =+DH24 -> 1209.0552 | DJ21: =+DI24 -> 1194.1872 | DK21: =+DI24 -> 1194.1872 | DL21: =+DJ24 -> 1203.3754 | DM21: =+DL24 -> 1225.5446 | DN21: =+DM24 -> 1246.3188 | DO21: =+DN24 -> 1317.0024 | DP21: =+DO24 -> 1419.7187 | DQ21: =+DP24 -> 1509.9821 | DR21: =+DQ24 -> 1468.9302 | DS21: =+DR24 -> 1441.3902 | DT21: =+DS24 -> 1363.6378 | ... EI21: =+EH24 -> 1137.1396 | EM21: formulae
B22: Duty 5% (Change According to Regulation) | C22: Duty 5% (Cambio de acuerdo a la regulación) | D22: =+D20*0.1 -> 145.44342 | E22: =+E20*0.1 -> 140.31397 | F22: =+F20*0.1 -> 140.25037 | G22: =+G20*0.1 -> 139.85232 | H22: =+H20*0.1 -> 145.44342 | I22: =+I20*0.1 -> 138.90337 | J22: =+J20*0.1 -> 124.41267 | K22: =+K20*0.1 -> 118.52051 | ... AS22: =+AS20*0.1 -> 148.02534 | AT22: =+AT20*0.05 -> 76.506988 | AU22: =+AU20*0.05 -> 77.767099 | AV22: 85.358152 | AW22: 86.086307 | AX22: =+AX20*0.05 -> 81.538772 | AY22: 87.033091 | AZ22: =+AZ20*0.05 -> 86.8 | BA22: =+BA20*0.05 -> 85.45 | BB22: =+BB20*0.05 -> 85.05 | BC22: =+BC20*0.05 -> 86.457665 | BD22: =+BD20*0.05 -> 88.192553 | BE22: =+BE20*0.05 -> 82.547873 | BF22: =+BF20*0.05 -> 80.436195 | BG22: =+BG20*0.05 -> 74.119323 | ... CV22: =+CV20*0.05 -> 68.397214 | CZ22: Precio Ingreso | DA22: 1272.9919 | DB22: 1346.809 | DC22: 1273.8321 | DD22: 1193.5092 | DE22: 1182.1111 | DF22: 1226.6076 | DG22: 1233.1194 | DH22: =+BT26 -> 1189.8952 | DI22: =+BU26 -> 1179.1737 | DJ22: =+BV26 -> 1213.6744 | DK22: =+BW26 -> 1244.3742 | DL22: =+BX26 -> 1267.6152 | DM22: =+BY26 -> 1267.6152 | DN22: =+BZ26 -> 1389.4579 | DO22: =+CA26 -> 1500.8057 | ... EI22: =+CU26 -> 1099.8627 | EM22: Duty 5% is it going to vary ?
B23: Landed Factor 8% | C23: Landed factor 8% | D23: =+D20*8% -> 116.35474 | E23: =+E20*8% -> 112.25118 | F23: =+F20*8% -> 112.20029 | G23: =+G20*8% -> 111.88186 | H23: =+H20*8% -> 116.35474 | I23: =+I20*8% -> 111.1227 | J23: =+J20*8% -> 99.530137 | K23: =+K20*8% -> 94.816411 | ... AP23: =+AP20*8% -> 88.03338 | AQ23: =+AQ21*8% -> 84.265293 | AR23: =+AR21*8% -> 83.265293 | AS23: =+AS21*8% -> 86.523165 | AT23: =+AT21*8% -> 87.023165 | AU23: =+AU21*8% -> 85.948434 | AV23: 98.09412 | AW23: 99.259168 | AX23: =+AX21*8% -> 92.063111 | AY23: 100.85039 | AZ23: =+AZ21*8% -> 100.48 | BA23: =+BA21*8% -> 100.56 | BB23: =+BB21*8% -> 105.36 | BC23: =+BC21*8% -> 107.64243 | BD23: =+BD21*8% -> 109.18189 | BE23: =+BE21*8% -> 100.1504 | BF23: =+BF21*8% -> 97.789896 | BG23: =+BG21*8% -> 93.828357 | ... CV23: =+CV21*8% -> 106.45736 | CZ23: Precio Consumo | DA23: 1267.0143 | DB23: 1304.1208 | DC23: 1298.9693 | DD23: 1254.8429 | DE23: 1215.9045 | DF23: 1220.6547 | DG23: 1226.1867 | DH23: =+SUMPRODUCT(DH16:DH17,DH21:DH22)/SUM(DH16:DH17) -> 1209.0552 | DI23: =+SUMPRODUCT(DI16:DI17,DI21:DI22)/SUM(DI16:DI17) -> 1194.1872 | DJ23: =+SUMPRODUCT(DJ16:DJ17,DJ21:DJ22)/SUM(DJ16:DJ17) -> 1203.3754 | DK23: =+SUMPRODUCT(DK16:DK17,DK21:DK22)/SUM(DK16:DK17) -> 1217.8503 | DL23: =+SUMPRODUCT(DL16:DL17,DL21:DL22)/SUM(DL16:DL17) -> 1225.5446 | DM23: =+SUMPRODUCT(DM16:DM17,DM21:DM22)/SUM(DM16:DM17) -> 1246.3188 | DN23: =+SUMPRODUCT(DN16:DN17,DN21:DN22)/SUM(DN16:DN17) -> 1317.0024 | DO23: =+SUMPRODUCT(DO16:DO17,DO21:DO22)/SUM(DO16:DO17) -> 1419.7187 | ... EI23: =+SUMPRODUCT(EI16:EI17,EI21:EI22)/SUM(EI16:EI17) -> 1122.3753 | EM23: Landed Factor 8% is it going to vary ?
B24: ZF Legislation Change | C24: Cambio legislacion ZF | BV24: =+('Cambio en Condiciones ZF'!$H$23/'PCR Enka'!$CD$22)/22 -> 18.958371 | BW24: =+('Cambio en Condiciones ZF'!$H$23/'PCR Enka'!$CD$22)/22 -> 18.958371 | BX24: =+('Cambio en Condiciones ZF'!$H$23/'PCR Enka'!$CD$22)/22 -> 18.958371 | BY24: =+('Cambio en Condiciones ZF'!$H$23/'PCR Enka'!$CD$22)/22 -> 18.958371 | BZ24: =+('Cambio en Condiciones ZF'!$H$23/'PCR Enka'!$CD$22)/22 -> 18.958371 | CA24: =+('Cambio en Condiciones ZF'!$H$23/'PCR Enka'!$CD$22)/22 -> 18.958371 | CB24: =+('Cambio en Condiciones ZF'!$H$23/'PCR Enka'!$CD$22)/22 -> 18.958371 | CC24: =+('Cambio en Condiciones ZF'!$H$23/'PCR Enka'!$CD$22)/22 -> 18.958371 | ... CV24: =+('Cambio en Condiciones ZF'!$H$23/'PCR Enka'!$CD$22)/22 -> 18.958371 | CZ24: Precio Inv Final | DA24: 1267.0143 | DB24: 1304.1208 | DC24: 1298.9693 | DD24: 1254.8429 | DE24: 1215.9045 | DF24: 1220.6547 | DG24: 1226.1867 | DH24: =+(SUMPRODUCT(DH16:DH17,DH21:DH22)-(DH18*DH23))/DH19 -> 1209.0552 | DI24: =+(SUMPRODUCT(DI16:DI17,DI21:DI22)-(DI18*DI23))/DI19 -> 1194.1872 | DJ24: =+(SUMPRODUCT(DJ16:DJ17,DJ21:DJ22)-(DJ18*DJ23))/DJ19 -> 1203.3754 | DK24: =+(SUMPRODUCT(DK16:DK17,DK21:DK22)-(DK18*DK23))/DK19 -> 1217.8503 | DL24: =+(SUMPRODUCT(DL16:DL17,DL21:DL22)-(DL18*DL23))/DL19 -> 1225.5446 | DM24: =+(SUMPRODUCT(DM16:DM17,DM21:DM22)-(DM18*DM23))/DM19 -> 1246.3188 | DN24: =+(SUMPRODUCT(DN16:DN17,DN21:DN22)-(DN18*DN23))/DN19 -> 1317.0024 | DO24: =+(SUMPRODUCT(DO16:DO17,DO21:DO22)-(DO18*DO23))/DO19 -> 1419.7187 | ... EI24: =+(SUMPRODUCT(EI16:EI17,EI21:EI22)-(EI18*EI23))/EI19 -> 1122.3753 | EM24: Need more understanding on this ?
B25: Sur Charge Alpek Br | C25: Sur Charge Alpek Br | CL25: 135 | CM25: 135 | CN25: 135 | CO25: 0 | CP25: 0 | CQ25: 0 | CR25: 0 | CS25: 0 | CT25: 0 | CU25: 0 | CV25: 0
B26: Total Resin Price ABI VIRGIN Formula | C26: Total resin price ABI Fórmula VIRGEN | D26: =+D20+D22+D23 -> 1716.2324 | E26: =+E20+E22+E23 -> 1655.7049 | F26: =+F20+F22+F23 -> 1654.9543 | G26: =+G20+G22+G23 -> 1650.2574 | H26: =+H20+H22+H23 -> 1716.2324 | I26: =+I20+I22+I23 -> 1639.0598 | J26: =+J20+J22+J23 -> 1468.0695 | K26: =+K20+K22+K23 -> 1398.5421 | ... AU26: =+AU20+AU22+AU23 -> 1719.0575 | AV26: 1890.6153 | AW26: 1907.0716 | AX26: =+AX20+AX22+AX23 -> 1804.3773 | AY26: 1928.5453 | AZ26: =+AZ20+AZ22+AZ23 -> 1923.28 | BA26: =+BA20+BA22+BA23 -> 1895.01 | BB26: =+BB20+BB22+BB23 -> 1891.41 | BC26: =+BC20+BC22+BC23 -> 1923.2534 | BD26: =+BD20+BD22+BD23 -> 1961.2255 | BE26: =+BE20+BE22+BE23 -> 1833.6557 | BF26: =+BF20+BF22+BF23 -> 1786.95 | BG26: =+BG20+BG22+BG23 -> 1650.3341 | ... BU26: =+BU20+BU22+BU23 -> 1179.1737 | BV26: =+BV20+BV22+BV23+BV24 -> 1213.6744 | BW26: =+BW20+BW22+BW23+BW24 -> 1244.3742 | BX26: =+BX20+BX22+BX23+BX24 -> 1267.6152 | BY26: =+BY20+BY22+BY23+BY24 -> 1267.6152 | BZ26: =+BZ20+BZ22+BZ23+BZ24 -> 1389.4579 | CA26: =+CA20+CA22+CA23+CA24 -> 1500.8057 | CB26: =+CB20+CB22+CB23+CB24 -> 1535.1617 | CC26: =+CC20+CC22+CC23+CC24 -> 1439.1078 | ... CK26: =+CK20+CK22+CK23+CK24 -> 1128.7642 | CL26: =+CL20+CL22+CL23+CL24+CL25 -> 1192.9767 | CM26: =+CM20+CM22+CM23+CM24+CM25 -> 1229.9559 | CN26: =+CN20+CN22+CN23+CN24+CN25 -> 1481.7339 | CO26: =+CO20+CO22+CO23+CO24+CO25 -> 1224.477 | CP26: =+CP20+CP22+CP23+CP24+CP25 -> 1204.7186 | CQ26: =+CQ20+CQ22+CQ23+CQ24+CQ25 -> 1176.8598 | CR26: =+CR20+CR22+CR23+CR24+CR25 -> 1095.0968 | CS26: =+CS20+CS22+CS23+CS24+CS25 -> 1079.0637 | ... CV26: =+CV20+CV22+CV23+CV24+CV25 -> 1561.7572 | EM26: formulae
B27: Final Price with Resin Freight Adjustment | C27: Precio Final con ajuste flete Resina | AK27: =+AK26+#REF! -> #REF! | AL27: =+AL26+#REF! -> #REF! | AM27: =+AM26+#REF! -> #REF! | AN27: =+AN26+#REF! -> #REF! | AO27: =+AO26+#REF! -> #REF! | AP27: =+AP26+#REF! -> #REF! | AQ27: =+AQ26+#REF! -> #REF! | AR27: =+AR26+#REF! -> #REF! | AS27: =+AS26+#REF! -> #REF! | AT27: =+AT26 -> 1693.6699 | AU27: =+AU26 -> 1719.0575 | AV27: 1890.6153 | AW27: 1907.0716 | AX27: =+AX26 -> 1804.3773 | AY27: 1928.5453 | AZ27: =+AZ26 -> 1923.28 | BA27: =+BA26 -> 1895.01 | BB27: =+BB26 -> 1891.41 | BC27: =+BC26 -> 1923.2534 | BD27: =+BD26 -> 1961.2255 | BE27: =+BE26 -> 1833.6557 | BF27: =+BF26 -> 1786.95 | BG27: =+BG26 -> 1650.3341 | ... CV27: =+CV26 -> 1561.7572 | CZ27: 2.which pricing is used as final (do we need to calculate the consumption values as well) ? Assuming its vpet (1100) | EM27: formulae
B28: Final Price FIFO | C28: Precio final FIFO | AK28: =+#REF! -> #REF! | AL28: =+#REF! -> #REF! | AM28: =+#REF! -> #REF! | AN28: =+#REF! -> #REF! | AO28: =+#REF! -> #REF! | AP28: =+#REF! -> #REF! | AQ28: =+#REF! -> #REF! | AR28: =+#REF! -> #REF! | ... AU28: =+#REF! -> #REF! | AV28: 1780.8032 | AW28: 1844.8576 | AX28: =+#REF! -> #REF! | AY28: 1880.1282 | AZ28: =+#REF! -> #REF! | BA28: =+#REF! -> #REF! | BB28: =+#REF! -> #REF! | BC28: =+#REF! -> #REF! | BD28: =+#REF! -> #REF! | BE28: =+#REF! -> #REF! | BF28: =+#REF! -> #REF! | BG28: =+#REF! -> #REF! | ... BL28: =+#REF! -> #REF! | BM28: =+DA24 -> 1267.0143 | BN28: =+DB24 -> 1304.1208 | BO28: =+DC24 -> 1298.9693 | BP28: =+DD24 -> 1254.8429 | BQ28: =+DE24 -> 1215.9045 | BR28: =+DF24 -> 1220.6547 | BS28: =+DG24 -> 1226.1867 | BT28: =+DH24 -> 1209.0552 | ... BV28: =+DJ24 -> 1203.3754 | BW28: =+DJ24 -> 1203.3754 | BX28: =+DL24 -> 1225.5446 | BY28: =+DL24 -> 1225.5446 | BZ28: =+DN24 -> 1317.0024 | CA28: =+DO24 -> 1419.7187 | CB28: =+DP24 -> 1509.9821 | CC28: =+DQ24 -> 1468.9302 | CD28: =+DR24 -> 1441.3902 | CE28: =+DS24 -> 1363.6378 | CF28: =+DT24 -> 1331.6467 | CG28: =+DU24 -> 1304.2778 | ... CU28: =+EI24 -> 1122.3753 | CZ28: 3. do we need the wighted avarge price calculation ?
C29: Ajuste
C30: Total | BC30: =+BC28+BC29 -> #REF! | BD30: =+BD28+BD29 -> #REF! | BE30: =+BE28+BE29 -> #REF! | BF30: =+BF28+BF29 -> #REF! | BG30: =+BG28+BG29 -> #REF! | BH30: =+BH28+BH29 -> #REF! | BI30: =+BI28+BI29 -> #REF! | BJ30: =+BJ28+BJ29 -> #REF! | ... CU30: =+CU28+CU29 -> 1122.3753 | CZ30: 5. In the Freight calculation - Regulaar of 97 $ is constant and the remaining is Incremental based on the Drewery Index ? How will handle future calculation here?
CZ31: translate the cam something sheet
C32: Resin PCR % Enkador | D32: =+D26*(1-5%) -> 1630.4208 | E32: =+E26*(1-5%) -> 1572.9196 | F32: =+F26*(1-5%) -> 1572.2066 | G32: =+G26*(1-5%) -> 1567.7445 | H32: =+H26*(1-5%) -> 1630.4208 | I32: =+I26*(1-5%) -> 1557.1068 | J32: =+J26*(1-5%) -> 1394.666 | K32: =+K26*(1-5%) -> 1328.615 | ... X32: =+X26*(1-5%) -> 1092.8639 | Y32: =1.33255813953488*1000 -> 1332.5581 | Z32: =+' PCR Enkador'!H55 -> 1386.3641 | AA32: =+Z32 -> 1386.3641 | AB32: =+AA32 -> 1386.3641 | AC32: =+AB32 -> 1386.3641 | AD32: =+AC32 -> 1386.3641 | AE32: =+' PCR Enkador'!H69 -> 1412.3596 | AF32: =+' PCR Enkador'!H69 -> 1412.3596 | AG32: =+' PCR Enkador'!H69 -> 1412.3596 | AH32: =+AG32 -> 1412.3596 | AI32: =+AH32 -> 1412.3596 | AJ32: =+' PCR Enkador'!H88 -> 1394.54 | AK32: =+' PCR Enkador'!H88 -> 1394.54 | AL32: =+AK32 -> 1394.54 | AM32: =+AL32 -> 1394.54 | AN32: =+' PCR Enkador'!H104 -> 1485 | AO32: =+AN32 -> 1485 | AP32: =+AO32 -> 1485 | AQ32: =+' PCR Enkador'!H124 -> 1514.8753 | AR32: =+AQ32 -> 1514.8753 | AS32: =+AR32 -> 1514.8753 | AT32: =+' PCR Enkador'!E139 -> 1748.1782 | AU32: =+' PCR Enkador'!F139 -> 2005.359 | AV32: 1942.1299 | AW32: 1863.1434 | AX32: =+' PCR Enkador'!I139 -> 2055.0951 | AY32: 2104.5194 | AZ32: =+' PCR Enkador'!K139 -> 2174.9407 | BA32: =+' PCR Enkador'!L139 -> 2224.6328 | BB32: =+' PCR Enkador'!L139 -> 2224.6328 | BC32: =+' PCR Enkador'!N139 -> 2351.9981 | BD32: =+' PCR Enkador'!O139 -> 2084.088 | BE32: =+' PCR Enkador'!P139 -> 2039.0612 | BF32: =+' PCR Enkador'!Q139 -> 1827.4006 | BG32: =+' PCR Enkador'!R139 -> 1572.153 | BH32: =+' PCR Enkador'!S139 -> 1511.4316 | BI32: =+' PCR Enkador'!T139 -> 1571.7048 | BJ32: =+' PCR Enkador'!U139 -> 1749.1772 | ... CJ32: =+' PCR Enkador'!AU139 -> 2426.0741 | CK32: =+FIFO!BH7 -> 2350.0219 | CL32: =+' PCR Enkador'!AW139 -> 2390.1839 | CM32: =+' PCR Enkador'!AX139 -> 2381.7182 | CN32: =+' PCR Enkador'!AY139 -> 2377.8054 | CO32: =+'PCR Aurora '!W21 -> 2309.209 | CP32: =+'PCR Aurora '!X21 -> 2315.1788 | CQ32: =+'PCR Aurora '!Y21 -> 2287.8265 | CR32: =+'PCR Aurora '!Z21 -> 2304.9182 | CS32: =+' PCR Enkador'!BD139 -> 2246.5395 | CT32: =+' PCR Enkador'!BE139 -> 2284.7438 | CU32: =+' PCR Enkador'!BG139 -> 0
C33: Resin PCR % Enkador FIFO | AQ33: =+AQ32 -> 1514.8753 | AR33: =+AR32 -> 1514.8753 | AS33: =+AS32 -> 1514.8753 | AT33: =+AT32 -> 1748.1782 | AU33: =+AU32 -> 2005.359 | AV33: 1942.1299 | AW33: 1863.1434 | AX33: =+AX32 -> 2055.0951 | AY33: 2104.5194 | AZ33: =+AZ32 -> 2174.9407 | BA33: =+BA32 -> 2224.6328 | BB33: =+BB32 -> 2224.6328 | BC33: =+BC32 -> 2351.9981 | BD33: =+BD32 -> 2084.088 | BE33: =+BE32 -> 2039.0612 | BF33: =+BF32 -> 1827.4006 | BG33: =+BG32 -> 1572.153 | ... BK33: =+BK32 -> 1692.4082 | BL33: =+FIFO!J9 -> 1690.2249 | BM33: =+FIFO!L9 -> 1699.0065 | BN33: =+FIFO!N9 -> 1698.7785 | BO33: =+FIFO!P8 -> 1730.0097 | BP33: =+FIFO!R8 -> 1773.5614 | BQ33: =+FIFO!T8 -> 1784.8755 | BR33: =+FIFO!V8 -> 1784.8628 | BS33: =+FIFO!X8 -> 1813.0215 | BT33: =+FIFO!Z8 -> 1904.7514 | BU33: =+FIFO!AB9 -> 1962.2861 | BV33: =+FIFO!AD8 -> 1845.712 | BW33: =+FIFO!AF8 -> 1890.2731 | BX33: =+FIFO!AH8 -> 1917.1799 | BY33: =+FIFO!AJ7 -> 2006.62 | BZ33: =+FIFO!AL8 -> 1943.4781 | CA33: =+FIFO!AN8 -> 2034.9008 | CB33: =+FIFO!AP8 -> 2114.7268 | CC33: =+FIFO!AR8 -> 2187.7265 | CD33: =+FIFO!AT8 -> 2235.089 | CE33: =+FIFO!AV8 -> 2269.3398 | CF33: =+FIFO!AX8 -> 2218.3559 | CG33: =+FIFO!AZ8 -> 2236.8572 | CH33: =+FIFO!BB8 -> 2321.2754 | CI33: =+FIFO!BD8 -> 2410.4813 | CJ33: =+FIFO!BF8 -> 2410.8753 | CK33: =+FIFO!BH8 -> 2358.2488 | CL33: =+FIFO!#REF! -> #REF! | CM33: =+FIFO!CA8 -> 0 | CN33: =+FIFO!BN34 -> 2373.4672 | CO33: =+FIFO!BO34 -> 0 | CP33: =+FIFO!BP34 -> 2373.4672 | CQ33: =+FIFO!BR34 -> 2373.4672 | CR33: =+FIFO!CA34 -> 0 | CS33: =+FIFO!CB34 -> 0 | CT33: =+FIFO!CC34 -> 0 | CU33: =+FIFO!CD34 -> 0 | CY33: =+FIFO!BQ34 -> 0 | CZ33: 7. Enakador , Enka , Aurora what are these ? Will it always be enka in the legislation calculation?
C34: Resin PCR % Enka | Z34: =+'PCR Enka'!C26 -> 1070.2457 | AA34: =+'PCR Enka'!D26 -> 1103.3118 | AB34: =+'PCR Enka'!D26 -> 1103.3118 | AC34: =+'PCR Enka'!E26 -> 1149.9847 | AD34: =+'PCR Enka'!E26 -> 1149.9847 | AE34: =+'PCR Enka'!F26 -> 1163.7352 | AF34: =+'PCR Enka'!F26 -> 1163.7352 | AG34: 6 | AH34: =+'PCR Enka'!H26 -> 1125.2337 | AI34: =+'PCR Enka'!I26 -> 1153.6209 | AJ34: =+'PCR Enka'!J26 -> 1197.5282 | AK34: =+'PCR Enka'!K26 -> 1277.3813 | AL34: =+'PCR Enka'!L26 -> 1467.9415 | AM34: =+'PCR Enka'!M26 -> 1432.478 | AN34: =+'PCR Enka'!N26 -> 1415.0274 | AO34: =+'PCR Enka'!O26 -> 1623.5225 | ... AU34: =+'PCR Enka'!U26 -> 1905.3661 | AV34: 1842.137 | AW34: 1765.8142 | AX34: =+'PCR Enka'!X26 -> 1957.7659 | AY34: 2007.3086 | AZ34: =+'PCR Enka'!Z26 -> 2077.6143 | BA34: =+'PCR Enka'!AA26 -> 2127.3064 | BB34: =+'PCR Enka'!AA26 -> 2127.3064 | BC34: =+'PCR Enka'!AC26 -> 2251.8217 | BD34: =+'PCR Enka'!AD26 -> 1986.3646 | BE34: =+'PCR Enka'!AE26 -> 1941.3379 | BF34: =+'PCR Enka'!AF26 -> 1729.6772 | BG34: =+'PCR Enka'!AG26 -> 1474.4296 | BH34: =+'PCR Enka'!AH26 -> 1413.7082 | BI34: =+'PCR Enka'!AI26 -> 1472.9887 | BJ34: =+'PCR Enka'!AJ26 -> 1650.4611 | ... BT34: =+'PCR Enka'!AT26 -> 1819.4162 | BU34: =+' PCR Enkador'!AF134 -> 1891.8355 | BV34: =+' PCR Enkador'!AG134 -> 1664.6783 | BW34: =+' PCR Enkador'!AH134 -> 1838.384 | BX34: =+' PCR Enkador'!AI134 -> 1862.1217 | BY34: =+' PCR Enkador'!AI134 -> 1862.1217 | BZ34: =+' PCR Enkador'!AK134 -> 1939.5828 | CA34: =+' PCR Enkador'!AL134 -> 1970.9734 | CB34: =+' PCR Enkador'!AM134 -> 2046.3999 | CC34: =+' PCR Enkador'!AN134 -> 2115.9076 | CD34: =+' PCR Enkador'!AO134 -> 2145.6482 | CE34: =+' PCR Enkador'!AP134 -> 2183.3734 | CF34: =+' PCR Enkador'!AQ134 -> 2108.3299 | CG34: =+' PCR Enkador'!AR134 -> 2139.863 | ... CJ34: =+' PCR Enkador'!AU134 -> 2328.0642 | CK34: =+FIFO!BH20 -> 2252.012 | CL34: =+' PCR Enkador'!AW134 -> 2292.174 | CM34: =+'PCR Aurora '!U14 -> 2283.7083 | CN34: =+'PCR Enka'!DS26 -> 2279.7955 | CO34: =+'PCR Aurora '!W14 -> 2211.1991 | CP34: =+'PCR Aurora '!X14 -> 2217.1689 | CQ34: =+'PCR Aurora '!Y14 -> 2189.8166 | CR34: =+'PCR Aurora '!Z14 -> 2206.9083 | CS34: =+'PCR Aurora '!AA40 -> 1925.9158 | CT34: =+'PCR Enka'!EI26 -> 2187.0429 | CU34: =+'PCR Enka'!EK26 -> 0 | CZ34: 8. Are the pricing below Row # 30 are also considered for the calculation ?
C35: Resin PCR % Enka FIFO | BL35: =+FIFO!J22 -> 1541.7236 | BM35: =+FIFO!L22 -> 1572.2305 | BN35: =+FIFO!N22 -> 1582.7075 | BO35: =+FIFO!P21 -> 1624.5182 | BP35: =+FIFO!R21 -> 1640.1021 | BQ35: =+FIFO!T21 -> 1640.1021 | BR35: =+FIFO!V21 -> 1640.1021 | BS35: =+FIFO!X21 -> 1640.1021 | BT35: =+FIFO!Z21 -> 1640.1021 | BU35: =+FIFO!AB22 -> 1640.1021 | BV35: =+FIFO!AD21 -> 1640.1021 | BW35: =+FIFO!AF21 -> 1640.1021 | BX35: =+FIFO!AH21 -> 1640.1021 | BY35: =+FIFO!AJ21 -> 1640.1021 | BZ35: =+FIFO!AL21 -> 1640.1021 | CA35: =+FIFO!AN21 -> 1756.8307 | CB35: =+FIFO!AP21 -> 1848.502 | CC35: =+FIFO!AR21 -> 1924.5346 | CD35: =+FIFO!AT21 -> 1924.5346 | CE35: =+FIFO!AV21 -> 1924.5346 | CF35: =+FIFO!AX21 -> 1924.5346 | CG35: =+FIFO!AZ21 -> 1924.5346 | CH35: =+FIFO!BB21 -> 1924.5346 | CI35: =+FIFO!BD21 -> 2047.4442 | CJ35: =+FIFO!BF21 -> 2047.5847 | CK35: =+FIFO!BH21 -> 2095.2472 | CL35: =+FIFO!BJ21 -> 2103.5509 | CM35: =+FIFO!BL21 -> 2141.3654 | CN35: =+FIFO!BN21 -> 2141.3654 | CO35: =+FIFO!BP21 -> 2141.3654 | CP35: =+FIFO!BR21 -> 2141.3654 | CQ35: =+FIFO!BR21 -> 2141.3654 | CR35: =+FIFO!BV21 -> 2141.3654 | CS35: =+FIFO!BV21 -> 2141.3654 | CT35: =+FIFO!BZ21 -> 2141.3654 | CU35: =+FIFO!CA21 -> 0 | CZ35: 9. Need more undestanding on the Legilation charges calculation , it refers to 2 sheets
C36: Resin PCR % Aurora Clear. | Z36: =+'PCR Enka'!C28 -> 0 | AA36: =+'PCR Enka'!D28 -> 0 | AB36: =+'PCR Enka'!D28 -> 0 | AC36: =+'PCR Enka'!E28 -> 0 | AD36: =+'PCR Enka'!E28 -> 0 | AE36: =+'PCR Enka'!F28 -> 0 | AF36: =+'PCR Enka'!F28 -> 0 | AG36: 6 | AH36: =+'PCR Enka'!H28 -> 0 | AI36: =+'PCR Enka'!I28 -> 0 | AJ36: =+'PCR Enka'!J28 -> 0 | AK36: =+'PCR Enka'!K28 -> 0 | AL36: =+'PCR Enka'!L28 -> 0 | AM36: =+'PCR Enka'!M28 -> 0 | AN36: =+'PCR Enka'!N28 -> 0 | AO36: =+'PCR Enka'!O28 -> 0 | ... AU36: =+'PCR Enka'!U28 -> 0 | AV36: 1842.137 | AW36: 1765.8142 | AX36: =+'PCR Enka'!X28 -> 0 | AY36: 2007.3086 | AZ36: =+'PCR Enka'!Z28 -> 0 | BA36: =+'PCR Enka'!AA28 -> 0 | BB36: =+'PCR Enka'!AA28 -> 0 | BC36: =+'PCR Enka'!AC28 -> 0 | BD36: =+'PCR Enka'!AD28 -> 0 | BE36: =+'PCR Enka'!AE28 -> 0 | BF36: =+'PCR Enka'!AF28 -> 0 | BG36: =+'PCR Enka'!AG28 -> 0 | BH36: =+'PCR Enka'!AH28 -> 0 | BI36: =+'PCR Enka'!AI28 -> 0 | BJ36: =+'PCR Enka'!AJ28 -> 0 | ... BT36: =+'PCR Enka'!AT28 -> 0 | BU36: =+' PCR Enkador'!AF136 -> 94.4 | BV36: =+' PCR Enkador'!AG136 -> 94.4 | BW36: =+' PCR Enkador'!AH136 -> 94.4 | BX36: =+' PCR Enkador'!AI136 -> 94.4 | BY36: =+' PCR Enkador'!AI136 -> 94.4 | BZ36: =+' PCR Enkador'!AK136 -> 94.4 | CA36: =+' PCR Enkador'!AL136 -> 94.4 | CB36: =+' PCR Enkador'!AM136 -> 94.4 | CC36: =+' PCR Enkador'!AN136 -> 94.4 | CD36: =+' PCR Enkador'!AO136 -> 94.4 | CE36: =+' PCR Enkador'!AP136 -> 94.4 | CF36: =+' PCR Enkador'!AQ136 -> 94.4 | CG36: =+' PCR Enkador'!AR136 -> 94.4 | CK36: =+'PCR Aurora '!S40 -> 2305.7167 | CL36: =+'PCR Aurora '!T40 -> 2302.3702 | CM36: =+'PCR Aurora '!U40 -> 2271.7916 | CN36: =+'PCR Aurora '!V40 -> 2155.0837 | CO36: =+'PCR Aurora '!W40 -> 1974.3326 | CP36: =+'PCR Aurora '!X40 -> 1974.0609 | CQ36: =+'PCR Aurora '!Y40 -> 1958.5504 | CR36: =+'PCR Aurora '!Z40 -> 1951.0595 | ... CU36: =+'PCR Aurora '!AC40 -> 1982.7376 | CZ36: 12. What are the units , Price for metric ton ?
C37: Resin PCR % Aurora. FIFO | BL37: =+FIFO!J24 -> 1536.7815 | BM37: =+FIFO!L24 -> 1541.7236 | BN37: =+FIFO!N24 -> 1572.2305 | BO37: =+FIFO!P23 -> 0 | BP37: =+FIFO!R23 -> 0 | BQ37: =+FIFO!T23 -> 0 | BR37: =+FIFO!V23 -> 0 | BS37: =+FIFO!X23 -> 0 | BT37: =+FIFO!Z23 -> 0 | BU37: =+FIFO!AB24 -> 1640.1021 | BV37: =+FIFO!AD23 -> 0 | BW37: =+FIFO!AF23 -> 0 | BX37: =+FIFO!AH23 -> 0 | BY37: =+FIFO!AJ23 -> 0 | BZ37: =+FIFO!AL23 -> 0 | CA37: =+FIFO!AN23 -> 0 | CB37: =+FIFO!AP23 -> 0 | CC37: =+FIFO!AR23 -> 0 | CD37: =+FIFO!AT23 -> 0 | CE37: =+FIFO!AV23 -> 0 | CF37: =+FIFO!AX23 -> 0 | CG37: =+FIFO!AZ23 -> 0 | CK37: =+FIFO!BH23 -> 0 | CL37: =+FIFO!#REF! -> #REF! | CM37: =+FIFO!CA23 -> 0 | CN37: =+FIFO!CB23 -> 0 | CO37: =+FIFO!CC23 -> 0 | CP37: =+FIFO!CD23 -> 0 | CQ37: =+FIFO!CE23 -> 0 | CR37: =+FIFO!CF23 -> 0 | CS37: =+FIFO!CG23 -> 0 | CT37: =+FIFO!CH23 -> 0 | CU37: =+FIFO!CI23 -> 0 | CZ37: 13. What is finance here ? We are using SOFR rate % for the finance calculation
C38: Resin PCR % Aurora Ambar. | Z38: =+'PCR Enka'!C30 -> Fecha | AA38: =+'PCR Enka'!D30 -> TRM | AB38: =+'PCR Enka'!D30 -> TRM | AC38: =+'PCR Enka'!E30 -> Fecha | AD38: =+'PCR Enka'!E30 -> Fecha | AE38: =+'PCR Enka'!F30 -> TRM | AF38: =+'PCR Enka'!F30 -> TRM | AG38: 6 | AH38: =+'PCR Enka'!H30 -> TRM | AI38: =+'PCR Enka'!I30 -> Fecha | AJ38: =+'PCR Enka'!J30 -> TRM | AK38: =+'PCR Enka'!K30 -> Fecha | AL38: =+'PCR Enka'!L30 -> TRM | AM38: =+'PCR Enka'!M30 -> Fecha | AN38: =+'PCR Enka'!N30 -> TRM | AO38: =+'PCR Enka'!O30 -> Fecha | ... AU38: =+'PCR Enka'!U30 -> Fecha | AV38: 1842.137 | AW38: 1765.8142 | AX38: =+'PCR Enka'!X30 -> TRM | AY38: 2007.3086 | AZ38: =+'PCR Enka'!Z30 -> TRM | BA38: =+'PCR Enka'!AA30 -> Fecha | BB38: =+'PCR Enka'!AA30 -> Fecha | BC38: =+'PCR Enka'!AC30 -> Fecha | BD38: =+'PCR Enka'!AD30 -> TRM | BE38: =+'PCR Enka'!AE30 -> Fecha | BF38: =+'PCR Enka'!AF30 -> TRM | BG38: =+'PCR Enka'!AG30 -> Fecha | BH38: =+'PCR Enka'!AH30 -> TRM | BI38: =+'PCR Enka'!AI30 -> Fecha | BJ38: =+'PCR Enka'!AJ30 -> TRM | ... BT38: =+'PCR Enka'!AT30 -> TRM | BU38: =+' PCR Enkador'!AF138 -> 97.700897 | BV38: =+' PCR Enkador'!AG138 -> 97.700897 | BW38: =+' PCR Enkador'!AH138 -> 98.610694 | BX38: =+' PCR Enkador'!AI138 -> 98.610694 | BY38: =+' PCR Enkador'!AI138 -> 98.610694 | BZ38: =+' PCR Enkador'!AK138 -> 98.610694 | CA38: =+' PCR Enkador'!AL138 -> 98.610694 | CB38: =+' PCR Enkador'!AM138 -> 98.610694 | CC38: =+' PCR Enkador'!AN138 -> 98.610694 | CD38: =+' PCR Enkador'!AO138 -> 98.610694 | CE38: =+' PCR Enkador'!AP138 -> 98.610694 | CF38: =+' PCR Enkador'!AQ138 -> 98.610694 | CG38: =+' PCR Enkador'!AR138 -> 98.009902 | CK38: =+'PCR Aurora '!S42 -> 0 | CL38: =+'PCR Aurora '!T42 -> 0 | CM38: =+'PCR Aurora '!U42 -> 0 | CN38: =+'PCR Aurora '!V42 -> 0 | CO38: =+'PCR Aurora '!W42 -> 0 | CP38: =+'PCR Aurora '!X42 -> 0 | CQ38: =+'PCR Aurora '!Y42 -> 0 | CR38: =+'PCR Aurora '!Z42 -> 0 | ... CU38: =+'PCR Aurora '!AC42 -> 1882.7376
C39: Resin PCR % Aurora. FIFO | BL39: =+FIFO!J26 -> 1541.7236 | BM39: =+FIFO!L26 -> 1572.2305 | BN39: =+FIFO!N26 -> 1582.7075 | BO39: =+FIFO!P25 -> 1688.6913 | BP39: =+FIFO!R25 -> 1735.1046 | BQ39: =+FIFO!T25 -> 1696.6764 | BR39: =+FIFO!V25 -> 1687.1596 | BS39: =+FIFO!X25 -> 1717.7417 | BT39: =+FIFO!Z25 -> 1819.4162 | BU39: =+FIFO!AB26 -> 1640.1021 | BV39: =+FIFO!AD25 -> 0 | BW39: =+FIFO!AF25 -> 0 | BX39: =+FIFO!AH25 -> 0 | BY39: =+FIFO!AJ25 -> 0 | BZ39: =+FIFO!AL25 -> 0 | CA39: =+FIFO!AN25 -> 1970.9734 | CB39: =+FIFO!AP25 -> 2046.3999 | CC39: =+FIFO!AR25 -> 2115.9076 | CD39: =+FIFO!AT25 -> 2145.6482 | CE39: =+FIFO!AV25 -> 2183.3734 | CF39: =+FIFO!AX25 -> 2108.3299 | CG39: =+FIFO!AZ25 -> 2139.863 | CK39: =+FIFO!BH25 -> 2252.012 | CL39: =+FIFO!#REF! -> #REF! | CM39: =+FIFO!CA25 -> 0 | CN39: =+FIFO!CB25 -> 0 | CO39: =+FIFO!CC25 -> 0 | CP39: =+FIFO!CD25 -> 0 | CQ39: =+FIFO!CE25 -> 0 | CR39: =+FIFO!CF25 -> 0 | CS39: =+FIFO!CG25 -> 0 | CT39: =+FIFO!CH25 -> 0 | CU39: =+FIFO!CI25 -> 0
C41: Precio ponderado bajo formula 50 PCR Aurora /50 Virgen | V41: =+(V32*50%)+(V66*50%) -> 531.97998 | W41: =+(W26*50%)+(W32*50%) -> 1100.761 | X41: =+(X26*50%)+(X32*50%) -> 1121.6234 | Y41: =+(Y26*50%)+(Y32*50%) -> 1241.4706 | Z41: =+(Z26*50%)+(Z32*50%) -> 1204.7359 | AA41: =+(AA26*50%)+(AA32*50%) -> 1154.2059 | AB41: =+(AB26*50%)+(AB32*50%) -> 1186.407 | AC41: =+(AC26*50%)+(AC32*50%) -> 1163.0802 | AD41: =+(AD26*50%)+(AD32*50%) -> 1174.222 | ... AJ41: =+(AJ26*50%)+(AJ32*50%) -> 1149.9627 | AK41: =+(AK27*50%)+(AK32*50%) -> #REF! | AL41: =+(AL27*50%)+(AL32*50%) -> #REF! | AM41: =+(AM27*50%)+(AM32*50%) -> #REF! | AN41: =+(AN27*50%)+(AN32*50%) -> #REF! | AO41: =+(AO27*50%)+(AO32*50%) -> #REF! | AP41: =+(AP27*50%)+(AP32*50%) -> #REF! | AQ41: =+(AQ28*50%)+(AQ33*50%) -> #REF! | AR41: =+(AR28*50%)+(AR33*50%) -> #REF! | AS41: =+(AS28*50%)+(AS33*50%) -> #REF! | AT41: =+(AT28*50%)+(AT33*50%) -> #REF! | AU41: =+(AU28*50%)+(AU33*50%) -> #REF! | AV41: 1861.4665 | AW41: 1854.0005 | AX41: =+(AX28*50%)+(AX33*50%) -> #REF! | AY41: 1992.3238 | AZ41: =+(AZ28*50%)+(AZ33*50%) -> #REF! | BA41: =+(BA28*50%)+(BA33*50%) -> #REF! | BB41: =+(BB28*50%)+(BB33*50%) -> #REF! | BC41: =+(BC30*50%)+(BC33*50%) -> #REF! | BD41: =+(BD30*50%)+(BD33*50%) -> #REF! | BE41: =+(BE30*50%)+(BE33*50%) -> #REF! | BF41: =+(BF30*50%)+(BF33*50%) -> #REF! | BG41: =+(BG30*50%)+(BG33*50%) -> #REF! | BH41: =+(BH30*50%)+(BH33*50%) -> #REF! | BI41: =+(BI30*50%)+(BI33*50%) -> #REF! | BJ41: =+(BJ30*50%)+(BJ33*50%) -> #REF! | ... CJ41: =+(CJ30*50%)+(CJ33*50%) -> 1794.7595 | CK41: =+(CK30*50%)+(CK36*50%) -> 1732.6105 | CL41: =+(CL30*50%)+(CL36*50%) -> 1736.1742 | CM41: =+(CM30*50%)+(CM36*50%) -> 1730.127 | CN41: =+(CN30*50%)+(CN36*50%) -> 1759.7594 | CO41: =+(CO30*50%)+(CO36*50%) -> 1630.5479 | CP41: =+(CP30*50%)+(CP36*50%) -> 1611.7818 | CQ41: =+(CQ30*50%)+(CQ36*50%) -> 1594.1294 | CR41: =+(CR30*50%)+(CR36*50%) -> 1576.2434 | ... CU41: =+(CU30*50%)+(CU36*50%) -> 1552.5564
C42: Scrap 1% | V42: =+V41*1% -> 5.3197998 | W42: =+W41*1% -> 11.00761 | X42: =+X41*1% -> 11.216234 | Y42: =+Y41*1% -> 12.414706 | Z42: =+Z41*1% -> 12.047359 | AA42: =+AA41*1% -> 11.542059 | AB42: =+AB41*1% -> 11.86407 | AC42: =+AC41*1% -> 11.630802 | ... AU42: =+AU41*1% -> #REF! | AV42: 18.614665 | AW42: 18.540005 | AX42: =+AX41*1% -> #REF! | AY42: 19.923238 | AZ42: =+AZ41*1% -> #REF! | BA42: =+BA41*1% -> #REF! | BB42: =+BB41*1% -> #REF! | BC42: =+BC41*1% -> #REF! | BD42: =+BD41*1% -> #REF! | BE42: =+BE41*1% -> #REF! | BF42: =+BF41*1% -> #REF! | BG42: =+BG41*1% -> #REF! | ... CU42: =+CU41*1% -> 15.525564
C43: Precio ponderado con scrap | V43: =+V42+V41 -> 537.29978 | W43: =+W42+W41 -> 1111.7686 | X43: =+X42+X41 -> 1132.8397 | Y43: =+Y42+Y41 -> 1253.8853 | Z43: =+Z42+Z41 -> 1216.7833 | AA43: =+AA42+AA41 -> 1165.748 | AB43: =+AB42+AB41 -> 1198.2711 | AC43: =+AC42+AC41 -> 1174.711 | ... AU43: =+AU42+AU41 -> #REF! | AV43: 1880.0812 | AW43: 1872.5405 | AX43: =+AX42+AX41 -> #REF! | AY43: 2012.247 | AZ43: =+AZ42+AZ41 -> #REF! | BA43: =+BA42+BA41 -> #REF! | BB43: =+BB42+BB41 -> #REF! | BC43: =+BC42+BC41 -> #REF! | BD43: =+BD42+BD41 -> #REF! | BE43: =+BE42+BE41 -> #REF! | BF43: =+BF42+BF41 -> #REF! | BG43: =+BG42+BG41 -> #REF! | ... CU43: =+CU42+CU41 -> 1568.082
C45: Precio ponderado bajo formula 100% PCR Enka | Z45: =+Z34 -> 1070.2457 | AA45: =+AA34 -> 1103.3118 | AB45: =+AB34 -> 1103.3118 | AC45: =+AC34 -> 1149.9847 | AD45: =+AD34 -> 1149.9847 | AE45: =+AE34 -> 1163.7352 | AF45: =+AF34 -> 1163.7352 | AG45: =+AG34 -> 6 | ... AU45: =+AU34 -> 1905.3661 | AV45: 1842.137 | AW45: 1765.8142 | AX45: =+AX34 -> 1957.7659 | AY45: 2007.3086 | AZ45: =+AZ34 -> 2077.6143 | BA45: =+BA34 -> 2127.3064 | BB45: =+BB34 -> 2127.3064 | BC45: =+BC34 -> 2251.8217 | BD45: =+BD34 -> 1986.3646 | BE45: =+BE34 -> 1941.3379 | BF45: =+BF34 -> 1729.6772 | BG45: =+BG34 -> 1474.4296 | ... BK45: =+BK34 -> 1593.6921 | BL45: =+BL35 -> 1541.7236 | BM45: =+BM35 -> 1572.2305 | BN45: =+BN35 -> 1582.7075 | BO45: =+BO35 -> 1624.5182 | BP45: =+BP35 -> 1640.1021 | BQ45: =+BQ35 -> 1640.1021 | BR45: =+BR35 -> 1640.1021 | BS45: =+BS35 -> 1640.1021 | ... BU45: =+BU35 -> 1640.1021 | BV45: =+FIFO!AB21 -> 1640.1021 | BW45: =+BW35 -> 1640.1021 | BX45: =+BX35 -> 1640.1021 | BY45: =+BY35 -> 1640.1021 | BZ45: =+BZ35 -> 1640.1021 | CA45: =+CA35 -> 1756.8307 | CB45: =+CB35 -> 1848.502 | CC45: =+CC35 -> 1924.5346 | CD45: =+CD35 -> 1924.5346 | ... CJ45: =+CJ35 -> 2047.5847 | CK45: =+FIFO!BH21 -> 2095.2472 | CL45: =+FIFO!BJ21 -> 2103.5509 | CM45: =+CM35 -> 2141.3654 | CN45: =+CN35 -> 2141.3654 | CO45: =+FIFO!BP20 -> 2211.1991 | CP45: =+CP35 -> 2141.3654 | CQ45: =+CQ35 -> 2141.3654 | CR45: =+'PCR Aurora '!Z14 -> 2206.9083 | CS45: =+'PCR Enka'!DX26 -> 2148.8386 | CT45: =+CT35 -> 2141.3654 | CU45: =+FIFO!BZ21 -> 2141.3654
C46: Scrap 1% | Z46: =+Z45*1% -> 10.702457 | AA46: =+AA45*1% -> 11.033118 | AB46: =+AB45*1% -> 11.033118 | AC46: =+AC45*1% -> 11.499847 | AD46: =+AD45*1% -> 11.499847 | AE46: =+AE45*1% -> 11.637352 | AF46: =+AF45*1% -> 11.637352 | AG46: =+AG45*1% -> 0.06 | ... AU46: =+AU45*1% -> 19.053661 | AV46: 18.42137 | AW46: 17.658142 | AX46: =+AX45*1% -> 19.577659 | AY46: 20.073086 | AZ46: =+AZ45*1% -> 20.776143 | BA46: =+BA45*1% -> 21.273064 | BB46: =+BB45*1% -> 21.273064 | BC46: =+BC45*1% -> 22.518217 | BD46: =+BD45*1% -> 19.863646 | BE46: =+BE45*1% -> 19.413379 | BF46: =+BF45*1% -> 17.296772 | BG46: =+BG45*1% -> 14.744296 | ... CU46: =+CU45*1% -> 21.413654
C47: Precio ponderado con scrap | Z47: =+Z46+Z45 -> 1080.9482 | AA47: =+AA46+AA45 -> 1114.3449 | AB47: =+AB46+AB45 -> 1114.3449 | AC47: =+AC46+AC45 -> 1161.4845 | AD47: =+AD46+AD45 -> 1161.4845 | AE47: =+AE46+AE45 -> 1175.3725 | AF47: =+AF46+AF45 -> 1175.3725 | AG47: =+AG46+AG45 -> 6.06 | ... AU47: =+AU46+AU45 -> 1924.4198 | AV47: 1860.5584 | AW47: 1783.4723 | AX47: =+AX46+AX45 -> 1977.3435 | AY47: 2027.3817 | AZ47: =+AZ46+AZ45 -> 2098.3905 | BA47: =+BA46+BA45 -> 2148.5795 | BB47: =+BB46+BB45 -> 2148.5795 | BC47: =+BC46+BC45 -> 2274.3399 | BD47: =+BD46+BD45 -> 2006.2282 | BE47: =+BE46+BE45 -> 1960.7512 | BF47: =+BF46+BF45 -> 1746.974 | BG47: =+BG46+BG45 -> 1489.1739 | ... CU47: =+CU46+CU45 -> 2162.7791
C49: Precio ponderado bajo formula 75 PCR Aurora /25 Virgen. | AI49: =+(AI26*25%)+(AI32*75%) -> 1288.0475 | AJ49: =+(AJ26*25%)+(AJ32*75%) -> 1272.2514 | AK49: =+(AK27*25%)+(AK32*75%) -> #REF! | AL49: =+(AL27*25%)+(AL32*75%) -> #REF! | AM49: =+(AM27*25%)+(AM32*75%) -> #REF! | AN49: =+(AN27*25%)+(AN32*75%) -> #REF! | AO49: =+(AO27*25%)+(AO32*75%) -> #REF! | AP49: =+(AP27*25%)+(AP32*75%) -> #REF! | AQ49: =+(AQ28*25%)+(AQ33*75%) -> #REF! | AR49: =+(AR28*25%)+(AR33*75%) -> #REF! | AS49: =+(AS28*25%)+(AS33*75%) -> #REF! | AT49: =+(AT28*25%)+(AT33*75%) -> #REF! | AU49: =+(AU28*25%)+(AU33*75%) -> #REF! | AV49: 1901.7982 | AW49: 1858.572 | AX49: =+(AX28*25%)+(AX33*75%) -> #REF! | AY49: 2048.4216 | AZ49: =+(AZ28*25%)+(AZ33*75%) -> #REF! | BA49: =+(BA28*25%)+(BA33*75%) -> #REF! | BB49: =+(BB28*25%)+(BB33*75%) -> #REF! | BC49: =+(BC30*25%)+(BC33*75%) -> #REF! | BD49: =+(BD30*25%)+(BD33*75%) -> #REF! | BE49: =+(BE30*25%)+(BE33*75%) -> #REF! | BF49: =+(BF30*25%)+(BF33*75%) -> #REF! | BG49: =+(BG30*25%)+(BG33*75%) -> #REF! | BH49: =+(BH30*25%)+(BH33*75%) -> #REF! | BI49: =+(BI30*25%)+(BI33*75%) -> #REF! | BJ49: =+(BJ30*25%)+(BJ33*75%) -> #REF! | ... CJ49: =+(CJ30*25%)+(CJ33*75%) -> 2102.8174 | CK49: =+(CK30*25%)+(CK36*75%) -> 2019.1636 | CL49: =+(CL30*25%)+(CL36*75%) -> 2019.2722 | CM49: =+(CM30*25%)+(CM36*75%) -> 2000.9593 | CN49: =+(CN30*25%)+(CN36*75%) -> 1957.4215 | CO49: =+(CO30*25%)+(CO36*75%) -> 1802.4403 | CP49: =+(CP30*25%)+(CP36*75%) -> 1792.9214 | CQ49: =+(CQ30*25%)+(CQ36*75%) -> 1776.3399 | CR49: =+(CR30*25%)+(CR36*75%) -> 1763.6515 | ... CU49: =+(CU30*25%)+(CU36*75%) -> 1767.647
C50: Scrap 1% | AI50: =+AI49*1% -> 12.880475 | AJ50: =+AJ49*1% -> 12.722514 | AK50: =+AK49*1% -> #REF! | AL50: =+AL49*1% -> #REF! | AM50: =+AM49*1% -> #REF! | AN50: =+AN49*1% -> #REF! | AO50: =+AO49*1% -> #REF! | AP50: =+AP49*1% -> #REF! | ... AU50: =+AU49*1% -> #REF! | AV50: 19.017982 | AW50: 18.58572 | AX50: =+AX49*1% -> #REF! | AY50: 20.484216 | AZ50: =+AZ49*1% -> #REF! | BA50: =+BA49*1% -> #REF! | BB50: =+BB49*1% -> #REF! | BC50: =+BC49*1% -> #REF! | BD50: =+BD49*1% -> #REF! | BE50: =+BE49*1% -> #REF! | BF50: =+BF49*1% -> #REF! | BG50: =+BG49*1% -> #REF! | ... CU50: =+CU49*1% -> 17.67647
C51: Precio ponderado con scrap | AI51: =+AI50+AI49 -> 1300.928 | AJ51: =+AJ50+AJ49 -> 1284.9739 | AK51: =+AK50+AK49 -> #REF! | AL51: =+AL50+AL49 -> #REF! | AM51: =+AM50+AM49 -> #REF! | AN51: =+AN50+AN49 -> #REF! | AO51: =+AO50+AO49 -> #REF! | AP51: =+AP50+AP49 -> #REF! | ... AU51: =+AU50+AU49 -> #REF! | AV51: 1920.8162 | AW51: 1877.1577 | AX51: =+AX50+AX49 -> #REF! | AY51: 2068.9058 | AZ51: =+AZ50+AZ49 -> #REF! | BA51: =+BA50+BA49 -> #REF! | BB51: =+BB50+BB49 -> #REF! | BC51: =+BC50+BC49 -> #REF! | BD51: =+BD50+BD49 -> #REF! | BE51: =+BE50+BE49 -> #REF! | BF51: =+BF50+BF49 -> #REF! | BG51: =+BG50+BG49 -> #REF! | ... CU51: =+CU50+CU49 -> 1785.3235
C53: Precio ponderado bajo formula 100% PCR Enkador | V53: =+V32 -> 1063.96 | W53: =+W32 -> 1072.5364 | X53: =+X32 -> 1092.8639 | Y53: =+Y32 -> 1332.5581 | Z53: =+Z32 -> 1386.3641 | AA53: =+AA32 -> 1386.3641 | AB53: =+AB32 -> 1386.3641 | AC53: =+AC32 -> 1386.3641 | ... AP53: =+AP32 -> 1485 | AQ53: =+AQ33 -> 1514.8753 | AR53: =+AR33 -> 1514.8753 | AS53: =+AS33 -> 1514.8753 | AT53: =+AT33 -> 1748.1782 | AU53: =+AU33 -> 2005.359 | AV53: 1942.1299 | AW53: 1863.1434 | AX53: =+AX33 -> 2055.0951 | AY53: 2104.5194 | AZ53: =+AZ33 -> 2174.9407 | BA53: =+BA33 -> 2224.6328 | BB53: =+BB33 -> 2224.6328 | BC53: =+BC33 -> 2351.9981 | BD53: =+BD33 -> 2084.088 | BE53: =+BE33 -> 2039.0612 | BF53: =+BF33 -> 1827.4006 | BG53: =+BG33 -> 1572.153 | ... CU53: =+CU33 -> 0
...

Sheet Fórmula Marzo 26
D1: FÓRMULA
D11: PRECIOS DE RESINA ABI MARZO 2026
CQ12: 137.45455 | CR12: 76.363636 | CS12: 65.136364 | CT12: 39.954545 | CU12: 6.5909091 | CX12: 1. couldn’t figure out the formula here. If its colombia why is it not quarterly
AF13: Fórmula
B14: Translation | D14: PRICE | E14: Jul-18 | F14: Ago-2018 | G14: Sep-18 | H14: Oct-18 | I14: Nov-18 | J14: Dic-18 | K14: Ene-19 | L14: Feb-19 | M14: Mar-19 | N14: Abr-19 | O14: May-19 | P14: Jun-19 | Q14: Jul-19 | R14: Ago-19 | S14: Sep-19 | T14: Oct-19 | U14: Nov-20 | V14: Dic-20 | W14: Ene-20 | X14: Feb-20 | Y14: Mar-20 | Z14: Abr-20 | AA14: May-20 | AB14: Jun-20 | AC14: Jun-20 | AD14: Jul-20 | AE14: Jul-20 | AF14: Ago-20 | AG14: Ago-20 | AH14: Sep-20 | AI14: Oct-20 | AJ14: Nov-20 | AK14: Dic-20 | AL14: Ene-21 | AM14: Feb-21 | AN14: Mar-21 | AO14: Abr-21 | AP14: May-21 | AQ14: Jun-21 | AR14: Jul-21 | AS14: Ago-21 | AT14: Sep-21 | AU14: Oct-21 | AV14: Nov-21 | AW14: Dic-21 | AX14: Ene-22 | AY14: Feb-22 | AZ14: Mar-22 | BA14: Abr-22 | BB14: Mayo-22 | BC14: Junio-22 | BD14: Julio-22 | BE14: Agosto-22 | BF14: Septiembre-22 | BG14: Octubre-22 | BH14: Noviembre-22 | BI14: Diciembre-22 | BJ14: Enero-23 | BK14: Febrero-23 | BL14: Marzo-23 | BM14: Abril-23 | BN14: Mayo-23 | BO14: Junio-23 | BP14: Julio-23 | BQ14: Agosto-23 | BR14: Septiembre-23 | BS14: Octubre-23 | BT14: Noviembre-23 | BU14: Diciembre-23 | BV14: Enero-24 | BW14: Febrero-24 | BX14: Marzo-24 | BY14: Abril-24 | BZ14: Mayo-24 | CA14: Junio-24 | CB14: Julio-24 | CC14: Agosto-24 | CD14: Septiembre-24 | CE14: Octubre-24 | CF14: Noviembre-24 | CG14: Diciembre-24 | CH14: Enero-25 | CI14: Febrero-25 | CJ14: Marzo-25 | CK14: Abril-25 | CL14: Mayo-25 | CM14: Junio-25 | CN14: Julio-25 | CO14: Agosto-25 | CP14: Septie-25 | CQ14: Oct-25 | CR14: Nov-25 | CS14: Dic-25 | CT14: Ene-26 | CU14: Feb-26 | CV14: Mar-26 | CX14: Resina Virgen
