Workbook
Name \P: #REF!
Name _________CTM1: #REF!
Name _________CTM2: #REF!
Name _________CTM3: #REF!
Name _________CTM4: #REF!
Name ________CTM1: #REF!
Name ________CTM2: #REF!
Name ________CTM3: #REF!
Name ________CTM4: #REF!
Name _______CTM1: #REF!
Name _______CTM2: #REF!
Name _______CTM3: #REF!
Name _______CTM4: #REF!
Name ______CTM1: #REF!
Name ______CTM2: #REF!
Name ______CTM3: #REF!
Name ______CTM4: #REF!
Name _____CTM1: #REF!
Name _____CTM2: #REF!
Name _____CTM3: #REF!
Name _____CTM4: #REF!
Name _____pag2: #REF!
Name _____pag3: #REF!
Name ____CTM1: #REF!
Name ____CTM2: #REF!
Name ____CTM3: #REF!
Name ____CTM4: #REF!
Name ____pag2: #REF!
Name ____pag3: #REF!
Name ___CTM1: #REF!
Name ___CTM2: #REF!
Name ___CTM3: #REF!
Name ___CTM4: #REF!
Name ___pag2: #REF!
Name ___pag3: #REF!
Name __CTM1: #REF!
Name __CTM2: #REF!
Name __CTM3: #REF!
Name __CTM4: #REF!
Name __pag2: #REF!
Name __pag3: #REF!
Name _38LINE: #REF!
Name _4LINEADJ: #REF!
Name _94BPRICE: #REF!
Name _CTM1: #REF!
Name _CTM2: #REF!
Name _CTM3: #REF!
Name _CTM4: #REF!
Name _MAG1: '[1]Mag 1'!$E$2:$E$208
Name _MAG1: #REF!
Name _MAG2: '[1]Mag 2'!$E$82:$E$208
Name _MAG2: #REF!
Name _MAG3: '[1]Mag 3'!$E$4:$E$208
Name _MAG3: #REF!
Name _MAG4: '[1]Mag 4'!$E$4:$E$208
Name _MAG4: #REF!
Name _MOR2: #REF!
Name _MOR6: #REF!
Name _MOR8: #REF!
Name _pag2: #REF!

Sheet ICIS Price Forecast
B2: ICIS Dashboard Price Forecast
B4: Generated | C4: 17 Apr 2026 22:17:20
B5: Date Range 1 | C5: From 17 Apr 2025 To 01 Oct 2027
B6: Original Currency | C6: USD | D6: USD
B7: Original Unit | C7: tonne | D7: tonne
B8: Selected Currency | C8: USD
B9: Selected Unit | C9: tonne
B10: Price Forecast Range | C10: 18 Months
B11: Price History Range | C11: 1 Year
B13: Date Range 1 | C13: PET Bottle Grade FOB China Spot Forecast Apr-2026 Latest | D13: PET Bottle Grade FOB China Spot 4-12 Weeks Full Market Range
B14: 18-Apr-2025 | D14: 730.00
B15: 25-Apr-2025 | D15: 735.00
B16: 02-May-2025 | D16: 752.50
B17: 09-May-2025 | D17: 755.00
B18: 16-May-2025 | D18: 792.50
B19: 23-May-2025 | D19: 790.00
B20: 30-May-2025 | D20: 785.00
B21: 06-Jun-2025 | D21: 780.00
B22: 13-Jun-2025 | D22: 782.50
B23: 20-Jun-2025 | D23: 812.50
B24: 27-Jun-2025 | D24: 797.50
B25: 04-Jul-2025 | D25: 785.00
... B50: 26-Dec-2025 | D50: 770.00
B51: 09-Jan-2026 | D51: 800
B52: 16-Jan-2026 | D52: 802.5
B53: 23-Jan-2026 | D53: 825
B54: 30-Jan-2026 | D54: 845
B55: 06-Feb-2026 | D55: 830
B56: 13-Feb-2026 | D56: 837.5
B57: 27-Feb-2026 | D57: 847.5
B58: 06-Mar-2026 | D58: 920
B59: 13-Mar-2026 | D59: 1135
B60: 20-Mar-2026 | D60: 1215
B61: 27-Mar-2026 | D61: 1175
B62: 01-Apr-2026 | C62: 1147.00 | D62: =C62 -> 1147.00
B63: 03-Apr-2026 | D63: 1190
B64: 10-Apr-2026 | D64: 1182.5
B65: 17-Apr-2026 | D65: 1190
B66: 01-May-2026 | C66: 1173
B67: 01-Jun-2026 | C67: 1054
...

Sheet Resina
B3: precios actuales ep a Octubre
B4: Costo de Resina Virgen Actual | E4: =+D30 -> 1055 | F4: 0.05 | H4: Costo de Resina Virgen Actual | J4: =+D30 -> 1055
B5: Costo de Resina PCR Actual (Enkador) | E5: =+E4-F5 -> 1002.25 | F5: =+E4*F4 -> 52.75 | H5: Costo de Resina PCR Actual | J5: 0
C6: =+(C10+C11)/C8*1000 -> 1052.2306 | D6: =+(D10+D11)/D8*1000 -> 1052.2306 | E6: =+(E10+E11)/E8*1000 -> 1065.55 | I6: =+(I10+I11)/I8*1000 -> 1060.275 | J6: =+(J10+J11)/J8*1000 -> 1060.275 | L6: Nueva metodología / nuevas condiciones
B7: Preformas | H7: Manantial | I7: 500ml SG | J7: 500ml CG | N7: IHS Julio para precio septiembre | O7: IHS Agosto para precio Octubre | P7: IHS Septiembre para precio Noviembre | Q7: IHS Octubre para precio Diciembre
B8: Gramaje | C8: 15.6 | D8: 16.7 | E8: 30.6 | H8: Gramaje | I8: 15 | J8: 20.5 | L8: IHS Asia Non Coke approved | N8: 938.13 | O8: 959 | P8: 1006.25 | Q8: 993.75 | R8: Revisar el actualizado
B9: Finish | C9: Short | D9: Short | E9: Short | H9: Finish | I9: Short | J9: Short | L9: Finance | N9: 25.09 | O9: 25.09 | P9: 25.09 | Q9: 25
B10: Resina Virgen | C10: =+(C8*E4/1000)*1.01*75% -> 12.466935 | D10: =+(D8*$E$4/1000)*1.01*75% -> 13.346014 | E10: =+(E8*E4/1000)*1.01 -> 32.60583 | H10: Resina Virgen | I10: =+(I8*J4/1000)*1.005 -> 15.904125 | J10: =+(J8*J4/1000)*1.005 -> 21.735637 | L10: Freight China-Gye | N10: 65 | O10: 65 | P10: 65 | Q10: 65 | R10: costo x TN | S10: Análisis
B11: Resina PCR | C11: =+(C8*$E$5/1000)*1.01*25% -> 3.9478628 | D11: =+(D8*$E$5/1000)*1.01*25% -> 4.2262377 | E11: 0 | H11: Resina PCR | I11: 0 | J11: 0 | N11: =SUM(N8:N10) -> 1028.22 | O11: =SUM(O8:O10) -> 1049.09 | P11: =SUM(P8:P10) -> 1096.34 | Q11: =SUM(Q8:Q10) -> 1083.75 | R11: FOB
B12: Nueva Conversion | C12: =C39 -> 13.806909 | D12: =D39 -> 13.806909 | E12: =E39 -> 16.175542 | H12: Conversión | I12: =I39 -> 28.109813 | J12: =J39 -> 28.109813 | L12: Landed factor 4% | N12: =+N11*4% -> 41.1288 | O12: =+O11*4% -> 41.9636 | P12: =+P11*4% -> 43.8536 | Q12: =+Q11*4% -> 43.35
B13: Recargo por Penalidad y energ | C13: 0 | D13: 0 | E13: 0 | H13: Recargo por Penalidad e incr | I13: 0 | J13: 0 | L13: Total resin price | N13: =+N12+N11 -> 1069.3488 | O13: =+O12+O11 -> 1091.0536 | P13: =+P12+P11 -> 1140.1936 | Q13: =+Q12+Q11 -> 1127.1
B14: Pigmento | C14: 1.638 | D14: 1.7535 | E14: 2.97 | H14: Pigmento | I14: 1.4 | J14: 2 | L14: Resin PCR % | N14: =+N13*(1-5%) -> 1015.8814 | O14: =+O13*(1-5%) -> 1036.5009 | P14: =+P13*(1-5%) -> 1083.1839 | Q14: =+Q13*(1-5%) -> 1070.745 | R14: Validar si nos está costando el 5% por debajo
B15: Empaque | C15: 0.20356 | D15: 0.20356 | E15: 0.284984 | H15: Empaque | I15: 1.27 | J15: 1.27225 | L15: Precio ponderado bajo formuala | N15: =+N13*75%+N14*25% -> 1055.9819 | O15: =+O13*75%+O14*25% -> 1077.4154 | P15: =+P13*75%+P14*25% -> 1125.9412 | Q15: =+Q13*75%+Q14*25% -> 1113.0113
B16: Flete | C16: 0.15 | D16: 0.15 | E16: 0.213738 | H16: Flete | I16: 8.34 | J16: 8.335782 | L16: Scrap 1% | N16: =+N15*1% -> 10.559819 | O16: =+O15*1% -> 10.774154 | P16: =+P15*1% -> 11.259412 | Q16: =+Q15*1% -> 11.130113
B17: Total | C17: =SUM(C10:C16) -> 32.213266 | D17: =SUM(D10:D16) -> 33.48622 | E17: =SUM(E10:E16) -> 52.250094 | H17: Total | I17: =SUM(I10:I16) -> 55.023938 | J17: =SUM(J10:J16) -> 61.453483 | L17: Precio pnderado con scrap | N17: =+N16+N15 -> 1066.5418 | O17: =+O16+O15 -> 1088.1896 | P17: =+P16+P15 -> 1137.2006 | Q17: =+Q16+Q15 -> 1124.1414
L18: Precio facturado Sep-Oct-Nov | N18: =+D6 -> 1052.2306 | O18: =+N18 -> 1052.2306 | P18: =+O18 -> 1052.2306 | Q18: =+P18 -> 1052.2306
B20: Toneladas | C20: Precio | D20: Total | N20: =+N17-N18 -> 14.311134 | O20: =+O17-O18 -> 35.958959 | P20: =+P17-P18 -> 84.969967 | Q20: =+Q17-Q18 -> 71.910738
B21: 92 | C21: =D21/B21 -> 995 | D21: 91540
B22: 69 | C22: =D22/B22 -> 995 | D22: 68655
B23: 110 | C23: =D23/B23 -> 995 | D23: 109450
B24: 44 | C24: =D24/B24 -> 995 | D24: 43780
B25: =SUM(B21:B24) -> 315 | C25: =SUM(C21:C24) -> 3980 | D25: =SUM(D21:D24) -> 313425
B28: Promedio Ponderado | D28: =+D25/B25 -> 995
B29: Gastos + Transporte + Almacenaje | D29: 60 | E29: Fijo | F29: =+D29/D30 -> 0.056872038
B30: Total | D30: =+D29+D28 -> 1055
B33: Preformas | H33: Manantial | I33: 500ml SG | J33: 500ml CG | R33: Manantial | S33: 500ml SG | T33: 500ml CG
B34: Gramaje | C34: 15.6 | D34: 16.7 | E34: 30.6 | H34: Gramaje | I34: 15 | J34: 20.5 | R34: Gramaje | S34: 15 | T34: 20.5
B35: Conversion Base | C35: 13.64 | D35: 13.64 | E35: 15.98 | H35: Conversión | I35: 27.77 | J35: 27.77 | R35: Conversión | S35: 27.77 | T35: 27.77
B36: % de Energia en MOR | C36: 0.23 | D36: 0.23 | E36: 0.23 | I36: 0.23 | J36: 0.23 | S36: 0.23 | T36: 0.23
B37: % Incremento Energia | C37: =0.097/0.0921-1 -> 0.05320304 | D37: =0.097/0.0921-1 -> 0.05320304 | E37: =0.097/0.0921-1 -> 0.05320304 | I37: =0.097/0.0921-1 -> 0.05320304 | J37: =0.097/0.0921-1 -> 0.05320304 | S37: =0.097/0.0921-1 -> 0.05320304 | T37: =0.097/0.0921-1 -> 0.05320304
B38: Incremento de energia | C38: =C35*C36*C37 -> 0.16690858 | D38: =D35*D36*D37 -> 0.16690858 | E38: =E35*E36*E37 -> 0.19554245 | I38: =I35*I36*I37 -> 0.33981314 | J38: =J35*J36*J37 -> 0.33981314 | S38: =S35*S36*S37 -> 0.33981314 | T38: =T35*T36*T37 -> 0.33981314
B39: Nueva Conversion | C39: =C35+C38 -> 13.806909 | D39: =D35+D38 -> 13.806909 | E39: =E35+E38 -> 16.175542 | I39: =I35+I38 -> 28.109813 | J39: =J35+J38 -> 28.109813 | S39: =S35+S38 -> 28.109813 | T39: =T35+T38 -> 28.109813
B52: Fórmula | J52: Factor mundial del precio de la resina

Sheet Sep17
B3: Costo de Resina Virgen Actual | E3: 1069.3488 | I3: Costo de Resina Virgen Actual | K3: 1069.3488
B4: Costo de Resina PCR Actual (Enkador) | E4: 1015.8814 | I4: Costo de Resina PCR Actual | K4: 0
C5: =+(C9+C10)/C7*1000 -> 1066.5418 | D5: =+(D9+D10)/D7*1000 -> 1066.5418 | F5: =+(F9+F10)/F7*1000 -> 1080.0423 | J5: =+(J9+J10)/J7*1000 -> 1074.6955 | K5: =+(K9+K10)/K7*1000 -> 1074.6955 | M5: Nueva metodología / nuevas condiciones
B6: Preformas | I6: Manantial | J6: 500ml SG | K6: 500ml CG | O6: IHS Julio para precio Septiembre | P6: IHS Agosto para precio Octubre | Q6: IHS Septiembre para precio Noviembre | R6: IHS Octubre para precio Diciembre
B7: Gramaje | C7: 15.6 | D7: 16.7 | E7: 20.5 | F7: 30.6 | G7: 30.6 | I7: Gramaje | J7: 15 | K7: 20.5 | M7: IHS Asia Non Coke approved | O7: 938.13 | P7: 959 | Q7: 1006.25 | R7: 993.75 | S7: Revisar el actualizado
B8: Finish | C8: Short | D8: Short | E8: Short | F8: Short | G8: Short | I8: Finish | J8: Short | K8: Short | M8: Finance | O8: 25.09 | P8: 25.09 | Q8: 25.09 | R8: 25
B9: Resina Virgen | C9: =+(C7*E3/1000)*1.01*75% -> 12.636495 | D9: =+(D7*$E$3/1000)*1.01*75% -> 13.52753 | E9: =+(E7*$E$3/1000)*1.01*75% -> 16.60565 | F9: =+(F7*E3/1000)*1.01 -> 33.049294 | G9: =+(G7*$E$3/1000)*1.01*75% -> 24.786971 | I9: Resina Virgen | J9: =+(J7*K3/1000)*1.005 -> 16.120433 | K9: =+(K7*K3/1000)*1.005 -> 22.031259 | M9: Freight China-Gye | O9: 65 | P9: 65 | Q9: 65 | R9: 65 | S9: costo x TN | T9: Análisis
B10: Resina PCR | C10: =+(C7*$E$4/1000)*1.01*25% -> 4.0015567 | D10: =+(D7*$E$4/1000)*1.01*25% -> 4.2837177 | E10: =+(E7*$E$4/1000)*1.01*25% -> 5.2584559 | F10: 0 | G10: =+(G7*$E$4/1000)*1.01*25% -> 7.8492073 | I10: Resina PCR | J10: 0 | K10: 0 | O10: =SUM(O7:O9) -> 1028.22 | P10: =SUM(P7:P9) -> 1049.09 | Q10: =SUM(Q7:Q9) -> 1096.34 | R10: =SUM(R7:R9) -> 1083.75 | S10: FOB
B11: Nueva Conversion | C11: 8.2 | D11: 8.2 | E11: 8.2 | F11: 11.15 | G11: 11.15 | I11: Conversión | J11: 27.2 | K11: 27.2 | M11: Landed factor 4% | O11: =+O10*4% -> 41.1288 | P11: =+P10*4% -> 41.9636 | Q11: =+Q10*4% -> 43.8536 | R11: =+R10*4% -> 43.35
B12: Recargo por Penalidad y energ | C12: 0 | D12: 0 | E12: 0 | F12: 0 | G12: 0 | I12: Recargo por Penalidad e incr | J12: 0 | K12: 0 | M12: Total resin price | O12: =+O11+O10 -> 1069.3488 | P12: =+P11+P10 -> 1091.0536 | Q12: =+Q11+Q10 -> 1140.1936 | R12: =+R11+R10 -> 1127.1
B13: Pigmento | C13: 1.3 | D13: 1.3 | E13: 1.3 | F13: 2.38 | G13: 2.38 | I13: Pigmento | J13: 0.81 | K13: 1.99 | M13: Resin PCR % | O13: =+O12*(1-5%) -> 1015.8814 | P13: =+P12*(1-5%) -> 1036.5009 | Q13: =+Q12*(1-5%) -> 1083.1839 | R13: =+R12*(1-5%) -> 1070.745 | S13: Validar si nos está costando el 5% por debajo
B14: Empaque | C14: 0.19 | D14: 0.19 | E14: 0.19 | F14: 0.33 | G14: 0.33 | I14: Empaque | J14: 2.71 | K14: 2.71 | M14: Precio ponderado bajo formuala | O14: =+O12*75%+O13*25% -> 1055.9819 | P14: =+P12*75%+P13*25% -> 1077.4154 | Q14: =+Q12*75%+Q13*25% -> 1125.9412 | R14: =+R12*75%+R13*25% -> 1113.0113
B15: Flete | C15: 0.16 | D15: 0.16 | E15: 0.16 | F15: 0.28 | G15: 0.28 | I15: Flete | J15: 7.77 | K15: 7.77 | M15: Scrap 1% | O15: =+O14*1% -> 10.559819 | P15: =+P14*1% -> 10.774154 | Q15: =+Q14*1% -> 11.259412 | R15: =+R14*1% -> 11.130113
B16: Total | C16: =SUM(C9:C15) -> 26.488051 | D16: =SUM(D9:D15) -> 27.661247 | E16: =SUM(E9:E15) -> 31.714106 | F16: =SUM(F9:F15) -> 47.189294 | G16: =SUM(G9:G15) -> 46.776178 | I16: Total | J16: =SUM(J9:J15) -> 54.610433 | K16: =SUM(K9:K15) -> 61.701259 | M16: Precio pnderado con scrap | O16: =+O15+O14 -> 1066.5418 | P16: =+P15+P14 -> 1088.1896 | Q16: =+Q15+Q14 -> 1137.2006 | R16: =+R15+R14 -> 1124.1414
M17: Precio facturado Sep-Oct-Nov | O17: =+D5 -> 1066.5418 | P17: =+O17 -> 1066.5418 | Q17: =+P17 -> 1066.5418 | R17: =+Q17 -> 1066.5418
B32: Fórmula | K32: Factor mundial del precio de la resina

Sheet Oct17
B3: Costo de Resina Virgen Actual | E3: 1091.0536 | I3: Costo de Resina Virgen Actual | K3: 1091.0536
B4: Costo de Resina PCR Actual (Enkador) | E4: 1036.5009 | I4: Costo de Resina PCR Actual | K4: 0
C5: =+(C9+C10)/C7*1000 -> 1088.446 | D5: =+(D9+D10)/D7*1000 -> 1088.1896 | F5: =+(F9+F10)/F7*1000 -> 1101.9641 | J5: =+(J9+J10)/J7*1000 -> 1096.3755 | K5: =+(K9+K10)/K7*1000 -> 1096.5089 | M5: Nueva metodología / nuevas condiciones
B6: Preformas | I6: Manantial | J6: 500ml SG | K6: 500ml CG | O6: IHS Julio para precio septiembre | P6: IHS Agosto para precio Octubre | Q6: IHS Septiembre para precio Noviembre | R6: IHS Octubre para precio Diciembre
B7: Gramaje | C7: 15.6 | D7: 16.7 | E7: 20.5 | F7: 30.6 | G7: 30.6 | I7: Gramaje | J7: 15 | K7: 20.5 | M7: IHS Asia Non Coke approved | O7: 938.13 | P7: 959 | Q7: 1006.25 | R7: 993.75 | S7: Revisar el actualizado
B8: Finish | C8: Short | D8: Short | E8: Short | F8: Short | G8: Short | I8: Finish | J8: Short | K8: Short | M8: Finance | O8: 25.09 | P8: 25.09 | Q8: 25.09 | R8: 25
B9: Resina Virgen | C9: =+(C7*E3/1000)*1.01*75% -> 12.89298 | D9: =+(D7*$E$3/1000)*1.01*75% -> 13.802101 | E9: =+(E7*$E$3/1000)*1.01*75% -> 16.942699 | F9: =+(F7*E3/1000)*1.01 -> 33.720103 | G9: =+(G7*$E$3/1000)*1.01*75% -> 25.290077 | I9: Resina Virgen | J9: =+(J7*K3/1000)*1.005-0.002 -> 16.445633 | K9: =+(K7*K3/1000)*1.005 -> 22.478432 | M9: Freight China-Gye | O9: 65 | P9: 65 | Q9: 65 | R9: 65 | S9: costo x TN | T9: Análisis
B10: Resina PCR | C10: =+(C7*$E$4/1000)*1.01*25%+0.004 -> 4.0867771 | D10: =+(D7*$E$4/1000)*1.01*25% -> 4.3706653 | E10: =+(E7*$E$4/1000)*1.01*25% -> 5.3651879 | F10: 0 | G10: =+(G7*$E$4/1000)*1.01*25% -> 8.0085244 | I10: Resina PCR | J10: 0 | K10: 0 | O10: =SUM(O7:O9) -> 1028.22 | P10: =SUM(P7:P9) -> 1049.09 | Q10: =SUM(Q7:Q9) -> 1096.34 | R10: =SUM(R7:R9) -> 1083.75 | S10: FOB
B11: Nueva Conversion | C11: 8.2 | D11: 8.2 | E11: 8.2 | F11: 11.15 | G11: 11.15 | I11: Conversión | J11: 27.2 | K11: 27.2 | M11: Landed factor 4% | O11: =+O10*4% -> 41.1288 | P11: =+P10*4% -> 41.9636 | Q11: =+Q10*4% -> 43.8536 | R11: =+R10*4% -> 43.35
B12: Recargo por Penalidad y energ | C12: 0 | D12: 0 | E12: 0 | F12: 0 | G12: 0 | I12: Recargo por Penalidad e incr | J12: 0 | K12: 0 | M12: Total resin price | O12: =+O11+O10 -> 1069.3488 | P12: =+P11+P10 -> 1091.0536 | Q12: =+Q11+Q10 -> 1140.1936 | R12: =+R11+R10 -> 1127.1
B13: Pigmento | C13: 1.3 | D13: 1.3 | E13: 1.3 | F13: 2.38 | G13: 2.38 | I13: Pigmento | J13: 0.81 | K13: 1.99 | M13: Resin PCR % | O13: =+O12*(1-5%) -> 1015.8814 | P13: =+P12*(1-5%) -> 1036.5009 | Q13: =+Q12*(1-5%) -> 1083.1839 | R13: =+R12*(1-5%) -> 1070.745 | S13: Validar si nos está costando el 5% por debajo
B14: Empaque | C14: 0.19 | D14: 0.19 | E14: 0.19 | F14: 0.33 | G14: 0.33 | I14: Empaque | J14: 2.71 | K14: 2.71 | M14: Precio ponderado bajo formuala | O14: =+O12*75%+O13*25% -> 1055.9819 | P14: =+P12*75%+P13*25% -> 1077.4154 | Q14: =+Q12*75%+Q13*25% -> 1125.9412 | R14: =+R12*75%+R13*25% -> 1113.0113
B15: Flete | C15: 0.16 | D15: 0.16 | E15: 0.16 | F15: 0.28 | G15: 0.28 | I15: Flete | J15: 7.77 | K15: 7.77 | M15: Scrap 1% | O15: =+O14*1% -> 10.559819 | P15: =+P14*1% -> 10.774154 | Q15: =+Q14*1% -> 11.259412 | R15: =+R14*1% -> 11.130113
B16: Total | C16: =SUM(C9:C15) -> 26.829758 | D16: =SUM(D9:D15) -> 28.022766 | E16: =SUM(E9:E15) -> 32.157886 | F16: =SUM(F9:F15) -> 47.860103 | G16: =SUM(G9:G15) -> 47.438601 | I16: Total | J16: =SUM(J9:J15) -> 54.935633 | K16: =SUM(K9:K15) -> 62.148432 | M16: Precio pnderado con scrap | O16: =+O15+O14 -> 1066.5418 | P16: =+P15+P14 -> 1088.1896 | Q16: =+Q15+Q14 -> 1137.2006 | R16: =+R15+R14 -> 1124.1414
M17: Precio facturado Sep-Oct-Nov | O17: =+D5 -> 1088.1896 | P17: =+O17 -> 1088.1896 | Q17: =+P17 -> 1088.1896 | R17: =+Q17 -> 1088.1896
B30: Fórmula | K30: Factor mundial del precio de la resina

Sheet Nov17
B3: Costo de Resina Virgen Actual | E3: 1140.1936 | J3: Costo de Resina Virgen Actual | L3: 1140.1936
B4: Costo de Resina PCR Actual (Enkador) | E4: 1083.1839 | J4: Costo de Resina PCR Actual | L4: 0
C5: =+(C9+C10)/C7*1000 -> 1137.2006 | D5: =+(D9+D10)/D7*1000 -> 1137.2006 | F5: =+(F9+F10)/F7*1000 -> 1151.5955 | K5: =+(K9+K10)/K7*1000 -> 1145.6946 | L5: =+(L9+L10)/L7*1000 -> 1145.8946 | N5: Nueva metodología / nuevas condiciones
B6: Preformas | J6: Manantial | K6: 500ml SG | L6: 500ml CG | P6: IHS Julio para precio Septiembre | Q6: IHS Agosto para precio Octubre | R6: IHS Septiembre para precio Noviembre | S6: IHS Octubre para precio Diciembre
B7: Gramaje | C7: 15.6 | D7: 16.7 | E7: 20.5 | F7: 30.6 | G7: 30.6 | H7: 38.6 | J7: Gramaje | K7: 15 | L7: 20.5 | N7: IHS Asia Non Coke approved | P7: 938.13 | Q7: 959 | R7: 1006.25 | S7: 993.75 | T7: Revisar el actualizado
B8: Finish | C8: Short | D8: Short | E8: Short | F8: Short | G8: Short | H8: Short | J8: Finish | K8: Short | L8: Short | N8: Finance | P8: 25.09 | Q8: 25.09 | R8: 25.09 | S8: 25
B9: Resina Virgen | C9: =+(C7*E3/1000)*1.01*75% -> 13.473668 | D9: =+(D7*$E$3/1000)*1.01*75% -> 14.423734 | E9: =+(E7*$E$3/1000)*1.01*75% -> 17.705781 | F9: =+(F7*E3/1000)*1.01 -> 35.238823 | G9: =+(G7*$E$3/1000)*1.01*75% -> 26.429118 | H9: =+(H7*$E$3/1000)*1.01*75% -> 33.338691 | J9: Resina Virgen | K9: =+(K7*L3/1000)*1.005-0.003 -> 17.185419 | L9: =+(L7*L3/1000)*1.005 -> 23.490839 | N9: Freight China-Gye | P9: 65 | Q9: 65 | R9: 65 | S9: 65 | T9: costo x TN | U9: Análisis
B10: Resina PCR | C10: =+(C7*$E$4/1000)*1.01*25% -> 4.2666615 | D10: =+(D7*$E$4/1000)*1.01*25% -> 4.5675158 | E10: =+(E7*$E$4/1000)*1.01*25% -> 5.6068308 | F10: 0 | G10: =+(G7*$E$4/1000)*1.01*25% -> 8.3692206 | H10: =+(H7*$E$4/1000)*1.01*25% -> 10.557252 | J10: Resina PCR | K10: 0 | L10: 0 | P10: =SUM(P7:P9) -> 1028.22 | Q10: =SUM(Q7:Q9) -> 1049.09 | R10: =SUM(R7:R9) -> 1096.34 | S10: =SUM(S7:S9) -> 1083.75 | T10: FOB
B11: Nueva Conversion | C11: 8.2 | D11: 8.2 | E11: 8.2 | F11: 11.15 | G11: 11.15 | H11: 11.15 | J11: Conversión | K11: 27.2 | L11: 27.2 | N11: Landed factor 4% | P11: =+P10*4% -> 41.1288 | Q11: =+Q10*4% -> 41.9636 | R11: =+R10*4% -> 43.8536 | S11: =+S10*4% -> 43.35
B12: Recargo por Penalidad y energ | C12: 0 | D12: 0 | E12: 0 | F12: 0 | G12: 0 | H12: 0 | J12: Recargo por Penalidad e incr | K12: 0 | L12: 0 | N12: Total resin price | P12: =+P11+P10 -> 1069.3488 | Q12: =+Q11+Q10 -> 1091.0536 | R12: =+R11+R10 -> 1140.1936 | S12: =+S11+S10 -> 1127.1
B13: Pigmento | C13: 1.3 | D13: 1.3 | E13: 1.3 | F13: 2.38 | G13: 2.38 | H13: 2.38 | J13: Pigmento | K13: 0.81 | L13: 1.99 | N13: Resin PCR % | P13: =+P12*(1-5%) -> 1015.8814 | Q13: =+Q12*(1-5%) -> 1036.5009 | R13: =+R12*(1-5%) -> 1083.1839 | S13: =+S12*(1-5%) -> 1070.745 | T13: Validar si nos está costando el 5% por debajo
B14: Empaque | C14: 0.19 | D14: 0.19 | E14: 0.19 | F14: 0.33 | G14: 0.33 | H14: 0.33 | J14: Empaque | K14: 2.71 | L14: 2.71 | N14: Precio ponderado bajo formuala | P14: =+P12*75%+P13*25% -> 1055.9819 | Q14: =+Q12*75%+Q13*25% -> 1077.4154 | R14: =+R12*75%+R13*25% -> 1125.9412 | S14: =+S12*75%+S13*25% -> 1113.0113
B15: Flete | C15: 0.16 | D15: 0.16 | E15: 0.16 | F15: 0.28 | G15: 0.28 | H15: 0.28 | J15: Flete | K15: 7.77 | L15: 7.77 | N15: Scrap 1% | P15: =+P14*1% -> 10.559819 | Q15: =+Q14*1% -> 10.774154 | R15: =+R14*1% -> 11.259412 | S15: =+S14*1% -> 11.130113
B16: Total | C16: =SUM(C9:C15) -> 27.590329 | D16: =SUM(D9:D15) -> 28.84125 | E16: =SUM(E9:E15) -> 33.162612 | F16: =SUM(F9:F15) -> 49.378823 | G16: =SUM(G9:G15) -> 48.938338 | H16: =SUM(H9:H15) -> 58.035943 | J16: Total | K16: =SUM(K9:K15) -> 55.675419 | L16: =SUM(L9:L15) -> 63.160839 | N16: Precio pnderado con scrap | P16: =+P15+P14 -> 1066.5418 | Q16: =+Q15+Q14 -> 1088.1896 | R16: =+R15+R14 -> 1137.2006 | S16: =+S15+S14 -> 1124.1414
N17: Precio facturado Sep-Oct-Nov | P17: =+D5 -> 1137.2006 | Q17: =+P17 -> 1137.2006 | R17: =+Q17 -> 1137.2006 | S17: =+R17 -> 1137.2006
B30: Fórmula | L30: Factor mundial del precio de la resina

Sheet Dic17
B3: Costo de Resina Virgen Actual | E3: =+S12 -> 1127.1 | J3: Costo de Resina Virgen Actual | L3: =+E3 -> 1127.1
B4: Costo de Resina PCR Actual (Enkador) | E4: =+S13 -> 1070.745 | J4: Costo de Resina PCR Actual | L4: 0
C5: =+(C9+C10)/C7*1000 -> 1124.1414 | D5: =+(D9+D10)/D7*1000 -> 1124.1414 | F5: =+(F9+F10)/F7*1000 -> 1138.371 | K5: =+(K9+K10)/K7*1000 -> 1132.7355 | L5: =+(L9+L10)/L7*1000 -> 1132.7355 | N5: Nueva metodología / nuevas condiciones
B6: Preformas | J6: Manantial | K6: 500ml SG | L6: 500ml CG | P6: IHS julio para precio septiembre | Q6: IHS agosto para precio octubre | R6: IHS septiembre para precio noviembre | S6: IHS Octubre para precio Diciembre | T6: IHS Noviembre para precio Enero | U6: IHS Diciembre para precio Febrero | V6: IHS Enero para precio Marzo
B7: Gramaje | C7: 15.6 | D7: 16.7 | E7: 20.5 | F7: 30.6 | G7: 30.6 | H7: 38.6 | J7: Gramaje | K7: 15 | L7: 20.5 | N7: IHS Asia Non Coke approved | P7: 938.13 | Q7: 959 | R7: 1006.25 | S7: 993.75 | T7: 1015.5 | U7: 1045.6 | V7: 1050 | W7: Revisar el actualizado
B8: Finish | C8: Short | D8: Short | E8: Short | F8: Short | G8: Short | H8: Short | J8: Finish | K8: Short | L8: Short | N8: Finance | P8: 25.09 | Q8: 25.09 | R8: 25.09 | S8: 25 | T8: 25 | U8: 25 | V8: 25
B9: Resina Virgen | C9: =+(C7*E3/1000)*1.01*75% -> 13.318941 | D9: =+(D7*$E$3/1000)*1.01*75% -> 14.258097 | E9: =+(E7*$E$3/1000)*1.01*75% -> 17.502454 | F9: =+(F7*E3/1000)*1.01 -> 34.834153 | G9: =+(G7*$E$3/1000)*1.01*75% -> 26.125614 | H9: =+(H7*$E$3/1000)*1.01*75% -> 32.95584 | J9: Resina Virgen | K9: =+(K7*L3/1000)*1.005 -> 16.991032 | L9: =+(L7*L3/1000)*1.005 -> 23.221078 | N9: Freight China-Gye | P9: 65 | Q9: 65 | R9: 65 | S9: 65 | T9: 65 | U9: 65 | V9: 65 | W9: costo x TN | X9: Análisis
B10: Resina PCR | C10: =+(C7*$E$4/1000)*1.01*25% -> 4.2176646 | D10: =+(D7*$E$4/1000)*1.01*25% -> 4.515064 | E10: =+(E7*$E$4/1000)*1.01*25% -> 5.5424438 | F10: 0 | G10: =+(G7*$E$4/1000)*1.01*25% -> 8.2731112 | H10: =+(H7*$E$4/1000)*1.01*25% -> 10.436016 | J10: Resina PCR | K10: 0 | L10: 0 | P10: =SUM(P7:P9) -> 1028.22 | Q10: =SUM(Q7:Q9) -> 1049.09 | R10: =SUM(R7:R9) -> 1096.34 | S10: =SUM(S7:S9) -> 1083.75 | T10: =SUM(T7:T9) -> 1105.5 | U10: =SUM(U7:U9) -> 1135.6 | V10: =SUM(V7:V9) -> 1140 | W10: FOB
B11: Nueva Conversion | C11: 8.2 | D11: 8.2 | E11: 8.2 | F11: 11.15 | G11: 11.15 | H11: 11.15 | J11: Conversión | K11: 27.2 | L11: 27.2 | N11: Landed factor 4% | P11: =+P10*4% -> 41.1288 | Q11: =+Q10*4% -> 41.9636 | R11: =+R10*4% -> 43.8536 | S11: =+S10*4% -> 43.35 | T11: =+T10*4% -> 44.22 | U11: =+U10*4% -> 45.424 | V11: =+V10*4% -> 45.6
B12: Recargo por Penalidad y energ | C12: 0 | D12: 0 | E12: 0 | F12: 0 | G12: 0 | H12: 0 | J12: Recargo por Penalidad e incr | K12: 0 | L12: 0 | N12: Total resin price | P12: =+P11+P10 -> 1069.3488 | Q12: =+Q11+Q10 -> 1091.0536 | R12: =+R11+R10 -> 1140.1936 | S12: =+S11+S10 -> 1127.1 | T12: =+T11+T10 -> 1149.72 | U12: =+U11+U10 -> 1181.024 | V12: =+V11+V10 -> 1185.6
B13: Pigmento | C13: 1.3 | D13: 1.3 | E13: 1.3 | F13: 2.38 | G13: 2.38 | H13: 2.38 | J13: Pigmento | K13: 0.81 | L13: 1.99 | N13: Resin PCR % | P13: =+P12*(1-5%) -> 1015.8814 | Q13: =+Q12*(1-5%) -> 1036.5009 | R13: =+R12*(1-5%) -> 1083.1839 | S13: =+S12*(1-5%) -> 1070.745 | T13: =+T12*(1-5%) -> 1092.234 | U13: =+U12*(1-5%) -> 1121.9728 | V13: =+V12*(1-5%) -> 1126.32 | W13: Validar si nos está costando el 5% por debajo
B14: Empaque | C14: 0.19 | D14: 0.19 | E14: 0.19 | F14: 0.33 | G14: 0.33 | H14: 0.33 | J14: Empaque | K14: 2.71 | L14: 2.71 | N14: Precio ponderado bajo formuala | P14: =+P12*75%+P13*25% -> 1055.9819 | Q14: =+Q12*75%+Q13*25% -> 1077.4154 | R14: =+R12*75%+R13*25% -> 1125.9412 | S14: =+S12*75%+S13*25% -> 1113.0113 | T14: =+T12*75%+T13*25% -> 1135.3485 | U14: =+U12*75%+U13*25% -> 1166.2612 | V14: =+V12*75%+V13*25% -> 1170.78
B15: Flete | C15: 0.16 | D15: 0.16 | E15: 0.16 | F15: 0.28 | G15: 0.28 | H15: 0.28 | J15: Flete | K15: 7.77 | L15: 7.77 | N15: Scrap 1% | P15: =+P14*1% -> 10.559819 | Q15: =+Q14*1% -> 10.774154 | R15: =+R14*1% -> 11.259412 | S15: =+S14*1% -> 11.130113 | T15: =+T14*1% -> 11.353485 | U15: =+U14*1% -> 11.662612 | V15: =+V14*1% -> 11.7078
B16: Total | C16: =SUM(C9:C15) -> 27.386605 | D16: =SUM(D9:D15) -> 28.623161 | E16: =SUM(E9:E15) -> 32.894898 | F16: =SUM(F9:F15) -> 48.974153 | G16: =SUM(G9:G15) -> 48.538726 | H16: =SUM(H9:H15) -> 57.531857 | J16: Total | K16: =SUM(K9:K15) -> 55.481032 | L16: =SUM(L9:L15) -> 62.891078 | N16: Precio pnderado con scrap | P16: =+P15+P14 -> 1066.5418 | Q16: =+Q15+Q14 -> 1088.1896 | R16: =+R15+R14 -> 1137.2006 | S16: =+S15+S14 -> 1124.1414 | T16: =+T15+T14 -> 1146.702 | U16: =+U15+U14 -> 1177.9238 | V16: =+V15+V14 -> 1182.4878
N17: Precio facturado Sep-Oct-Nov | P17: =+D5 -> 1124.1414 | Q17: =+P17 -> 1124.1414 | R17: =+Q17 -> 1124.1414 | S17: =+R17 -> 1124.1414 | T17: =+S17 -> 1124.1414 | U17: =+T17 -> 1124.1414 | V17: =+U17 -> 1124.1414
B32: Fórmula | L32: Factor mundial del precio de la resina

Sheet Ene18
B3: Costo de Resina Virgen Actual | E3: =+U12 -> 1149.72 | I3: 0.05 | K3: Costo de Resina Virgen Actual | M3: =+E3 -> 1149.72
B4: Costo de Resina PCR Actual (Enkador) | E4: =+U13 -> 1092.234 | I4: =+E3*I3 -> 57.486 | K4: Costo de Resina PCR Actual | M4: 0
C5: =+(C9+C10)/C7*1000 -> 1146.702 | D5: =+(D9+D10)/D7*1000 -> 1146.702 | F5: =+(F9+F10)/F7*1000 -> 1161.2172 | L5: =+(L9+L10)/L7*1000 -> 1155.4686 | M5: =+(M9+M10)/M7*1000 -> 1155.4686 | O5: Nueva metodología / nuevas condiciones
B6: Preformas | K6: Manantial | L6: 500ml SG | M6: 500ml CG | Q6: IHS julio para precio septiembre | R6: IHS agosto para precio octubre | S6: IHS septiembre para precio noviembre | T6: IHS Octubre para precio Diciembre | U6: IHS Noviembre para precio Enero | V6: IHS Diciembre para precio Febrero | W6: IHS Enero para precio Marzo
B7: Gramaje | C7: 15.6 | D7: 16.7 | E7: 20.5 | F7: 30.6 | G7: 30.6 | H7: 38.6 | K7: Gramaje | L7: 15 | M7: 20.5 | O7: IHS Asia Non Coke approved | Q7: 938.13 | R7: 959 | S7: 1006.25 | T7: 993.75 | U7: 1015.5 | V7: 1045.6 | W7: 1050 | X7: Revisar el actualizado
B8: Finish | C8: Short | D8: Short | E8: Short | F8: Short | G8: Short | H8: Short | K8: Finish | L8: Short | M8: Short | O8: Finance | Q8: 25.09 | R8: 25.09 | S8: 25.09 | T8: 25 | U8: 25 | V8: 25 | W8: 25
B9: Resina Virgen | C9: =+(C7*E3/1000)*1.01*75% -> 13.586241 | D9: =+(D7*$E$3/1000)*1.01*75% -> 14.544245 | E9: =+(E7*$E$3/1000)*1.01*75% -> 17.853714 | F9: =+(F7*E3/1000)*1.01 -> 35.533246 | G9: =+(G7*$E$3/1000)*1.01*75% -> 26.649935 | H9: =+(H7*$E$3/1000)*1.01*75% -> 33.617238 | K9: Resina Virgen | L9: =+(L7*M3/1000)*1.005 -> 17.332029 | M9: =+(M7*M3/1000)*1.005 -> 23.687106 | O9: Freight China-Gye | Q9: 65 | R9: 65 | S9: 65 | T9: 65 | U9: 65 | V9: 65 | W9: 65 | X9: costo x TN | Y9: Análisis
B10: Resina PCR | C10: =+(C7*$E$4/1000)*1.01*25% -> 4.3023097 | D10: =+(D7*$E$4/1000)*1.01*25% -> 4.6056777 | E10: =+(E7*$E$4/1000)*1.01*25% -> 5.6536762 | F10: 0 | G10: =+(G7*$E$4/1000)*1.01*25% -> 8.439146 | H10: =+(H7*$E$4/1000)*1.01*25% -> 10.645459 | K10: Resina PCR | L10: 0 | M10: 0 | Q10: =SUM(Q7:Q9) -> 1028.22 | R10: =SUM(R7:R9) -> 1049.09 | S10: =SUM(S7:S9) -> 1096.34 | T10: =SUM(T7:T9) -> 1083.75 | U10: =SUM(U7:U9) -> 1105.5 | V10: =SUM(V7:V9) -> 1135.6 | W10: =SUM(W7:W9) -> 1140 | X10: FOB
B11: Nueva Conversion | C11: 8.2 | D11: 8.2 | E11: 8.2 | F11: 11.15 | G11: 11.15 | H11: 11.15 | K11: Conversión | L11: 27.2 | M11: 27.2 | O11: Landed factor 4% | Q11: =+Q10*4% -> 41.1288 | R11: =+R10*4% -> 41.9636 | S11: =+S10*4% -> 43.8536 | T11: =+T10*4% -> 43.35 | U11: =+U10*4% -> 44.22 | V11: =+V10*4% -> 45.424 | W11: =+W10*4% -> 45.6
B12: Recargo por Penalidad y energ | C12: 0 | D12: 0 | E12: 0 | F12: 0 | G12: 0 | H12: 0 | K12: Recargo por Penalidad e incr | L12: 0 | M12: 0 | O12: Total resin price | Q12: =+Q11+Q10 -> 1069.3488 | R12: =+R11+R10 -> 1091.0536 | S12: =+S11+S10 -> 1140.1936 | T12: =+T11+T10 -> 1127.1 | U12: =+U11+U10 -> 1149.72 | V12: =+V11+V10 -> 1181.024 | W12: =+W11+W10 -> 1185.6
B13: Pigmento | C13: 1.3 | D13: 1.3 | E13: 1.3 | F13: 2.38 | G13: 2.38 | H13: 2.38 | K13: Pigmento | L13: 0.81 | M13: 1.99 | O13: Resin PCR % | Q13: =+Q12*(1-5%) -> 1015.8814 | R13: =+R12*(1-5%) -> 1036.5009 | S13: =+S12*(1-5%) -> 1083.1839 | T13: =+T12*(1-5%) -> 1070.745 | U13: =+U12*(1-5%) -> 1092.234 | V13: =+V12*(1-5%) -> 1121.9728 | W13: =+W12*(1-5%) -> 1126.32 | X13: Validar si nos está costando el 5% por debajo
B14: Empaque | C14: 0.19 | D14: 0.19 | E14: 0.19 | F14: 0.33 | G14: 0.33 | H14: 0.33 | K14: Empaque | L14: 2.71 | M14: 2.71 | O14: Precio ponderado bajo formuala | Q14: =+Q12*75%+Q13*25% -> 1055.9819 | R14: =+R12*75%+R13*25% -> 1077.4154 | S14: =+S12*75%+S13*25% -> 1125.9412 | T14: =+T12*75%+T13*25% -> 1113.0113 | U14: =+U12*75%+U13*25% -> 1135.3485 | V14: =+V12*75%+V13*25% -> 1166.2612 | W14: =+W12*75%+W13*25% -> 1170.78
B15: Flete | C15: 0.16 | D15: 0.16 | E15: 0.16 | F15: 0.28 | G15: 0.28 | H15: 0.28 | K15: Flete | L15: 7.77 | M15: 7.77 | O15: Scrap 1% | Q15: =+Q14*1% -> 10.559819 | R15: =+R14*1% -> 10.774154 | S15: =+S14*1% -> 11.259412 | T15: =+T14*1% -> 11.130113 | U15: =+U14*1% -> 11.353485 | V15: =+V14*1% -> 11.662612 | W15: =+W14*1% -> 11.7078
B16: Total | C16: =SUM(C9:C15) -> 27.738551 | D16: =SUM(D9:D15) -> 28.999923 | E16: =SUM(E9:E15) -> 33.357391 | F16: =SUM(F9:F15) -> 49.673246 | G16: =SUM(G9:G15) -> 49.229081 | H16: =SUM(H9:H15) -> 58.402697 | K16: Total | L16: =SUM(L9:L15) -> 55.822029 | M16: =SUM(M9:M15) -> 63.357106 | O16: Precio pnderado con scrap | Q16: =+Q15+Q14 -> 1066.5418 | R16: =+R15+R14 -> 1088.1896 | S16: =+S15+S14 -> 1137.2006 | T16: =+T15+T14 -> 1124.1414 | U16: =+U15+U14 -> 1146.702 | V16: =+V15+V14 -> 1177.9238 | W16: =+W15+W14 -> 1182.4878
O17: Precio facturado Sep-Oct-Nov | Q17: =+D5 -> 1146.702 | R17: =+Q17 -> 1146.702 | S17: =+R17 -> 1146.702 | T17: =+S17 -> 1146.702 | U17: =+T17 -> 1146.702 | V17: =+U17 -> 1146.702 | W17: =+V17 -> 1146.702
B33: Fórmula | M33: Factor mundial del precio de la resina

Sheet Feb18
B3: Costo de Resina Virgen Actual | E3: =+X12 -> 1181.024 | I3: 0.05 | K3: Costo de Resina Virgen Actual | M3: =+E3 -> 1181.024
B4: Costo de Resina PCR Actual (Enkador) | E4: =+X13 -> 1121.9728 | I4: =+E3*I3 -> 59.0512 | K4: Costo de Resina PCR Actual | M4: =+E4 -> 1121.9728
C5: =+(C9+C10)/C7*1000 -> 1177.9238 | D5: =+(D9+D10)/D7*1000 -> 1177.9238 | F5: =+(F9+F10)/F7*1000 -> 1192.8342 | L5: =+(L9+L10)/L7*1000 -> 1186.9291 | M5: =+(M9+M10)/M7*1000 -> 1186.9291 | Q5: Nueva metodología / nuevas condiciones
B6: Preformas | K6: Manantial | L6: 500ml SG | M6: 500ml CG | S6: IHS julio para precio septiembre | T6: IHS agosto para precio octubre | U6: IHS septiembre para precio noviembre | V6: IHS Octubre para precio Diciembre | W6: IHS Noviembre para precio Enero | X6: IHS Diciembre para precio Febrero | Y6: IHS Enero para precio Marzo
B7: Gramaje | C7: 15.6 | D7: 16.7 | E7: 20.5 | F7: 30.6 | G7: 30.6 | H7: 38.6 | K7: Gramaje | L7: 15 | M7: 20.5 | N7: 15 | O7: 20.5 | Q7: IHS Asia Non Coke approved | S7: 938.13 | T7: 959 | U7: 1006.25 | V7: 993.75 | W7: 1015.5 | X7: 1045.6 | Y7: 1050 | Z7: Revisar el actualizado
B8: Finish | C8: Short | D8: Short | E8: Short | F8: Short | G8: Short | H8: Short | K8: Finish | L8: Short | M8: Short | N8: Short | O8: Short | Q8: Finance | S8: 25.09 | T8: 25.09 | U8: 25.09 | V8: 25 | W8: 25 | X8: 25 | Y8: 25
B9: Resina Virgen | C9: =+(C7*E3/1000)*1.01*75% -> 13.956161 | D9: =+(D7*$E$3/1000)*1.01*75% -> 14.940249 | E9: =+(E7*$E$3/1000)*1.01*75% -> 18.339826 | F9: =+(F7*E3/1000)*1.01 -> 36.500728 | G9: =+(G7*$E$3/1000)*1.01*75% -> 27.375546 | H9: =+(H7*$E$3/1000)*1.01*75% -> 34.532551 | K9: Resina Virgen | L9: =+(L7*M3/1000)*1.005 -> 17.803937 | M9: =+(M7*M3/1000)*1.005 -> 24.332047 | N9: =+(N7*M3/1000)*1.005*75% -> 13.352953 | O9: =+(O7*M3/1000)*1.005*75% -> 18.249035 | Q9: Freight China-Gye | S9: 65 | T9: 65 | U9: 65 | V9: 65 | W9: 65 | X9: 65 | Y9: 65 | Z9: costo x TN | AA9: Análisis
B10: Resina PCR | C10: =+(C7*$E$4/1000)*1.01*25% -> 4.4194509 | D10: =+(D7*$E$4/1000)*1.01*25% -> 4.7310788 | E10: =+(E7*$E$4/1000)*1.01*25% -> 5.8076117 | F10: 0 | G10: =+(G7*$E$4/1000)*1.01*25% -> 8.6689228 | H10: =+(H7*$E$4/1000)*1.01*25% -> 10.935308 | K10: Resina PCR | L10: 0 | M10: 0 | N10: =+(N7*M4/1000)*1.005*25% -> 4.228435 | O10: =+(O7*M4/1000)*1.005*25% -> 5.7788612 | S10: =SUM(S7:S9) -> 1028.22 | T10: =SUM(T7:T9) -> 1049.09 | U10: =SUM(U7:U9) -> 1096.34 | V10: =SUM(V7:V9) -> 1083.75 | W10: =SUM(W7:W9) -> 1105.5 | X10: =SUM(X7:X9) -> 1135.6 | Y10: =SUM(Y7:Y9) -> 1140 | Z10: FOB
B11: Nueva Conversion | C11: 8.2 | D11: 8.2 | E11: 8.2 | F11: 11.15 | G11: 11.15 | H11: 11.15 | K11: Conversión | L11: 27.2 | M11: 27.2 | N11: 27.2 | O11: 27.2 | Q11: Landed factor 4% | S11: =+S10*4% -> 41.1288 | T11: =+T10*4% -> 41.9636 | U11: =+U10*4% -> 43.8536 | V11: =+V10*4% -> 43.35 | W11: =+W10*4% -> 44.22 | X11: =+X10*4% -> 45.424 | Y11: =+Y10*4% -> 45.6
B12: Recargo por Penalidad y energ | C12: 0 | D12: 0 | E12: 0 | F12: 0 | G12: 0 | H12: 0 | K12: Recargo por Penalidad e incr | L12: 0 | M12: 0 | N12: 0 | O12: 0 | Q12: Total resin price | S12: =+S11+S10 -> 1069.3488 | T12: =+T11+T10 -> 1091.0536 | U12: =+U11+U10 -> 1140.1936 | V12: =+V11+V10 -> 1127.1 | W12: =+W11+W10 -> 1149.72 | X12: =+X11+X10 -> 1181.024 | Y12: =+Y11+Y10 -> 1185.6
B13: Pigmento | C13: 1.3 | D13: 1.3 | E13: 1.3 | F13: 2.38 | G13: 2.38 | H13: 2.38 | K13: Pigmento | L13: 0.81 | M13: 1.99 | N13: 0.81 | O13: 1.99 | Q13: Resin PCR % | S13: =+S12*(1-5%) -> 1015.8814 | T13: =+T12*(1-5%) -> 1036.5009 | U13: =+U12*(1-5%) -> 1083.1839 | V13: =+V12*(1-5%) -> 1070.745 | W13: =+W12*(1-5%) -> 1092.234 | X13: =+X12*(1-5%) -> 1121.9728 | Y13: =+Y12*(1-5%) -> 1126.32 | Z13: Validar si nos está costando el 5% por debajo
B14: Empaque | C14: 0.19 | D14: 0.19 | E14: 0.19 | F14: 0.33 | G14: 0.33 | H14: 0.33 | K14: Empaque | L14: 2.71 | M14: 2.71 | N14: 2.71 | O14: 2.71 | Q14: Precio ponderado bajo formuala | S14: =+S12*75%+S13*25% -> 1055.9819 | T14: =+T12*75%+T13*25% -> 1077.4154 | U14: =+U12*75%+U13*25% -> 1125.9412 | V14: =+V12*75%+V13*25% -> 1113.0113 | W14: =+W12*75%+W13*25% -> 1135.3485 | X14: =+X12*75%+X13*25% -> 1166.2612 | Y14: =+Y12*75%+Y13*25% -> 1170.78
B15: Flete | C15: 0.16 | D15: 0.16 | E15: 0.16 | F15: 0.28 | G15: 0.28 | H15: 0.28 | K15: Flete | L15: 7.77 | M15: 7.77 | N15: 7.77 | O15: 7.77 | Q15: Scrap 1% | S15: =+S14*1% -> 10.559819 | T15: =+T14*1% -> 10.774154 | U15: =+U14*1% -> 11.259412 | V15: =+V14*1% -> 11.130113 | W15: =+W14*1% -> 11.353485 | X15: =+X14*1% -> 11.662612 | Y15: =+Y14*1% -> 11.7078
B16: Total | C16: =SUM(C9:C15) -> 28.225611 | D16: =SUM(D9:D15) -> 29.521328 | E16: =SUM(E9:E15) -> 33.997438 | F16: =SUM(F9:F15) -> 50.640728 | G16: =SUM(G9:G15) -> 50.184469 | H16: =SUM(H9:H15) -> 59.607859 | K16: Total | L16: =SUM(L9:L15) -> 56.293937 | M16: =SUM(M9:M15) -> 64.002047 | N16: =SUM(N9:N15) -> 56.071388 | O16: =SUM(O9:O15) -> 63.697896 | Q16: Precio pnderado con scrap | S16: =+S15+S14 -> 1066.5418 | T16: =+T15+T14 -> 1088.1896 | U16: =+U15+U14 -> 1137.2006 | V16: =+V15+V14 -> 1124.1414 | W16: =+W15+W14 -> 1146.702 | X16: =+X15+X14 -> 1177.9238 | Y16: =+Y15+Y14 -> 1182.4878
Q17: Precio facturado Sep-Oct-Nov | S17: =+D5 -> 1177.9238 | T17: =+S17 -> 1177.9238 | U17: =+T17 -> 1177.9238 | V17: =+U17 -> 1177.9238 | W17: =+V17 -> 1177.9238 | X17: =+W17 -> 1177.9238 | Y17: =+X17 -> 1177.9238
B32: Fórmula | M32: Factor mundial del precio de la resina

Sheet Mar18
B3: Costo de Resina Virgen Actual | E3: =+Y12 -> 1241.5 | I3: 0.05 | K3: Costo de Resina Virgen Actual | M3: =+E3 -> 1241.5
B4: Costo de Resina PCR Actual (Enkador) | E4: =+Y13 -> 1179.425 | I4: =+E3*I3 -> 62.075 | K4: Costo de Resina PCR Actual | M4: =+E4 -> 1179.425
C5: =+(C9+C10)/C7*1000 -> 1238.2411 | D5: =+(D9+D10)/D7*1000 -> 1238.2411 | F5: =+(F9+F10)/F7*1000 -> 1253.915 | L5: =+(L9+L10)/L7*1000 -> 1247.7075 | M5: =+(M9+M10)/M7*1000 -> 1247.7075 | Q5: Nueva metodología / nuevas condiciones
B6: Preformas | K6: Manantial | L6: 500ml SG | M6: 500ml CG | S6: IHS julio para precio septiembre | T6: IHS agosto para precio octubre | U6: IHS septiembre para precio noviembre | V6: IHS Octubre para precio Diciembre | W6: IHS Noviembre para precio Enero | X6: IHS Diciembre para precio Febrero | Y6: IHS Enero para precio Marzo | Z6: IHS Febrero para precio Abril
B7: Gramaje | C7: 15.6 | D7: 16.7 | E7: 20.5 | F7: 30.6 | G7: 30.6 | H7: 38.6 | K7: Gramaje | L7: 15 | M7: 20.5 | N7: 15 | O7: 20.5 | Q7: IHS Asia Non Coke approved | S7: 938.13 | T7: 959 | U7: 1006.25 | V7: 993.75 | W7: 1015.5 | X7: 1045.6 | Y7: 1103.75 | Z7: 1110
B8: Finish | C8: Short | D8: Short | E8: Short | F8: Short | G8: Short | H8: Short | K8: Finish | L8: Short | M8: Short | N8: Short | O8: Short | Q8: Finance | S8: 25.09 | T8: 25.09 | U8: 25.09 | V8: 25 | W8: 25 | X8: 25 | Y8: 25 | Z8: 25
B9: Resina Virgen | C9: =+(C7*E3/1000)*1.01*75% -> 14.670805 | D9: =+(D7*$E$3/1000)*1.01*75% -> 15.705285 | E9: =+(E7*$E$3/1000)*1.01*75% -> 19.278943 | F9: =+(F7*E3/1000)*1.01 -> 38.369799 | G9: =+(G7*$E$3/1000)*1.01*75% -> 28.777349 | H9: =+(H7*$E$3/1000)*1.01*75% -> 36.300839 | K9: Resina Virgen | L9: =+(L7*M3/1000)*1.005 -> 18.715612 | M9: =+(M7*M3/1000)*1.005 -> 25.578004 | N9: =+(N7*M3/1000)*1.005*75% -> 14.036709 | O9: =+(O7*M3/1000)*1.005*75% -> 19.183503 | Q9: Freight China-Gye | S9: 65 | T9: 65 | U9: 65 | V9: 65 | W9: 65 | X9: 65 | Y9: 65 | Z9: 65 | AA9: costo x TN | AB9: Análisis
B10: Resina PCR | C10: =+(C7*$E$4/1000)*1.01*25% -> 4.6457551 | D10: =+(D7*$E$4/1000)*1.01*25% -> 4.9733404 | E10: =+(E7*$E$4/1000)*1.01*25% -> 6.1049987 | F10: 0 | G10: =+(G7*$E$4/1000)*1.01*25% -> 9.1128273 | H10: =+(H7*$E$4/1000)*1.01*25% -> 11.495266 | K10: Resina PCR | L10: 0 | M10: 0 | N10: =+(N7*M4/1000)*1.005*25% -> 4.444958 | O10: =+(O7*M4/1000)*1.005*25% -> 6.0747759 | S10: =SUM(S7:S9) -> 1028.22 | T10: =SUM(T7:T9) -> 1049.09 | U10: =SUM(U7:U9) -> 1096.34 | V10: =SUM(V7:V9) -> 1083.75 | W10: =SUM(W7:W9) -> 1105.5 | X10: =SUM(X7:X9) -> 1135.6 | Y10: =SUM(Y7:Y9) -> 1193.75 | Z10: =SUM(Z7:Z9) -> 1200 | AA10: FOB
B11: Nueva Conversion | C11: 8.2 | D11: 8.2 | E11: 8.2 | F11: 11.15 | G11: 11.15 | H11: 11.15 | K11: Conversión | L11: 27.2 | M11: 27.2 | N11: 27.2 | O11: 27.2 | Q11: Landed factor 4% | S11: =+S10*4% -> 41.1288 | T11: =+T10*4% -> 41.9636 | U11: =+U10*4% -> 43.8536 | V11: =+V10*4% -> 43.35 | W11: =+W10*4% -> 44.22 | X11: =+X10*4% -> 45.424 | Y11: =+Y10*4% -> 47.75 | Z11: =+Z10*4% -> 48
B12: Recargo por Penalidad y energ | C12: 0 | D12: 0 | E12: 0 | F12: 0 | G12: 0 | H12: 0 | K12: Recargo por Penalidad e incr | L12: 0 | M12: 0 | N12: 0 | O12: 0 | Q12: Total resin price | S12: =+S11+S10 -> 1069.3488 | T12: =+T11+T10 -> 1091.0536 | U12: =+U11+U10 -> 1140.1936 | V12: =+V11+V10 -> 1127.1 | W12: =+W11+W10 -> 1149.72 | X12: =+X11+X10 -> 1181.024 | Y12: =+Y11+Y10 -> 1241.5 | Z12: =+Z11+Z10 -> 1248
B13: Pigmento | C13: 1.3 | D13: 1.3 | E13: 1.3 | F13: 2.38 | G13: 2.38 | H13: 2.38 | K13: Pigmento | L13: 0.81 | M13: 1.99 | N13: 0.81 | O13: 1.99 | Q13: Resin PCR % | S13: =+S12*(1-5%) -> 1015.8814 | T13: =+T12*(1-5%) -> 1036.5009 | U13: =+U12*(1-5%) -> 1083.1839 | V13: =+V12*(1-5%) -> 1070.745 | W13: =+W12*(1-5%) -> 1092.234 | X13: =+X12*(1-5%) -> 1121.9728 | Y13: =+Y12*(1-5%) -> 1179.425 | Z13: =+Z12*(1-5%) -> 1185.6 | AA13: Validar si nos está costando el 5% por debajo
B14: Empaque | C14: 0.19 | D14: 0.19 | E14: 0.19 | F14: 0.33 | G14: 0.33 | H14: 0.33 | K14: Empaque | L14: 2.71 | M14: 2.71 | N14: 2.71 | O14: 2.71 | Q14: Precio ponderado bajo formuala | S14: =+S12*75%+S13*25% -> 1055.9819 | T14: =+T12*75%+T13*25% -> 1077.4154 | U14: =+U12*75%+U13*25% -> 1125.9412 | V14: =+V12*75%+V13*25% -> 1113.0113 | W14: =+W12*75%+W13*25% -> 1135.3485 | X14: =+X12*75%+X13*25% -> 1166.2612 | Y14: =+Y12*75%+Y13*25% -> 1225.9813 | Z14: =+Z12*75%+Z13*25% -> 1232.4
B15: Flete | C15: 0.16 | D15: 0.16 | E15: 0.16 | F15: 0.28 | G15: 0.28 | H15: 0.28 | K15: Flete | L15: 7.77 | M15: 7.77 | N15: 7.77 | O15: 7.77 | Q15: Scrap 1% | S15: =+S14*1% -> 10.559819 | T15: =+T14*1% -> 10.774154 | U15: =+U14*1% -> 11.259412 | V15: =+V14*1% -> 11.130113 | W15: =+W14*1% -> 11.353485 | X15: =+X14*1% -> 11.662612 | Y15: =+Y14*1% -> 12.259813 | Z15: =+Z14*1% -> 12.324
B16: Total | C16: =SUM(C9:C15) -> 29.166561 | D16: =SUM(D9:D15) -> 30.528626 | E16: =SUM(E9:E15) -> 35.233942 | F16: =SUM(F9:F15) -> 52.509799 | G16: =SUM(G9:G15) -> 52.030177 | H16: =SUM(H9:H15) -> 61.936105 | K16: Total | L16: =SUM(L9:L15) -> 57.205613 | M16: =SUM(M9:M15) -> 65.248004 | N16: =SUM(N9:N15) -> 56.971667 | O16: =SUM(O9:O15) -> 64.928279 | Q16: Precio pnderado con scrap | S16: =+S15+S14 -> 1066.5418 | T16: =+T15+T14 -> 1088.1896 | U16: =+U15+U14 -> 1137.2006 | V16: =+V15+V14 -> 1124.1414 | W16: =+W15+W14 -> 1146.702 | X16: =+X15+X14 -> 1177.9238 | Y16: =+Y15+Y14 -> 1238.2411 | Z16: =+Z15+Z14 -> 1244.724
Q17: Precio facturado Sep-Oct-Nov | S17: =+D5 -> 1238.2411 | T17: =+S17 -> 1238.2411 | U17: =+T17 -> 1238.2411 | V17: =+U17 -> 1238.2411 | W17: =+V17 -> 1238.2411 | X17: =+W17 -> 1238.2411 | Y17: =+X17 -> 1238.2411 | Z17: =+Y17 -> 1238.2411
L25: Actualización | M25: 43145
B32: Fórmula | M32: Factor mundial del precio de la resina

Sheet Abril18
B3: Costo de Resina Virgen Actual | E3: =+Z12 -> 1288.3 | I3: 0.05 | K3: Costo de Resina Virgen Actual | M3: =+E3 -> 1288.3
B4: Costo de Resina PCR Actual (Enkador) | E4: =+Z13 -> 1223.885 | I4: =+E3*I3 -> 64.415 | K4: Costo de Resina PCR Actual | M4: =+E4 -> 1223.885
C5: =+(C9+C10)/C7*1000 -> 1284.9182 | D5: =+(D9+D10)/D7*1000 -> 1284.9182 | E5: =+(E9+E10)/E7*1000 -> 1284.9182 | F5: =+(F9+F10)/F7*1000 -> 1301.183 | G5: =+(G9+G10)/G7*1000 -> 1284.9182 | H5: =+(H9+H10)/H7*1000 -> 1284.9182 | L5: =+(L9+L10)/L7*1000 -> 1294.7415 | M5: =+(M9+M10)/M7*1000 -> 1294.7415 | Q5: Nueva metodología / nuevas condiciones
B6: Preformas | K6: Manantial | L6: 500ml SG | M6: 500ml CG | N6: 500ml SG | O6: 500ml CG | S6: IHS julio para precio septiembre | T6: IHS agosto para precio octubre | U6: IHS septiembre para precio noviembre | V6: IHS Octubre para precio Diciembre | W6: IHS Noviembre para precio Enero | X6: IHS Diciembre para precio Febrero | Y6: IHS Enero para precio Marzo | Z6: IHS Febrero para precio Abril | AA6: IHS Marzo para precio Mayo
B7: Gramaje | C7: 15.6 | D7: 16.7 | E7: 20.5 | F7: 30.6 | G7: 30.6 | H7: 38.6 | K7: Gramaje | L7: 15 | M7: 20.5 | N7: 15 | O7: 20.5 | Q7: IHS Asia Non Coke approved | S7: 938.13 | T7: 959 | U7: 1006.25 | V7: 993.75 | W7: 1015.5 | X7: 1045.6 | Y7: 1103.75 | Z7: 1148.75 | AA7: 1170
B8: Finish | C8: Short | D8: Short | E8: Short | F8: Short | G8: Short | H8: Short | K8: Finish | L8: Short | M8: Short | N8: Short | O8: Short | Q8: Finance | S8: 25.09 | T8: 25.09 | U8: 25.09 | V8: 25 | W8: 25 | X8: 25 | Y8: 25 | Z8: 25 | AA8: 25
B9: Resina Virgen | C9: =+(C7*E3/1000)*1.01*75% -> 15.223841 | D9: =+(D7*$E$3/1000)*1.01*75% -> 16.297317 | E9: =+(E7*$E$3/1000)*1.01*75% -> 20.005689 | F9: =+(F7*E3/1000)*1.01 -> 39.8162 | G9: =+(G7*$E$3/1000)*1.01*75% -> 29.86215 | H9: =+(H7*$E$3/1000)*1.01*75% -> 37.669248 | K9: Resina Virgen | L9: =+(L7*M3/1000)*1.005 -> 19.421122 | M9: =+(M7*M3/1000)*1.005 -> 26.542201 | N9: =+(N7*M3/1000)*1.005*75% -> 14.565842 | O9: =+(O7*M3/1000)*1.005*75% -> 19.906651 | Q9: Freight China-Gye | S9: 65 | T9: 65 | U9: 65 | V9: 65 | W9: 65 | X9: 65 | Y9: 65 | Z9: 65 | AA9: 65 | AB9: costo x TN | AC9: Análisis
B10: Resina PCR | C10: =+(C7*$E$4/1000)*1.01*25% -> 4.820883 | D10: =+(D7*$E$4/1000)*1.01*25% -> 5.1608171 | E10: =+(E7*$E$4/1000)*1.01*25% -> 6.3351347 | F10: 0 | G10: =+(G7*$E$4/1000)*1.01*25% -> 9.4563475 | H10: =+(H7*$E$4/1000)*1.01*25% -> 11.928595 | K10: Resina PCR | L10: 0 | M10: 0 | N10: =+(N7*M4/1000)*1.005*25% -> 4.6125166 | O10: =+(O7*M4/1000)*1.005*25% -> 6.3037727 | S10: =SUM(S7:S9) -> 1028.22 | T10: =SUM(T7:T9) -> 1049.09 | U10: =SUM(U7:U9) -> 1096.34 | V10: =SUM(V7:V9) -> 1083.75 | W10: =SUM(W7:W9) -> 1105.5 | X10: =SUM(X7:X9) -> 1135.6 | Y10: =SUM(Y7:Y9) -> 1193.75 | Z10: =SUM(Z7:Z9) -> 1238.75 | AA10: =SUM(AA7:AA9) -> 1260 | AB10: FOB
B11: Nueva Conversion | C11: 8.2 | D11: 8.2 | E11: 8.2 | F11: 11.15 | G11: 11.15 | H11: 11.15 | K11: Conversión | L11: 27.2 | M11: 27.2 | N11: 27.2 | O11: 27.2 | Q11: Landed factor 4% | S11: =+S10*4% -> 41.1288 | T11: =+T10*4% -> 41.9636 | U11: =+U10*4% -> 43.8536 | V11: =+V10*4% -> 43.35 | W11: =+W10*4% -> 44.22 | X11: =+X10*4% -> 45.424 | Y11: =+Y10*4% -> 47.75 | Z11: =+Z10*4% -> 49.55 | AA11: =+AA10*4% -> 50.4
B12: Recargo por Penalidad y energ | C12: 0 | D12: 0 | E12: 0 | F12: 0 | G12: 0 | H12: 0 | K12: Recargo por Penalidad e incr | L12: 0 | M12: 0 | N12: 0 | O12: 0 | Q12: Total resin price | S12: =+S11+S10 -> 1069.3488 | T12: =+T11+T10 -> 1091.0536 | U12: =+U11+U10 -> 1140.1936 | V12: =+V11+V10 -> 1127.1 | W12: =+W11+W10 -> 1149.72 | X12: =+X11+X10 -> 1181.024 | Y12: =+Y11+Y10 -> 1241.5 | Z12: =+Z11+Z10 -> 1288.3 | AA12: =+AA11+AA10 -> 1310.4
B13: Pigmento | C13: 1.3 | D13: 1.3 | E13: 1.3 | F13: 2.38 | G13: 2.38 | H13: 2.38 | K13: Pigmento | L13: 0.81 | M13: 1.99 | N13: 0.81 | O13: 1.99 | Q13: Resin PCR % | S13: =+S12*(1-5%) -> 1015.8814 | T13: =+T12*(1-5%) -> 1036.5009 | U13: =+U12*(1-5%) -> 1083.1839 | V13: =+V12*(1-5%) -> 1070.745 | W13: =+W12*(1-5%) -> 1092.234 | X13: =+X12*(1-5%) -> 1121.9728 | Y13: =+Y12*(1-5%) -> 1179.425 | Z13: =+Z12*(1-5%) -> 1223.885 | AA13: =+AA12*(1-5%) -> 1244.88 | AB13: Validar si nos está costando el 5% por debajo
B14: Empaque | C14: 0.19 | D14: 0.19 | E14: 0.19 | F14: 0.33 | G14: 0.33 | H14: 0.33 | K14: Empaque | L14: 2.71 | M14: 2.71 | N14: 2.71 | O14: 2.71 | Q14: Precio ponderado bajo formuala | S14: =+S12*75%+S13*25% -> 1055.9819 | T14: =+T12*75%+T13*25% -> 1077.4154 | U14: =+U12*75%+U13*25% -> 1125.9412 | V14: =+V12*75%+V13*25% -> 1113.0113 | W14: =+W12*75%+W13*25% -> 1135.3485 | X14: =+X12*75%+X13*25% -> 1166.2612 | Y14: =+Y12*75%+Y13*25% -> 1225.9813 | Z14: =+Z12*75%+Z13*25% -> 1272.1962 | AA14: =+AA12*75%+AA13*25% -> 1294.02
B15: Flete | C15: 0.16 | D15: 0.16 | E15: 0.16 | F15: 0.28 | G15: 0.28 | H15: 0.28 | K15: Flete | L15: 7.77 | M15: 7.77 | N15: 7.77 | O15: 7.77 | Q15: Scrap 1% | S15: =+S14*1% -> 10.559819 | T15: =+T14*1% -> 10.774154 | U15: =+U14*1% -> 11.259412 | V15: =+V14*1% -> 11.130113 | W15: =+W14*1% -> 11.353485 | X15: =+X14*1% -> 11.662612 | Y15: =+Y14*1% -> 12.259813 | Z15: =+Z14*1% -> 12.721963 | AA15: =+AA14*1% -> 12.9402
B16: Total | C16: =SUM(C9:C15) -> 29.894724 | D16: =SUM(D9:D15) -> 31.308134 | E16: =SUM(E9:E15) -> 36.190823 | F16: =SUM(F9:F15) -> 53.9562 | G16: =SUM(G9:G15) -> 53.458497 | H16: =SUM(H9:H15) -> 63.737843 | K16: Total | L16: =SUM(L9:L15) -> 57.911123 | M16: =SUM(M9:M15) -> 66.212201 | N16: =SUM(N9:N15) -> 57.668358 | O16: =SUM(O9:O15) -> 65.880423 | Q16: Precio pnderado con scrap | S16: =+S15+S14 -> 1066.5418 | T16: =+T15+T14 -> 1088.1896 | U16: =+U15+U14 -> 1137.2006 | V16: =+V15+V14 -> 1124.1414 | W16: =+W15+W14 -> 1146.702 | X16: =+X15+X14 -> 1177.9238 | Y16: =+Y15+Y14 -> 1238.2411 | Z16: =+Z15+Z14 -> 1284.9182 | AA16: =+AA15+AA14 -> 1306.9602
Q17: Precio facturado Sep-Oct-Nov | S17: =+D5 -> 1284.9182 | T17: =+S17 -> 1284.9182 | U17: =+T17 -> 1284.9182 | V17: =+U17 -> 1284.9182 | W17: =+V17 -> 1284.9182 | X17: =+W17 -> 1284.9182 | Y17: =+X17 -> 1284.9182 | Z17: =+Y17 -> 1284.9182 | AA17: =+Z17 -> 1284.9182
L25: Actualización | M25: 43180
B32: Fórmula | M32: Factor mundial del precio de la resina

Sheet Mayo18
B3: Costo de Resina Virgen Actual | E3: =+AB12 -> 1307.28 | I3: 0.05 | K3: Costo de Resina Virgen Actual | M3: =+E3 -> 1307.28
B4: Costo de Resina PCR Actual (Enkador) | E4: =+AB13 -> 1241.916 | I4: =+E3*I3 -> 65.364 | K4: Costo de Resina PCR Actual | M4: =+E4 -> 1241.916
C5: =+(C9+C10)/C7*1000 -> 1303.8484 | D5: =+(D9+D10)/D7*1000 -> 1303.8484 | E5: =+(E9+E10)/E7*1000 -> 1303.8484 | F5: =+(F9+F10)/F7*1000 -> 1320.3528 | G5: =+(G9+G10)/G7*1000 -> 1303.8484 | H5: =+(H9+H10)/H7*1000 -> 1303.8484 | L5: =+(L9+L10)/L7*1000 -> 1313.8164 | M5: =+(M9+M10)/M7*1000 -> 1313.8164 | R5: Nueva metodología / nuevas condiciones
B6: Preformas | K6: Manantial | L6: 500ml SG | M6: 500ml CG | N6: 500ml SG | O6: 500ml CG | P6: 1000ml SG | T6: IHS julio para precio septiembre | U6: IHS agosto para precio octubre | V6: IHS septiembre para precio noviembre | W6: IHS Octubre para precio Diciembre | X6: IHS Noviembre para precio Enero | Y6: IHS Diciembre para precio Febrero | Z6: IHS Enero para precio Marzo | AA6: IHS Febrero para precio Abril | AB6: IHS Marzo para precio Mayo
B7: Gramaje | C7: 15.6 | D7: 16.7 | E7: 20.5 | F7: 30.6 | G7: 30.6 | H7: 38.6 | K7: Gramaje | L7: 15 | M7: 20.5 | N7: 15 | O7: 20.5 | P7: 30.6 | R7: IHS Asia Non Coke approved | T7: 938.13 | U7: 959 | V7: 1006.25 | W7: 993.75 | X7: 1015.5 | Y7: 1045.6 | Z7: 1103.75 | AA7: 1148.75 | AB7: 1167
B8: Finish | C8: Short | D8: Short | E8: Short | F8: Short | G8: Short | H8: Short | K8: Finish | L8: Short | M8: Short | N8: Short | O8: Short | P8: Short | R8: Finance | T8: 25.09 | U8: 25.09 | V8: 25.09 | W8: 25 | X8: 25 | Y8: 25 | Z8: 25 | AA8: 25 | AB8: 25
B9: Resina Virgen | C9: =+(C7*E3/1000)*1.01*75% -> 15.448128 | D9: =+(D7*$E$3/1000)*1.01*75% -> 16.537419 | E9: =+(E7*$E$3/1000)*1.01*75% -> 20.300424 | F9: =+(F7*E3/1000)*1.01 -> 40.402796 | G9: =+(G7*$E$3/1000)*1.01*75% -> 30.302097 | H9: =+(H7*$E$3/1000)*1.01*75% -> 38.224214 | K9: Resina Virgen | L9: =+(L7*M3/1000)*1.005 -> 19.707246 | M9: =+(M7*M3/1000)*1.005 -> 26.933236 | N9: =+(N7*M3/1000)*1.005*75% -> 14.780434 | O9: =+(O7*M3/1000)*1.005*75% -> 20.199927 | P9: =+(P7*M3/1000)*1.005*75% -> 30.152086 | R9: Freight China-Gye | T9: 65 | U9: 65 | V9: 65 | W9: 65 | X9: 65 | Y9: 65 | Z9: 65 | AA9: 65 | AB9: 65 | AC9: costo x TN | AD9: Análisis
B10: Resina PCR | C10: =+(C7*$E$4/1000)*1.01*25% -> 4.8919071 | D10: =+(D7*$E$4/1000)*1.01*25% -> 5.2368493 | E10: =+(E7*$E$4/1000)*1.01*25% -> 6.4284677 | F10: 0 | G10: =+(G7*$E$4/1000)*1.01*25% -> 9.595664 | H10: =+(H7*$E$4/1000)*1.01*25% -> 12.104334 | K10: Resina PCR | L10: 0 | M10: 0 | N10: =+(N7*M4/1000)*1.005*25% -> 4.6804709 | O10: =+(O7*M4/1000)*1.005*25% -> 6.3966436 | P10: =+(P7*M4/1000)*1.005*25% -> 9.5481607 | T10: =SUM(T7:T9) -> 1028.22 | U10: =SUM(U7:U9) -> 1049.09 | V10: =SUM(V7:V9) -> 1096.34 | W10: =SUM(W7:W9) -> 1083.75 | X10: =SUM(X7:X9) -> 1105.5 | Y10: =SUM(Y7:Y9) -> 1135.6 | Z10: =SUM(Z7:Z9) -> 1193.75 | AA10: =SUM(AA7:AA9) -> 1238.75 | AB10: =SUM(AB7:AB9) -> 1257 | AC10: FOB
B11: Nueva Conversion | C11: 8.2 | D11: 8.2 | E11: 8.2 | F11: 11.15 | G11: 11.15 | H11: 11.15 | K11: Conversión | L11: 27.2 | M11: 27.2 | N11: 27.2 | O11: 27.2 | P11: =11.15+28.25 -> 39.4 | R11: Landed factor 4% | T11: =+T10*4% -> 41.1288 | U11: =+U10*4% -> 41.9636 | V11: =+V10*4% -> 43.8536 | W11: =+W10*4% -> 43.35 | X11: =+X10*4% -> 44.22 | Y11: =+Y10*4% -> 45.424 | Z11: =+Z10*4% -> 47.75 | AA11: =+AA10*4% -> 49.55 | AB11: =+AB10*4% -> 50.28
B12: Recargo por Penalidad y energ | C12: 0 | D12: 0 | E12: 0 | F12: 0 | G12: 0 | H12: 0 | K12: Recargo por Penalidad e incr | L12: 0 | M12: 0 | N12: 0 | O12: 0 | P12: 0 | R12: Total resin price | T12: =+T11+T10 -> 1069.3488 | U12: =+U11+U10 -> 1091.0536 | V12: =+V11+V10 -> 1140.1936 | W12: =+W11+W10 -> 1127.1 | X12: =+X11+X10 -> 1149.72 | Y12: =+Y11+Y10 -> 1181.024 | Z12: =+Z11+Z10 -> 1241.5 | AA12: =+AA11+AA10 -> 1288.3 | AB12: =+AB11+AB10 -> 1307.28
B13: Pigmento | C13: 1.3 | D13: 1.3 | E13: 1.3 | F13: 2.38 | G13: 2.38 | H13: 2.38 | K13: Pigmento | L13: 0.81 | M13: 1.99 | N13: 0.81 | O13: 1.99 | P13: 2.97 | R13: Resin PCR % | T13: =+T12*(1-5%) -> 1015.8814 | U13: =+U12*(1-5%) -> 1036.5009 | V13: =+V12*(1-5%) -> 1083.1839 | W13: =+W12*(1-5%) -> 1070.745 | X13: =+X12*(1-5%) -> 1092.234 | Y13: =+Y12*(1-5%) -> 1121.9728 | Z13: =+Z12*(1-5%) -> 1179.425 | AA13: =+AA12*(1-5%) -> 1223.885 | AB13: =+AB12*(1-5%) -> 1241.916 | AC13: Validar si nos está costando el 5% por debajo
B14: Empaque | C14: 0.19 | D14: 0.19 | E14: 0.19 | F14: 0.33 | G14: 0.33 | H14: 0.33 | K14: Empaque | L14: 2.71 | M14: 2.71 | N14: 2.71 | O14: 2.71 | P14: 4.44 | R14: Precio ponderado bajo formuala | T14: =+T12*75%+T13*25% -> 1055.9819 | U14: =+U12*75%+U13*25% -> 1077.4154 | V14: =+V12*75%+V13*25% -> 1125.9412 | W14: =+W12*75%+W13*25% -> 1113.0113 | X14: =+X12*75%+X13*25% -> 1135.3485 | Y14: =+Y12*75%+Y13*25% -> 1166.2612 | Z14: =+Z12*75%+Z13*25% -> 1225.9813 | AA14: =+AA12*75%+AA13*25% -> 1272.1962 | AB14: =+AB12*75%+AB13*25% -> 1290.939
B15: Flete | C15: 0.16 | D15: 0.16 | E15: 0.16 | F15: 0.28 | G15: 0.28 | H15: 0.28 | K15: Flete | L15: 7.77 | M15: 7.77 | N15: 7.77 | O15: 7.77 | P15: 15.99 | R15: Scrap 1% | T15: =+T14*1% -> 10.559819 | U15: =+U14*1% -> 10.774154 | V15: =+V14*1% -> 11.259412 | W15: =+W14*1% -> 11.130113 | X15: =+X14*1% -> 11.353485 | Y15: =+Y14*1% -> 11.662612 | Z15: =+Z14*1% -> 12.259813 | AA15: =+AA14*1% -> 12.721963 | AB15: =+AB14*1% -> 12.90939
B16: Total | C16: =SUM(C9:C15) -> 30.190035 | D16: =SUM(D9:D15) -> 31.624268 | E16: =SUM(E9:E15) -> 36.578892 | F16: =SUM(F9:F15) -> 54.542796 | G16: =SUM(G9:G15) -> 54.037761 | H16: =SUM(H9:H15) -> 64.468548 | K16: Total | L16: =SUM(L9:L15) -> 58.197246 | M16: =SUM(M9:M15) -> 66.603236 | N16: =SUM(N9:N15) -> 57.950905 | O16: =SUM(O9:O15) -> 66.266571 | P16: =SUM(P9:P15) -> 102.50025 | R16: Precio pnderado con scrap | T16: =+T15+T14 -> 1066.5418 | U16: =+U15+U14 -> 1088.1896 | V16: =+V15+V14 -> 1137.2006 | W16: =+W15+W14 -> 1124.1414 | X16: =+X15+X14 -> 1146.702 | Y16: =+Y15+Y14 -> 1177.9238 | Z16: =+Z15+Z14 -> 1238.2411 | AA16: =+AA15+AA14 -> 1284.9182 | AB16: =+AB15+AB14 -> 1303.8484
R17: Precio facturado Sep-Oct-Nov | T17: =+D5 -> 1303.8484 | U17: =+T17 -> 1303.8484 | V17: =+U17 -> 1303.8484 | W17: =+V17 -> 1303.8484 | X17: =+W17 -> 1303.8484 | Y17: =+X17 -> 1303.8484 | Z17: =+Y17 -> 1303.8484 | AA17: =+Z17 -> 1303.8484 | AB17: =+AA17 -> 1303.8484
B32: Fórmula | M32: Factor mundial del precio de la resina

Sheet Junio18
B3: Costo de Resina Virgen Actual | E3: =+AC12 -> 1363.7 | I3: 0.05 | K3: Costo de Resina Virgen Actual | M3: =+E3 -> 1363.7
B4: Costo de Resina PCR Actual (Enkador) | E4: =+AC13 -> 1295.515 | I4: =+E3*I3 -> 68.185 | K4: Costo de Resina PCR Actual | M4: =+E4 -> 1295.515
C5: =+(C9+C10)/C7*1000 -> 1360.1203 | D5: =+(D9+D10)/D7*1000 -> 1360.1203 | E5: =+(E9+E10)/E7*1000 -> 1360.1203 | F5: =+(F9+F10)/F7*1000 -> 1377.337 | G5: =+(G9+G10)/G7*1000 -> 1360.1203 | H5: =+(H9+H10)/H7*1000 -> 1360.1203 | L5: =+(L9+L10)/L7*1000 -> 1370.5185 | M5: =+(M9+M10)/M7*1000 -> 1370.5185 | R5: Nueva metodología / nuevas condiciones
B6: Preformas | K6: Manantial | L6: 500ml SG | M6: 500ml CG | N6: 500ml SG | O6: 500ml CG | P6: 1000ml SG | T6: IHS julio para precio septiembre | U6: IHS agosto para precio octubre | V6: IHS septiembre para precio noviembre | W6: IHS Octubre para precio Diciembre | X6: IHS Noviembre para precio Enero | Y6: IHS Diciembre para precio Febrero | Z6: IHS Enero para precio Marzo | AA6: IHS Febrero para precio Abril | AB6: IHS Marzo para precio Mayo | AC6: IHS Abril para precio Junio
B7: Gramaje | C7: 15.6 | D7: 16.7 | E7: 20.5 | F7: 30.6 | G7: 30.6 | H7: 38.6 | K7: Gramaje | L7: 15 | M7: 20.5 | N7: 15 | O7: 20.5 | P7: 30.6 | R7: IHS Asia Non Coke approved | T7: 938.13 | U7: 959 | V7: 1006.25 | W7: 993.75 | X7: 1015.5 | Y7: 1045.6 | Z7: 1103.75 | AA7: 1148.75 | AB7: 1167 | AC7: 1221.25
B8: Finish | C8: Short | D8: Short | E8: Short | F8: Short | G8: Short | H8: Short | K8: Finish | L8: Short | M8: Short | N8: Short | O8: Short | P8: Short | R8: Finance | T8: 25.09 | U8: 25.09 | V8: 25.09 | W8: 25 | X8: 25 | Y8: 25 | Z8: 25 | AA8: 25 | AB8: 25 | AC8: 25
B9: Resina Virgen | C9: =+(C7*E3/1000)*1.01*75% -> 16.114843 | D9: =+(D7*$E$3/1000)*1.01*75% -> 17.251146 | E9: =+(E7*$E$3/1000)*1.01*75% -> 21.176556 | F9: =+(F7*E3/1000)*1.01 -> 42.146512 | G9: =+(G7*$E$3/1000)*1.01*75% -> 31.609884 | H9: =+(H7*$E$3/1000)*1.01*75% -> 39.873906 | K9: Resina Virgen | L9: =+(L7*M3/1000)*1.005 -> 20.557778 | M9: =+(M7*M3/1000)*1.005 -> 28.095629 | N9: =+(N7*M3/1000)*1.005*75% -> 15.418333 | O9: =+(O7*M3/1000)*1.005*75% -> 21.071722 | P9: =+(P7*M3/1000)*1.005*75% -> 31.4534 | R9: Freight China-Gye | T9: 65 | U9: 65 | V9: 65 | W9: 65 | X9: 65 | Y9: 65 | Z9: 65 | AA9: 65 | AB9: 65 | AC9: 65
B10: Resina PCR | C10: =+(C7*$E$4/1000)*1.01*25% -> 5.1030336 | D10: =+(D7*$E$4/1000)*1.01*25% -> 5.4628629 | E10: =+(E7*$E$4/1000)*1.01*25% -> 6.7059095 | F10: 0 | G10: =+(G7*$E$4/1000)*1.01*25% -> 10.009797 | H10: =+(H7*$E$4/1000)*1.01*25% -> 12.626737 | K10: Resina PCR | L10: 0 | M10: 0 | N10: =+(N7*M4/1000)*1.005*25% -> 4.8824722 | O10: =+(O7*M4/1000)*1.005*25% -> 6.6727119 | P10: =+(P7*M4/1000)*1.005*25% -> 9.9602432 | T10: =SUM(T7:T9) -> 1028.22 | U10: =SUM(U7:U9) -> 1049.09 | V10: =SUM(V7:V9) -> 1096.34 | W10: =SUM(W7:W9) -> 1083.75 | X10: =SUM(X7:X9) -> 1105.5 | Y10: =SUM(Y7:Y9) -> 1135.6 | Z10: =SUM(Z7:Z9) -> 1193.75 | AA10: =SUM(AA7:AA9) -> 1238.75 | ... AC10: =SUM(AC7:AC9) -> 1311.25
B11: Nueva Conversion | C11: 8.2 | D11: 8.2 | E11: 8.2 | F11: 11.15 | G11: 11.15 | H11: 11.15 | K11: Conversión | L11: 27.2 | M11: 27.2 | N11: 27.2 | O11: 27.2 | P11: =11.15+28.25 -> 39.4 | R11: Landed factor 4% | T11: =+T10*4% -> 41.1288 | U11: =+U10*4% -> 41.9636 | V11: =+V10*4% -> 43.8536 | W11: =+W10*4% -> 43.35 | X11: =+X10*4% -> 44.22 | Y11: =+Y10*4% -> 45.424 | Z11: =+Z10*4% -> 47.75 | AA11: =+AA10*4% -> 49.55 | ... AC11: =+AC10*4% -> 52.45
B12: Recargo por Penalidad y energ | C12: 0 | D12: 0 | E12: 0 | F12: 0 | G12: 0 | H12: 0 | K12: Recargo por Penalidad e incr | L12: 0 | M12: 0 | N12: 0 | O12: 0 | P12: 0 | R12: Total resin price | T12: =+T11+T10 -> 1069.3488 | U12: =+U11+U10 -> 1091.0536 | V12: =+V11+V10 -> 1140.1936 | W12: =+W11+W10 -> 1127.1 | X12: =+X11+X10 -> 1149.72 | Y12: =+Y11+Y10 -> 1181.024 | Z12: =+Z11+Z10 -> 1241.5 | AA12: =+AA11+AA10 -> 1288.3 | ... AC12: =+AC11+AC10 -> 1363.7
B13: Pigmento | C13: 1.3 | D13: 1.3 | E13: 1.3 | F13: 2.38 | G13: 2.38 | H13: 2.38 | K13: Pigmento | L13: 0.81 | M13: 1.99 | N13: 0.81 | O13: 1.99 | P13: 2.97 | R13: Resin PCR % | T13: =+T12*(1-5%) -> 1015.8814 | U13: =+U12*(1-5%) -> 1036.5009 | V13: =+V12*(1-5%) -> 1083.1839 | W13: =+W12*(1-5%) -> 1070.745 | X13: =+X12*(1-5%) -> 1092.234 | Y13: =+Y12*(1-5%) -> 1121.9728 | Z13: =+Z12*(1-5%) -> 1179.425 | AA13: =+AA12*(1-5%) -> 1223.885 | ... AC13: =+AC12*(1-5%) -> 1295.515
B14: Empaque | C14: 0.19 | D14: 0.19 | E14: 0.19 | F14: 0.33 | G14: 0.33 | H14: 0.33 | K14: Empaque | L14: 2.71 | M14: 2.71 | N14: 2.71 | O14: 2.71 | P14: 4.44 | R14: Precio ponderado bajo formuala | T14: =+T12*75%+T13*25% -> 1055.9819 | U14: =+U12*75%+U13*25% -> 1077.4154 | V14: =+V12*75%+V13*25% -> 1125.9412 | W14: =+W12*75%+W13*25% -> 1113.0113 | X14: =+X12*75%+X13*25% -> 1135.3485 | Y14: =+Y12*75%+Y13*25% -> 1166.2612 | Z14: =+Z12*75%+Z13*25% -> 1225.9813 | AA14: =+AA12*75%+AA13*25% -> 1272.1962 | ... AC14: =+AC12*75%+AC13*25% -> 1346.6537
B15: Flete | C15: 0.16 | D15: 0.16 | E15: 0.16 | F15: 0.28 | G15: 0.28 | H15: 0.28 | K15: Flete | L15: 7.77 | M15: 7.77 | N15: 7.77 | O15: 7.77 | P15: 15.99 | R15: Scrap 1% | T15: =+T14*1% -> 10.559819 | U15: =+U14*1% -> 10.774154 | V15: =+V14*1% -> 11.259412 | W15: =+W14*1% -> 11.130113 | X15: =+X14*1% -> 11.353485 | Y15: =+Y14*1% -> 11.662612 | Z15: =+Z14*1% -> 12.259813 | AA15: =+AA14*1% -> 12.721963 | ... AC15: =+AC14*1% -> 13.466537
B16: Total | C16: =SUM(C9:C15) -> 31.067876 | D16: =SUM(D9:D15) -> 32.564009 | E16: =SUM(E9:E15) -> 37.732466 | F16: =SUM(F9:F15) -> 56.286512 | G16: =SUM(G9:G15) -> 55.759681 | H16: =SUM(H9:H15) -> 66.640643 | K16: Total | L16: =SUM(L9:L15) -> 59.047778 | M16: =SUM(M9:M15) -> 67.765629 | N16: =SUM(N9:N15) -> 58.790805 | O16: =SUM(O9:O15) -> 67.414434 | P16: =SUM(P9:P15) -> 104.21364 | R16: Precio pnderado con scrap | T16: =+T15+T14 -> 1066.5418 | U16: =+U15+U14 -> 1088.1896 | V16: =+V15+V14 -> 1137.2006 | W16: =+W15+W14 -> 1124.1414 | X16: =+X15+X14 -> 1146.702 | Y16: =+Y15+Y14 -> 1177.9238 | Z16: =+Z15+Z14 -> 1238.2411 | AA16: =+AA15+AA14 -> 1284.9182 | ... AC16: =+AC15+AC14 -> 1360.1203
