Workbook

Sheet CSD List
B3: LISTA DE PRECIOS PF CSD AB INBEV
B7: 46082
B9: Type | C9: Preform Weight (gr) | D9: AR$/ 000
B10: SS 500 | C10: 19.5 | D10: =+VLOOKUP(C10,'CSD Pricing'!$D$104:$ZC$121,MATCH('CSD List'!$B$7,'CSD Pricing'!$D$2:$ZD$2,0),0) -> 48764.347
B11: SS 500 - 19.5G PCR 100% | C11: 19.5 | D11: =+VLOOKUP(C11,'CSD Pricing'!$D$104:$ZC$121,MATCH('CSD List'!$B$7,'CSD Pricing'!$D$2:$ZD$2,0),0) -> 48764.347
B12: SS 500 | C12: 22.1 | D12: =+VLOOKUP(C12,'CSD Pricing'!$D$104:$ZC$121,MATCH('CSD List'!$B$7,'CSD Pricing'!$D$2:$ZD$2,0),0) -> 53631.969
B13: SS 500 | C13: 22 | D13: =+VLOOKUP(C13,'CSD Pricing'!$D$104:$ZC$121,MATCH('CSD List'!$B$7,'CSD Pricing'!$D$2:$ZD$2,0),0) -> 0
B14: SS 500 | C14: 25 | D14: =+VLOOKUP(C14,'CSD Pricing'!$D$104:$ZC$121,MATCH('CSD List'!$B$7,'CSD Pricing'!$D$2:$ZD$2,0),0) -> 59061.239
B15: SS 500 - 25G PCR 100% | C15: 25 | D15: =+VLOOKUP(C15,'CSD Pricing'!$D$104:$ZC$121,MATCH('CSD List'!$B$7,'CSD Pricing'!$D$2:$ZD$2,0),0) -> 59061.239
B16: MS 1500 | C16: 37.2 | D16: =+VLOOKUP(C16,'CSD Pricing'!$D$104:$ZC$121,MATCH('CSD List'!$B$7,'CSD Pricing'!$D$2:$ZD$2,0),0) -> 86842.996
B17: MS 1500 | C17: 40 | D17: =+VLOOKUP(C17,'CSD Pricing'!$D$104:$ZC$121,MATCH('CSD List'!$B$7,'CSD Pricing'!$D$2:$ZD$2,0),0) -> 0
B18: MS 1500 | C18: 44 | D18: =+VLOOKUP(C18,'CSD Pricing'!$D$104:$ZC$121,MATCH('CSD List'!$B$7,'CSD Pricing'!$D$2:$ZD$2,0),0) -> 99573.699
B19: MS 2000/2250 | C19: 42.6 | D19: =+VLOOKUP(C19,'CSD Pricing'!$D$104:$ZC$121,MATCH('CSD List'!$B$7,'CSD Pricing'!$D$2:$ZD$2,0),0) -> 0
B20: MS 2000/2250 | C20: 46.6 | D20: =+VLOOKUP(C20,'CSD Pricing'!$D$104:$ZC$121,MATCH('CSD List'!$B$7,'CSD Pricing'!$D$2:$ZD$2,0),0) -> 106366.53
B21: MS 2000/2250 20% PCR | C21: 46.6 | D21: =+VLOOKUP(C21,'CSD Pricing'!$D$104:$ZC$121,MATCH('CSD List'!$B$7,'CSD Pricing'!$D$2:$ZD$2,0),0) -> 106366.53
... B27: MS 3000 | C27: 62 | D27: =+VLOOKUP(C27,'CSD Pricing'!$D$104:$ZC$121,MATCH('CSD List'!$B$7,'CSD Pricing'!$D$2:$ZD$2,0),0) -> 135711.22
B28: SS 500 | C28: 19.5 PQS (U03) | D28: =+VLOOKUP(C28,'CSD Pricing'!#REF!,MATCH('CSD List'!$B$7,'CSD Pricing'!$D$2:$ZD$2,0),0) -> #REF!
B29: MS 1500 | C29: 37.2 PQS (U03) | D29: =+VLOOKUP(C29,'CSD Pricing'!#REF!,MATCH('CSD List'!$B$7,'CSD Pricing'!$D$2:$ZD$2,0),0) -> #REF!
B30: MS 1500 | C30: 44 PQS (U03) | D30: =+VLOOKUP(C30,'CSD Pricing'!#REF!,MATCH('CSD List'!$B$7,'CSD Pricing'!$D$2:$ZD$2,0),0) -> #REF!
B31: MS 2000/2250 | C31: 46.6 PQS (U03) | D31: =+VLOOKUP(C31,'CSD Pricing'!#REF!,MATCH('CSD List'!$B$7,'CSD Pricing'!$D$2:$ZD$2,0),0) -> #REF!
B32: MS 2000/2250 | C32: 52 PQS (U03) | D32: =+VLOOKUP(C32,'CSD Pricing'!#REF!,MATCH('CSD List'!$B$7,'CSD Pricing'!$D$2:$ZD$2,0),0) -> #REF!
B33: MS 3000 | C33: 54.7 PQS (U03) | D33: =+VLOOKUP(C33,'CSD Pricing'!#REF!,MATCH('CSD List'!$B$7,'CSD Pricing'!$D$2:$ZD$2,0),0) -> #REF!
B34: MS 3000 | C34: 62 PQS (U03) | D34: =+VLOOKUP(C34,'CSD Pricing'!#REF!,MATCH('CSD List'!$B$7,'CSD Pricing'!$D$2:$ZD$2,0),0) -> #REF!
B36: Valor Resina Virgen Dak | C36: =HLOOKUP(B7,'CSD Pricing'!2:3,2,0) -> 1257.4968
B37: Valor Resina PQS | C37: =HLOOKUP(B7,'CSD Pricing'!2:5,4,0) -> #N/A
B38: Valor Resina PCR | C38: =HLOOKUP(B7,'CSD Pricing'!2:6,5,0) -> 1257.4968

Sheet HF List
B3: PRICING LIST PF HS AB INBEV
B7: 46082
B9: Type | C9: Preform Weight (gr) | D9: AR$/ 000
B10: 300 ML | C10: 24 | D10: =+VLOOKUP(C10,'HF Pricing'!$D$56:$EB$63,MATCH('HF List'!$B$7,'HF Pricing'!$D$2:$ZB$2,0),0) -> 68103.093
B11: 300 ML | C11: 30 | D11: =+VLOOKUP(C11,'HF Pricing'!$D$56:$EB$63,MATCH('HF List'!$B$7,'HF Pricing'!$D$2:$ZB$2,0),0) -> 80984.313
B12: 300 ML | C12: 30.4 Virgen | D12: =+VLOOKUP(C12,'HF Pricing'!$D$56:$EB$63,MATCH('HF List'!$B$7,'HF Pricing'!$D$2:$ZB$2,0),0) -> 80141.79
B13: 300 ML | C13: 30.4 30% PCR | D13: =+VLOOKUP(C13,'HF Pricing'!$D$56:$ZB$63,MATCH('HF List'!$B$7,'HF Pricing'!$D$2:$ZB$2,0),0) -> 80141.79
B14: 340 ML | C14: 34 Virgen | D14: =+VLOOKUP(C14,'HF Pricing'!$D$56:$ZB$63,MATCH('HF List'!$B$7,'HF Pricing'!$D$2:$ZB$2,0),0) -> 87042.014
B15: 340 ML | C15: 34 30% PCR | D15: =+VLOOKUP(C15,'HF Pricing'!$D$56:$ZB$63,MATCH('HF List'!$B$7,'HF Pricing'!$D$2:$ZB$2,0),0) -> 87042.014
B16: 750 ML | C16: 44.8 | D16: =+VLOOKUP(C16,'HF Pricing'!$D$56:$ZB$63,MATCH('HF List'!$B$7,'HF Pricing'!$D$2:$ZB$2,0),0) -> 117568.95
B17: 1250 ML | C17: 52 | D17: =+VLOOKUP(C17,'HF Pricing'!$D$56:$ZB$63,MATCH('HF List'!$B$7,'HF Pricing'!$D$2:$ZB$2,0),0) -> 130943.11
B21: Valor Resina Virgen Amcor | C21: =HLOOKUP(B7,'HF Pricing'!2:3,2,0) -> 1287.4315
B22: Valor Resina Virgen Ushuaia | C22: =HLOOKUP(B7,'HF Pricing'!2:4,3,0) -> 1293.8228
B23: Valor Resina PCR | C23: =HLOOKUP(B7,'HF Pricing'!2:5,4,0) -> 1287.4315

Sheet CSD Pricing
C2: Month | K2: 43101 | L2: 43132 | M2: 43160 | N2: 43191 | O2: 43221 | P2: 43252 | Q2: 43282 | R2: 43313 | S2: 43344 | T2: 43374 | U2: 43405 | V2: 43435 | W2: 43466 | X2: 43497 | Y2: 43525 | Z2: 43556 | AA2: 43586 | AB2: 43617 | AC2: 43647 | AD2: 43678 | AE2: 43709 | AF2: 43739 | AG2: 43770 | AH2: 43800 | AI2: 43831 | AJ2: 43862 | AK2: 43891 | AL2: 43922 | AM2: 43952 | AN2: 43983 | AO2: 44013 | AP2: 44044 | AQ2: 44075 | AR2: 44105 | AS2: 44136 | AT2: 44166 | AU2: 44197 | AV2: 44228 | AW2: 44256 | AX2: 44287 | AY2: 44317 | AZ2: 44348 | BA2: 44378 | BB2: 44409 | BC2: 44440 | BD2: 44470 | BE2: 44501 | BF2: 44531 | BG2: 44562 | BH2: 44593 | BI2: 44621 | BJ2: 44652 | BK2: 44682 | BL2: 44713 | BM2: 44743 | BN2: 44774 | BO2: 44805 | BP2: 44835 | BQ2: 44866 | BR2: 44896 | BT2: 44927 | BU2: 44958 | BV2: 44986 | BW2: 45017 | BX2: 45047 | BY2: 45078 | BZ2: 45108 | CA2: 45139 | CB2: 45170 | CC2: 45200 | CD2: 45231 | CE2: 45261 | CF2: 45292 | CG2: 45323 | CH2: 45352 | CI2: 45383 | CJ2: 45413 | CK2: 45444 | CL2: 45474 | CM2: 45505 | CO2: 45536 | CP2: 45566 | CQ2: 45597 | CR2: 45627 | CS2: 45658 | CT2: 45689 | CU2: 45717 | CV2: 45748 | CW2: 45778 | CX2: 45809 | CY2: 45839 | CZ2: 45870 | DA2: 45901 | DB2: 45931 | DC2: 45962 | DD2: 45992 | DE2: 46023 | DF2: 46054 | DG2: 46082
C3: Resin Virgen Price | K3: 1342.9442 | L3: 1374.5998 | M3: 1390.1923 | N3: 1432.5895 | O3: 1463.5562 | P3: 1494.6312 | Q3: 1574.2419 | R3: 1656.8327 | S3: 1693.0693 | T3: 1694.1975 | U3: 1694.0531 | V3: 1711.9398 | W3: 1695.6105 | X3: 1676.6117 | Y3: 1606.0031 | Z3: 1544.9132 | AA3: 1511.464 | AB3: 1491.7034 | AC3: 1491.7034 | AD3: 1223.0042 | AE3: 1272.6947 | AF3: 1178.271 | AG3: 1154.4432 | AH3: 1124.4239 | AI3: 1123.162 | AJ3: 1128.4456 | AK3: 1145.5328 | AL3: 1101.8412 | AM3: 1021.2324 | AN3: 927.68903 | AO3: 943.27499 | AP3: 952.71874 | AQ3: 930.63904 | AR3: 917.60359 | AS3: 919.73461 | AT3: 916.37867 | AU3: 923.78502 | AV3: 997.43551 | AW3: 1160.698 | AX3: #N/A | AY3: #N/A | AZ3: #N/A | BA3: #N/A | BB3: #N/A | BC3: 1494.3256 | BD3: 1501.9696 | BE3: 1486.8851 | BF3: 1664.4992 | BG3: 1678.4033 | BH3: 1570.4271 | BI3: 1733.0951 | BJ3: 1846.0531 | BK3: 1966.1218 | BL3: 2104.0935 | BM3: 2154.5856 | BN3: 2153.47 | BO3: 1937.575 | BP3: 1749.7903 | BQ3: 1695.6645 | BR3: 1622.6628 | BT3: 1532.1838 | BU3: 1517.9026 | BV3: 1494.758 | BW3: 1522.7956 | BX3: 1528.6676 | BY3: 1585.5978 | BZ3: 1494.2782 | CA3: 1429.177 | CB3: 1247.769 | CC3: 1301.1494 | CD3: 1312.7931 | CE3: 1285.056 | CF3: 1800 | CG3: 1836 | CH3: 1748 | CI3: 1703 | CJ3: 1500.0011 | CK3: 1500.0033 | CL3: 1499.9984 | CM3: 1500 | CO3: 1801 | CP3: ='Balance Resinas'!C19 -> 1166.5997 | CQ3: ='Balance Resinas'!$C28 -> 1424.3203 | CR3: ='Balance Resinas'!$C37 -> 1504.4159 | CS3: ='Balance Resinas'!$C46 -> 1524.8199 | CT3: ='Balance Resinas'!$C55 -> 1513.7984 | CU3: ='Balance Resinas'!$C64 -> 1488.7116 | CV3: ='Balance Resinas'!$C73 -> 1472.3492 | CW3: ='Balance Resinas'!$C82 -> 1425.2627 | CX3: ='Balance Resinas'!$C91 -> 1382.0971 | CY3: ='Balance Resinas'!$C100 -> 1321.4159 | CZ3: ='Balance Resinas'!$C109 -> 1283.764 | DA3: ='Balance Resinas'!$C118 -> 1317.8329 | DB3: ='Balance Resinas'!$C127 -> 1369.6513 | DC3: ='Balance Resinas'!$C136 -> 1380.2021 | DD3: ='Balance Resinas'!$C145 -> 1344.145 | DE3: ='Balance Resinas'!$C154 -> 1299.679 | DF3: ='Balance Resinas'!$C163 -> 1279.5923 | DG3: =+'Balance Resinas'!C172 -> 1257.4968
C4: Nylon price | K4: 8580 | L4: 8580 | M4: 8580 | N4: 8580 | O4: 8580 | P4: 8580 | Q4: 8580 | R4: 8580 | S4: 8580 | T4: 8580 | U4: 8580 | V4: 8580 | W4: 8580 | X4: 8580 | Y4: 8580 | Z4: 8580 | AA4: 8580 | AB4: 8580 | AC4: 8580 | AD4: 8580 | AE4: 8580 | AF4: 8580 | AG4: 8580 | AH4: 8580 | AI4: 8580 | AJ4: 8580 | AK4: 8580 | AL4: 8580 | AM4: 8580 | AN4: 8580 | AO4: 8580 | AP4: 8580 | AQ4: 8580 | AR4: 8580 | AS4: 8580 | AT4: 8580 | AU4: 8580 | AV4: 8580 | AW4: 8580 | AX4: 8580 | AY4: 8580 | AZ4: 8580 | BA4: 8580 | BB4: 8580 | BC4: 8580 | BD4: 8580 | BE4: 8580 | BF4: 8580 | BG4: 8580 | BH4: 8580 | BI4: 8580 | BJ4: 8580 | BK4: 8580 | BL4: 8580 | BM4: 8580 | BN4: 8580 | BO4: 8580 | BP4: 8580 | BQ4: 8580 | BR4: 8580 | BT4: 8580 | BU4: 8580 | BV4: 8580 | BW4: 8580 | BX4: 8580 | BY4: 8580 | BZ4: 8580 | CA4: 8580 | CB4: 8580 | CC4: 8580 | CD4: 8580 | CE4: 8580 | CF4: 8580 | CG4: 8580 | CH4: 8580 | CI4: 8580 | CJ4: 8580 | CK4: 8580 | CL4: 8580 | CM4: 8580 | CO4: 8580 | CP4: 8580 | CQ4: 8580 | CR4: 8580 | CS4: 8580 | CT4: 8580 | CU4: 8580 | CV4: 8580 | CW4: 8580 | CX4: 8580 | CY4: 8580 | CZ4: 8580 | DA4: 8580 | DB4: 8580 | DC4: 8580 | DD4: 8580 | DE4: 8580 | DF4: 8580 | DG4: 8580
C5: PQS Price | AP5: 995.71874 | AQ5: 973.63904 | AR5: 960.60359 | AS5: 962.73461 | AT5: 959.37867 | AU5: 966.78502 | AV5: 1040.4355 | AW5: 1203.698 | AX5: #N/A | AY5: #N/A | AZ5: #N/A | BA5: #N/A | BB5: #N/A | BC5: 1609.3256 | BD5: 1616.9696 | BE5: 1601.8851 | BF5: 1782.8556 | BG5: 1797.1347 | BH5: 1686.2221 | BI5: 1850.3826 | BJ5: 1923.1931 | BK5: 2015.5118 | BL5: 2183.056 | BM5: 2234.0731 | BN5: 2203.52 | BO5: 1984.325 | BP5: 1795.6778 | BQ5: 1740.1045 | BR5: 1665.6628 | BT5: 1575.1838 | BU5: 1560.9026 | BV5: 1537.758 | BW5: 1565.7956 | BX5: 1571.6676 | BY5: 1629.1603 | BZ5: 1537.2782 | CA5: 1472.177 | CB5: 1290.769 | CC5: 1344.1494 | CD5: 1355.7931 | CE5: 1328.056 | CF5: 0 | CG5: 0 | CH5: 0 | CI5: #N/A | CJ5: #N/A | CK5: #N/A | CL5: #N/A | CM5: #N/A | CO5: #N/A | CP5: #N/A | CQ5: #N/A | CR5: #N/A | CS5: #N/A | CT5: #N/A | CU5: #N/A | CV5: #N/A | CW5: #N/A | CX5: #N/A | CY5: #N/A | CZ5: #N/A | DA5: #N/A | DB5: #N/A | DC5: #N/A | DD5: #N/A | DE5: #N/A | DF5: #N/A | DG5: #N/A
C6: Resin PCR Vinisa Price | CG6: 2450 | CH6: 2450 | CI6: 2450 | CJ6: 2450 | CK6: 2450 | CL6: 2450 | CM6: 2450 | CO6: 1801 | CP6: =CP3 -> 1166.5997 | CQ6: =CQ3 -> 1424.3203 | CR6: =CR3 -> 1504.4159 | CS6: =CS3 -> 1524.8199 | CT6: =CT3 -> 1513.7984 | CU6: =CU3 -> 1488.7116 | CV6: =CV3 -> 1472.3492 | CW6: =CW3 -> 1425.2627 | ... DG6: =DG3 -> 1257.4968
C7: Scrap % | K7: 0.005 | L7: 0.005 | M7: 0.005 | N7: 0.005 | O7: 0.005 | P7: 0.005 | Q7: 0.005 | R7: 0.005 | S7: 0.005 | T7: 0.005 | U7: 0.005 | V7: 0.005 | W7: 0.005 | X7: 0.005 | Y7: 0.005 | Z7: 0.005 | AA7: 0.005 | AB7: 0.005 | AC7: =+AB7 -> 0.005 | AD7: 0.005 | AE7: 0.005 | AF7: 0.005 | AG7: 0.005 | AH7: 0.005 | AI7: 0.005 | AJ7: 0.005 | AK7: 0.005 | AL7: 0.005 | AM7: 0.005 | AN7: 0.005 | AO7: 0.005 | AP7: 0.005 | AQ7: 0.005 | AR7: 0.005 | AS7: 0.005 | AT7: 0.005 | AU7: 0.005 | AV7: 0.005 | AW7: 0.005 | AX7: 0.005 | AY7: 0.005 | AZ7: 0.005 | BA7: 0.005 | BB7: 0.005 | BC7: 0.005 | BD7: 0.005 | BE7: 0.005 | BF7: 0.005 | BG7: 0.005 | BH7: 0.005 | BI7: 0.005 | BJ7: 0.005 | BK7: 0.005 | BL7: 0.005 | BM7: 0.005 | BN7: 0.005 | BO7: 0.005 | BP7: 0.005 | BQ7: 0.005 | BR7: 0.005 | BT7: 0.005 | BU7: 0.005 | BV7: 0.005 | BW7: 0.005 | BX7: 0.005 | BY7: 0.005 | BZ7: 0.005 | CA7: 0.005 | CB7: 0.005 | CC7: 0.005 | CD7: 0.005 | CE7: 0.005 | CF7: 0.005 | CG7: 0.005 | CH7: 0.005 | CI7: 0.005 | CJ7: 0.005 | CK7: 0.005 | CL7: 0.005 | CM7: 0.005 | CO7: 0.005 | CP7: 0.005 | CQ7: 0.005 | CR7: 0.005 | CS7: 0.005 | CT7: 0.005 | CU7: 0.005 | CV7: 0.005 | CW7: 0.005 | CX7: 0.005 | CY7: 0.005 | CZ7: 0.005 | DA7: 0.005 | DB7: 0.005 | DC7: 0.005 | DD7: 0.005 | DE7: 0.005 | DF7: 0.005 | DG7: 0.005
C8: Tax | K8: 0.052705 | L8: 0.052705 | M8: 0.052705 | N8: 0.052705 | O8: 0.052705 | P8: 0.052705 | Q8: 0.052705 | R8: 0.052705 | S8: 0.052705 | T8: 0.052705 | U8: 0.052705 | V8: 0.052705 | W8: 0.052705 | X8: 0.052705 | Y8: 0.052705 | Z8: 0.052705 | AA8: 0.052705 | AB8: 0.052705 | AC8: =+AB8 -> 0.052705 | AD8: 0.052705 | AE8: 0.052705 | AF8: 0.052705 | AG8: 0.052705 | AH8: 0.052705 | AI8: 0.052705 | AJ8: 0.052705 | AK8: 0.052705 | AL8: 0.052705 | AM8: 0.052705 | AN8: 0.052705 | AO8: 0.052705 | AP8: 0.052705 | AQ8: 0.052705 | AR8: 0.052705 | AS8: 0.052705 | AT8: 0.052705 | AU8: 0.052705 | AV8: 0.052705 | AW8: 0.052705 | AX8: 0.052705 | AY8: 0.052705 | AZ8: 0.052705 | BA8: 0.052705 | BB8: 0.052705 | BC8: 0.052705 | BD8: 0.052705 | BE8: 0.052705 | BF8: 0.052705 | BG8: 0.052705 | BH8: 0.052705 | BI8: 0.052705 | BJ8: 0.052705 | BK8: 0.052705 | BL8: 0.052705 | BM8: 0.052705 | BN8: 0.052705 | BO8: 0.052705 | BP8: 0.052705 | BQ8: 0.052705 | BR8: 0.052705 | BT8: 0.052705 | BU8: 0.052705 | BV8: 0.052705 | BW8: 0.052705 | BX8: 0.052705 | BY8: 0.052705 | BZ8: 0.052705 | CA8: 0.052705 | CB8: 0.052705 | CC8: 0.052705 | CD8: 0.052705 | CE8: 0.052705 | CF8: 0.052705 | CG8: 0.052705 | CH8: 0.052705 | CI8: 0.052705 | CJ8: 0.052705 | CK8: 0.052705 | CL8: 0.052705 | CM8: 0.052705 | CO8: 0.052705 | CP8: 0.052705 | CQ8: 0.052705 | CR8: 0.0525 | CS8: 0.0525 | CT8: 0.0525 | CU8: 0.0525 | CV8: 0.0525 | CW8: 0.0525 | CX8: 0.0525 | CY8: 0.0525 | CZ8: 0.0525 | DA8: 0.0525 | DB8: 0.0525 | DC8: 0.0525 | DD8: 0.0525 | DE8: 0.0525 | DF8: 0.0525 | DG8: 0.0525
C9: IPC C.A.B.A./ Nuevo contrato IPC INDEC | E9: 0.018 | F9: 0.016 | G9: 0.016 | H9: 0.015 | I9: 0.013 | J9: 0.033 | K9: 0.016 | L9: 0.026 | M9: 0.021 | N9: 0.03 | O9: 0.023 | P9: 0.037 | Q9: 0.027 | R9: 0.037 | S9: 0.06 | T9: 0.053 | U9: 0.028 | V9: 0.024 | W9: 0.038 | X9: 0.034 | Y9: 0.04 | Z9: 0.037 | AA9: 0.031 | AB9: 0.028 | AC9: 0.028 | AD9: 0.022 | AE9: 0.034 | AF9: 0.05 | AG9: 0.028 | AH9: 0.04 | AI9: 0.035 | AJ9: 0.024 | AK9: 0.018 | AL9: 0.027 | AM9: 0.02 | AN9: 0.01 | AO9: 0.014 | AP9: 0.016 | AQ9: 0.024 | AR9: 0.022 | AS9: 0.025 | AT9: 0.031 | AU9: 0.038 | AV9: 0.038 | AW9: 0.029 | AX9: 0.039 | AY9: 0.04 | AZ9: 0.036 | BA9: 0.032 | BB9: 0.029 | BC9: 0.029 | BD9: 0.034 | BE9: 0.037 | BF9: 0.025 | BG9: 0.038 | BH9: 0.04 | BI9: 0.041 | BJ9: 0.059 | BK9: 0.053 | BL9: 0.055 | BM9: 0.051 | BN9: 0.077 | BO9: 0.062 | BP9: 0.056 | BQ9: 0.07 | BR9: 0.058 | BT9: 0.058 | BU9: 0.073 | BV9: 0.06 | BW9: 0.071 | BX9: 0.078 | BY9: 0.075 | BZ9: 0.071 | CA9: 0.073 | CB9: 0.108 | CC9: 0.12 | CD9: 0.094 | CE9: 0.119 | CF9: 0.211 | CG9: 0.217 | CH9: 0.141 | CI9: 0.132 | CJ9: 0.098 | CK9: 0.044 | CL9: 0.048 | CM9: 0.051 | CO9: 0.042 | CP9: 0.04 | CQ9: 0.032 | CR9: 0.032 | CS9: 0.033 | CT9: 0.031 | CU9: 0.021 | CV9: 0.032 | CW9: 0.023 | CX9: 0.016 | CY9: 0.021 | CZ9: 0.025 | DA9: 0.016 | DB9: 0.022 | DC9: 0.022 | DD9: 0.024 | DE9: 0.027 | DF9: 0.031
C10: IPP Caucho | E10: 0.018 | F10: 0.018 | G10: 0.014 | H10: 0.009 | I10: 0.008 | J10: 0.019 | K10: 0.025 | L10: 0.04 | M10: 0.024 | N10: 0.016 | O10: 0.097 | P10: 0.078488053 | Q10: 0.041 | R10: 0.041 | S10: 0.181 | T10: 0.028 | U10: 0.006 | V10: 0.032 | W10: 0.013 | X10: 0.027 | Y10: 0.026 | Z10: 0.052 | AA10: 0.04 | AB10: 0.011 | AC10: 0.011 | AD10: 0.006 | AE10: 0.135 | AF10: 0.067 | AG10: 0.045 | AH10: 0.043 | AI10: 0.019 | AJ10: 0.017 | AK10: 0.011 | AL10: 0.014 | AM10: 0.011 | AN10: 0.049 | AO10: 0.025 | AP10: 0.046 | AQ10: 0.03 | AR10: 0.04 | AS10: 0.049 | AT10: 0.07 | AU10: 0.034 | AV10: 0.068 | AW10: 0.065 | AX10: 0.056 | AY10: 0.067 | AZ10: 0.041 | BA10: 0.034 | BB10: 0.036 | BC10: 0.027 | BD10: 0.018 | BE10: 0.029 | BF10: 0.044 | BG10: 0.027 | BH10: 0.031 | BI10: 0.04 | BJ10: 0.051 | BK10: 0.046 | BL10: 0.054 | BM10: 0.046 | BN10: 0.094 | BO10: 0.064 | BP10: 0.061 | BQ10: 0.07 | BR10: 0.057 | BT10: 0.061 | BU10: 0.064 | BV10: 0.062 | BW10: 0.063 | BX10: 0.069 | BY10: 0.081 | BZ10: 0.071 | CA10: 0.072 | CB10: 0.17 | CC10: 0.1 | CD10: 0.086 | CE10: 0.111 | CF10: 0.683 | CG10: 0.122 | CH10: 0.177 | CI10: 0.032 | CJ10: 0.015 | CK10: 0.002 | CL10: -0.004 | CM10: 0.004 | CO10: -0.001 | CP10: 0.027 | CQ10: 0.02 | CR10: 0.01 | CS10: -0.007 | CT10: 0.008 | CU10: 0.007 | CV10: 0.005 | CW10: 0.039 | CX10: 0.004 | CY10: 0.012 | CZ10: 0.03 | DA10: 0.032 | DB10: 0.04 | DC10: 0.012 | DD10: 0.014 | DE10: 0.01 | DF10: 0.012
C11: Monthly Inflation | E11: =+(E9+E10)/2 -> 0.018 | F11: =+(F9+F10)/2 -> 0.017 | G11: =+(G9+G10)/2 -> 0.015 | H11: =+(H9+H10)/2 -> 0.012 | I11: =+(I9+I10)/2 -> 0.0105 | J11: =+(J9+J10)/2 -> 0.026 | K11: =+(K9+K10)/2 -> 0.0205 | L11: =+(L9+L10)/2 -> 0.033 | ... AB11: =+(AB9+AB10)/2 -> 0.0195 | AC11: =+AB11 -> 0.0195 | AD11: =+(AD9+AD10)/2 -> 0.014 | AE11: =+(AE9+AE10)/2 -> 0.0845 | AF11: =+(AF9+AF10)/2 -> 0.0585 | AG11: =+(AG9+AG10)/2 -> 0.0365 | AH11: =+(AH9+AH10)/2 -> 0.0415 | AI11: =+(AI9+AI10)/2 -> 0.027 | AJ11: =+(AJ9+AJ10)/2 -> 0.0205 | AK11: =+(AK9+AK10)/2 -> 0.0145 | ... BR11: =+(BR9+BR10)/2 -> 0.0575 | BT11: =+(BT9+BT10)/2 -> 0.0595 | BU11: =+(BU9+BU10)/2 -> 0.0685 | BV11: =+(BV9+BV10)/2 -> 0.061 | BW11: =+(BW9+BW10)/2 -> 0.067 | BX11: =+(BX9+BX10)/2 -> 0.0735 | BY11: =+(BY9+BY10)/2 -> 0.078 | BZ11: =+(BZ9+BZ10)/2 -> 0.071 | CA11: =+(CA9+CA10)/2 -> 0.0725 | ... CM11: =+(CM9+CM10)/2 -> 0.0275 | CO11: =+(CO9+CO10)/2 -> 0.0205 | CP11: =+(CP9+CP10)/2 -> 0.0335 | CQ11: =+(CQ9+CQ10)/2 -> 0.026 | CR11: =+(CR9+CR10)/2 -> 0.021 | CS11: =+(CS9+CS10)/2 -> 0.013 | CT11: =+(CT9+CT10)/2 -> 0.0195 | CU11: =+(CU9+CU10)/2 -> 0.014 | CV11: =+(CV9+CV10)/2 -> 0.0185 | ... DF11: =+(DF9+DF10)/2 -> 0.0215
C12: Annual Inflation | P12: =+(((1+E$9)+(1+E$10))/2*((1+F$9)+(1+F$10))/2*((1+G$9)+(1+G$10))/2*((1+H$9)+(1+H$10))/2*((1+I$9)+(1+I$10))/2*((1+J$9)+(1+J$10))/2*((1+K$9)+(1+K$10))/2*((1+L$9)+(1+L$10))/2*((1+M$9)+(1+M$10))/2*((1+N$9)+(1+N$10))/2*((1+O$9)+(1+O$10))/2*((1+P$9)+(1+P$10))/2-1) -> 0.36313131 | V12: =+(((1+K$9)+(1+K$10))/2*((1+L$9)+(1+L$10))/2*((1+M$9)+(1+M$10))/2*((1+N$9)+(1+N$10))/2*((1+O$9)+(1+O$10))/2*((1+P$9)+(1+P$10))/2*((1+Q$9)+(1+Q$10))/2*((1+R$9)+(1+R$10))/2*((1+S$9)+(1+S$10))/2*((1+T$9)+(1+T$10))/2*((1+U$9)+(1+U$10))/2*((1+V$9)+(1+V$10))/2-1) -> 0.61898501 | AB12: =+(((1+Q$9)+(1+Q$10))/2*((1+R$9)+(1+R$10))/2*((1+S$9)+(1+S$10))/2*((1+T$9)+(1+T$10))/2*((1+U$9)+(1+U$10))/2*((1+V$9)+(1+V$10))/2*((1+W$9)+(1+W$10))/2*((1+X$9)+(1+X$10))/2*((1+Y$9)+(1+Y$10))/2*((1+Z$9)+(1+Z$10))/2*((1+AA$9)+(1+AA$10))/2*((1+AB$9)+(1+AB$10))/2-1) -> 0.57628179 | AH12: =+(((1+W$9)+(1+W$10))/2*((1+X$9)+(1+X$10))/2*((1+Y$9)+(1+Y$10))/2*((1+Z$9)+(1+Z$10))/2*((1+AA$9)+(1+AA$10))/2*((1+AB$9)+(1+AB$10))/2*((1+AC$9)+(1+AC$10))/2*((1+AD$9)+(1+AD$10))/2*((1+AE$9)+(1+AE$10))/2*((1+AF$9)+(1+AF$10))/2*((1+AG$9)+(1+AG$10))/2*((1+AH$9)+(1+AH$10))/2-1) -> 0.54206949 | AN12: =(1+AC11)*(1+AD11)*(1+AE11)*(1+AF11)*(1+AG11)*(1+AH11)*(1+AI11)*(1+AJ11)*(1+AK11)*(1+AL11)*(1+AM11)*(1+AN11)-1 -> 0.453212 | AT12: =(1+AI11)*(1+AJ11)*(1+AK11)*(1+AL11)*(1+AM11)*(1+AN11)*(1+AO11)*(1+AP11)*(1+AQ11)*(1+AR11)*(1+AS11)*(1+AT11)-1 -> 0.37532269 | AZ12: =(1+AO11)*(1+AP11)*(1+AQ11)*(1+AR11)*(1+AS11)*(1+AT11)*(1+AU11)*(1+AV11)*(1+AW11)*(1+AX11)*(1+AY11)*(1+AZ11)-1 -> 0.58701013 | BF12: =(1+AU11)*(1+AV11)*(1+AW11)*(1+AX11)*(1+AY11)*(1+AZ11)*(1+BA11)*(1+BB11)*(1+BC11)*(1+BD11)*(1+BE11)*(1+BF11)-1 -> 0.57358988 | BL12: =(1+BA11)*(1+BB11)*(1+BC11)*(1+BD11)*(1+BE11)*(1+BF11)*(1+BG11)*(1+BH11)*(1+BI11)*(1+BJ11)*(1+BK11)*(1+BL11)-1 -> 0.56144039 | BR12: =(1+BG11)*(1+BH11)*(1+BI11)*(1+BJ11)*(1+BK11)*(1+BL11)*(1+BM11)*(1+BN11)*(1+BO11)*(1+BP11)*(1+BQ11)*(1+BR11)-1 -> 0.88213286 | BY12: =(1+BM11)*(1+BN11)*(1+BO11)*(1+BP11)*(1+BQ11)*(1+BR11)*(1+BT11)*(1+BU11)*(1+BV11)*(1+BW11)*(1+BX11)*(1+BY11)-1 -> 1.1491298 | CE12: =(1+BT11)*(1+BU11)*(1+BV11)*(1+BW11)*(1+BX11)*(1+BY11)*(1+BZ11)*(1+CA11)*(1+CB11)*(1+CC11)*(1+CD11)*(1+CE11)-1 -> 1.6176462 | CF12: =(1+BU11)*(1+BV11)*(1+BW11)*(1+BX11)*(1+BY11)*(1+BZ11)*(1+CA11)*(1+CB11)*(1+CC11)*(1+CD11)*(1+CE11)*(1+CF11)-1 -> 2.5750203 | CG12: =(1+BV11)*(1+BW11)*(1+BX11)*(1+BY11)*(1+BZ11)*(1+CA11)*(1+CB11)*(1+CC11)*(1+CD11)*(1+CE11)*(1+CF11)*(1+CG11)-1 -> 2.9129492 | CH12: =(1+BW11)*(1+BX11)*(1+BY11)*(1+BZ11)*(1+CA11)*(1+CB11)*(1+CC11)*(1+CD11)*(1+CE11)*(1+CF11)*(1+CG11)*(1+CH11)-1 -> 3.2743715 | CI12: =(1+BX11)*(1+BY11)*(1+BZ11)*(1+CA11)*(1+CB11)*(1+CC11)*(1+CD11)*(1+CE11)*(1+CF11)*(1+CG11)*(1+CH11)*(1+CI11)-1 -> 3.334461 | CJ12: =(1+BY11)*(1+BZ11)*(1+CA11)*(1+CB11)*(1+CC11)*(1+CD11)*(1+CE11)*(1+CF11)*(1+CG11)*(1+CH11)*(1+CI11)*(1+CJ11)-1 -> 3.2658203 | CK12: =(1+BZ11)*(1+CA11)*(1+CB11)*(1+CC11)*(1+CD11)*(1+CE11)*(1+CF11)*(1+CG11)*(1+CH11)*(1+CI11)*(1+CJ11)*(1+CK11)-1 -> 3.0481764 | CL12: =(1+CA11)*(1+CB11)*(1+CC11)*(1+CD11)*(1+CE11)*(1+CF11)*(1+CG11)*(1+CH11)*(1+CI11)*(1+CJ11)*(1+CK11)*(1+CL11)-1 -> 2.8629657 | CM12: =(1+CB11)*(1+CC11)*(1+CD11)*(1+CE11)*(1+CF11)*(1+CG11)*(1+CH11)*(1+CI11)*(1+CJ11)*(1+CK11)*(1+CL11)*(1+CM11)-1 -> 2.7008832 | CO12: =(1+CD11)*(1+CE11)*(1+CF11)*(1+CG11)*(1+CH11)*(1+CI11)*(1+CJ11)*(1+CK11)*(1+CL11)*(1+CM11)*(1+CO11)-1 -> 1.9872508 | CP12: =(1+CE11)*(1+CF11)*(1+CG11)*(1+CH11)*(1+CI11)*(1+CJ11)*(1+CK11)*(1+CL11)*(1+CM11)*(1+CO11)*(1+CP11)-1 -> 1.8324071 | CQ12: =(1+CF11)*(1+CG11)*(1+CH11)*(1+CI11)*(1+CJ11)*(1+CK11)*(1+CL11)*(1+CM11)*(1+CN11)*(1+CP11)*(1+CQ11)-1 -> 1.5539663 | CR12: =(1+CG11)*(1+CH11)*(1+CI11)*(1+CJ11)*(1+CK11)*(1+CL11)*(1+CM11)*(1+CN11)*(1+CO11)*(1+CQ11)*(1+CR11)-1 -> 0.77940537 | CS12: =(1+CH11)*(1+CI11)*(1+CJ11)*(1+CK11)*(1+CL11)*(1+CM11)*(1+CN11)*(1+CO11)*(1+CP11)*(1+CR11)*(1+CS11)-1 -> 0.55255586 | CT12: =(1+CI11)*(1+CJ11)*(1+CK11)*(1+CL11)*(1+CM11)*(1+CN11)*(1+CO11)*(1+CP11)*(1+CQ11)*(1+CS11)*(1+CT11)-1 -> 0.37237453 | CU12: =(1+CJ11)*(1+CK11)*(1+CL11)*(1+CM11)*(1+CN11)*(1+CO11)*(1+CP11)*(1+CQ11)*(1+CR11)*(1+CT11)*(1+CU11)-1 -> 0.29628244 | CV12: =(1+CK11)*(1+CL11)*(1+CM11)*(1+CN11)*(1+CO11)*(1+CP11)*(1+CQ11)*(1+CR11)*(1+CS11)*(1+CU11)*(1+CV11)-1 -> 0.24169058 | CW12: =(1+CL11)*(1+CM11)*(1+CN11)*(1+CO11)*(1+CP11)*(1+CQ11)*(1+CR11)*(1+CS11)*(1+CT11)*(1+CV11)*(1+CW11)-1 -> 0.25818845 | ... CZ12: =(1+CO11)*(1+CP11)*(1+CQ11)*(1+CR11)*(1+CS11)*(1+CT11)*(1+CU11)*(1+CV11)*(1+CW11)*(1+CY11)*(1+CZ11)-1 -> 0.26893722 | DA12: =(1+CP11)*(1+CQ11)*(1+CR11)*(1+CS11)*(1+CT11)*(1+CU11)*(1+CV11)*(1+CW11)*(1+CX11)*(1+CY11)*(1+CZ11)*(1+DA11)-1 -> 0.28602217 | DB12: =(1+CQ11)*(1+CR11)*(1+CS11)*(1+CT11)*(1+CU11)*(1+CV11)*(1+CW11)*(1+CX11)*(1+CY11)*(1+CZ11)*(1+DA11)*(1+DB11)-1 -> 0.28291133 | DC12: =(1+CR11)*(1+CS11)*(1+CT11)*(1+CU11)*(1+CV11)*(1+CW11)*(1+CX11)*(1+CY11)*(1+CZ11)*(1+DA11)*(1+DB11)*(1+DC11)-1 -> 0.27165772 | DD12: =(1+CS11)*(1+CT11)*(1+CU11)*(1+CV11)*(1+CW11)*(1+CX11)*(1+CY11)*(1+CZ11)*(1+DA11)*(1+DB11)*(1+DC11)*(1+DD11)-1 -> 0.26916672 | DE12: =(1+CT11)*(1+CU11)*(1+CV11)*(1+CW11)*(1+CX11)*(1+CY11)*(1+CZ11)*(1+DA11)*(1+DB11)*(1+DC11)*(1+DD11)*(1+DE11)-1 -> 0.27605756 | DF12: =(1+CU11)*(1+CV11)*(1+CW11)*(1+CX11)*(1+CY11)*(1+CZ11)*(1+DA11)*(1+DB11)*(1+DC11)*(1+DD11)*(1+DE11)*(1+DF11)-1 -> 0.27856086
C13: Efficiency % | P13: =+IF(P12=0,0,IF(P12<=10%,50%,IF(P12<=20%,15%,10%))) -> 0.1 | V13: =+IF(V12=0,0,IF(V12<=10%,50%,IF(V12<=20%,15%,10%))) -> 0.1 | AB13: =+IF(AB12=0,0,IF(AB12<=10%,50%,IF(AB12<=20%,15%,10%))) -> 0.1 | AH13: =+IF(AH12=0,0,IF(AH12<=10%,50%,IF(AH12<=20%,15%,10%))) -> 0.1 | AN13: =+IF(AN12=0,0,IF(AN12<=10%,50%,IF(AN12<=20%,15%,10%))) -> 0.1 | AT13: =+IF(AT12=0,0,IF(AT12<=10%,50%,IF(AT12<=20%,15%,10%))) -> 0.1 | AZ13: =+IF(AZ12=0,0,IF(AZ12<=10%,50%,IF(AZ12<=20%,15%,10%))) -> 0.1 | BF13: =+IF(BF12=0,0,IF(BF12<=10%,50%,IF(BF12<=20%,15%,10%))) -> 0.1 | BL13: =+IF(BL12=0,0,IF(BL12<=10%,50%,IF(BL12<=20%,15%,10%))) -> 0.1 | BR13: =+IF(BR12=0,0,IF(BR12<=10%,50%,IF(BR12<=20%,15%,10%))) -> 0.1 | BY13: =+IF(BY12=0,0,IF(BY12<=10%,50%,IF(BY12<=20%,15%,10%))) -> 0.1 | CE13: =+IF(CE12=0,0,IF(CE12<=10%,50%,IF(CE12<=20%,15%,10%))) -> 0.1 | CF13: =+IF(CF12=0,0,IF(CF12<=10%,50%,IF(CF12<=20%,15%,10%))) -> 0.1 | CG13: =+IF(CG12=0,0,IF(CG12<=10%,50%,IF(CG12<=20%,15%,10%))) -> 0.1 | CH13: =+IF(CH12=0,0,IF(CH12<=10%,50%,IF(CH12<=20%,15%,10%))) -> 0.1 | CI13: =+IF(CI12=0,0,IF(CI12<=10%,50%,IF(CI12<=20%,15%,10%))) -> 0.1 | CJ13: =+IF(CJ12=0,0,IF(CJ12<=10%,50%,IF(CJ12<=20%,15%,10%))) -> 0.1 | CK13: =+IF(CK12=0,0,IF(CK12<=10%,50%,IF(CK12<=20%,15%,10%))) -> 0.1 | CL13: =+IF(CL12=0,0,IF(CL12<=10%,50%,IF(CL12<=20%,15%,10%))) -> 0.1
C14: Accumulated Inflation | Q14: =+((1+$K$11)*(1+$L$11)*(1+$M$11)*(1+$N$11)*(1+$O$11)*(1+$P$11)-1)*(1-$P$13) -> 0.21270807 | R14: =+Q14 -> 0.21270807 | S14: =+R14 -> 0.21270807 | T14: =+S14 -> 0.21270807 | U14: =+T14 -> 0.21270807 | V14: =+U14 -> 0.21270807 | W14: =(1+$Q$14)*((((1+$Q$11)*(1+$R$11)*(1+$S$11)*(1+$T$11)*(1+$U$11)*(1+$V$11)-1)*(1-$V$13))+1)-1 -> 0.55050328 | X14: =(1+$Q$14)*((((1+$Q$11)*(1+$R$11)*(1+$S$11)*(1+$T$11)*(1+$U$11)*(1+$V$11)-1)*(1-$V$13))+1)-1 -> 0.55050328 | Y14: =(1+$Q$14)*((((1+$Q$11)*(1+$R$11)*(1+$S$11)*(1+$T$11)*(1+$U$11)*(1+$V$11)-1)*(1-$V$13))+1)-1 -> 0.55050328 | Z14: =(1+$Q$14)*((((1+$Q$11)*(1+$R$11)*(1+$S$11)*(1+$T$11)*(1+$U$11)*(1+$V$11)-1)*(1-$V$13))+1)-1 -> 0.55050328 | AA14: =(1+$Q$14)*((((1+$Q$11)*(1+$R$11)*(1+$S$11)*(1+$T$11)*(1+$U$11)*(1+$V$11)-1)*(1-$V$13))+1)-1 -> 0.55050328 | AB14: =(1+$Q$14)*((((1+$Q$11)*(1+$R$11)*(1+$S$11)*(1+$T$11)*(1+$U$11)*(1+$V$11)-1)*(1-$V$13))+1)-1 -> 0.55050328 | AC14: =+AB14 -> 0.55050328 | AD14: =(1+$W$14)*((((1+$W$11)*(1+$X$11)*(1+$Y$11)*(1+$Z$11)*(1+$AA$11)*(1+$AB$11)-1)*(1-$AB$13))+1)-1 -> 0.83480153 | AE14: =+AD14 -> 0.83480153 | AF14: =+AE14 -> 0.83480153 | AG14: =+AF14 -> 0.83480153 | AH14: =+AG14 -> 0.83480153 | AI14: =(1+$AH$14)*((((1+$AC$11)*(1+$AD$11)*(1+$AE$11)*(1+$AF$11)*(1+$AG$11)*(1+$AH$11)-1)*(1-$AH$13))+1)-1 -> 1.2989449 | AJ14: =(1+$AH$14)*((((1+$AC$11)*(1+$AD$11)*(1+$AE$11)*(1+$AF$11)*(1+$AG$11)*(1+$AH$11)-1)*(1-$AH$13))+1)-1 -> 1.2989449 | AK14: =(1+$AH$14)*((((1+$AC$11)*(1+$AD$11)*(1+$AE$11)*(1+$AF$11)*(1+$AG$11)*(1+$AH$11)-1)*(1-$AH$13))+1)-1 -> 1.2989449 | AL14: =(1+$AH$14)*((((1+$AC$11)*(1+$AD$11)*(1+$AE$11)*(1+$AF$11)*(1+$AG$11)*(1+$AH$11)-1)*(1-$AH$13))+1)-1 -> 1.2989449 | AM14: =(1+$AH$14)*((((1+$AC$11)*(1+$AD$11)*(1+$AE$11)*(1+$AF$11)*(1+$AG$11)*(1+$AH$11)-1)*(1-$AH$13))+1)-1 -> 1.2989449 | AN14: =(1+$AH$14)*((((1+$AC$11)*(1+$AD$11)*(1+$AE$11)*(1+$AF$11)*(1+$AG$11)*(1+$AH$11)-1)*(1-$AH$13))+1)-1 -> 1.2989449 | AO14: =(1+$AN$14)*((((1+$AI$11)*(1+$AJ$11)*(1+$AK$11)*(1+$AL$11)*(1+$AM$11)*(1+$AN$11)-1)*(1-$AN$13))+1)-1 -> 1.5769635 | AP14: =(1+$AN$14)*((((1+$AI$11)*(1+$AJ$11)*(1+$AK$11)*(1+$AL$11)*(1+$AM$11)*(1+$AN$11)-1)*(1-$AN$13))+1)-1 -> 1.5769635 | AQ14: =(1+$AN$14)*((((1+$AI$11)*(1+$AJ$11)*(1+$AK$11)*(1+$AL$11)*(1+$AM$11)*(1+$AN$11)-1)*(1-$AN$13))+1)-1 -> 1.5769635 | AR14: =(1+$AN$14)*((((1+$AI$11)*(1+$AJ$11)*(1+$AK$11)*(1+$AL$11)*(1+$AM$11)*(1+$AN$11)-1)*(1-$AN$13))+1)-1 -> 1.5769635 | AS14: =(1+$AN$14)*((((1+$AI$11)*(1+$AJ$11)*(1+$AK$11)*(1+$AL$11)*(1+$AM$11)*(1+$AN$11)-1)*(1-$AN$13))+1)-1 -> 1.5769635 | AT14: =(1+$AN$14)*((((1+$AI$11)*(1+$AJ$11)*(1+$AK$11)*(1+$AL$11)*(1+$AM$11)*(1+$AN$11)-1)*(1-$AN$13))+1)-1 -> 1.5769635 | AU14: =(1+$AT$14)*((((1+$AO$11)*(1+$AP$11)*(1+$AQ$11)*(1+$AR$11)*(1+$AS$11)*(1+$AT$11)-1)*(1-$AT$13))+1)-1 -> 2.069601 | AV14: =(1+$AT$14)*((((1+$AO$11)*(1+$AP$11)*(1+$AQ$11)*(1+$AR$11)*(1+$AS$11)*(1+$AT$11)-1)*(1-$AT$13))+1)-1 -> 2.069601 | AW14: =(1+$AT$14)*((((1+$AO$11)*(1+$AP$11)*(1+$AQ$11)*(1+$AR$11)*(1+$AS$11)*(1+$AT$11)-1)*(1-$AT$13))+1)-1 -> 2.069601 | AX14: =(1+$AT$14)*((((1+$AO$11)*(1+$AP$11)*(1+$AQ$11)*(1+$AR$11)*(1+$AS$11)*(1+$AT$11)-1)*(1-$AT$13))+1)-1 -> 2.069601 | AY14: =(1+$AT$14)*((((1+$AO$11)*(1+$AP$11)*(1+$AQ$11)*(1+$AR$11)*(1+$AS$11)*(1+$AT$11)-1)*(1-$AT$13))+1)-1 -> 2.069601 | AZ14: =(1+$AT$14)*((((1+$AO$11)*(1+$AP$11)*(1+$AQ$11)*(1+$AR$11)*(1+$AS$11)*(1+$AT$11)-1)*(1-$AT$13))+1)-1 -> 2.069601 | BA14: =(1+$AZ$14)*((((1+$AU$11)*(1+$AV$11)*(1+$AW$11)*(1+$AX$11)*(1+$AY$11)*(1+$AZ$11)-1)*(1-$AZ$13))+1)-1 -> 2.9231757 | BB14: =(1+$AZ$14)*((((1+$AU$11)*(1+$AV$11)*(1+$AW$11)*(1+$AX$11)*(1+$AY$11)*(1+$AZ$11)-1)*(1-$AZ$13))+1)-1 -> 2.9231757 | BC14: =(1+$AZ$14)*((((1+$AU$11)*(1+$AV$11)*(1+$AW$11)*(1+$AX$11)*(1+$AY$11)*(1+$AZ$11)-1)*(1-$AZ$13))+1)-1 -> 2.9231757 | BD14: =(1+$AZ$14)*((((1+$AU$11)*(1+$AV$11)*(1+$AW$11)*(1+$AX$11)*(1+$AY$11)*(1+$AZ$11)-1)*(1-$AZ$13))+1)-1 -> 2.9231757 | BE14: =(1+$AZ$14)*((((1+$AU$11)*(1+$AV$11)*(1+$AW$11)*(1+$AX$11)*(1+$AY$11)*(1+$AZ$11)-1)*(1-$AZ$13))+1)-1 -> 2.9231757 | BF14: =(1+$AZ$14)*((((1+$AU$11)*(1+$AV$11)*(1+$AW$11)*(1+$AX$11)*(1+$AY$11)*(1+$AZ$11)-1)*(1-$AZ$13))+1)-1 -> 2.9231757 | BG14: =(1+$BF$14)*((((1+$BA$11)*(1+$BB$11)*(1+$BC$11)*(1+$BD$11)*(1+$BE$11)*(1+$BF$11)-1)*(1-$BF$13))+1)-1 -> 3.6369682 | BH14: =(1+$BF$14)*((((1+$BA$11)*(1+$BB$11)*(1+$BC$11)*(1+$BD$11)*(1+$BE$11)*(1+$BF$11)-1)*(1-$BF$13))+1)-1 -> 3.6369682 | BI14: =(1+$BF$14)*((((1+$BA$11)*(1+$BB$11)*(1+$BC$11)*(1+$BD$11)*(1+$BE$11)*(1+$BF$11)-1)*(1-$BF$13))+1)-1 -> 3.6369682 | BJ14: =(1+$BF$14)*((((1+$BA$11)*(1+$BB$11)*(1+$BC$11)*(1+$BD$11)*(1+$BE$11)*(1+$BF$11)-1)*(1-$BF$13))+1)-1 -> 3.6369682 | BK14: =(1+$BF$14)*((((1+$BA$11)*(1+$BB$11)*(1+$BC$11)*(1+$BD$11)*(1+$BE$11)*(1+$BF$11)-1)*(1-$BF$13))+1)-1 -> 3.6369682 | BL14: =(1+$BF$14)*((((1+$BA$11)*(1+$BB$11)*(1+$BC$11)*(1+$BD$11)*(1+$BE$11)*(1+$BF$11)-1)*(1-$BF$13))+1)-1 -> 3.6369682 | BM14: =(1+$BL$14)*((((1+$BG$11)*(1+$BH$11)*(1+$BI$11)*(1+$BJ$11)*(1+$BK$11)*(1+$BL$11)-1)*(1-$BL$13))+1)-1 -> 4.8842094 | BN14: =(1+$BL$14)*((((1+$BG$11)*(1+$BH$11)*(1+$BI$11)*(1+$BJ$11)*(1+$BK$11)*(1+$BL$11)-1)*(1-$BL$13))+1)-1 -> 4.8842094 | BO14: =(1+$BL$14)*((((1+$BG$11)*(1+$BH$11)*(1+$BI$11)*(1+$BJ$11)*(1+$BK$11)*(1+$BL$11)-1)*(1-$BL$13))+1)-1 -> 4.8842094 | BP14: =(1+$BL$14)*((((1+$BG$11)*(1+$BH$11)*(1+$BI$11)*(1+$BJ$11)*(1+$BK$11)*(1+$BL$11)-1)*(1-$BL$13))+1)-1 -> 4.8842094 | BQ14: =(1+$BL$14)*((((1+$BG$11)*(1+$BH$11)*(1+$BI$11)*(1+$BJ$11)*(1+$BK$11)*(1+$BL$11)-1)*(1-$BL$13))+1)-1 -> 4.8842094 | BR14: =(1+$BL$14)*((((1+$BG$11)*(1+$BH$11)*(1+$BI$11)*(1+$BJ$11)*(1+$BK$11)*(1+$BL$11)-1)*(1-$BL$13))+1)-1 -> 4.8842094 | BT14: =(1+$BR$14)*((((1+$BM$11)*(1+$BN$11)*(1+$BO$11)*(1+$BP$11)*(1+$BQ$11)*(1+$BR$11)-1)*(1-$BR$13))+1)-1 -> 7.2623393 | BU14: =(1+$BR$14)*((((1+$BM$11)*(1+$BN$11)*(1+$BO$11)*(1+$BP$11)*(1+$BQ$11)*(1+$BR$11)-1)*(1-$BR$13))+1)-1 -> 7.2623393 | BV14: =(1+$BR$14)*((((1+$BM$11)*(1+$BN$11)*(1+$BO$11)*(1+$BP$11)*(1+$BQ$11)*(1+$BR$11)-1)*(1-$BR$13))+1)-1 -> 7.2623393 | BW14: =(1+$BR$14)*((((1+$BM$11)*(1+$BN$11)*(1+$BO$11)*(1+$BP$11)*(1+$BQ$11)*(1+$BR$11)-1)*(1-$BR$13))+1)-1 -> 7.2623393 | BX14: =(1+$BR$14)*((((1+$BM$11)*(1+$BN$11)*(1+$BO$11)*(1+$BP$11)*(1+$BQ$11)*(1+$BR$11)-1)*(1-$BR$13))+1)-1 -> 7.2623393 | BY14: =(1+$BR$14)*((((1+$BM$11)*(1+$BN$11)*(1+$BO$11)*(1+$BP$11)*(1+$BQ$11)*(1+$BR$11)-1)*(1-$BR$13))+1)-1 -> 7.2623393 | BZ14: =(1+$BY$14)*((((1+$BT$11)*(1+$BU$11)*(1+$BV$11)*(1+$BW$11)*(1+$BX$11)*(1+$BY$11)-1)*(1-$BY$13))+1)-1 -> 10.854866 | CA14: =(1+$BY$14)*((((1+$BT$11)*(1+$BU$11)*(1+$BV$11)*(1+$BW$11)*(1+$BX$11)*(1+$BY$11)-1)*(1-$BY$13))+1)-1 -> 10.854866 | CB14: =(1+$BY$14)*((((1+$BT$11)*(1+$BU$11)*(1+$BV$11)*(1+$BW$11)*(1+$BX$11)*(1+$BY$11)-1)*(1-$BY$13))+1)-1 -> 10.854866 | CC14: =(1+$BY$14)*((((1+$BT$11)*(1+$BU$11)*(1+$BV$11)*(1+$BW$11)*(1+$BX$11)*(1+$BY$11)-1)*(1-$BY$13))+1)-1 -> 10.854866 | CD14: =(1+$BY$14)*((((1+$BT$11)*(1+$BU$11)*(1+$BV$11)*(1+$BW$11)*(1+$BX$11)*(1+$BY$11)-1)*(1-$BY$13))+1)-1 -> 10.854866 | CE14: =(1+$BY$14)*((((1+$BT$11)*(1+$BU$11)*(1+$BV$11)*(1+$BW$11)*(1+$BX$11)*(1+$BY$11)-1)*(1-$BY$13))+1)-1 -> 10.854866 | CF14: =(1+$CE$14)*((((1+$BZ$11)*(1+$CA$11)*(1+$CB$11)*(1+$CC$11)*(1+$CD$11)*(1+$CE$11)-1)*(1-$CE$13))+1)-1 -> 19.016513 | CG14: =+CF14*(1+(CF11*(1-CF13))) -> 26.666856 | CH14: =+CG14*(1+(CG11*(1-CG13))) -> 30.734885 | CI14: =+CH14*(1+(CH11*(1-CH13))) -> 35.133047 | CJ14: =+CI14*(1+(CI11*(1-CI13))) -> 37.725865 | CK14: =+CJ14*(1+(CJ11*(1-CJ13))) -> 39.644226 | CL14: =+CK14*(1+(CK11*(1-CK13))) -> 40.464861 | CM14: =+CL14*(1+(CL11*(1-CL13))) -> 41.266065 | CO14: =1*(1+(CM11))-1 -> 0.0275 | CP14: =1*(1+(CO11))-1 -> 0.0205 | CQ14: =1*(1+(CP11))-1 -> 0.0335 | CR14: =1*(1+(CQ11))-1 -> 0.026 | CS14: =1*(1+(CR11))-1 -> 0.021 | CT14: =1*(1+(CS11))-1 -> 0.013 | CU14: =1*(1+(CT11))-1 -> 0.0195 | CV14: =1*(1+(CU11))-1 -> 0.014 | CW14: =1*(1+(CV11))-1 -> 0.0185 | ... DG14: =1*(1+(DF11))-1 -> 0.0215
BT15: =1+(((1+BT11)-1)) -> 1.0595 | BU15: =1+(((1+BU11)-1)) -> 1.0685 | BV15: =1+(((1+BV11)-1)) -> 1.061 | BW15: =1+(((1+BW11)-1)) -> 1.067 | BX15: =1+(((1+BX11)-1)) -> 1.0735 | BY15: =1+(((1+BY11)-1)) -> 1.078 | BZ15: =1+(((1+BZ11)-1)) -> 1.071 | CA15: =1+(((1+CA11)-1)) -> 1.0725 | ... CM15: =1+(((1+CM11)-1)) -> 1.0275 | CO15: =1+(((1+CO11)-1)) -> 1.0205 | CP15: =1+(((1+CP11)-1)) -> 1.0335 | CQ15: =1+(((1+CQ11)-1)) -> 1.026 | CR15: =1+(((1+CR11)-1)) -> 1.021 | CS15: =1+(((1+CS11)-1)) -> 1.013 | CT15: =1+(((1+CT11)-1)) -> 1.0195 | CU15: =1+(((1+CU11)-1)) -> 1.014 | CV15: =1+(((1+CV11)-1)) -> 1.0185 | ... DG15: =1+(((1+DG11)-1)) -> 1
A16: 17.4 | C16: FX Rate | K16: 18.6678 | L16: 19.6378 | M16: 20.2008 | N16: 20.1883 | O16: 22.3873 | P16: 25.5732 | Q16: 27.6313 | R16: 28.1558 | S16: 36.0401 | T16: 37.7419 | U16: 36.0974 | V16: 37.6768 | W16: 37.540588 | X16: 37.8426 | Y16: 40.278833 | Z16: 42.7495 | AA16: 44.6298 | AB16: 44.5014 | AC16: =+AB16 -> 44.5014 | AD16: 42.3633 | AE16: 57.9 | AF16: 56.3589 | AG16: 60 | AH16: 59.85 | AI16: 59.815 | AJ16: 60.35 | AK16: 62.21 | AL16: 64.409 | AM16: 66.84 | AN16: 68.54 | AO16: 70.46 | AP16: 72.32 | AQ16: 74.18 | AR16: 76.18 | AS16: 78.32 | AT16: 81.31 | AU16: 84.15 | AV16: 87.33 | AW16: 89.82 | AX16: 92 | AY16: 93.56 | AZ16: 94.73 | BA16: 95.72 | BB16: 96.69 | BC16: 97.74 | BD16: 98.74 | BE16: 99.72 | BF16: 100.96 | BG16: 102.72 | BH16: 105.02 | BI16: 107.45 | BJ16: 110.89 | BK16: 115.73 | BL16: 120.2 | BM16: 125.45 | BN16: 132.42 | BO16: 141.15 | BP16: 150.69 | BQ16: 157.28 | BR16: 166.96 | BT16: 176.05 | BU16: 187.57 | BV16: 197.15 | BW16: 211.22 | BX16: 225.2 | BY16: 240.25 | BZ16: 257.9 | CA16: 276.15 | CB16: 350.1 | CC16: 350 | CD16: 350 | CE16: 361.1 | CF16: 807.95 | CG16: 825.7 | CH16: 848 | CI16: 858 | CJ16: 890.5 | CK16: 907.5 | CL16: 914.5 | CM16: 931.5 | CO16: 953.5 | CP16: 975.5 | CQ16: 998 | CR16: 1013 | CS16: 1035.5 | CT16: 1054.75 | CU16: 1064.5 | CV16: 1076 | CW16: 1170 | CX16: 1188 | CY16: 1205 | CZ16: 1374 | DA16: 1342 | DB16: 1401.7 | DC16: 1434.43 | DD16: 1428.15 | DE16: 1447.5789 | DF16: 1448.9524 | DG16: 1407.5
C17: Type | D17: Wgt | K17: AR$ | L17: AR$ | M17: AR$ | N17: AR$ | O17: AR$ | P17: AR$ | Q17: AR$ | R17: AR$ | S17: AR$ | T17: AR$ | U17: AR$ | V17: AR$ | W17: AR$ | X17: AR$ | Y17: AR$ | Z17: AR$ | AA17: AR$ | AB17: AR$ | AC17: =+AB17 -> AR$ | AD17: AR$ | AE17: AR$ | AF17: AR$ | AG17: AR$ | AH17: AR$ | AI17: AR$ | AJ17: AR$ | AK17: AR$ | AL17: AR$ | AM17: AR$ | AN17: AR$ | AO17: AR$ | AP17: AR$ | AQ17: AR$ | AR17: AR$ | AS17: AR$ | AT17: AR$ | AU17: AR$ | AV17: AR$ | AW17: AR$ | AX17: AR$ | AY17: AR$ | AZ17: AR$ | BA17: AR$ | BB17: AR$ | BC17: AR$ | BD17: AR$ | BE17: AR$ | BF17: AR$ | BG17: AR$ | BH17: AR$ | BI17: AR$ | BJ17: AR$ | BK17: AR$ | BL17: AR$ | BM17: AR$ | BN17: AR$ | BO17: AR$ | BP17: AR$ | BQ17: AR$ | BR17: AR$ | BT17: AR$ | BU17: AR$ | BV17: AR$ | BW17: AR$ | BX17: AR$ | BY17: AR$ | BZ17: AR$ | CA17: AR$ | CB17: AR$ | CC17: AR$ | CD17: AR$ | CE17: AR$ | CF17: AR$ | CG17: AR$ | CH17: AR$ | CI17: AR$ | CJ17: AR$ | CK17: AR$ | CL17: AR$ | CM17: AR$ | CO17: AR$ | CP17: AR$ | CQ17: AR$ | CR17: AR$ | CS17: AR$ | CT17: AR$ | CU17: AR$ | CV17: AR$ | CW17: AR$ | CX17: AR$ | CY17: AR$ | CZ17: AR$ | DA17: AR$ | DB17: AR$ | DC17: AR$ | DD17: AR$ | DE17: AR$ | DF17: AR$ | DG17: AR$
C18: Resina
C19: SS 250 | D19: 12.5 | BT19: =((+(7*BT$3*(1+BT$7)*0/1000*(1+BT$8))+(95%*$D19*BT$3*(1+BT$7)/1000*(1+BT$8))+(5%*$D19*BT$4*(1+BT$7)/1000*(1+BT$8)))*BT$16) -> 4387.6516 | BU19: =((+(7*BU$3*(1+BU$7)*0/1000*(1+BU$8))+(95%*$D19*BU$3*(1+BU$7)/1000*(1+BU$8))+(5%*$D19*BU$4*(1+BU$7)/1000*(1+BU$8)))*BU$16) -> 4641.1079 | BV19: =((95%*$D19*BV$3*(1+BV$7)/1000*(1+BV$8))+(5%*$D19*BV$4*(1+BV$7)/1000*(1+BV$8)))*BV$16 -> 4820.8229 | BW19: =((95%*$D19*BW$3*(1+BW$7)/1000*(1+BW$8))+(5%*$D19*BW$4*(1+BW$7)/1000*(1+BW$8)))*BW$16 -> 5239.272 | BX19: =((95%*$D19*BX$3*(1+BX$7)/1000*(1+BX$8))+(5%*$D19*BX$4*(1+BX$7)/1000*(1+BX$8)))*BX$16 -> 5602.6568 | BY19: =((95%*$D19*BY$3*(1+BY$7)/1000*(1+BY$8))+(5%*$D19*BY$4*(1+BY$7)/1000*(1+BY$8)))*BY$16 -> 6148.9146 | BZ19: =((95%*$D19*BZ$3*(1+BZ$7)/1000*(1+BZ$8))+(5%*$D19*BZ$4*(1+BZ$7)/1000*(1+BZ$8)))*BZ$16 -> 6304.7614 | CA19: =((95%*$D19*CA$3*(1+CA$7)/1000*(1+CA$8))+(5%*$D19*CA$4*(1+CA$7)/1000*(1+CA$8)))*CA$16 -> 6525.0501 | CB19: =((95%*$D19*CB$3*(1+CB$7)/1000*(1+CB$8))+(5%*$D19*CB$4*(1+CB$7)/1000*(1+CB$8)))*CB$16 -> 7474.4767 | CC19: =((95%*$D19*CC$3*(1+CC$7)/1000*(1+CC$8))+(5%*$D19*CC$4*(1+CC$7)/1000*(1+CC$8)))*CC$16 -> 7707.0649 | ... CM19: =((95%*$D19*CM$3*(1+CM$7)/1000*(1+CM$8))+(5%*$D19*CM$4*(1+CM$7)/1000*(1+CM$8)))*CM$16 -> 22838.909 | CO19: =((95%*$D19*CO$3*(1+CO$7)/1000*(1+CO$8))+(5%*$D19*CO$4*(1+CO$7)/1000*(1+CO$8)))*CO$16 -> 26984.047 | CP19: =((95%*$D19*CP$3*(1+CP$7)/1000*(1+CP$8))+(5%*$D19*CP$4*(1+CP$7)/1000*(1+CP$8)))*CP$16 -> 19831.707 | CQ19: =((95%*$D19*CQ$3*(1+CQ$7)/1000*(1+CQ$8))+(5%*$D19*CQ$4*(1+CQ$7)/1000*(1+CQ$8)))*CQ$16 -> 23520.493 | CR19: =((95%*$D19*CR$3*(1+CR$7)/1000*(1+CR$8))+(5%*$D19*CR$4*(1+CR$7)/1000*(1+CR$8)))*CR$16 -> 24888.513 | CS19: =((95%*$D19*CS$3*(1+CS$7)/1000*(1+CS$8))+(5%*$D19*CS$4*(1+CS$7)/1000*(1+CS$8)))*CS$16 -> 25706.709 | CT19: =((95%*$D19*CT$3*(1+CT$7)/1000*(1+CT$8))+(5%*$D19*CT$4*(1+CT$7)/1000*(1+CT$8)))*CT$16 -> 26038.578 | CU19: =((95%*$D19*CU$3*(1+CU$7)/1000*(1+CU$8))+(5%*$D19*CU$4*(1+CU$7)/1000*(1+CU$8)))*CU$16 -> 25943.838 | CV19: =((95%*$D19*CV$3*(1+CV$7)/1000*(1+CV$8))+(5%*$D19*CV$4*(1+CV$7)/1000*(1+CV$8)))*CV$16 -> 26002.967 | ... DG19: =((95%*$D19*DG$3*(1+DG$7)/1000*(1+DG$8))+(5%*$D19*DG$4*(1+DG$7)/1000*(1+DG$8)))*DG$16 -> 30215.62
C20: SS 500 | D20: 19.5 | BT20: =((3.14*BT$3*(1+BT$7)*0/1000*(1+BT$8))+($D20*BT$3*(1+BT$7)/1000*(1+BT$8)))*BT$16 -> 5564.8603 | BU20: =((3.14*BU$3*(1+BU$7)*0/1000*(1+BU$8))+($D20*BU$3*(1+BU$7)/1000*(1+BU$8)))*BU$16 -> 5873.739 | BV20: =(($D20*BV$3*(1+BV$7)/1000*(1+BV$8)))*BV$16 -> 6079.6003 | BW20: =(($D20*BW$3*(1+BW$7)/1000*(1+BW$8)))*BW$16 -> 6635.6583 | BX20: =(($D20*BX$3*(1+BX$7)/1000*(1+BX$8)))*BX$16 -> 7102.1331 | BY20: =(($D20*BY$3*(1+BY$7)/1000*(1+BY$8)))*BY$16 -> 7858.9365 | BZ20: =(($D20*BZ$3*(1+BZ$7)/1000*(1+BZ$8)))*BZ$16 -> 7950.4214 | CA20: =(($D20*CA$3*(1+CA$7)/1000*(1+CA$8)))*CA$16 -> 8142.1372 | CB20: =(($D20*CB$3*(1+CB$7)/1000*(1+CB$8)))*CB$16 -> 9012.259 | CC20: =(($D20*CC$3*(1+CC$7)/1000*(1+CC$8)))*CC$16 -> 9395.1251 | ... CL20: =(($D20*CL$3*(1+CL$7)/1000*(1+CL$8)))*CL$16 -> 28299.701 | CM20: 28825.807 | CO20: =(($D20*CO$3*(1+CO$7)/1000*(1+CO$8)))*CO$16 -> 35427.603 | CP20: =(($D20*CP$3*(1+CP$7)/1000*(1+CP$8)))*CP$16 -> 23477.75 | CQ20: =(($D20*CQ$3*(1+CQ$7)/1000*(1+CQ$8)))*CQ$16 -> 29325.509 | CR20: =(($D20*CR$3*(1+CR$7)/1000*(1+CR$8)))*CR$16 -> 31434.036 | CS20: =(($D20*CS$3*(1+CS$7)/1000*(1+CS$8)))*CS$16 -> 32568.025 | CT20: =(($D20*CT$3*(1+CT$7)/1000*(1+CT$8)))*CT$16 -> 32933.686 | CU20: =(($D20*CU$3*(1+CU$7)/1000*(1+CU$8)))*CU$16 -> 32687.298 | CV20: =(($D20*CV$3*(1+CV$7)/1000*(1+CV$8)))*CV$16 -> 32677.279 | ... DG20: =(($D20*DG$3*(1+DG$7)/1000*(1+DG$8)))*DG$16 -> 36507.163
C21: SS 500 - 19.5G PCR 100% | D21: 19.5 | CF21: =(($D21*CF$6*(1+CF$7)/1000*(1+CF$8)))*CF$16 -> 0 | CG21: =(($D21*CG$6*(1+CG$7)/1000*(1+CG$8)))*CG$16 -> 41734.549 | CH21: =(($D21*CH$6*(1+CH$7)/1000*(1+CH$8)))*CH$16 -> 42861.69 | CI21: =(($D21*CI$6*(1+CI$7)/1000*(1+CI$8)))*CI$16 -> 43367.135 | CJ21: =(($D21*CJ$6*(1+CJ$7)/1000*(1+CJ$8)))*CJ$16 -> 45009.829 | CK21: =(($D21*CK$6*(1+CK$7)/1000*(1+CK$8)))*CK$16 -> 45869.085 | CL21: =(($D21*CL$6*(1+CL$7)/1000*(1+CL$8)))*CL$16 -> 46222.896 | CM21: 47082.152 | CO21: =(($D21*CO$6*(1+CO$7)/1000*(1+CO$8)))*CO$16 -> 35427.603 | CP21: =(($D21*CP$6*(1+CP$7)/1000*(1+CP$8)))*CP$16 -> 23477.75 | CQ21: =(($D21*CQ$6*(1+CQ$7)/1000*(1+CQ$8)))*CQ$16 -> 29325.509 | CR21: =(($D21*CR$6*(1+CR$7)/1000*(1+CR$8)))*CR$16 -> 31434.036 | CS21: =(($D21*CS$6*(1+CS$7)/1000*(1+CS$8)))*CS$16 -> 32568.025 | CT21: =(($D21*CT$6*(1+CT$7)/1000*(1+CT$8)))*CT$16 -> 32933.686 | CU21: =(($D21*CU$6*(1+CU$7)/1000*(1+CU$8)))*CU$16 -> 32687.298 | CV21: =(($D21*CV$6*(1+CV$7)/1000*(1+CV$8)))*CV$16 -> 32677.279 | ... DG21: =(($D21*DG$6*(1+DG$7)/1000*(1+DG$8)))*DG$16 -> 36507.163
C22: SS 500 | D22: 22.1 | BT22: =+($D22*BT$3*(1+BT$7)/1000*(1+BT$8))*BT$16 -> 6306.8416 | BU22: =+($D22*BU$3*(1+BU$7)/1000*(1+BU$8))*BU$16 -> 6656.9042 | BV22: =+($D22*BV$3*(1+BV$7)/1000*(1+BV$8))*BV$16 -> 6890.2137 | BW22: =+($D22*BW$3*(1+BW$7)/1000*(1+BW$8))*BW$16 -> 7520.4127 | BX22: =+($D22*BX$3*(1+BX$7)/1000*(1+BX$8))*BX$16 -> 8049.0842 | BY22: =+($D22*BY$3*(1+BY$7)/1000*(1+BY$8))*BY$16 -> 8906.7947 | BZ22: =+($D22*BZ$3*(1+BZ$7)/1000*(1+BZ$8))*BZ$16 -> 9010.4776 | CA22: =+($D22*CA$3*(1+CA$7)/1000*(1+CA$8))*CA$16 -> 9227.7555 | ... CL22: =+($D22*CL$3*(1+CL$7)/1000*(1+CL$8))*CL$16 -> 32072.995 | CM22: 32669.248 | CO22: =+($D22*CO$3*(1+CO$7)/1000*(1+CO$8))*CO$16 -> 40151.283 | CP22: =+($D22*CP$3*(1+CP$7)/1000*(1+CP$8))*CP$16 -> 26608.117 | CQ22: =+($D22*CQ$3*(1+CQ$7)/1000*(1+CQ$8))*CQ$16 -> 33235.577 | CR22: =+($D22*CR$3*(1+CR$7)/1000*(1+CR$8))*CR$16 -> 35625.241 | CS22: =+($D22*CS$3*(1+CS$7)/1000*(1+CS$8))*CS$16 -> 36910.429 | CT22: =+($D22*CT$3*(1+CT$7)/1000*(1+CT$8))*CT$16 -> 37324.845 | CU22: =+($D22*CU$3*(1+CU$7)/1000*(1+CU$8))*CU$16 -> 37045.605 | CV22: =+($D22*CV$3*(1+CV$7)/1000*(1+CV$8))*CV$16 -> 37034.249 | ... DG22: =+($D22*DG$3*(1+DG$7)/1000*(1+DG$8))*DG$16 -> 41374.785
C23: SS 500 | D23: 22 | BT23: =+($D23*BT$3*(1+BT$7)/1000*(1+BT$8))*BT$16 -> 6278.3039 | BU23: =+($D23*BU$3*(1+BU$7)/1000*(1+BU$8))*BU$16 -> 6626.7825 | BV23: =+($D23*BV$3*(1+BV$7)/1000*(1+BV$8))*BV$16*0 -> 0 | BW23: =+($D23*BW$3*(1+BW$7)/1000*(1+BW$8))*BW$16*0 -> 0 | BX23: =+($D23*BX$3*(1+BX$7)/1000*(1+BX$8))*BX$16*0 -> 0 | BY23: =+($D23*BY$3*(1+BY$7)/1000*(1+BY$8))*BY$16*0 -> 0 | BZ23: =+($D23*BZ$3*(1+BZ$7)/1000*(1+BZ$8))*BZ$16*0 -> 0 | CA23: =+($D23*CA$3*(1+CA$7)/1000*(1+CA$8))*CA$16*0 -> 0 | CB23: =+($D23*CB$3*(1+CB$7)/1000*(1+CB$8))*CB$16*0 -> 0 | CC23: =+($D23*CC$3*(1+CC$7)/1000*(1+CC$8))*CC$16*0 -> 0 | ... CL23: =+($D23*CL$3*(1+CL$7)/1000*(1+CL$8))*CL$16*0 -> 0 | CM23: 0 | CO23: =+($D23*CO$3*(1+CO$7)/1000*(1+CO$8))*CO$16*0 -> 0 | CP23: =+($D23*CP$3*(1+CP$7)/1000*(1+CP$8))*CP$16*0 -> 0 | CQ23: =+($D23*CQ$3*(1+CQ$7)/1000*(1+CQ$8))*CQ$16*0 -> 0 | CR23: =+($D23*CR$3*(1+CR$7)/1000*(1+CR$8))*CR$16*0 -> 0 | CS23: =+($D23*CS$3*(1+CS$7)/1000*(1+CS$8))*CS$16*0 -> 0 | CT23: =+($D23*CT$3*(1+CT$7)/1000*(1+CT$8))*CT$16*0 -> 0 | CU23: =+($D23*CU$3*(1+CU$7)/1000*(1+CU$8))*CU$16*0 -> 0 | CV23: =+($D23*CV$3*(1+CV$7)/1000*(1+CV$8))*CV$16*0 -> 0 | ... DG23: =+($D23*DG$3*(1+DG$7)/1000*(1+DG$8))*DG$16*0 -> 0
C24: SS 500 | D24: 25 | BT24: =+($D24*BT$3*(1+BT$7)/1000*(1+BT$8))*BT$16 -> 7134.4362 | BU24: =+($D24*BU$3*(1+BU$7)/1000*(1+BU$8))*BU$16 -> 7530.4347 | BV24: =+($D24*BV$3*(1+BV$7)/1000*(1+BV$8))*BV$16 -> 7794.3594 | BW24: =+($D24*BW$3*(1+BW$7)/1000*(1+BW$8))*BW$16 -> 8507.2542 | BX24: =+($D24*BX$3*(1+BX$7)/1000*(1+BX$8))*BX$16 -> 9105.2989 | BY24: =+($D24*BY$3*(1+BY$7)/1000*(1+BY$8))*BY$16 -> 10075.56 | BZ24: =+($D24*BZ$3*(1+BZ$7)/1000*(1+BZ$8))*BZ$16 -> 10192.848 | CA24: =+($D24*CA$3*(1+CA$7)/1000*(1+CA$8))*CA$16 -> 10438.637 | ... CL24: =+($D24*CL$3*(1+CL$7)/1000*(1+CL$8))*CL$16 -> 36281.668 | CM24: 36956.163 | CO24: =+($D24*CO$3*(1+CO$7)/1000*(1+CO$8))*CO$16 -> 45420.004 | CP24: =+($D24*CP$3*(1+CP$7)/1000*(1+CP$8))*CP$16 -> 30099.68 | CQ24: =+($D24*CQ$3*(1+CQ$7)/1000*(1+CQ$8))*CQ$16 -> 37596.806 | CR24: =+($D24*CR$3*(1+CR$7)/1000*(1+CR$8))*CR$16 -> 40300.047 | CS24: =+($D24*CS$3*(1+CS$7)/1000*(1+CS$8))*CS$16 -> 41753.879 | CT24: =+($D24*CT$3*(1+CT$7)/1000*(1+CT$8))*CT$16 -> 42222.675 | CU24: =+($D24*CU$3*(1+CU$7)/1000*(1+CU$8))*CU$16 -> 41906.793 | CV24: =+($D24*CV$3*(1+CV$7)/1000*(1+CV$8))*CV$16 -> 41893.947 | ... DG24: =+($D24*DG$3*(1+DG$7)/1000*(1+DG$8))*DG$16 -> 46804.055
C25: SS 500 - 25G PCR 100% | D25: 25 | CF25: =+($D25*CF$6*(1+CF$7)/1000*(1+CF$8))*CF$16 -> 0 | CG25: =+($D25*CG$6*(1+CG$7)/1000*(1+CG$8))*CG$16 -> 53505.832 | CH25: =+($D25*CH$6*(1+CH$7)/1000*(1+CH$8))*CH$16 -> 54950.885 | CI25: =+($D25*CI$6*(1+CI$7)/1000*(1+CI$8))*CI$16 -> 55598.891 | CJ25: =+($D25*CJ$6*(1+CJ$7)/1000*(1+CJ$8))*CJ$16 -> 57704.91 | CK25: =+($D25*CK$6*(1+CK$7)/1000*(1+CK$8))*CK$16 -> 58806.519 | CL25: =+($D25*CL$6*(1+CL$7)/1000*(1+CL$8))*CL$16 -> 59260.123 | CM25: 60361.733 | CO25: =+($D25*CO$6*(1+CO$7)/1000*(1+CO$8))*CO$16 -> 45420.004 | CP25: =+($D25*CP$6*(1+CP$7)/1000*(1+CP$8))*CP$16 -> 30099.68 | CQ25: =+($D25*CQ$6*(1+CQ$7)/1000*(1+CQ$8))*CQ$16 -> 37596.806 | CR25: =+($D25*CR$6*(1+CR$7)/1000*(1+CR$8))*CR$16 -> 40300.047 | CS25: =+($D25*CS$6*(1+CS$7)/1000*(1+CS$8))*CS$16 -> 41753.879 | CT25: =+($D25*CT$6*(1+CT$7)/1000*(1+CT$8))*CT$16 -> 42222.675 | CU25: =+($D25*CU$6*(1+CU$7)/1000*(1+CU$8))*CU$16 -> 41906.793 | CV25: =+($D25*CV$6*(1+CV$7)/1000*(1+CV$8))*CV$16 -> 41893.947 | ... DG25: =+($D25*DG$6*(1+DG$7)/1000*(1+DG$8))*DG$16 -> 46804.055
C26: MS 1500 | D26: 37.2 | BT26: =+(4.62*BT$3*(1+BT$7)*0/1000*(1+BT$8))+($D$26*BT$3*(1+BT$7)/1000*(1+BT$8))*BT$16 -> 10616.041 | BU26: =+(4.62*BU$3*(1+BU$7)*0/1000*(1+BU$8))+($D$26*BU$3*(1+BU$7)/1000*(1+BU$8))*BU$16 -> 11205.287 | BV26: =+(+(D26*BV$3*(1+BV$7)/1000*(1+BV$8))*BV$16) -> 11598.007 | BW26: =+(+($D$26*BW$3*(1+BW$7)/1000*(1+BW$8))*BW$16) -> 12658.794 | BX26: =+(+($D$26*BX$3*(1+BX$7)/1000*(1+BX$8))*BX$16) -> 13548.685 | BY26: =+(+($D$26*BY$3*(1+BY$7)/1000*(1+BY$8))*BY$16) -> 14992.433 | BZ26: =+(+($D$26*BZ$3*(1+BZ$7)/1000*(1+BZ$8))*BZ$16) -> 15166.958 | CA26: =+(+($D$26*CA$3*(1+CA$7)/1000*(1+CA$8))*CA$16) -> 15532.693 | CB26: =+(+($D$26*CB$3*(1+CB$7)/1000*(1+CB$8))*CB$16) -> 17192.617 | CC26: =+(+($D$26*CC$3*(1+CC$7)/1000*(1+CC$8))*CC$16) -> 17923.008 | CD26: =+(+($D$26*CD$3*(1+CD$7)/1000*(1+CD$8))*CD$16) -> 18083.397 | ... CL26: =+(+($D$26*CL$3*(1+CL$7)/1000*(1+CL$8))*CL$16) -> 53987.122 | CM26: 54990.771 | CO26: =+(+($D$26*CO$3*(1+CO$7)/1000*(1+CO$8))*CO$16) -> 67584.966 | CP26: =+(+($D$26*CP$3*(1+CP$7)/1000*(1+CP$8))*CP$16) -> 44788.323 | CQ26: =+(+($D$26*CQ$3*(1+CQ$7)/1000*(1+CQ$8))*CQ$16) -> 55944.048 | CR26: =+(+($D$26*CR$3*(1+CR$7)/1000*(1+CR$8))*CR$16) -> 59966.469 | CS26: =+(+($D$26*CS$3*(1+CS$7)/1000*(1+CS$8))*CS$16) -> 62129.771 | CT26: =+(+($D$26*CT$3*(1+CT$7)/1000*(1+CT$8))*CT$16) -> 62827.34 | CU26: =+(+($D$26*CU$3*(1+CU$7)/1000*(1+CU$8))*CU$16) -> 62357.308 | CV26: =+(+($D$26*CV$3*(1+CV$7)/1000*(1+CV$8))*CV$16) -> 62338.193 | ... DG26: =+(+($D$26*DG$3*(1+DG$7)/1000*(1+DG$8))*DG$16) -> 69644.434
C27: MS 1500 | D27: 40 | BT27: =+($D27*BT$3*(1+BT$7)/1000*(1+BT$8))*BT$16 -> 11415.098 | BU27: =+($D27*BU$3*(1+BU$7)/1000*(1+BU$8))*BU$16 -> 12048.695 | BV27: =+($D27*BV$3*(1+BV$7)/1000*(1+BV$8))*BV$16*0 -> 0 | BW27: =+($D27*BW$3*(1+BW$7)/1000*(1+BW$8))*BW$16*0 -> 0 | BX27: =+($D27*BX$3*(1+BX$7)/1000*(1+BX$8))*BX$16*0 -> 0 | BY27: =+($D27*BY$3*(1+BY$7)/1000*(1+BY$8))*BY$16*0 -> 0 | BZ27: =+($D27*BZ$3*(1+BZ$7)/1000*(1+BZ$8))*BZ$16*0 -> 0 | CA27: =+($D27*CA$3*(1+CA$7)/1000*(1+CA$8))*CA$16*0 -> 0 | CB27: =+($D27*CB$3*(1+CB$7)/1000*(1+CB$8))*CB$16*0 -> 0 | CC27: =+($D27*CC$3*(1+CC$7)/1000*(1+CC$8))*CC$16*0 -> 0 | ... CL27: =+($D27*CL$3*(1+CL$7)/1000*(1+CL$8))*CL$16*0 -> 0 | CM27: 0 | CO27: =+($D27*CO$3*(1+CO$7)/1000*(1+CO$8))*CO$16*0 -> 0 | CP27: =+($D27*CP$3*(1+CP$7)/1000*(1+CP$8))*CP$16*0 -> 0 | CQ27: =+($D27*CQ$3*(1+CQ$7)/1000*(1+CQ$8))*CQ$16*0 -> 0 | CR27: =+($D27*CR$3*(1+CR$7)/1000*(1+CR$8))*CR$16*0 -> 0 | CS27: =+($D27*CS$3*(1+CS$7)/1000*(1+CS$8))*CS$16*0 -> 0 | CT27: =+($D27*CT$3*(1+CT$7)/1000*(1+CT$8))*CT$16*0 -> 0 | CU27: =+($D27*CU$3*(1+CU$7)/1000*(1+CU$8))*CU$16*0 -> 0 | CV27: =+($D27*CV$3*(1+CV$7)/1000*(1+CV$8))*CV$16*0 -> 0 | ... DG27: =+($D27*DG$3*(1+DG$7)/1000*(1+DG$8))*DG$16*0 -> 0
C28: MS 1500 | D28: 44 | BT28: =+($D28*BT$3*(1+BT$7)/1000*(1+BT$8))*BT$16 -> 12556.608 | BU28: =+($D28*BU$3*(1+BU$7)/1000*(1+BU$8))*BU$16 -> 13253.565 | BV28: =+($D28*BV$3*(1+BV$7)/1000*(1+BV$8))*BV$16 -> 13718.073 | BW28: =+($D28*BW$3*(1+BW$7)/1000*(1+BW$8))*BW$16 -> 14972.767 | BX28: =+($D28*BX$3*(1+BX$7)/1000*(1+BX$8))*BX$16 -> 16025.326 | BY28: =+($D28*BY$3*(1+BY$7)/1000*(1+BY$8))*BY$16 -> 17732.985 | BZ28: =+($D28*BZ$3*(1+BZ$7)/1000*(1+BZ$8))*BZ$16 -> 17939.412 | CA28: =+($D28*CA$3*(1+CA$7)/1000*(1+CA$8))*CA$16 -> 18372.002 | ... CL28: =+($D28*CL$3*(1+CL$7)/1000*(1+CL$8))*CL$16 -> 63855.736 | CM28: 65042.847 | CO28: =+($D28*CO$3*(1+CO$7)/1000*(1+CO$8))*CO$16 -> 79939.207 | CP28: =+($D28*CP$3*(1+CP$7)/1000*(1+CP$8))*CP$16 -> 52975.436 | CQ28: =+($D28*CQ$3*(1+CQ$7)/1000*(1+CQ$8))*CQ$16 -> 66170.379 | CR28: =+($D28*CR$3*(1+CR$7)/1000*(1+CR$8))*CR$16 -> 70928.082 | CS28: =+($D28*CS$3*(1+CS$7)/1000*(1+CS$8))*CS$16 -> 73486.826 | CT28: =+($D28*CT$3*(1+CT$7)/1000*(1+CT$8))*CT$16 -> 74311.908 | CU28: =+($D28*CU$3*(1+CU$7)/1000*(1+CU$8))*CU$16 -> 73755.956 | CV28: =+($D28*CV$3*(1+CV$7)/1000*(1+CV$8))*CV$16 -> 73733.347 | ... DG28: =+($D28*DG$3*(1+DG$7)/1000*(1+DG$8))*DG$16 -> 82375.137
C29: MS 2000/2250 | D29: 42.6 | BT29: =(4*BT$3*(1+BT$7)*0/1000*(1+BT$8))+($D29*BT$3*(1+BT$7)/1000*(1+BT$8))*BT$16 -> 12157.079 | BU29: =(4*BU$3*(1+BU$7)*0/1000*(1+BU$8))+($D29*BU$3*(1+BU$7)/1000*(1+BU$8))*BU$16 -> 12831.861 | BV29: =(4*BV$3*(1+BV$7)*0/1000*(1+BV$8))+($D29*BV$3*(1+BV$7)/1000*(1+BV$8))*BV$16*0 -> 0 | BW29: =(4*BW$3*(1+BW$7)*0/1000*(1+BW$8))+($D29*BW$3*(1+BW$7)/1000*(1+BW$8))*BW$16*0 -> 0 | BX29: =(4*BX$3*(1+BX$7)*0/1000*(1+BX$8))+($D29*BX$3*(1+BX$7)/1000*(1+BX$8))*BX$16*0 -> 0 | BY29: =(4*BY$3*(1+BY$7)*0/1000*(1+BY$8))+($D29*BY$3*(1+BY$7)/1000*(1+BY$8))*BY$16*0 -> 0 | BZ29: =(4*BZ$3*(1+BZ$7)*0/1000*(1+BZ$8))+($D29*BZ$3*(1+BZ$7)/1000*(1+BZ$8))*BZ$16*0 -> 0 | CA29: =(4*CA$3*(1+CA$7)*0/1000*(1+CA$8))+($D29*CA$3*(1+CA$7)/1000*(1+CA$8))*CA$16*0 -> 0 | CB29: =(4*CB$3*(1+CB$7)*0/1000*(1+CB$8))+($D29*CB$3*(1+CB$7)/1000*(1+CB$8))*CB$16*0 -> 0 | CC29: =(4*CC$3*(1+CC$7)*0/1000*(1+CC$8))+($D29*CC$3*(1+CC$7)/1000*(1+CC$8))*CC$16*0 -> 0 | ... CL29: =(4*CL$3*(1+CL$7)*0/1000*(1+CL$8))+($D29*CL$3*(1+CL$7)/1000*(1+CL$8))*CL$16*0 -> 0 | CM29: 0 | CO29: =(4*CO$3*(1+CO$7)*0/1000*(1+CO$8))+($D29*CO$3*(1+CO$7)/1000*(1+CO$8))*CO$16*0 -> 0 | CP29: =(4*CP$3*(1+CP$7)*0/1000*(1+CP$8))+($D29*CP$3*(1+CP$7)/1000*(1+CP$8))*CP$16*0 -> 0 | CQ29: =(4*CQ$3*(1+CQ$7)*0/1000*(1+CQ$8))+($D29*CQ$3*(1+CQ$7)/1000*(1+CQ$8))*CQ$16*0 -> 0 | CR29: =(4*CR$3*(1+CR$7)*0/1000*(1+CR$8))+($D29*CR$3*(1+CR$7)/1000*(1+CR$8))*CR$16*0 -> 0 | CS29: =(4*CS$3*(1+CS$7)*0/1000*(1+CS$8))+($D29*CS$3*(1+CS$7)/1000*(1+CS$8))*CS$16*0 -> 0 | CT29: =(4*CT$3*(1+CT$7)*0/1000*(1+CT$8))+($D29*CT$3*(1+CT$7)/1000*(1+CT$8))*CT$16*0 -> 0 | CU29: =(4*CU$3*(1+CU$7)*0/1000*(1+CU$8))+($D29*CU$3*(1+CU$7)/1000*(1+CU$8))*CU$16*0 -> 0 | CV29: =(4*CV$3*(1+CV$7)*0/1000*(1+CV$8))+($D29*CV$3*(1+CV$7)/1000*(1+CV$8))*CV$16*0 -> 0 | ... DG29: =(4*DG$3*(1+DG$7)*0/1000*(1+DG$8))+($D29*DG$3*(1+DG$7)/1000*(1+DG$8))*DG$16*0 -> 0
C30: MS 2000/2250 | D30: 46.6 | BT30: =(4.833*BT$3*(1+BT$7)*0/1000*(1+BT$8))+($D30*BT$3*(1+BT$7)/1000*(1+BT$8))*BT$16 -> 13298.589 | BU30: =(4.833*BU$3*(1+BU$7)*0/1000*(1+BU$8))+($D30*BU$3*(1+BU$7)/1000*(1+BU$8))*BU$16 -> 14036.73 | BV30: =(+($D30*BV$3*(1+BV$7)/1000*(1+BV$8))*BV$16) -> 14528.686 | BW30: =(+($D30*BW$3*(1+BW$7)/1000*(1+BW$8))*BW$16) -> 15857.522 | BX30: =(+($D30*BX$3*(1+BX$7)/1000*(1+BX$8))*BX$16) -> 16972.277 | BY30: =(+($D30*BY$3*(1+BY$7)/1000*(1+BY$8))*BY$16) -> 18780.843 | BZ30: =(+($D30*BZ$3*(1+BZ$7)/1000*(1+BZ$8))*BZ$16) -> 18999.469 | CA30: =(+($D30*CA$3*(1+CA$7)/1000*(1+CA$8))*CA$16) -> 19457.62 | CB30: =(+($D30*CB$3*(1+CB$7)/1000*(1+CB$8))*CB$16) -> 21536.988 | CC30: =(+($D30*CC$3*(1+CC$7)/1000*(1+CC$8))*CC$16) -> 22451.94 | ... CL30: =(+($D30*CL$3*(1+CL$7)/1000*(1+CL$8))*CL$16) -> 67629.03 | CM30: 68886.288 | CO30: =(+($D30*CO$3*(1+CO$7)/1000*(1+CO$8))*CO$16) -> 84662.887 | CP30: =(+($D30*CP$3*(1+CP$7)/1000*(1+CP$8))*CP$16) -> 56105.803 | CQ30: =(+($D30*CQ$3*(1+CQ$7)/1000*(1+CQ$8))*CQ$16) -> 70080.447 | CR30: =(+($D30*CR$3*(1+CR$7)/1000*(1+CR$8))*CR$16) -> 75119.287 | CS30: =(+($D30*CS$3*(1+CS$7)/1000*(1+CS$8))*CS$16) -> 77829.23 | CT30: =(+($D30*CT$3*(1+CT$7)/1000*(1+CT$8))*CT$16) -> 78703.066 | CU30: =(+($D30*CU$3*(1+CU$7)/1000*(1+CU$8))*CU$16) -> 78114.262 | CV30: =(+($D30*CV$3*(1+CV$7)/1000*(1+CV$8))*CV$16) -> 78090.318 | ... DG30: =(+($D30*DG$3*(1+DG$7)/1000*(1+DG$8))*DG$16) -> 87242.759
C31: MS 2000/2250 20% PCR | D31: 46.6 | CG31: =(+((($D31*CG$3*0.8)+($D31*CG$6*0.2))*(1+CG$7)/1000*(1+CG$8))*CG$16) -> 79739.048 | CH31: =(+((($D31*CH$3*0.8)+($D31*CH$6*0.2))*(1+CH$7)/1000*(1+CH$8))*CH$16) -> 78949.341 | CI31: =(+((($D31*CI$3*0.8)+($D31*CI$6*0.2))*(1+CI$7)/1000*(1+CI$8))*CI$16) -> 78357.528 | CJ31: =(+((($D31*CJ$3*0.8)+($D31*CJ$6*0.2))*(1+CJ$7)/1000*(1+CJ$8))*CJ$16) -> 74195.833 | CK31: =(+((($D31*CK$3*0.8)+($D31*CK$6*0.2))*(1+CK$7)/1000*(1+CK$8))*CK$16) -> 75612.342 | CL31: =(+((($D31*CL$3*0.8)+($D31*CL$6*0.2))*(1+CL$7)/1000*(1+CL$8))*CL$16) -> 76195.398 | CM31: 77611.884 | CO31: =(+((($D31*CO$3*0.8)+($D31*CO$6*0.2))*(1+CO$7)/1000*(1+CO$8))*CO$16)*0 -> 0 | CP31: =(+((($D31*CP$3*0.8)+($D31*CP$6*0.2))*(1+CP$7)/1000*(1+CP$8))*CP$16)*0 -> 0 | CQ31: =(+((($D31*CQ$3*0.8)+($D31*CQ$6*0.2))*(1+CQ$7)/1000*(1+CQ$8))*CQ$16)*0 -> 0 | CR31: =(+((($D31*CR$3*0.8)+($D31*CR$6*0.2))*(1+CR$7)/1000*(1+CR$8))*CR$16)*0 -> 0 | CS31: =(+($D31*CS$3*(1+CS$7)/1000*(1+CS$8))*CS$16) -> 77829.23 | CT31: =(+($D31*CT$3*(1+CT$7)/1000*(1+CT$8))*CT$16) -> 78703.066 | CU31: =(+($D31*CU$3*(1+CU$7)/1000*(1+CU$8))*CU$16) -> 78114.262 | CV31: =(+($D31*CV$3*(1+CV$7)/1000*(1+CV$8))*CV$16) -> 78090.318 | CW31: =(+($D31*CW$3*(1+CW$7)/1000*(1+CW$8))*CW$16) -> 82196.793 | CX31: =(+($D31*CX$3*(1+CX$7)/1000*(1+CX$8))*CX$16) -> 80933.641 | CY31: =(+($D31*CY$3*(1+CY$7)/1000*(1+CY$8))*CY$16) -> 78487.531 | CZ31: =(+($D31*CZ$3*(1+CZ$7)/1000*(1+CZ$8))*CZ$16) -> 86945.279 | ... DG31: =(+($D31*DG$3*(1+DG$7)/1000*(1+DG$8))*DG$16) -> 87242.759
C32: MS 2000/2250 | D32: 48 | BT32: =+(4*BT$3*(1+BT$7)*0/1000*(1+BT$8))+($D32*BT$3*(1+BT$7)/1000*(1+BT$8))*BT$16 -> 13698.118 | BU32: =+(4*BU$3*(1+BU$7)*0/1000*(1+BU$8))+($D32*BU$3*(1+BU$7)/1000*(1+BU$8))*BU$16 -> 14458.435 | BV32: =+(+($D32*BV$3*(1+BV$7)/1000*(1+BV$8))*BV$16) -> 14965.17 | BW32: =+(+($D32*BW$3*(1+BW$7)/1000*(1+BW$8))*BW$16) -> 16333.928 | BX32: =+(+($D32*BX$3*(1+BX$7)/1000*(1+BX$8))*BX$16) -> 17482.174 | BY32: =+(+($D32*BY$3*(1+BY$7)/1000*(1+BY$8))*BY$16) -> 19345.074 | BZ32: =+(+($D32*BZ$3*(1+BZ$7)/1000*(1+BZ$8))*BZ$16) -> 19570.268 | CA32: =+(+($D32*CA$3*(1+CA$7)/1000*(1+CA$8))*CA$16) -> 20042.184 | CB32: =+(+($D32*CB$3*(1+CB$7)/1000*(1+CB$8))*CB$16) -> 22184.022 | CC32: =+(+($D32*CC$3*(1+CC$7)/1000*(1+CC$8))*CC$16) -> 23126.462 | ... CL32: =+(+($D32*CL$3*(1+CL$7)/1000*(1+CL$8))*CL$16) -> 69660.803 | CM32: 70955.833 | CO32: =+(+($D32*CO$3*(1+CO$7)/1000*(1+CO$8))*CO$16) -> 87206.407 | CP32: =+(+($D32*CP$3*(1+CP$7)/1000*(1+CP$8))*CP$16) -> 57791.385 | CQ32: =+(+($D32*CQ$3*(1+CQ$7)/1000*(1+CQ$8))*CQ$16) -> 72185.868 | CR32: =+(+($D32*CR$3*(1+CR$7)/1000*(1+CR$8))*CR$16) -> 77376.089 | CS32: =+(+($D32*CS$3*(1+CS$7)/1000*(1+CS$8))*CS$16) -> 80167.447 | CT32: =+(+($D32*CT$3*(1+CT$7)/1000*(1+CT$8))*CT$16) -> 81067.536 | CU32: =+(+($D32*CU$3*(1+CU$7)/1000*(1+CU$8))*CU$16) -> 80461.042 | CV32: =+(+($D32*CV$3*(1+CV$7)/1000*(1+CV$8))*CV$16) -> 80436.379 | ... DG32: =+(+($D32*DG$3*(1+DG$7)/1000*(1+DG$8))*DG$16) -> 89863.786
C33: MS 2000/2250 | D33: 49.6 | BT33: =+(4.833*BT$3*(1+BT$7)*0/1000*(1+BT$8))+($D33*BT$3*(1+BT$7)/1000*(1+BT$8))*BT$16 -> 14154.721 | BU33: =+(4.833*BU$3*(1+BU$7)*0/1000*(1+BU$8))+($D33*BU$3*(1+BU$7)/1000*(1+BU$8))*BU$16 -> 14940.382 | BV33: =+(($D33*BV$3*(1+BV$7)/1000*(1+BV$8))*BV$16)*0 -> 0 | BW33: =+(($D33*BW$3*(1+BW$7)/1000*(1+BW$8))*BW$16)*0 -> 0 | BX33: =+(($D33*BX$3*(1+BX$7)/1000*(1+BX$8))*BX$16)*0 -> 0 | BY33: =+(($D33*BY$3*(1+BY$7)/1000*(1+BY$8))*BY$16)*0 -> 0 | BZ33: =+(($D33*BZ$3*(1+BZ$7)/1000*(1+BZ$8))*BZ$16)*0 -> 0 | CA33: =+(($D33*CA$3*(1+CA$7)/1000*(1+CA$8))*CA$16)*0 -> 0 | CB33: =+(($D33*CB$3*(1+CB$7)/1000*(1+CB$8))*CB$16)*0 -> 0 | CC33: =+(($D33*CC$3*(1+CC$7)/1000*(1+CC$8))*CC$16)*0 -> 0 | ... CL33: =+(($D33*CL$3*(1+CL$7)/1000*(1+CL$8))*CL$16)*0 -> 0 | CM33: 0 | CO33: =+(($D33*CO$3*(1+CO$7)/1000*(1+CO$8))*CO$16)*0 -> 0 | CP33: =+(($D33*CP$3*(1+CP$7)/1000*(1+CP$8))*CP$16)*0 -> 0 | CQ33: =+(($D33*CQ$3*(1+CQ$7)/1000*(1+CQ$8))*CQ$16)*0 -> 0 | CR33: =+(($D33*CR$3*(1+CR$7)/1000*(1+CR$8))*CR$16)*0 -> 0 | CS33: =+(($D33*CS$3*(1+CS$7)/1000*(1+CS$8))*CS$16)*0 -> 0 | CT33: =+(($D33*CT$3*(1+CT$7)/1000*(1+CT$8))*CT$16)*0 -> 0 | CU33: =+(($D33*CU$3*(1+CU$7)/1000*(1+CU$8))*CU$16)*0 -> 0 | CV33: =+(($D33*CV$3*(1+CV$7)/1000*(1+CV$8))*CV$16)*0 -> 0 | ... DG33: =+(($D33*DG$3*(1+DG$7)/1000*(1+DG$8))*DG$16)*0 -> 0
C34: MS 2000/2250 | D34: 52 | BT34: =+($D34*BT$3*(1+BT$7)/1000*(1+BT$8))*BT$16 -> 14839.627 | BU34: =+($D34*BU$3*(1+BU$7)/1000*(1+BU$8))*BU$16 -> 15663.304 | BV34: =+($D34*BV$3*(1+BV$7)/1000*(1+BV$8))*BV$16 -> 16212.268 | BW34: =+($D34*BW$3*(1+BW$7)/1000*(1+BW$8))*BW$16 -> 17695.089 | BX34: =+($D34*BX$3*(1+BX$7)/1000*(1+BX$8))*BX$16 -> 18939.022 | BY34: =+($D34*BY$3*(1+BY$7)/1000*(1+BY$8))*BY$16 -> 20957.164 | BZ34: =+($D34*BZ$3*(1+BZ$7)/1000*(1+BZ$8))*BZ$16 -> 21201.124 | CA34: =+($D34*CA$3*(1+CA$7)/1000*(1+CA$8))*CA$16 -> 21712.366 | ... CL34: =+($D34*CL$3*(1+CL$7)/1000*(1+CL$8))*CL$16 -> 75465.87 | CM34: 76868.819 | CO34: =+($D34*CO$3*(1+CO$7)/1000*(1+CO$8))*CO$16 -> 94473.608 | CP34: =+($D34*CP$3*(1+CP$7)/1000*(1+CP$8))*CP$16 -> 62607.334 | CQ34: =+($D34*CQ$3*(1+CQ$7)/1000*(1+CQ$8))*CQ$16 -> 78201.357 | CR34: =+($D34*CR$3*(1+CR$7)/1000*(1+CR$8))*CR$16 -> 83824.097 | CS34: =+($D34*CS$3*(1+CS$7)/1000*(1+CS$8))*CS$16 -> 86848.067 | CT34: =+($D34*CT$3*(1+CT$7)/1000*(1+CT$8))*CT$16 -> 87823.164 | CU34: =+($D34*CU$3*(1+CU$7)/1000*(1+CU$8))*CU$16 -> 87166.129 | CV34: =+($D34*CV$3*(1+CV$7)/1000*(1+CV$8))*CV$16 -> 87139.41 | ... DG34: =+($D34*DG$3*(1+DG$7)/1000*(1+DG$8))*DG$16 -> 97352.435
C35: MS 3000 | D35: 54.7 | BT35: =+(5.18*BT$3*(1+BT$7)*0/1000*(1+BT$8))+($D35*BT$3*(1+BT$7)/1000*(1+BT$8))*BT$16 -> 15610.146 | BU35: =+(5.18*BU$3*(1+BU$7)*0/1000*(1+BU$8))+($D35*BU$3*(1+BU$7)/1000*(1+BU$8))*BU$16 -> 16476.591 | BV35: =+(+($D35*BV$3*(1+BV$7)/1000*(1+BV$8))*BV$16) -> 17054.058 | BW35: =+(+($D35*BW$3*(1+BW$7)/1000*(1+BW$8))*BW$16) -> 18613.872 | BX35: =+(+($D35*BX$3*(1+BX$7)/1000*(1+BX$8))*BX$16) -> 19922.394 | BY35: =+(+($D35*BY$3*(1+BY$7)/1000*(1+BY$8))*BY$16) -> 22045.324 | BZ35: =+(+($D35*BZ$3*(1+BZ$7)/1000*(1+BZ$8))*BZ$16) -> 22301.951 | CA35: =+(+($D35*CA$3*(1+CA$7)/1000*(1+CA$8))*CA$16) -> 22839.739 | CB35: =+(+($D35*CB$3*(1+CB$7)/1000*(1+CB$8))*CB$16) -> 25280.542 | CC35: =+(+($D35*CC$3*(1+CC$7)/1000*(1+CC$8))*CC$16) -> 26354.53 | ... CL35: =+(+($D35*CL$3*(1+CL$7)/1000*(1+CL$8))*CL$16) -> 79384.29 | CM35: 80860.085 | CO35: =+(+($D35*CO$3*(1+CO$7)/1000*(1+CO$8))*CO$16) -> 99378.968 | CP35: =+(+($D35*CP$3*(1+CP$7)/1000*(1+CP$8))*CP$16) -> 65858.099 | CQ35: =+(+($D35*CQ$3*(1+CQ$7)/1000*(1+CQ$8))*CQ$16) -> 82261.812 | CR35: =+(+($D35*CR$3*(1+CR$7)/1000*(1+CR$8))*CR$16) -> 88176.502 | CS35: =+(+($D35*CS$3*(1+CS$7)/1000*(1+CS$8))*CS$16) -> 91357.486 | CT35: =+(+($D35*CT$3*(1+CT$7)/1000*(1+CT$8))*CT$16) -> 92383.213 | CU35: =+(+($D35*CU$3*(1+CU$7)/1000*(1+CU$8))*CU$16) -> 91692.063 | CV35: =+(+($D35*CV$3*(1+CV$7)/1000*(1+CV$8))*CV$16) -> 91663.956 | ... DG35: =+(+($D35*DG$3*(1+DG$7)/1000*(1+DG$8))*DG$16) -> 102407.27
