Workbook

Sheet PET
B3: IHS
B4: 44835 | C4: 1015.63
B5: =EOMONTH(B4,1) -> 44895 | C5: 950
B6: =EOMONTH(B5,1) -> 44926 | C6: 940
B7: Promedio | C7: =+AVERAGE(C4:C6) -> 968.54333
B9: Recargos | C9: 13
B10: Flete Marítimo | C10: 163.33
B12: Nacionalización (%) | C12: 33.18
B14: Valor vPET | C14: =(C10+C9+C7)+C12 -> 1178.0533

Sheet RPET
B3: Valor rPET
C5: Materia Prima | D5: Scrap | E5: Conversión | F5: rPET
B6: 44866 | C6: =+C12 -> 730.34 | D6: 0.309 | E6: 631.4 | F6: =+C6/(1-D6)+E6 -> 1688.332 | G6: Perú
B7: =+B6 -> 44866 | C7: =+C13 -> 0 | D7: 0.362 | E7: 649 | F7: =+C7/(1-D7)+E7 -> 649 | G7: Panamá
F8: =+SUMPRODUCT(F6:F7,D12:D13) -> 1688.332
C11: Valor Paca | D11: %
B12: Perú | C12: 730.34 | D12: =1-D13 -> 1
B13: Panamá | D13: 0

Sheet PRECIOS
F1: PR | G1: CC | H1: Flete | I1: DDP
B3: Precios Preforma ABI - Panamá
B4: =C8 -> Abril 2026
B6: CLIENTE | C6: ABI
B7: PAÍS : | C7: Panamá
B8: PERÍODO : | C8: =TEXT(DATE(2020,Inputs!D6,1),"mmmm")&" "&Inputs!C6 -> Abril 2026
B9: Actualización: | C9: Mensual
B11: Precio de Resina | C11: USD/TM
B12: Resina rPET | C12: =Inputs!$P$12 -> 1429.585
B13: Resina vPET | C13: =Inputs!$H$11 -> 1048.5
B15: Flete Pref (USD/Cont) | C15: =Inputs!U13 -> 1986.5268
N16: Base
B17: Weight (g) | C17: Color | D17: Finish | E17: %rPET | F17: Resina (US$/millar) | G17: Nuevo precio de conversión Incluido Color (US$/millar) | H17: Flete (US$/millar) | I17: Gastos a DDP y Almacenamiento (US$/millar) | J17: Precio DDP Preforma (US$/millar) | L17: Preformas (Mill x caja) | N17: Nuevo precio de conversión Incluido Color (US$/millar)
A18: =B18&C18&E18 -> 15.7Green0 | B18: 15.7 | C18: Green | D18: 1881 | E18: 0 | F18: =+($C$13/1000*(1-E18)+$C$12/1000*E18)*B18*(1+0.5%) -> 16.543757 | G18: =N18*(1+(Inputs!AA$8/Inputs!AA$7-1)*50%) -> 7.8995639 | H18: =C$15/36/$L18 -> 2.8298103 | I18: 6.9465682 | J18: =+SUM(F18:I18) -> 34.2197 | L18: 19.5 | N18: 7.7764599
A19: =B19&C19&E19 -> 15.7Green0.25 | B19: 15.7 | C19: Green | D19: 1881 | E19: 0.25 | F19: =+($C$13/1000*(1-E19)+$C$12/1000*E19)*B19*(1+0.5%) -> 18.046995 | G19: =N19*(1+(Inputs!AA$8/Inputs!AA$7-1)*50%) -> 7.8995639 | H19: =C$15/36/$L19 -> 2.8298103 | I19: 6.9465682 | J19: =+SUM(F19:I19) -> 35.722937 | L19: 19.5 | N19: 7.7764599
A20: =B20&C20&E20 -> 17.7Clear0 | B20: 17.7 | C20: Clear | D20: 1881 | E20: 0 | F20: =+($C$13/1000*(1-E20)+$C$12/1000*E20)*B20*(1+0.5%) -> 18.651242 | G20: =N20*(1+(Inputs!AA$8/Inputs!AA$7-1)*50%) -> 7.3701977 | H20: =C$15/36/$L20 -> 2.8298103 | I20: 6.9465682 | J20: =+SUM(F20:I20) -> 35.797818 | L20: 19.5 | N20: 7.2553431
A21: =B21&C21&E21 -> 17.7Green0 | B21: 17.7 | C21: Green | D21: 1881 | E21: 0 | F21: =+($C$13/1000*(1-E21)+$C$12/1000*E21)*B21*(1+0.5%) -> 18.651242 | G21: =N21*(1+(Inputs!AA$8/Inputs!AA$7-1)*50%) -> 7.8995639 | H21: =C$15/36/$L21 -> 2.8298103 | I21: 6.9465682 | J21: =+SUM(F21:I21) -> 36.327185 | L21: 19.5 | N21: 7.7764599
A22: =B22&C22&E22 -> 17.7Green0.25 | B22: 17.7 | C22: Green | D22: 1881 | E22: 0.25 | F22: =+($C$13/1000*(1-E22)+$C$12/1000*E22)*B22*(1+0.5%) -> 20.345975 | G22: =N22*(1+(Inputs!AA$8/Inputs!AA$7-1)*50%) -> 7.8995639 | H22: =C$15/36/$L22 -> 2.8298103 | I22: 6.9465682 | J22: =+SUM(F22:I22) -> 38.021917 | L22: 19.5 | N22: 7.7764599
A23: =B23&C23&E23 -> 19.7Clear0 | B23: 19.7 | C23: Clear | D23: 1881 | E23: 0 | F23: =+($C$13/1000*(1-E23)+$C$12/1000*E23)*B23*(1+0.5%) -> 20.758727 | G23: =N23*(1+(Inputs!AA$8/Inputs!AA$7-1)*50%) -> 7.3809198 | H23: =C$15/36/$L23 -> 2.8298103 | I23: 6.9465682 | J23: =+SUM(F23:I23) -> 37.916026 | L23: 19.5 | N23: 7.2658981
A24: =B24&C24&E24 -> 19.7Clear0.25 | B24: 19.7 | C24: Clear | D24: 1881 | E24: 0.25 | F24: =+($C$13/1000*(1-E24)+$C$12/1000*E24)*B24*(1+0.5%) -> 22.644955 | G24: =N24*(1+(Inputs!AA$8/Inputs!AA$7-1)*50%) -> 7.3809198 | H24: =C$15/36/$L24 -> 2.8298103 | I24: 6.9465682 | J24: =+SUM(F24:I24) -> 39.802253 | L24: 19.5 | N24: 7.2658981
A25: =B25&C25&E25 -> 19.7Green0 | B25: 19.7 | C25: Green | D25: 1881 | E25: 0 | F25: =+($C$13/1000*(1-E25)+$C$12/1000*E25)*B25*(1+0.5%) -> 20.758727 | G25: =N25*(1+(Inputs!AA$8/Inputs!AA$7-1)*50%) -> 7.9701014 | H25: =C$15/36/$L25 -> 2.8298103 | I25: 6.9465682 | J25: =+SUM(F25:I25) -> 38.505207 | L25: 19.5 | N25: 7.8458981
A26: =B26&C26&E26 -> 19.7Green0.25 | B26: 19.7 | C26: Green | D26: 1881 | E26: 0.25 | F26: =+($C$13/1000*(1-E26)+$C$12/1000*E26)*B26*(1+0.5%) -> 22.644955 | G26: =N26*(1+(Inputs!AA$8/Inputs!AA$7-1)*50%) -> 7.9701014 | H26: =C$15/36/$L26 -> 2.8298103 | I26: 6.9465682 | J26: =+SUM(F26:I26) -> 40.391435 | L26: 19.5 | N26: 7.8458981
A27: =B27&C27&E27 -> 23.7Clear0 | B27: 23.7 | C27: Clear | D27: 1881 | E27: 0 | F27: =+($C$13/1000*(1-E27)+$C$12/1000*E27)*B27*(1+0.5%) -> 24.973697 | G27: =N27*(1+(Inputs!AA$8/Inputs!AA$7-1)*50%) -> 10.797194 | H27: =C$15/36/$L27 -> 3.4488313 | I27: 6.7284415 | J27: =+SUM(F27:I27) -> 45.948164 | L27: 16 | N27: 10.628934
A28: =B28&C28&E28 -> 23.7Clear0.25 | B28: 23.7 | C28: Clear | D28: 1881 | E28: 0.25 | F28: =+($C$13/1000*(1-E28)+$C$12/1000*E28)*B28*(1+0.5%) -> 27.242915 | G28: =N28*(1+(Inputs!AA$8/Inputs!AA$7-1)*50%) -> 10.797194 | H28: =C$15/36/$L28 -> 3.4488313 | I28: 6.7284415 | J28: =+SUM(F28:I28) -> 48.217382 | L28: 16 | N28: 10.628934
A29: =B29&C29&E29 -> 23.7Green0 | B29: 23.7 | C29: Green | D29: 1881 | E29: 0 | F29: =+($C$13/1000*(1-E29)+$C$12/1000*E29)*B29*(1+0.5%) -> 24.973697 | G29: =N29*(1+(Inputs!AA$8/Inputs!AA$7-1)*50%) -> 11.487958 | H29: =C$15/36/$L29 -> 3.4488313 | I29: 6.7284415 | J29: =+SUM(F29:I29) -> 46.638928 | L29: =L27 -> 16 | N29: 11.308934
A30: =B30&C30&E30 -> 23.7Green0.25 | B30: 23.7 | C30: Green | D30: 1881 | E30: 0.25 | F30: =+($C$13/1000*(1-E30)+$C$12/1000*E30)*B30*(1+0.5%) -> 27.242915 | G30: =N30*(1+(Inputs!AA$8/Inputs!AA$7-1)*50%) -> 11.487958 | H30: =C$15/36/$L30 -> 3.4488313 | I30: 6.7284415 | J30: =+SUM(F30:I30) -> 48.908146 | L30: =L28 -> 16 | N30: 11.308934
A31: =B31&C31&E31 -> 33.7Clear0 | B31: 33.7 | C31: Clear | D31: 1881 | E31: 0 | F31: =+($C$13/1000*(1-E31)+$C$12/1000*E31)*B31*(1+0.5%) -> 35.511122 | G31: =N31*(1+(Inputs!AA$8/Inputs!AA$7-1)*50%) -> 11.055504 | H31: =C$15/36/$L31 -> 4.7983739 | I31: 8.2458124 | J31: =+SUM(F31:I31) -> 59.610813 | L31: 11.5 | N31: 10.883219
A32: =B32&C32&E32 -> 33.7Clear0.25 | B32: 33.7 | C32: Clear | D32: 1881 | E32: 0.25 | F32: =+($C$13/1000*(1-E32)+$C$12/1000*E32)*B32*(1+0.5%) -> 38.737816 | G32: =N32*(1+(Inputs!AA$8/Inputs!AA$7-1)*50%) -> 11.055504 | H32: =C$15/36/$L32 -> 4.7983739 | I32: 8.2458124 | J32: =+SUM(F32:I32) -> 62.837507 | L32: 11.5 | N32: 10.883219
A33: =B33&C33&E33 -> 33.7Green0 | B33: 33.7 | C33: Green | D33: 1881 | E33: 0 | F33: =+($C$13/1000*(1-E33)+$C$12/1000*E33)*B33*(1+0.5%) -> 35.511122 | G33: =N33*(1+(Inputs!AA$8/Inputs!AA$7-1)*50%) -> 12.04086 | H33: =C$15/36/$L33 -> 4.7983739 | I33: 8.2458124 | J33: =+SUM(F33:I33) -> 60.596168 | L33: =L31 -> 11.5 | N33: 11.853219
A34: =B34&C34&E34 -> 33.7Green0.25 | B34: 33.7 | C34: Green | D34: 1881 | E34: 0.25 | F34: =+($C$13/1000*(1-E34)+$C$12/1000*E34)*B34*(1+0.5%) -> 38.737816 | G34: =N34*(1+(Inputs!AA$8/Inputs!AA$7-1)*50%) -> 12.04086 | H34: =C$15/36/$L34 -> 4.7983739 | I34: 8.2458124 | J34: =+SUM(F34:I34) -> 63.822862 | L34: =L32 -> 11.5 | N34: 11.853219
A35: =B35&C35&E35 -> 39.5Clear0 | B35: 39.5 | C35: Clear | D35: 1881 | E35: 0 | F35: =+($C$13/1000*(1-E35)+$C$12/1000*E35)*B35*(1+0.5%) -> 41.622829 | G35: =N35*(1+(Inputs!AA$8/Inputs!AA$7-1)*50%) -> 13.136341 | H35: =C$15/36/$L35 -> 6.5692024 | I35: 10.54588 | J35: =+SUM(F35:I35) -> 71.874253 | L35: 8.4 | N35: 12.931629
A36: =B36&C36&E36 -> 39.5Clear0.25 | B36: 39.5 | C36: Clear | D36: 1881 | E36: 0.25 | F36: =+($C$13/1000*(1-E36)+$C$12/1000*E36)*B36*(1+0.5%) -> 45.404859 | G36: =N36*(1+(Inputs!AA$8/Inputs!AA$7-1)*50%) -> 13.136341 | H36: =C$15/36/$L36 -> 6.5692024 | I36: 10.54588 | J36: =+SUM(F36:I36) -> 75.656283 | L36: 8.4 | N36: 12.931629
A37: =B37&C37&E37 -> 39.5Green0 | B37: 39.5 | C37: Green | D37: 1881 | E37: 0 | F37: =+($C$13/1000*(1-E37)+$C$12/1000*E37)*B37*(1+0.5%) -> 41.622829 | G37: =N37*(1+(Inputs!AA$8/Inputs!AA$7-1)*50%) -> 14.395971 | H37: =C$15/36/$L37 -> 6.5692024 | I37: 10.54588 | J37: =+SUM(F37:I37) -> 73.133883 | L37: =L35 -> 8.4 | N37: 14.171629
A38: =B38&C38&E38 -> 39.5Green0.25 | B38: 39.5 | C38: Green | D38: 1881 | E38: 0.25 | F38: =+($C$13/1000*(1-E38)+$C$12/1000*E38)*B38*(1+0.5%) -> 45.404859 | G38: =N38*(1+(Inputs!AA$8/Inputs!AA$7-1)*50%) -> 14.395971 | H38: =C$15/36/$L38 -> 6.5692024 | I38: 10.54588 | J38: =+SUM(F38:I38) -> 76.915913 | L38: =L36 -> 8.4 | N38: 14.171629
A39: =B39&C39&E39 -> 42.7Green0 | B39: 42.7 | C39: Green | D39: 1881 | E39: 0 | F39: =+($C$13/1000*(1-E39)+$C$12/1000*E39)*B39*(1+0.5%) -> 44.994805 | G39: =N39*(1+(Inputs!AA$8/Inputs!AA$7-1)*50%) -> 14.39742 | H39: =C$15/36/$L39 -> 6.5692024 | I39: 10.54588 | J39: =+SUM(F39:I39) -> 76.507307 | L39: 8.4 | N39: 14.173055
A40: =B40&C40&E40 -> 42.7Green0.25 | B40: 42.7 | C40: Green | D40: 1881 | E40: 0.25 | F40: =+($C$13/1000*(1-E40)+$C$12/1000*E40)*B40*(1+0.5%) -> 49.083227 | G40: =N40*(1+(Inputs!AA$8/Inputs!AA$7-1)*50%) -> 14.39742 | H40: =C$15/36/$L40 -> 6.5692024 | I40: 10.54588 | J40: =+SUM(F40:I40) -> 80.59573 | L40: 8.4 | N40: 14.173055
A41: =B41&C41&E41 -> 42.7Clear0 | B41: 42.7 | C41: Clear | D41: 1881 | E41: 0 | F41: =+($C$13/1000*(1-E41)+$C$12/1000*E41)*B41*(1+0.5%) -> 44.994805 | G41: =N41*(1+(Inputs!AA$8/Inputs!AA$7-1)*50%) -> 13.13779 | H41: =C$15/36/$L41 -> 6.5692024 | I41: 10.54588 | J41: =+SUM(F41:I41) -> 75.247678 | L41: =L39 -> 8.4 | N41: 12.933055
A42: =B42&C42&E42 -> 42.7Clear0.25 | B42: 42.7 | C42: Clear | D42: 1881 | E42: 0.25 | F42: =+($C$13/1000*(1-E42)+$C$12/1000*E42)*B42*(1+0.5%) -> 49.083227 | G42: =N42*(1+(Inputs!AA$8/Inputs!AA$7-1)*50%) -> 13.13779 | H42: =C$15/36/$L42 -> 6.5692024 | I42: 10.54588 | J42: =+SUM(F42:I42) -> 79.3361 | L42: =L40 -> 8.4 | N42: 12.933055
A43: =B43&C43&E43 -> 51.2Clear0 | B43: 51.2 | C43: Clear | D43: 1881 | E43: 0 | F43: =+($C$13/1000*(1-E43)+$C$12/1000*E43)*B43*(1+0.5%) -> 53.951616 | G43: =N43*(1+(Inputs!AA$8/Inputs!AA$7-1)*50%) -> 13.146581 | H43: =C$15/36/$L43 -> 7.4569324 | I43: 7.7723724 | J43: =+SUM(F43:I43) -> 82.327502 | L43: 7.4 | N43: 12.941709
A44: =B44&C44&E44 -> 51.2Clear0.25 | B44: 51.2 | C44: Clear | D44: 1881 | E44: 0.25 | F44: =+($C$13/1000*(1-E44)+$C$12/1000*E44)*B44*(1+0.5%) -> 58.853893 | G44: =N44*(1+(Inputs!AA$8/Inputs!AA$7-1)*50%) -> 13.146581 | H44: =C$15/36/$L44 -> 7.4569324 | I44: 7.7723724 | J44: =+SUM(F44:I44) -> 87.229779 | L44: 7.4 | N44: 12.941709
...

Sheet PreformasBI
A1: País | B1: Cliente | C1: Gramaje | D1: Tipo de resina | E1: Precio de resina USD/Mill | F1: Precio de conversión USD/Mill | G1: Vigencia | H1: Actualización
A2: Panamá | B2: ABI | C2: =PRECIOS!B23 -> 19.7 | D2: CSD | E2: =PRECIOS!F23 -> 20.758727 | F2: =PRECIOS!G23 -> 7.3809198 | G2: 45200 | H2: Mensual
A3: Panamá | B3: ABI | C3: =PRECIOS!B24 -> 19.7 | D3: 25% RPET | E3: =PRECIOS!F24 -> 22.644955 | F3: =PRECIOS!G24 -> 7.3809198 | G3: 45200 | H3: Mensual
A4: Panamá | B4: ABI | C4: =PRECIOS!#REF! -> #REF! | D4: CSD | E4: =PRECIOS!#REF! -> #REF! | F4: =PRECIOS!#REF! -> #REF! | G4: 45200 | H4: Mensual
A5: Panamá | B5: ABI | C5: =PRECIOS!#REF! -> #REF! | D5: 25% RPET | E5: =PRECIOS!#REF! -> #REF! | F5: =PRECIOS!#REF! -> #REF! | G5: 45200 | H5: Mensual
A6: Panamá | B6: ABI | C6: =PRECIOS!B27 -> 23.7 | D6: CSD | E6: =PRECIOS!F27 -> 24.973697 | F6: =PRECIOS!G27 -> 10.797194 | G6: 45200 | H6: Mensual
A7: Panamá | B7: ABI | C7: =PRECIOS!B28 -> 23.7 | D7: 25% RPET | E7: =PRECIOS!F28 -> 27.242915 | F7: =PRECIOS!G28 -> 10.797194 | G7: 45200 | H7: Mensual
A8: Panamá | B8: ABI | C8: =PRECIOS!#REF! -> #REF! | D8: CSD | E8: =PRECIOS!#REF! -> #REF! | F8: =PRECIOS!#REF! -> #REF! | G8: 45200 | H8: Mensual
A9: Panamá | B9: ABI | C9: =PRECIOS!#REF! -> #REF! | D9: 25% RPET | E9: =PRECIOS!#REF! -> #REF! | F9: =PRECIOS!#REF! -> #REF! | G9: 45200 | H9: Mensual
A10: Panamá | B10: ABI | C10: =PRECIOS!#REF! -> #REF! | D10: CSD | E10: =PRECIOS!#REF! -> #REF! | F10: =PRECIOS!#REF! -> #REF! | G10: 45200 | H10: Mensual
A11: Panamá | B11: ABI | C11: =PRECIOS!#REF! -> #REF! | D11: 25% RPET | E11: =PRECIOS!#REF! -> #REF! | F11: =PRECIOS!#REF! -> #REF! | G11: 45200 | H11: Mensual
A12: Panamá | B12: ABI | C12: =PRECIOS!B31 -> 33.7 | D12: CSD | E12: =PRECIOS!F31 -> 35.511122 | F12: =PRECIOS!G31 -> 11.055504 | G12: 45200 | H12: Mensual
A13: Panamá | B13: ABI | C13: =PRECIOS!B32 -> 33.7 | D13: 25% RPET | E13: =PRECIOS!F32 -> 38.737816 | F13: =PRECIOS!G32 -> 11.055504 | G13: 45200 | H13: Mensual
A14: Panamá | B14: ABI | C14: =PRECIOS!B35 -> 39.5 | D14: CSD | E14: =PRECIOS!F35 -> 41.622829 | F14: =PRECIOS!G35 -> 13.136341 | G14: 45200 | H14: Mensual
A15: Panamá | B15: ABI | C15: =PRECIOS!B36 -> 39.5 | D15: 25% RPET | E15: =PRECIOS!F36 -> 45.404859 | F15: =PRECIOS!G36 -> 13.136341 | G15: 45200 | H15: Mensual
A16: Panamá | B16: ABI | C16: =PRECIOS!B41 -> 42.7 | D16: CSD | E16: =PRECIOS!F41 -> 44.994805 | F16: =PRECIOS!G41 -> 13.13779 | G16: 45200 | H16: Mensual
A17: Panamá | B17: ABI | C17: =PRECIOS!B42 -> 42.7 | D17: 25% RPET | E17: =PRECIOS!F42 -> 49.083227 | F17: =PRECIOS!G42 -> 13.13779 | G17: 45200 | H17: Mensual
A18: Panamá | B18: ABI | C18: =PRECIOS!#REF! -> #REF! | D18: CSD | E18: =PRECIOS!#REF! -> #REF! | F18: =PRECIOS!#REF! -> #REF! | G18: 45200 | H18: Mensual
A19: Panamá | B19: ABI | C19: =PRECIOS!#REF! -> #REF! | D19: 25% RPET | E19: =PRECIOS!#REF! -> #REF! | F19: =PRECIOS!#REF! -> #REF! | G19: 45200 | H19: Mensual
A20: Panamá | B20: ABI | C20: =PRECIOS!B43 -> 51.2 | D20: CSD | E20: =PRECIOS!F43 -> 53.951616 | F20: =PRECIOS!G43 -> 13.146581 | G20: 45200 | H20: Mensual
A21: Panamá | B21: ABI | C21: =PRECIOS!B44 -> 51.2 | D21: 25% RPET | E21: =PRECIOS!F44 -> 58.853893 | F21: =PRECIOS!G44 -> 13.146581 | G21: 45200 | H21: Mensual

Sheet Inputs
B2: HOJA DE INPUTS | G2: 1. vPET | K2: 1.2 Fletes Marítimos Internacionales: | O2: 2. Resina Reciclado | T2: 3. Costos Logisticos de Preforma | Z2: 5. IPC
G3: 1.1 Indice de precios de resina | K3: Indices Fletes Maritimos Drewry | T3: Origen | U3: Perú | V3: Lima | Z3: Fuente: | AA3: U.S. BLS
G4: Índice: | K4: Índice: | O4: Inventario Final | P4: Perú | T4: Destino | U4: Panamá | Z4: CPI for All Urban Consumers (CPI-U)
C5: AÑO | D5: MES | G5: ICIS - ASIA SE - Low | K5: Central China (Shanghai) to Peru (Callao) | O5: Mes | P5: Precio Paca | T5: Mes | U5: 2026-2 | Z5: IPC USA
B6: *ACTUALIZAR A LP: | C6: 2026 | D6: 4 | G6: Mes | H6: USD/TM | K6: Mes | L6: Flete (USD/TM) | O6: 2026-2 | P6: 485.17558 | Q6: USD / TM | T6: EXW Referencial | U6: 30000 | Z6: Mes | AA6: IPC | AB6: Inflación acum
G7: 2026-2 | H7: 852.5 | K7: 2026-2 | L7: 55.272727 | T7: Transporte: | U7: Marítimo | Y7: Base | Z7: 2024-6 | AA7: 314.175
C8: PERIODO | D8: MES INICIAL | G8: Promedio FOB | H8: =AVERAGE(H7:H7) -> 852.5 | O8: Scrap | P8: 0.3 | Y8: Actual | Z8: 2025-11 | AA8: 324.122 | AB8: =AA8/AA7-1 -> 0.031660699 | AC8: Actualizar en Ene-26, con CPI Nov-25
C9: =UPPER(C6&"-"&D6) -> 2026-4 | D9: =D6 -> 4 | G9: Flete marítimo | H9: =IF(L7>180,L7+25,161) -> 161 | O9: Conversión | P9: =725*(1+(Inputs!AA$8/Inputs!AA$7-1)*50%) -> 736.477 | Q9: USD / TM | T9: Gastos FOB Callao | U9: 1060 | V9: EXW - FOB
G10: Nacionalización (%) | H10: 35 | O10: Precio rPET | P10: =+P6/(1-P8)+P9 -> 1429.585 | Q10: USD / TM | T10: Flete marítimo | U10: 900 | V10: FOB - CIF
B11: Validez Inicial | C11: =DATE($C$6,$D$6,1) -> 46113 | G11: Precio DDP | H11: =+H8+H9+H10 -> 1048.5 | T11: Seguro | U11: 26.5268
B12: Validez Final | C12: =IF(ISNUMBER($D$6),EOMONTH(C11,0),0) + IF(LEFT($D$6,1)="B",EOMONTH(C11,1),0) + IF(LEFT($D$6,1)="Q",EOMONTH(C11,2),0) + IF(LEFT($D$6,1)="S",EOMONTH(C11,5),0) -> 46142 | O12: Precio rPET ponderado | P12: =+SUMPRODUCT(P10:Q10,P16:Q16) -> 1429.585 | Q12: USD / TM | T12: Arancel PT Preformas | U12: 0
G13: Merma sobre precio DDP | H13: 0.005 | T13: TOTAL | U13: 1986.5268 | V13: USD/Contenedor
P14: PERÚ
O15: Valor Paca | P15: =+P6 -> 485.17558
O16: % | P16: =1-Q16 -> 1
O18: Merma sobre precio DDP | P18: 0.005

Sheet Sheet1
F6: ICIS | G6: Promedio FOB | H6: 852.5 | I6: ICIS Asia Low Index
F7: OF | G7: Flete marítimo | H7: 161 | I7: Constant as per formulae
F8: IT | G8: Tax | H8: 0
G9: Precio CIF | H9: =(H7+H6)*(1+H8) -> 1013.5
F10: Customs Clearance | G10: Nacionalización (%) | H10: 35
G11: Precio DDP | H11: =H9+H10 -> 1048.5
